2025-07-24 12:25:35,305 [INFO] users: Email configuration for tenant proliance: host=smtp.gmail.com, port=587, use_ssl=False, host_user=ekenehanson@gmail.com, host_password=*******************, default_from_email=ekenehanson@gmail.com
2025-07-24 12:25:56,391 [ERROR] users: Failed to send password reset email to admin@prolianceltd.com: [WinError 10060] A connection attempt failed because the connected party did not properly respond after a period of time, or established connection failed because connected host has failed to respond
Traceback (most recent call last):
  File "C:\Users\CPT-003\Desktop\CRM\crm_api\users\views.py", line 165, in post
    email.send(fail_silently=False)
    ~~~~~~~~~~^^^^^^^^^^^^^^^^^^^^^
  File "C:\Users\CPT-003\Desktop\CRM\crm_api\venv\Lib\site-packages\django\core\mail\message.py", line 307, in send
    return self.get_connection(fail_silently).send_messages([self])
           ~~~~~~~~~~~~~~~~~~~~~~~~~~~~~~~~~~~~~~~~~~~~~~~~^^^^^^^^
  File "C:\Users\CPT-003\Desktop\CRM\crm_api\venv\Lib\site-packages\django\core\mail\backends\smtp.py", line 128, in send_messages
    new_conn_created = self.open()
  File "C:\Users\CPT-003\Desktop\CRM\crm_api\venv\Lib\site-packages\django\core\mail\backends\smtp.py", line 86, in open
    self.connection = self.connection_class(
                      ~~~~~~~~~~~~~~~~~~~~~^
        self.host, self.port, **connection_params
        ^^^^^^^^^^^^^^^^^^^^^^^^^^^^^^^^^^^^^^^^^
    )
    ^
  File "C:\Users\CPT-003\AppData\Local\Programs\Python\Python313\Lib\smtplib.py", line 255, in __init__
    (code, msg) = self.connect(host, port)
                  ~~~~~~~~~~~~^^^^^^^^^^^^
  File "C:\Users\CPT-003\AppData\Local\Programs\Python\Python313\Lib\smtplib.py", line 341, in connect
    self.sock = self._get_socket(host, port, self.timeout)
                ~~~~~~~~~~~~~~~~^^^^^^^^^^^^^^^^^^^^^^^^^^
  File "C:\Users\CPT-003\AppData\Local\Programs\Python\Python313\Lib\smtplib.py", line 312, in _get_socket
    return socket.create_connection((host, port), timeout,
           ~~~~~~~~~~~~~~~~~~~~~~~~^^^^^^^^^^^^^^^^^^^^^^^
                                    self.source_address)
                                    ^^^^^^^^^^^^^^^^^^^^
  File "C:\Users\CPT-003\AppData\Local\Programs\Python\Python313\Lib\socket.py", line 864, in create_connection
    raise exceptions[0]
  File "C:\Users\CPT-003\AppData\Local\Programs\Python\Python313\Lib\socket.py", line 849, in create_connection
    sock.connect(sa)
    ~~~~~~~~~~~~^^^^
TimeoutError: [WinError 10060] A connection attempt failed because the connected party did not properly respond after a period of time, or established connection failed because connected host has failed to respond
2025-07-24 12:25:56,400 [ERROR] django.request: Internal Server Error: /api/user/password/reset/
2025-07-24 12:25:56,401 [ERROR] django.server: "POST /api/user/password/reset/ HTTP/1.1" 500 370
2025-07-24 12:26:07,094 [INFO] django.utils.autoreload: C:\Users\CPT-003\Desktop\CRM\crm_api\users\views.py changed, reloading.
2025-07-24 12:26:11,926 [INFO] django.utils.autoreload: Watching for file changes with StatReloader
2025-07-24 12:26:30,501 [INFO] users: Email configuration for tenant proliance: host=smtp.gmail.com, port=587, use_ssl=False, host_user=ekenehanson@gmail.com, host_password=*******************, default_from_email=ekenehanson@gmail.com
2025-07-24 12:26:51,538 [ERROR] users: Failed to send password reset email to admin@prolianceltd.com: [WinError 10060] A connection attempt failed because the connected party did not properly respond after a period of time, or established connection failed because connected host has failed to respond
Traceback (most recent call last):
  File "C:\Users\CPT-003\Desktop\CRM\crm_api\users\views.py", line 167, in post
    email.send(fail_silently=False)
    ~~~~~~~~~~^^^^^^^^^^^^^^^^^^^^^
  File "C:\Users\CPT-003\Desktop\CRM\crm_api\venv\Lib\site-packages\django\core\mail\message.py", line 307, in send
    return self.get_connection(fail_silently).send_messages([self])
           ~~~~~~~~~~~~~~~~~~~~~~~~~~~~~~~~~~~~~~~~~~~~~~~~^^^^^^^^
  File "C:\Users\CPT-003\Desktop\CRM\crm_api\venv\Lib\site-packages\django\core\mail\backends\smtp.py", line 128, in send_messages
    new_conn_created = self.open()
  File "C:\Users\CPT-003\Desktop\CRM\crm_api\venv\Lib\site-packages\django\core\mail\backends\smtp.py", line 86, in open
    self.connection = self.connection_class(
                      ~~~~~~~~~~~~~~~~~~~~~^
        self.host, self.port, **connection_params
        ^^^^^^^^^^^^^^^^^^^^^^^^^^^^^^^^^^^^^^^^^
    )
    ^
  File "C:\Users\CPT-003\AppData\Local\Programs\Python\Python313\Lib\smtplib.py", line 255, in __init__
    (code, msg) = self.connect(host, port)
                  ~~~~~~~~~~~~^^^^^^^^^^^^
  File "C:\Users\CPT-003\AppData\Local\Programs\Python\Python313\Lib\smtplib.py", line 341, in connect
    self.sock = self._get_socket(host, port, self.timeout)
                ~~~~~~~~~~~~~~~~^^^^^^^^^^^^^^^^^^^^^^^^^^
  File "C:\Users\CPT-003\AppData\Local\Programs\Python\Python313\Lib\smtplib.py", line 312, in _get_socket
    return socket.create_connection((host, port), timeout,
           ~~~~~~~~~~~~~~~~~~~~~~~~^^^^^^^^^^^^^^^^^^^^^^^
                                    self.source_address)
                                    ^^^^^^^^^^^^^^^^^^^^
  File "C:\Users\CPT-003\AppData\Local\Programs\Python\Python313\Lib\socket.py", line 864, in create_connection
    raise exceptions[0]
  File "C:\Users\CPT-003\AppData\Local\Programs\Python\Python313\Lib\socket.py", line 849, in create_connection
    sock.connect(sa)
    ~~~~~~~~~~~~^^^^
TimeoutError: [WinError 10060] A connection attempt failed because the connected party did not properly respond after a period of time, or established connection failed because connected host has failed to respond
2025-07-24 12:26:51,547 [ERROR] django.request: Internal Server Error: /api/user/password/reset/
2025-07-24 12:26:51,547 [ERROR] django.server: "POST /api/user/password/reset/ HTTP/1.1" 500 370
2025-07-24 12:31:21,388 [INFO] django.utils.autoreload: C:\Users\CPT-003\Desktop\CRM\crm_api\users\views.py changed, reloading.
2025-07-24 12:31:25,410 [INFO] django.utils.autoreload: Watching for file changes with StatReloader
2025-07-24 12:31:45,243 [INFO] django.utils.autoreload: C:\Users\CPT-003\Desktop\CRM\crm_api\users\views.py changed, reloading.
2025-07-24 12:31:49,379 [INFO] django.utils.autoreload: Watching for file changes with StatReloader
2025-07-24 12:32:31,919 [INFO] django.utils.autoreload: C:\Users\CPT-003\Desktop\CRM\crm_api\users\views.py changed, reloading.
2025-07-24 12:32:35,987 [INFO] django.utils.autoreload: Watching for file changes with StatReloader
2025-07-24 12:32:39,830 [INFO] django.utils.autoreload: C:\Users\CPT-003\Desktop\CRM\crm_api\users\views.py changed, reloading.
2025-07-24 12:32:43,349 [INFO] django.utils.autoreload: Watching for file changes with StatReloader
2025-07-24 12:32:57,067 [INFO] django.utils.autoreload: C:\Users\CPT-003\Desktop\CRM\crm_api\users\views.py changed, reloading.
2025-07-24 12:33:01,116 [INFO] django.utils.autoreload: Watching for file changes with StatReloader
2025-07-24 12:33:13,030 [INFO] users: Email configuration for tenant proliance user admin@prolianceltd.com: host=smtp.gmail.com, port=587, use_ssl=False, host_user=ekenehanson@gmail.com, host_password=*******************, default_from_email=ekenehanson@gmail.com
2025-07-24 12:33:34,118 [ERROR] users: Failed to send password reset email to admin@prolianceltd.com: [WinError 10060] A connection attempt failed because the connected party did not properly respond after a period of time, or established connection failed because connected host has failed to respond
Traceback (most recent call last):
  File "C:\Users\CPT-003\Desktop\CRM\crm_api\users\views.py", line 170, in post
    email.send(fail_silently=False)
    ~~~~~~~~~~^^^^^^^^^^^^^^^^^^^^^
  File "C:\Users\CPT-003\Desktop\CRM\crm_api\venv\Lib\site-packages\django\core\mail\message.py", line 307, in send
    return self.get_connection(fail_silently).send_messages([self])
           ~~~~~~~~~~~~~~~~~~~~~~~~~~~~~~~~~~~~~~~~~~~~~~~~^^^^^^^^
  File "C:\Users\CPT-003\Desktop\CRM\crm_api\venv\Lib\site-packages\django\core\mail\backends\smtp.py", line 128, in send_messages
    new_conn_created = self.open()
  File "C:\Users\CPT-003\Desktop\CRM\crm_api\venv\Lib\site-packages\django\core\mail\backends\smtp.py", line 86, in open
    self.connection = self.connection_class(
                      ~~~~~~~~~~~~~~~~~~~~~^
        self.host, self.port, **connection_params
        ^^^^^^^^^^^^^^^^^^^^^^^^^^^^^^^^^^^^^^^^^
    )
    ^
  File "C:\Users\CPT-003\AppData\Local\Programs\Python\Python313\Lib\smtplib.py", line 255, in __init__
    (code, msg) = self.connect(host, port)
                  ~~~~~~~~~~~~^^^^^^^^^^^^
  File "C:\Users\CPT-003\AppData\Local\Programs\Python\Python313\Lib\smtplib.py", line 341, in connect
    self.sock = self._get_socket(host, port, self.timeout)
                ~~~~~~~~~~~~~~~~^^^^^^^^^^^^^^^^^^^^^^^^^^
  File "C:\Users\CPT-003\AppData\Local\Programs\Python\Python313\Lib\smtplib.py", line 312, in _get_socket
    return socket.create_connection((host, port), timeout,
           ~~~~~~~~~~~~~~~~~~~~~~~~^^^^^^^^^^^^^^^^^^^^^^^
                                    self.source_address)
                                    ^^^^^^^^^^^^^^^^^^^^
  File "C:\Users\CPT-003\AppData\Local\Programs\Python\Python313\Lib\socket.py", line 864, in create_connection
    raise exceptions[0]
  File "C:\Users\CPT-003\AppData\Local\Programs\Python\Python313\Lib\socket.py", line 849, in create_connection
    sock.connect(sa)
    ~~~~~~~~~~~~^^^^
TimeoutError: [WinError 10060] A connection attempt failed because the connected party did not properly respond after a period of time, or established connection failed because connected host has failed to respond
2025-07-24 12:33:34,131 [ERROR] django.request: Internal Server Error: /api/user/password/reset/
2025-07-24 12:33:34,132 [ERROR] django.server: "POST /api/user/password/reset/ HTTP/1.1" 500 370
2025-07-24 12:34:24,013 [INFO] django.utils.autoreload: C:\Users\CPT-003\Desktop\CRM\crm_api\users\views.py changed, reloading.
2025-07-24 12:34:27,521 [INFO] django.utils.autoreload: Watching for file changes with StatReloader
2025-07-24 12:34:39,933 [INFO] users: Email configuration for tenant proliance user admin@prolianceltd.com: host=smtp.gmail.com, port=587, use_ssl=False, host_user=ekenehanson@gmail.com, host_password=*******************, default_from_email=ekenehanson@gmail.com
2025-07-24 12:35:01,027 [ERROR] users: Failed to send password reset email to admin@prolianceltd.com: [WinError 10060] A connection attempt failed because the connected party did not properly respond after a period of time, or established connection failed because connected host has failed to respond
Traceback (most recent call last):
  File "C:\Users\CPT-003\Desktop\CRM\crm_api\users\views.py", line 172, in post
    email.send(fail_silently=False)
    ~~~~~~~~~~^^^^^^^^^^^^^^^^^^^^^
  File "C:\Users\CPT-003\Desktop\CRM\crm_api\venv\Lib\site-packages\django\core\mail\message.py", line 307, in send
    return self.get_connection(fail_silently).send_messages([self])
           ~~~~~~~~~~~~~~~~~~~~~~~~~~~~~~~~~~~~~~~~~~~~~~~~^^^^^^^^
  File "C:\Users\CPT-003\Desktop\CRM\crm_api\venv\Lib\site-packages\django\core\mail\backends\smtp.py", line 128, in send_messages
    new_conn_created = self.open()
  File "C:\Users\CPT-003\Desktop\CRM\crm_api\venv\Lib\site-packages\django\core\mail\backends\smtp.py", line 86, in open
    self.connection = self.connection_class(
                      ~~~~~~~~~~~~~~~~~~~~~^
        self.host, self.port, **connection_params
        ^^^^^^^^^^^^^^^^^^^^^^^^^^^^^^^^^^^^^^^^^
    )
    ^
  File "C:\Users\CPT-003\AppData\Local\Programs\Python\Python313\Lib\smtplib.py", line 255, in __init__
    (code, msg) = self.connect(host, port)
                  ~~~~~~~~~~~~^^^^^^^^^^^^
  File "C:\Users\CPT-003\AppData\Local\Programs\Python\Python313\Lib\smtplib.py", line 341, in connect
    self.sock = self._get_socket(host, port, self.timeout)
                ~~~~~~~~~~~~~~~~^^^^^^^^^^^^^^^^^^^^^^^^^^
  File "C:\Users\CPT-003\AppData\Local\Programs\Python\Python313\Lib\smtplib.py", line 312, in _get_socket
    return socket.create_connection((host, port), timeout,
           ~~~~~~~~~~~~~~~~~~~~~~~~^^^^^^^^^^^^^^^^^^^^^^^
                                    self.source_address)
                                    ^^^^^^^^^^^^^^^^^^^^
  File "C:\Users\CPT-003\AppData\Local\Programs\Python\Python313\Lib\socket.py", line 864, in create_connection
    raise exceptions[0]
  File "C:\Users\CPT-003\AppData\Local\Programs\Python\Python313\Lib\socket.py", line 849, in create_connection
    sock.connect(sa)
    ~~~~~~~~~~~~^^^^
TimeoutError: [WinError 10060] A connection attempt failed because the connected party did not properly respond after a period of time, or established connection failed because connected host has failed to respond
2025-07-24 12:35:01,036 [ERROR] django.request: Internal Server Error: /api/user/password/reset/
2025-07-24 12:35:01,037 [ERROR] django.server: "POST /api/user/password/reset/ HTTP/1.1" 500 370
2025-07-24 12:35:03,956 [INFO] django.utils.autoreload: C:\Users\CPT-003\Desktop\CRM\crm_api\users\views.py changed, reloading.
2025-07-24 12:35:08,349 [INFO] django.utils.autoreload: Watching for file changes with StatReloader
2025-07-24 12:35:37,463 [INFO] django.utils.autoreload: C:\Users\CPT-003\Desktop\CRM\crm_api\users\views.py changed, reloading.
2025-07-24 12:35:41,095 [INFO] django.utils.autoreload: Watching for file changes with StatReloader
2025-07-24 12:36:04,329 [INFO] users: Email configuration for tenant proliance user admin@prolianceltd.com: host=smtp.gmail.com, port=587, use_ssl=False, host_user=ekenehanson@gmail.com, host_password=*******************, default_from_email=ekenehanson@gmail.com
2025-07-24 12:36:25,362 [ERROR] users: Failed to send password reset email to admin@prolianceltd.com: [WinError 10060] A connection attempt failed because the connected party did not properly respond after a period of time, or established connection failed because connected host has failed to respond
Traceback (most recent call last):
  File "C:\Users\CPT-003\Desktop\CRM\crm_api\users\views.py", line 173, in post
    email.send(fail_silently=False)
    ~~~~~~~~~~^^^^^^^^^^^^^^^^^^^^^
  File "C:\Users\CPT-003\Desktop\CRM\crm_api\venv\Lib\site-packages\django\core\mail\message.py", line 307, in send
    return self.get_connection(fail_silently).send_messages([self])
           ~~~~~~~~~~~~~~~~~~~~~~~~~~~~~~~~~~~~~~~~~~~~~~~~^^^^^^^^
  File "C:\Users\CPT-003\Desktop\CRM\crm_api\venv\Lib\site-packages\django\core\mail\backends\smtp.py", line 128, in send_messages
    new_conn_created = self.open()
  File "C:\Users\CPT-003\Desktop\CRM\crm_api\venv\Lib\site-packages\django\core\mail\backends\smtp.py", line 86, in open
    self.connection = self.connection_class(
                      ~~~~~~~~~~~~~~~~~~~~~^
        self.host, self.port, **connection_params
        ^^^^^^^^^^^^^^^^^^^^^^^^^^^^^^^^^^^^^^^^^
    )
    ^
  File "C:\Users\CPT-003\AppData\Local\Programs\Python\Python313\Lib\smtplib.py", line 255, in __init__
    (code, msg) = self.connect(host, port)
                  ~~~~~~~~~~~~^^^^^^^^^^^^
  File "C:\Users\CPT-003\AppData\Local\Programs\Python\Python313\Lib\smtplib.py", line 341, in connect
    self.sock = self._get_socket(host, port, self.timeout)
                ~~~~~~~~~~~~~~~~^^^^^^^^^^^^^^^^^^^^^^^^^^
  File "C:\Users\CPT-003\AppData\Local\Programs\Python\Python313\Lib\smtplib.py", line 312, in _get_socket
    return socket.create_connection((host, port), timeout,
           ~~~~~~~~~~~~~~~~~~~~~~~~^^^^^^^^^^^^^^^^^^^^^^^
                                    self.source_address)
                                    ^^^^^^^^^^^^^^^^^^^^
  File "C:\Users\CPT-003\AppData\Local\Programs\Python\Python313\Lib\socket.py", line 864, in create_connection
    raise exceptions[0]
  File "C:\Users\CPT-003\AppData\Local\Programs\Python\Python313\Lib\socket.py", line 849, in create_connection
    sock.connect(sa)
    ~~~~~~~~~~~~^^^^
TimeoutError: [WinError 10060] A connection attempt failed because the connected party did not properly respond after a period of time, or established connection failed because connected host has failed to respond
2025-07-24 12:36:25,389 [ERROR] django.request: Internal Server Error: /api/user/password/reset/
2025-07-24 12:36:25,389 [ERROR] django.server: "POST /api/user/password/reset/ HTTP/1.1" 500 370
2025-07-24 12:36:35,105 [INFO] django.utils.autoreload: C:\Users\CPT-003\Desktop\CRM\crm_api\users\views.py changed, reloading.
2025-07-24 12:36:38,520 [INFO] django.utils.autoreload: Watching for file changes with StatReloader
2025-07-24 12:36:52,764 [INFO] django.utils.autoreload: C:\Users\CPT-003\Desktop\CRM\crm_api\users\views.py changed, reloading.
2025-07-24 12:36:56,625 [INFO] django.utils.autoreload: Watching for file changes with StatReloader
2025-07-24 12:37:13,203 [INFO] django.utils.autoreload: C:\Users\CPT-003\Desktop\CRM\crm_api\users\views.py changed, reloading.
2025-07-24 12:37:16,868 [INFO] django.utils.autoreload: Watching for file changes with StatReloader
2025-07-24 12:37:55,748 [ERROR] users: Failed to send password reset email to admin@prolianceltd.com: [WinError 10060] A connection attempt failed because the connected party did not properly respond after a period of time, or established connection failed because connected host has failed to respond
Traceback (most recent call last):
  File "C:\Users\CPT-003\Desktop\CRM\crm_api\users\views.py", line 175, in post
    email.send(fail_silently=False)
    ~~~~~~~~~~^^^^^^^^^^^^^^^^^^^^^
  File "C:\Users\CPT-003\Desktop\CRM\crm_api\venv\Lib\site-packages\django\core\mail\message.py", line 307, in send
    return self.get_connection(fail_silently).send_messages([self])
           ~~~~~~~~~~~~~~~~~~~~~~~~~~~~~~~~~~~~~~~~~~~~~~~~^^^^^^^^
  File "C:\Users\CPT-003\Desktop\CRM\crm_api\venv\Lib\site-packages\django\core\mail\backends\smtp.py", line 128, in send_messages
    new_conn_created = self.open()
  File "C:\Users\CPT-003\Desktop\CRM\crm_api\venv\Lib\site-packages\django\core\mail\backends\smtp.py", line 86, in open
    self.connection = self.connection_class(
                      ~~~~~~~~~~~~~~~~~~~~~^
        self.host, self.port, **connection_params
        ^^^^^^^^^^^^^^^^^^^^^^^^^^^^^^^^^^^^^^^^^
    )
    ^
  File "C:\Users\CPT-003\AppData\Local\Programs\Python\Python313\Lib\smtplib.py", line 255, in __init__
    (code, msg) = self.connect(host, port)
                  ~~~~~~~~~~~~^^^^^^^^^^^^
  File "C:\Users\CPT-003\AppData\Local\Programs\Python\Python313\Lib\smtplib.py", line 341, in connect
    self.sock = self._get_socket(host, port, self.timeout)
                ~~~~~~~~~~~~~~~~^^^^^^^^^^^^^^^^^^^^^^^^^^
  File "C:\Users\CPT-003\AppData\Local\Programs\Python\Python313\Lib\smtplib.py", line 312, in _get_socket
    return socket.create_connection((host, port), timeout,
           ~~~~~~~~~~~~~~~~~~~~~~~~^^^^^^^^^^^^^^^^^^^^^^^
                                    self.source_address)
                                    ^^^^^^^^^^^^^^^^^^^^
  File "C:\Users\CPT-003\AppData\Local\Programs\Python\Python313\Lib\socket.py", line 864, in create_connection
    raise exceptions[0]
  File "C:\Users\CPT-003\AppData\Local\Programs\Python\Python313\Lib\socket.py", line 849, in create_connection
    sock.connect(sa)
    ~~~~~~~~~~~~^^^^
TimeoutError: [WinError 10060] A connection attempt failed because the connected party did not properly respond after a period of time, or established connection failed because connected host has failed to respond
2025-07-24 12:37:55,771 [ERROR] django.request: Internal Server Error: /api/user/password/reset/
2025-07-24 12:37:55,771 [ERROR] django.server: "POST /api/user/password/reset/ HTTP/1.1" 500 370
2025-07-24 12:38:13,006 [INFO] django.utils.autoreload: C:\Users\CPT-003\Desktop\CRM\crm_api\lumina_care\settings.py changed, reloading.
2025-07-24 12:38:20,543 [INFO] django.utils.autoreload: Watching for file changes with StatReloader
2025-07-24 12:41:44,680 [INFO] django.utils.autoreload: C:\Users\CPT-003\Desktop\CRM\crm_api\lumina_care\settings.py changed, reloading.
2025-07-24 12:41:54,656 [INFO] django.utils.autoreload: Watching for file changes with StatReloader
2025-07-24 12:42:29,011 [ERROR] users: Failed to send password reset email to admin@prolianceltd.com: [WinError 10060] A connection attempt failed because the connected party did not properly respond after a period of time, or established connection failed because connected host has failed to respond
Traceback (most recent call last):
  File "C:\Users\CPT-003\Desktop\CRM\crm_api\users\views.py", line 175, in post
    email.send(fail_silently=False)
    ~~~~~~~~~~^^^^^^^^^^^^^^^^^^^^^
  File "C:\Users\CPT-003\Desktop\CRM\crm_api\venv\Lib\site-packages\django\core\mail\message.py", line 307, in send
    return self.get_connection(fail_silently).send_messages([self])
           ~~~~~~~~~~~~~~~~~~~~~~~~~~~~~~~~~~~~~~~~~~~~~~~~^^^^^^^^
  File "C:\Users\CPT-003\Desktop\CRM\crm_api\venv\Lib\site-packages\django\core\mail\backends\smtp.py", line 128, in send_messages
    new_conn_created = self.open()
  File "C:\Users\CPT-003\Desktop\CRM\crm_api\venv\Lib\site-packages\django\core\mail\backends\smtp.py", line 86, in open
    self.connection = self.connection_class(
                      ~~~~~~~~~~~~~~~~~~~~~^
        self.host, self.port, **connection_params
        ^^^^^^^^^^^^^^^^^^^^^^^^^^^^^^^^^^^^^^^^^
    )
    ^
  File "C:\Users\CPT-003\AppData\Local\Programs\Python\Python313\Lib\smtplib.py", line 255, in __init__
    (code, msg) = self.connect(host, port)
                  ~~~~~~~~~~~~^^^^^^^^^^^^
  File "C:\Users\CPT-003\AppData\Local\Programs\Python\Python313\Lib\smtplib.py", line 341, in connect
    self.sock = self._get_socket(host, port, self.timeout)
                ~~~~~~~~~~~~~~~~^^^^^^^^^^^^^^^^^^^^^^^^^^
  File "C:\Users\CPT-003\AppData\Local\Programs\Python\Python313\Lib\smtplib.py", line 312, in _get_socket
    return socket.create_connection((host, port), timeout,
           ~~~~~~~~~~~~~~~~~~~~~~~~^^^^^^^^^^^^^^^^^^^^^^^
                                    self.source_address)
                                    ^^^^^^^^^^^^^^^^^^^^
  File "C:\Users\CPT-003\AppData\Local\Programs\Python\Python313\Lib\socket.py", line 864, in create_connection
    raise exceptions[0]
  File "C:\Users\CPT-003\AppData\Local\Programs\Python\Python313\Lib\socket.py", line 849, in create_connection
    sock.connect(sa)
    ~~~~~~~~~~~~^^^^
TimeoutError: [WinError 10060] A connection attempt failed because the connected party did not properly respond after a period of time, or established connection failed because connected host has failed to respond
2025-07-24 12:42:29,019 [ERROR] django.request: Internal Server Error: /api/user/password/reset/
2025-07-24 12:42:29,020 [ERROR] django.server: "POST /api/user/password/reset/ HTTP/1.1" 500 370
2025-07-24 12:48:46,416 [INFO] django.utils.autoreload: C:\Users\CPT-003\Desktop\CRM\crm_api\users\views.py changed, reloading.
2025-07-24 12:48:49,509 [INFO] django.utils.autoreload: Watching for file changes with StatReloader
2025-07-24 12:50:11,488 [ERROR] users: Failed to send password reset email to admin@prolianceltd.com: [WinError 10060] A connection attempt failed because the connected party did not properly respond after a period of time, or established connection failed because connected host has failed to respond
Traceback (most recent call last):
  File "C:\Users\CPT-003\Desktop\CRM\crm_api\users\views.py", line 177, in post
    email.send(fail_silently=False)
    ~~~~~~~~~~^^^^^^^^^^^^^^^^^^^^^
  File "C:\Users\CPT-003\Desktop\CRM\crm_api\venv\Lib\site-packages\django\core\mail\message.py", line 307, in send
    return self.get_connection(fail_silently).send_messages([self])
           ~~~~~~~~~~~~~~~~~~~~~~~~~~~~~~~~~~~~~~~~~~~~~~~~^^^^^^^^
  File "C:\Users\CPT-003\Desktop\CRM\crm_api\venv\Lib\site-packages\django\core\mail\backends\smtp.py", line 128, in send_messages
    new_conn_created = self.open()
  File "C:\Users\CPT-003\Desktop\CRM\crm_api\venv\Lib\site-packages\django\core\mail\backends\smtp.py", line 86, in open
    self.connection = self.connection_class(
                      ~~~~~~~~~~~~~~~~~~~~~^
        self.host, self.port, **connection_params
        ^^^^^^^^^^^^^^^^^^^^^^^^^^^^^^^^^^^^^^^^^
    )
    ^
  File "C:\Users\CPT-003\AppData\Local\Programs\Python\Python313\Lib\smtplib.py", line 255, in __init__
    (code, msg) = self.connect(host, port)
                  ~~~~~~~~~~~~^^^^^^^^^^^^
  File "C:\Users\CPT-003\AppData\Local\Programs\Python\Python313\Lib\smtplib.py", line 341, in connect
    self.sock = self._get_socket(host, port, self.timeout)
                ~~~~~~~~~~~~~~~~^^^^^^^^^^^^^^^^^^^^^^^^^^
  File "C:\Users\CPT-003\AppData\Local\Programs\Python\Python313\Lib\smtplib.py", line 312, in _get_socket
    return socket.create_connection((host, port), timeout,
           ~~~~~~~~~~~~~~~~~~~~~~~~^^^^^^^^^^^^^^^^^^^^^^^
                                    self.source_address)
                                    ^^^^^^^^^^^^^^^^^^^^
  File "C:\Users\CPT-003\AppData\Local\Programs\Python\Python313\Lib\socket.py", line 864, in create_connection
    raise exceptions[0]
  File "C:\Users\CPT-003\AppData\Local\Programs\Python\Python313\Lib\socket.py", line 849, in create_connection
    sock.connect(sa)
    ~~~~~~~~~~~~^^^^
TimeoutError: [WinError 10060] A connection attempt failed because the connected party did not properly respond after a period of time, or established connection failed because connected host has failed to respond
2025-07-24 12:50:11,498 [ERROR] django.request: Internal Server Error: /api/user/password/reset/
2025-07-24 12:50:11,499 [ERROR] django.server: "POST /api/user/password/reset/ HTTP/1.1" 500 370
2025-07-24 12:50:24,696 [WARNING] django.request: Bad Request: /api/user/password/reset/confirm/
2025-07-24 12:50:24,697 [WARNING] django.server: "POST /api/user/password/reset/confirm/ HTTP/1.1" 400 30
2025-07-24 12:51:38,017 [INFO] django.utils.autoreload: C:\Users\CPT-003\Desktop\CRM\crm_api\users\models.py changed, reloading.
2025-07-24 12:51:40,961 [INFO] django.utils.autoreload: Watching for file changes with StatReloader
2025-07-24 12:51:53,794 [INFO] django.utils.autoreload: C:\Users\CPT-003\Desktop\CRM\crm_api\users\models.py changed, reloading.
2025-07-24 12:51:57,667 [INFO] django.utils.autoreload: Watching for file changes with StatReloader
2025-07-24 12:56:57,032 [INFO] django.utils.autoreload: C:\Users\CPT-003\Desktop\CRM\crm_api\users\views.py changed, reloading.
2025-07-24 12:57:00,224 [INFO] django.utils.autoreload: Watching for file changes with StatReloader
2025-07-24 13:01:35,844 [INFO] django.utils.autoreload: C:\Users\CPT-003\Desktop\CRM\crm_api\users\views.py changed, reloading.
2025-07-24 13:01:38,971 [INFO] django.utils.autoreload: Watching for file changes with StatReloader
2025-07-24 13:01:57,988 [INFO] django.utils.autoreload: C:\Users\CPT-003\Desktop\CRM\crm_api\users\views.py changed, reloading.
2025-07-24 13:02:00,927 [INFO] django.utils.autoreload: Watching for file changes with StatReloader
2025-07-24 13:02:29,731 [INFO] django.utils.autoreload: C:\Users\CPT-003\Desktop\CRM\crm_api\lumina_care\settings.py changed, reloading.
2025-07-24 13:02:32,793 [INFO] django.utils.autoreload: Watching for file changes with StatReloader
2025-07-24 13:05:02,028 [INFO] django.utils.autoreload: C:\Users\CPT-003\Desktop\CRM\crm_api\users\views.py changed, reloading.
2025-07-24 13:05:05,657 [INFO] django.utils.autoreload: Watching for file changes with StatReloader
2025-07-24 13:08:16,726 [INFO] django.utils.autoreload: C:\Users\CPT-003\Desktop\CRM\crm_api\lumina_care\middleware.py changed, reloading.
2025-07-24 13:08:20,139 [INFO] django.utils.autoreload: Watching for file changes with StatReloader
2025-07-24 13:08:46,322 [INFO] django.utils.autoreload: C:\Users\CPT-003\Desktop\CRM\crm_api\lumina_care\middleware.py changed, reloading.
2025-07-24 13:08:50,181 [INFO] django.utils.autoreload: Watching for file changes with StatReloader
2025-07-24 13:11:21,053 [INFO] django.utils.autoreload: Watching for file changes with StatReloader
2025-07-24 13:12:47,090 [INFO] django.server: "OPTIONS /api/token/ HTTP/1.1" 200 0
2025-07-24 13:12:48,244 [INFO] django.server: "POST /api/token/ HTTP/1.1" 200 965
2025-07-24 13:12:48,284 [INFO] django.server: "OPTIONS /api/token/validate/ HTTP/1.1" 200 0
2025-07-24 13:12:48,290 [INFO] django.server: "OPTIONS /api/token/validate/ HTTP/1.1" 200 0
2025-07-24 13:12:48,308 [INFO] django.server: "GET /api/token/validate/ HTTP/1.1" 200 389
2025-07-24 13:12:48,397 [INFO] django.server: "GET /api/token/validate/ HTTP/1.1" 200 389
2025-07-24 13:12:48,623 [INFO] django.server: "OPTIONS /api/user/tenant-users/ HTTP/1.1" 200 0
2025-07-24 13:12:48,623 [INFO] django.server: "OPTIONS /api/user/tenant-users/ HTTP/1.1" 200 0
2025-07-24 13:12:48,645 [INFO] users: Retrieved 3 users for tenant proliance
2025-07-24 13:12:48,658 [INFO] django.server: "GET /api/user/tenant-users/ HTTP/1.1" 200 1022
2025-07-24 13:12:48,668 [INFO] users: Retrieved 3 users for tenant proliance
2025-07-24 13:12:48,681 [INFO] django.server: "GET /api/user/tenant-users/ HTTP/1.1" 200 1022
2025-07-24 13:13:24,452 [INFO] django.utils.autoreload: C:\Users\CPT-003\Desktop\CRM\crm_api\lumina_care\settings.py changed, reloading.
2025-07-24 13:13:28,434 [INFO] django.utils.autoreload: Watching for file changes with StatReloader
2025-07-24 13:14:01,997 [INFO] django.utils.autoreload: C:\Users\CPT-003\Desktop\CRM\crm_api\job_application\views.py changed, reloading.
2025-07-24 13:14:05,997 [INFO] django.utils.autoreload: Watching for file changes with StatReloader
2025-07-24 13:18:03,573 [INFO] django.utils.autoreload: C:\Users\CPT-003\Desktop\CRM\crm_api\job_application\views.py changed, reloading.
2025-07-24 13:18:07,874 [INFO] django.utils.autoreload: Watching for file changes with StatReloader
2025-07-24 13:19:23,021 [INFO] django.utils.autoreload: C:\Users\CPT-003\Desktop\CRM\crm_api\job_application\views.py changed, reloading.
2025-07-24 13:19:27,848 [INFO] django.utils.autoreload: Watching for file changes with StatReloader
2025-07-24 13:23:27,508 [INFO] django.utils.autoreload: C:\Users\CPT-003\Desktop\CRM\crm_api\lumina_care\settings.py changed, reloading.
2025-07-24 13:23:30,907 [INFO] django.utils.autoreload: Watching for file changes with StatReloader
2025-07-24 13:30:08,523 [INFO] django.utils.autoreload: C:\Users\CPT-003\Desktop\CRM\crm_api\lumina_care\settings.py changed, reloading.
2025-07-24 13:30:12,136 [INFO] django.utils.autoreload: Watching for file changes with StatReloader
2025-07-24 13:33:46,765 [INFO] django.utils.autoreload: C:\Users\CPT-003\Desktop\CRM\crm_api\lumina_care\settings.py changed, reloading.
2025-07-24 13:33:50,303 [INFO] django.utils.autoreload: Watching for file changes with StatReloader
2025-07-24 13:34:32,426 [INFO] django.server: "POST /api/token/ HTTP/1.1" 200 965
2025-07-24 13:34:32,467 [INFO] django.server: "GET /api/token/validate/ HTTP/1.1" 200 389
2025-07-24 13:34:32,550 [INFO] django.server: "GET /api/token/validate/ HTTP/1.1" 200 389
2025-07-24 13:34:32,567 [INFO] users: Retrieved 3 users for tenant proliance
2025-07-24 13:34:32,581 [INFO] django.server: "GET /api/user/tenant-users/ HTTP/1.1" 200 1022
2025-07-24 13:34:32,593 [INFO] users: Retrieved 3 users for tenant proliance
2025-07-24 13:34:32,613 [INFO] django.server: "GET /api/user/tenant-users/ HTTP/1.1" 200 1022
2025-07-24 13:34:36,023 [INFO] django.server: "OPTIONS /api/talent-engine/requisitions/ HTTP/1.1" 200 0
2025-07-24 13:34:36,026 [INFO] django.server: "OPTIONS /api/talent-engine/requisitions/ HTTP/1.1" 200 0
2025-07-24 13:34:36,147 [INFO] django.server: "GET /api/talent-engine/requisitions/ HTTP/1.1" 200 6330
2025-07-24 13:34:36,198 [INFO] django.server: "GET /api/talent-engine/requisitions/ HTTP/1.1" 200 6330
2025-07-24 13:34:39,308 [INFO] django.server: "GET /api/talent-engine/requisitions/ HTTP/1.1" 200 6330
2025-07-24 13:34:39,334 [INFO] django.server: "GET /api/talent-engine/requisitions/ HTTP/1.1" 200 6330
2025-07-24 13:34:42,966 [INFO] django.server: "OPTIONS /api/talent-engine-job-applications/applications/job-requisitions/PRO-0001/applications/ HTTP/1.1" 200 0
2025-07-24 13:34:42,967 [INFO] django.server: "OPTIONS /api/talent-engine-job-applications/applications/job-requisitions/PRO-0001/applications/ HTTP/1.1" 200 0
2025-07-24 13:34:48,978 [INFO] django.server: "GET /api/talent-engine-job-applications/applications/job-requisitions/PRO-0001/applications/ HTTP/1.1" 200 5674185
2025-07-24 13:34:55,126 [INFO] django.server: "GET /api/talent-engine-job-applications/applications/job-requisitions/PRO-0001/applications/ HTTP/1.1" 200 5674185
2025-07-24 13:41:19,780 [INFO] django.utils.autoreload: C:\Users\CPT-003\Desktop\CRM\crm_api\users\views.py changed, reloading.
2025-07-24 13:41:23,295 [INFO] django.utils.autoreload: Watching for file changes with StatReloader
2025-07-24 13:42:57,806 [WARNING] django.request: Bad Request: /api/user/password/reset/
2025-07-24 13:42:57,806 [WARNING] django.server: "POST /api/user/password/reset/ HTTP/1.1" 400 30
2025-07-24 13:43:18,058 [WARNING] django.request: Bad Request: /api/user/password/reset/
2025-07-24 13:43:18,059 [WARNING] django.server: "POST /api/user/password/reset/ HTTP/1.1" 400 30
2025-07-24 13:43:27,108 [WARNING] django.request: Bad Request: /api/user/password/reset/
2025-07-24 13:43:27,109 [WARNING] django.server: "POST /api/user/password/reset/ HTTP/1.1" 400 30
2025-07-24 13:44:08,196 [INFO] django.utils.autoreload: C:\Users\CPT-003\Desktop\CRM\crm_api\lumina_care\middleware.py changed, reloading.
2025-07-24 13:44:11,338 [INFO] django.utils.autoreload: Watching for file changes with StatReloader
2025-07-24 13:44:54,473 [ERROR] users: Failed to send password reset email to support@prolianceltd.com: [WinError 10060] A connection attempt failed because the connected party did not properly respond after a period of time, or established connection failed because connected host has failed to respond
Traceback (most recent call last):
  File "C:\Users\CPT-003\Desktop\CRM\crm_api\users\views.py", line 179, in post
    email.send(fail_silently=False)
    ~~~~~~~~~~^^^^^^^^^^^^^^^^^^^^^
  File "C:\Users\CPT-003\Desktop\CRM\crm_api\venv\Lib\site-packages\django\core\mail\message.py", line 307, in send
    return self.get_connection(fail_silently).send_messages([self])
           ~~~~~~~~~~~~~~~~~~~~~~~~~~~~~~~~~~~~~~~~~~~~~~~~^^^^^^^^
  File "C:\Users\CPT-003\Desktop\CRM\crm_api\venv\Lib\site-packages\django\core\mail\backends\smtp.py", line 128, in send_messages
    new_conn_created = self.open()
  File "C:\Users\CPT-003\Desktop\CRM\crm_api\venv\Lib\site-packages\django\core\mail\backends\smtp.py", line 86, in open
    self.connection = self.connection_class(
                      ~~~~~~~~~~~~~~~~~~~~~^
        self.host, self.port, **connection_params
        ^^^^^^^^^^^^^^^^^^^^^^^^^^^^^^^^^^^^^^^^^
    )
    ^
  File "C:\Users\CPT-003\AppData\Local\Programs\Python\Python313\Lib\smtplib.py", line 255, in __init__
    (code, msg) = self.connect(host, port)
                  ~~~~~~~~~~~~^^^^^^^^^^^^
  File "C:\Users\CPT-003\AppData\Local\Programs\Python\Python313\Lib\smtplib.py", line 341, in connect
    self.sock = self._get_socket(host, port, self.timeout)
                ~~~~~~~~~~~~~~~~^^^^^^^^^^^^^^^^^^^^^^^^^^
  File "C:\Users\CPT-003\AppData\Local\Programs\Python\Python313\Lib\smtplib.py", line 312, in _get_socket
    return socket.create_connection((host, port), timeout,
           ~~~~~~~~~~~~~~~~~~~~~~~~^^^^^^^^^^^^^^^^^^^^^^^
                                    self.source_address)
                                    ^^^^^^^^^^^^^^^^^^^^
  File "C:\Users\CPT-003\AppData\Local\Programs\Python\Python313\Lib\socket.py", line 864, in create_connection
    raise exceptions[0]
  File "C:\Users\CPT-003\AppData\Local\Programs\Python\Python313\Lib\socket.py", line 849, in create_connection
    sock.connect(sa)
    ~~~~~~~~~~~~^^^^
TimeoutError: [WinError 10060] A connection attempt failed because the connected party did not properly respond after a period of time, or established connection failed because connected host has failed to respond
2025-07-24 13:44:54,484 [ERROR] django.request: Internal Server Error: /api/user/password/reset/
2025-07-24 13:44:54,484 [ERROR] django.server: "POST /api/user/password/reset/ HTTP/1.1" 500 370
2025-07-24 13:46:19,955 [INFO] django.utils.autoreload: C:\Users\CPT-003\Desktop\CRM\crm_api\users\views.py changed, reloading.
2025-07-24 13:46:23,291 [INFO] django.utils.autoreload: Watching for file changes with StatReloader
2025-07-24 13:46:56,631 [ERROR] users: Failed to send password reset email to support@prolianceltd.com: [WinError 10060] A connection attempt failed because the connected party did not properly respond after a period of time, or established connection failed because connected host has failed to respond
Traceback (most recent call last):
  File "C:\Users\CPT-003\Desktop\CRM\crm_api\users\views.py", line 179, in post
    email.send(fail_silently=False)
    ~~~~~~~~~~^^^^^^^^^^^^^^^^^^^^^
  File "C:\Users\CPT-003\Desktop\CRM\crm_api\venv\Lib\site-packages\django\core\mail\message.py", line 307, in send
    return self.get_connection(fail_silently).send_messages([self])
           ~~~~~~~~~~~~~~~~~~~~~~~~~~~~~~~~~~~~~~~~~~~~~~~~^^^^^^^^
  File "C:\Users\CPT-003\Desktop\CRM\crm_api\venv\Lib\site-packages\django\core\mail\backends\smtp.py", line 128, in send_messages
    new_conn_created = self.open()
  File "C:\Users\CPT-003\Desktop\CRM\crm_api\venv\Lib\site-packages\django\core\mail\backends\smtp.py", line 86, in open
    self.connection = self.connection_class(
                      ~~~~~~~~~~~~~~~~~~~~~^
        self.host, self.port, **connection_params
        ^^^^^^^^^^^^^^^^^^^^^^^^^^^^^^^^^^^^^^^^^
    )
    ^
  File "C:\Users\CPT-003\AppData\Local\Programs\Python\Python313\Lib\smtplib.py", line 255, in __init__
    (code, msg) = self.connect(host, port)
                  ~~~~~~~~~~~~^^^^^^^^^^^^
  File "C:\Users\CPT-003\AppData\Local\Programs\Python\Python313\Lib\smtplib.py", line 341, in connect
    self.sock = self._get_socket(host, port, self.timeout)
                ~~~~~~~~~~~~~~~~^^^^^^^^^^^^^^^^^^^^^^^^^^
  File "C:\Users\CPT-003\AppData\Local\Programs\Python\Python313\Lib\smtplib.py", line 312, in _get_socket
    return socket.create_connection((host, port), timeout,
           ~~~~~~~~~~~~~~~~~~~~~~~~^^^^^^^^^^^^^^^^^^^^^^^
                                    self.source_address)
                                    ^^^^^^^^^^^^^^^^^^^^
  File "C:\Users\CPT-003\AppData\Local\Programs\Python\Python313\Lib\socket.py", line 864, in create_connection
    raise exceptions[0]
  File "C:\Users\CPT-003\AppData\Local\Programs\Python\Python313\Lib\socket.py", line 849, in create_connection
    sock.connect(sa)
    ~~~~~~~~~~~~^^^^
TimeoutError: [WinError 10060] A connection attempt failed because the connected party did not properly respond after a period of time, or established connection failed because connected host has failed to respond
2025-07-24 13:46:56,643 [ERROR] django.request: Internal Server Error: /api/user/password/reset/
2025-07-24 13:46:56,644 [ERROR] django.server: "POST /api/user/password/reset/ HTTP/1.1" 500 370
2025-07-24 13:47:32,062 [INFO] django.utils.autoreload: C:\Users\CPT-003\Desktop\CRM\crm_api\users\views.py changed, reloading.
2025-07-24 13:47:35,935 [INFO] django.utils.autoreload: Watching for file changes with StatReloader
