2025-07-24 12:25:35,305 [INFO] users: Email configuration for tenant proliance: host=smtp.gmail.com, port=587, use_ssl=False, host_user=ekenehanson@gmail.com, host_password=*******************, default_from_email=ekenehanson@gmail.com
2025-07-24 12:25:56,391 [ERROR] users: Failed to send password reset email to admin@prolianceltd.com: [WinError 10060] A connection attempt failed because the connected party did not properly respond after a period of time, or established connection failed because connected host has failed to respond
Traceback (most recent call last):
  File "C:\Users\CPT-003\Desktop\CRM\crm_api\users\views.py", line 165, in post
    email.send(fail_silently=False)
    ~~~~~~~~~~^^^^^^^^^^^^^^^^^^^^^
  File "C:\Users\CPT-003\Desktop\CRM\crm_api\venv\Lib\site-packages\django\core\mail\message.py", line 307, in send
    return self.get_connection(fail_silently).send_messages([self])
           ~~~~~~~~~~~~~~~~~~~~~~~~~~~~~~~~~~~~~~~~~~~~~~~~^^^^^^^^
  File "C:\Users\CPT-003\Desktop\CRM\crm_api\venv\Lib\site-packages\django\core\mail\backends\smtp.py", line 128, in send_messages
    new_conn_created = self.open()
  File "C:\Users\CPT-003\Desktop\CRM\crm_api\venv\Lib\site-packages\django\core\mail\backends\smtp.py", line 86, in open
    self.connection = self.connection_class(
                      ~~~~~~~~~~~~~~~~~~~~~^
        self.host, self.port, **connection_params
        ^^^^^^^^^^^^^^^^^^^^^^^^^^^^^^^^^^^^^^^^^
    )
    ^
  File "C:\Users\CPT-003\AppData\Local\Programs\Python\Python313\Lib\smtplib.py", line 255, in __init__
    (code, msg) = self.connect(host, port)
                  ~~~~~~~~~~~~^^^^^^^^^^^^
  File "C:\Users\CPT-003\AppData\Local\Programs\Python\Python313\Lib\smtplib.py", line 341, in connect
    self.sock = self._get_socket(host, port, self.timeout)
                ~~~~~~~~~~~~~~~~^^^^^^^^^^^^^^^^^^^^^^^^^^
  File "C:\Users\CPT-003\AppData\Local\Programs\Python\Python313\Lib\smtplib.py", line 312, in _get_socket
    return socket.create_connection((host, port), timeout,
           ~~~~~~~~~~~~~~~~~~~~~~~~^^^^^^^^^^^^^^^^^^^^^^^
                                    self.source_address)
                                    ^^^^^^^^^^^^^^^^^^^^
  File "C:\Users\CPT-003\AppData\Local\Programs\Python\Python313\Lib\socket.py", line 864, in create_connection
    raise exceptions[0]
  File "C:\Users\CPT-003\AppData\Local\Programs\Python\Python313\Lib\socket.py", line 849, in create_connection
    sock.connect(sa)
    ~~~~~~~~~~~~^^^^
TimeoutError: [WinError 10060] A connection attempt failed because the connected party did not properly respond after a period of time, or established connection failed because connected host has failed to respond
2025-07-24 12:25:56,400 [ERROR] django.request: Internal Server Error: /api/user/password/reset/
2025-07-24 12:25:56,401 [ERROR] django.server: "POST /api/user/password/reset/ HTTP/1.1" 500 370
2025-07-24 12:26:07,094 [INFO] django.utils.autoreload: C:\Users\CPT-003\Desktop\CRM\crm_api\users\views.py changed, reloading.
2025-07-24 12:26:11,926 [INFO] django.utils.autoreload: Watching for file changes with StatReloader
2025-07-24 12:26:30,501 [INFO] users: Email configuration for tenant proliance: host=smtp.gmail.com, port=587, use_ssl=False, host_user=ekenehanson@gmail.com, host_password=*******************, default_from_email=ekenehanson@gmail.com
2025-07-24 12:26:51,538 [ERROR] users: Failed to send password reset email to admin@prolianceltd.com: [WinError 10060] A connection attempt failed because the connected party did not properly respond after a period of time, or established connection failed because connected host has failed to respond
Traceback (most recent call last):
  File "C:\Users\CPT-003\Desktop\CRM\crm_api\users\views.py", line 167, in post
    email.send(fail_silently=False)
    ~~~~~~~~~~^^^^^^^^^^^^^^^^^^^^^
  File "C:\Users\CPT-003\Desktop\CRM\crm_api\venv\Lib\site-packages\django\core\mail\message.py", line 307, in send
    return self.get_connection(fail_silently).send_messages([self])
           ~~~~~~~~~~~~~~~~~~~~~~~~~~~~~~~~~~~~~~~~~~~~~~~~^^^^^^^^
  File "C:\Users\CPT-003\Desktop\CRM\crm_api\venv\Lib\site-packages\django\core\mail\backends\smtp.py", line 128, in send_messages
    new_conn_created = self.open()
  File "C:\Users\CPT-003\Desktop\CRM\crm_api\venv\Lib\site-packages\django\core\mail\backends\smtp.py", line 86, in open
    self.connection = self.connection_class(
                      ~~~~~~~~~~~~~~~~~~~~~^
        self.host, self.port, **connection_params
        ^^^^^^^^^^^^^^^^^^^^^^^^^^^^^^^^^^^^^^^^^
    )
    ^
  File "C:\Users\CPT-003\AppData\Local\Programs\Python\Python313\Lib\smtplib.py", line 255, in __init__
    (code, msg) = self.connect(host, port)
                  ~~~~~~~~~~~~^^^^^^^^^^^^
  File "C:\Users\CPT-003\AppData\Local\Programs\Python\Python313\Lib\smtplib.py", line 341, in connect
    self.sock = self._get_socket(host, port, self.timeout)
                ~~~~~~~~~~~~~~~~^^^^^^^^^^^^^^^^^^^^^^^^^^
  File "C:\Users\CPT-003\AppData\Local\Programs\Python\Python313\Lib\smtplib.py", line 312, in _get_socket
    return socket.create_connection((host, port), timeout,
           ~~~~~~~~~~~~~~~~~~~~~~~~^^^^^^^^^^^^^^^^^^^^^^^
                                    self.source_address)
                                    ^^^^^^^^^^^^^^^^^^^^
  File "C:\Users\CPT-003\AppData\Local\Programs\Python\Python313\Lib\socket.py", line 864, in create_connection
    raise exceptions[0]
  File "C:\Users\CPT-003\AppData\Local\Programs\Python\Python313\Lib\socket.py", line 849, in create_connection
    sock.connect(sa)
    ~~~~~~~~~~~~^^^^
TimeoutError: [WinError 10060] A connection attempt failed because the connected party did not properly respond after a period of time, or established connection failed because connected host has failed to respond
2025-07-24 12:26:51,547 [ERROR] django.request: Internal Server Error: /api/user/password/reset/
2025-07-24 12:26:51,547 [ERROR] django.server: "POST /api/user/password/reset/ HTTP/1.1" 500 370
2025-07-24 12:31:21,388 [INFO] django.utils.autoreload: C:\Users\CPT-003\Desktop\CRM\crm_api\users\views.py changed, reloading.
2025-07-24 12:31:25,410 [INFO] django.utils.autoreload: Watching for file changes with StatReloader
2025-07-24 12:31:45,243 [INFO] django.utils.autoreload: C:\Users\CPT-003\Desktop\CRM\crm_api\users\views.py changed, reloading.
2025-07-24 12:31:49,379 [INFO] django.utils.autoreload: Watching for file changes with StatReloader
2025-07-24 12:32:31,919 [INFO] django.utils.autoreload: C:\Users\CPT-003\Desktop\CRM\crm_api\users\views.py changed, reloading.
2025-07-24 12:32:35,987 [INFO] django.utils.autoreload: Watching for file changes with StatReloader
2025-07-24 12:32:39,830 [INFO] django.utils.autoreload: C:\Users\CPT-003\Desktop\CRM\crm_api\users\views.py changed, reloading.
2025-07-24 12:32:43,349 [INFO] django.utils.autoreload: Watching for file changes with StatReloader
2025-07-24 12:32:57,067 [INFO] django.utils.autoreload: C:\Users\CPT-003\Desktop\CRM\crm_api\users\views.py changed, reloading.
2025-07-24 12:33:01,116 [INFO] django.utils.autoreload: Watching for file changes with StatReloader
2025-07-24 12:33:13,030 [INFO] users: Email configuration for tenant proliance user admin@prolianceltd.com: host=smtp.gmail.com, port=587, use_ssl=False, host_user=ekenehanson@gmail.com, host_password=*******************, default_from_email=ekenehanson@gmail.com
2025-07-24 12:33:34,118 [ERROR] users: Failed to send password reset email to admin@prolianceltd.com: [WinError 10060] A connection attempt failed because the connected party did not properly respond after a period of time, or established connection failed because connected host has failed to respond
Traceback (most recent call last):
  File "C:\Users\CPT-003\Desktop\CRM\crm_api\users\views.py", line 170, in post
    email.send(fail_silently=False)
    ~~~~~~~~~~^^^^^^^^^^^^^^^^^^^^^
  File "C:\Users\CPT-003\Desktop\CRM\crm_api\venv\Lib\site-packages\django\core\mail\message.py", line 307, in send
    return self.get_connection(fail_silently).send_messages([self])
           ~~~~~~~~~~~~~~~~~~~~~~~~~~~~~~~~~~~~~~~~~~~~~~~~^^^^^^^^
  File "C:\Users\CPT-003\Desktop\CRM\crm_api\venv\Lib\site-packages\django\core\mail\backends\smtp.py", line 128, in send_messages
    new_conn_created = self.open()
  File "C:\Users\CPT-003\Desktop\CRM\crm_api\venv\Lib\site-packages\django\core\mail\backends\smtp.py", line 86, in open
    self.connection = self.connection_class(
                      ~~~~~~~~~~~~~~~~~~~~~^
        self.host, self.port, **connection_params
        ^^^^^^^^^^^^^^^^^^^^^^^^^^^^^^^^^^^^^^^^^
    )
    ^
  File "C:\Users\CPT-003\AppData\Local\Programs\Python\Python313\Lib\smtplib.py", line 255, in __init__
    (code, msg) = self.connect(host, port)
                  ~~~~~~~~~~~~^^^^^^^^^^^^
  File "C:\Users\CPT-003\AppData\Local\Programs\Python\Python313\Lib\smtplib.py", line 341, in connect
    self.sock = self._get_socket(host, port, self.timeout)
                ~~~~~~~~~~~~~~~~^^^^^^^^^^^^^^^^^^^^^^^^^^
  File "C:\Users\CPT-003\AppData\Local\Programs\Python\Python313\Lib\smtplib.py", line 312, in _get_socket
    return socket.create_connection((host, port), timeout,
           ~~~~~~~~~~~~~~~~~~~~~~~~^^^^^^^^^^^^^^^^^^^^^^^
                                    self.source_address)
                                    ^^^^^^^^^^^^^^^^^^^^
  File "C:\Users\CPT-003\AppData\Local\Programs\Python\Python313\Lib\socket.py", line 864, in create_connection
    raise exceptions[0]
  File "C:\Users\CPT-003\AppData\Local\Programs\Python\Python313\Lib\socket.py", line 849, in create_connection
    sock.connect(sa)
    ~~~~~~~~~~~~^^^^
TimeoutError: [WinError 10060] A connection attempt failed because the connected party did not properly respond after a period of time, or established connection failed because connected host has failed to respond
2025-07-24 12:33:34,131 [ERROR] django.request: Internal Server Error: /api/user/password/reset/
2025-07-24 12:33:34,132 [ERROR] django.server: "POST /api/user/password/reset/ HTTP/1.1" 500 370
2025-07-24 12:34:24,013 [INFO] django.utils.autoreload: C:\Users\CPT-003\Desktop\CRM\crm_api\users\views.py changed, reloading.
2025-07-24 12:34:27,521 [INFO] django.utils.autoreload: Watching for file changes with StatReloader
2025-07-24 12:34:39,933 [INFO] users: Email configuration for tenant proliance user admin@prolianceltd.com: host=smtp.gmail.com, port=587, use_ssl=False, host_user=ekenehanson@gmail.com, host_password=*******************, default_from_email=ekenehanson@gmail.com
2025-07-24 12:35:01,027 [ERROR] users: Failed to send password reset email to admin@prolianceltd.com: [WinError 10060] A connection attempt failed because the connected party did not properly respond after a period of time, or established connection failed because connected host has failed to respond
Traceback (most recent call last):
  File "C:\Users\CPT-003\Desktop\CRM\crm_api\users\views.py", line 172, in post
    email.send(fail_silently=False)
    ~~~~~~~~~~^^^^^^^^^^^^^^^^^^^^^
  File "C:\Users\CPT-003\Desktop\CRM\crm_api\venv\Lib\site-packages\django\core\mail\message.py", line 307, in send
    return self.get_connection(fail_silently).send_messages([self])
           ~~~~~~~~~~~~~~~~~~~~~~~~~~~~~~~~~~~~~~~~~~~~~~~~^^^^^^^^
  File "C:\Users\CPT-003\Desktop\CRM\crm_api\venv\Lib\site-packages\django\core\mail\backends\smtp.py", line 128, in send_messages
    new_conn_created = self.open()
  File "C:\Users\CPT-003\Desktop\CRM\crm_api\venv\Lib\site-packages\django\core\mail\backends\smtp.py", line 86, in open
    self.connection = self.connection_class(
                      ~~~~~~~~~~~~~~~~~~~~~^
        self.host, self.port, **connection_params
        ^^^^^^^^^^^^^^^^^^^^^^^^^^^^^^^^^^^^^^^^^
    )
    ^
  File "C:\Users\CPT-003\AppData\Local\Programs\Python\Python313\Lib\smtplib.py", line 255, in __init__
    (code, msg) = self.connect(host, port)
                  ~~~~~~~~~~~~^^^^^^^^^^^^
  File "C:\Users\CPT-003\AppData\Local\Programs\Python\Python313\Lib\smtplib.py", line 341, in connect
    self.sock = self._get_socket(host, port, self.timeout)
                ~~~~~~~~~~~~~~~~^^^^^^^^^^^^^^^^^^^^^^^^^^
  File "C:\Users\CPT-003\AppData\Local\Programs\Python\Python313\Lib\smtplib.py", line 312, in _get_socket
    return socket.create_connection((host, port), timeout,
           ~~~~~~~~~~~~~~~~~~~~~~~~^^^^^^^^^^^^^^^^^^^^^^^
                                    self.source_address)
                                    ^^^^^^^^^^^^^^^^^^^^
  File "C:\Users\CPT-003\AppData\Local\Programs\Python\Python313\Lib\socket.py", line 864, in create_connection
    raise exceptions[0]
  File "C:\Users\CPT-003\AppData\Local\Programs\Python\Python313\Lib\socket.py", line 849, in create_connection
    sock.connect(sa)
    ~~~~~~~~~~~~^^^^
TimeoutError: [WinError 10060] A connection attempt failed because the connected party did not properly respond after a period of time, or established connection failed because connected host has failed to respond
2025-07-24 12:35:01,036 [ERROR] django.request: Internal Server Error: /api/user/password/reset/
2025-07-24 12:35:01,037 [ERROR] django.server: "POST /api/user/password/reset/ HTTP/1.1" 500 370
2025-07-24 12:35:03,956 [INFO] django.utils.autoreload: C:\Users\CPT-003\Desktop\CRM\crm_api\users\views.py changed, reloading.
2025-07-24 12:35:08,349 [INFO] django.utils.autoreload: Watching for file changes with StatReloader
2025-07-24 12:35:37,463 [INFO] django.utils.autoreload: C:\Users\CPT-003\Desktop\CRM\crm_api\users\views.py changed, reloading.
2025-07-24 12:35:41,095 [INFO] django.utils.autoreload: Watching for file changes with StatReloader
2025-07-24 12:36:04,329 [INFO] users: Email configuration for tenant proliance user admin@prolianceltd.com: host=smtp.gmail.com, port=587, use_ssl=False, host_user=ekenehanson@gmail.com, host_password=*******************, default_from_email=ekenehanson@gmail.com
2025-07-24 12:36:25,362 [ERROR] users: Failed to send password reset email to admin@prolianceltd.com: [WinError 10060] A connection attempt failed because the connected party did not properly respond after a period of time, or established connection failed because connected host has failed to respond
Traceback (most recent call last):
  File "C:\Users\CPT-003\Desktop\CRM\crm_api\users\views.py", line 173, in post
    email.send(fail_silently=False)
    ~~~~~~~~~~^^^^^^^^^^^^^^^^^^^^^
  File "C:\Users\CPT-003\Desktop\CRM\crm_api\venv\Lib\site-packages\django\core\mail\message.py", line 307, in send
    return self.get_connection(fail_silently).send_messages([self])
           ~~~~~~~~~~~~~~~~~~~~~~~~~~~~~~~~~~~~~~~~~~~~~~~~^^^^^^^^
  File "C:\Users\CPT-003\Desktop\CRM\crm_api\venv\Lib\site-packages\django\core\mail\backends\smtp.py", line 128, in send_messages
    new_conn_created = self.open()
  File "C:\Users\CPT-003\Desktop\CRM\crm_api\venv\Lib\site-packages\django\core\mail\backends\smtp.py", line 86, in open
    self.connection = self.connection_class(
                      ~~~~~~~~~~~~~~~~~~~~~^
        self.host, self.port, **connection_params
        ^^^^^^^^^^^^^^^^^^^^^^^^^^^^^^^^^^^^^^^^^
    )
    ^
  File "C:\Users\CPT-003\AppData\Local\Programs\Python\Python313\Lib\smtplib.py", line 255, in __init__
    (code, msg) = self.connect(host, port)
                  ~~~~~~~~~~~~^^^^^^^^^^^^
  File "C:\Users\CPT-003\AppData\Local\Programs\Python\Python313\Lib\smtplib.py", line 341, in connect
    self.sock = self._get_socket(host, port, self.timeout)
                ~~~~~~~~~~~~~~~~^^^^^^^^^^^^^^^^^^^^^^^^^^
  File "C:\Users\CPT-003\AppData\Local\Programs\Python\Python313\Lib\smtplib.py", line 312, in _get_socket
    return socket.create_connection((host, port), timeout,
           ~~~~~~~~~~~~~~~~~~~~~~~~^^^^^^^^^^^^^^^^^^^^^^^
                                    self.source_address)
                                    ^^^^^^^^^^^^^^^^^^^^
  File "C:\Users\CPT-003\AppData\Local\Programs\Python\Python313\Lib\socket.py", line 864, in create_connection
    raise exceptions[0]
  File "C:\Users\CPT-003\AppData\Local\Programs\Python\Python313\Lib\socket.py", line 849, in create_connection
    sock.connect(sa)
    ~~~~~~~~~~~~^^^^
TimeoutError: [WinError 10060] A connection attempt failed because the connected party did not properly respond after a period of time, or established connection failed because connected host has failed to respond
2025-07-24 12:36:25,389 [ERROR] django.request: Internal Server Error: /api/user/password/reset/
2025-07-24 12:36:25,389 [ERROR] django.server: "POST /api/user/password/reset/ HTTP/1.1" 500 370
2025-07-24 12:36:35,105 [INFO] django.utils.autoreload: C:\Users\CPT-003\Desktop\CRM\crm_api\users\views.py changed, reloading.
2025-07-24 12:36:38,520 [INFO] django.utils.autoreload: Watching for file changes with StatReloader
2025-07-24 12:36:52,764 [INFO] django.utils.autoreload: C:\Users\CPT-003\Desktop\CRM\crm_api\users\views.py changed, reloading.
2025-07-24 12:36:56,625 [INFO] django.utils.autoreload: Watching for file changes with StatReloader
2025-07-24 12:37:13,203 [INFO] django.utils.autoreload: C:\Users\CPT-003\Desktop\CRM\crm_api\users\views.py changed, reloading.
2025-07-24 12:37:16,868 [INFO] django.utils.autoreload: Watching for file changes with StatReloader
2025-07-24 12:37:55,748 [ERROR] users: Failed to send password reset email to admin@prolianceltd.com: [WinError 10060] A connection attempt failed because the connected party did not properly respond after a period of time, or established connection failed because connected host has failed to respond
Traceback (most recent call last):
  File "C:\Users\CPT-003\Desktop\CRM\crm_api\users\views.py", line 175, in post
    email.send(fail_silently=False)
    ~~~~~~~~~~^^^^^^^^^^^^^^^^^^^^^
  File "C:\Users\CPT-003\Desktop\CRM\crm_api\venv\Lib\site-packages\django\core\mail\message.py", line 307, in send
    return self.get_connection(fail_silently).send_messages([self])
           ~~~~~~~~~~~~~~~~~~~~~~~~~~~~~~~~~~~~~~~~~~~~~~~~^^^^^^^^
  File "C:\Users\CPT-003\Desktop\CRM\crm_api\venv\Lib\site-packages\django\core\mail\backends\smtp.py", line 128, in send_messages
    new_conn_created = self.open()
  File "C:\Users\CPT-003\Desktop\CRM\crm_api\venv\Lib\site-packages\django\core\mail\backends\smtp.py", line 86, in open
    self.connection = self.connection_class(
                      ~~~~~~~~~~~~~~~~~~~~~^
        self.host, self.port, **connection_params
        ^^^^^^^^^^^^^^^^^^^^^^^^^^^^^^^^^^^^^^^^^
    )
    ^
  File "C:\Users\CPT-003\AppData\Local\Programs\Python\Python313\Lib\smtplib.py", line 255, in __init__
    (code, msg) = self.connect(host, port)
                  ~~~~~~~~~~~~^^^^^^^^^^^^
  File "C:\Users\CPT-003\AppData\Local\Programs\Python\Python313\Lib\smtplib.py", line 341, in connect
    self.sock = self._get_socket(host, port, self.timeout)
                ~~~~~~~~~~~~~~~~^^^^^^^^^^^^^^^^^^^^^^^^^^
  File "C:\Users\CPT-003\AppData\Local\Programs\Python\Python313\Lib\smtplib.py", line 312, in _get_socket
    return socket.create_connection((host, port), timeout,
           ~~~~~~~~~~~~~~~~~~~~~~~~^^^^^^^^^^^^^^^^^^^^^^^
                                    self.source_address)
                                    ^^^^^^^^^^^^^^^^^^^^
  File "C:\Users\CPT-003\AppData\Local\Programs\Python\Python313\Lib\socket.py", line 864, in create_connection
    raise exceptions[0]
  File "C:\Users\CPT-003\AppData\Local\Programs\Python\Python313\Lib\socket.py", line 849, in create_connection
    sock.connect(sa)
    ~~~~~~~~~~~~^^^^
TimeoutError: [WinError 10060] A connection attempt failed because the connected party did not properly respond after a period of time, or established connection failed because connected host has failed to respond
2025-07-24 12:37:55,771 [ERROR] django.request: Internal Server Error: /api/user/password/reset/
2025-07-24 12:37:55,771 [ERROR] django.server: "POST /api/user/password/reset/ HTTP/1.1" 500 370
2025-07-24 12:38:13,006 [INFO] django.utils.autoreload: C:\Users\CPT-003\Desktop\CRM\crm_api\lumina_care\settings.py changed, reloading.
2025-07-24 12:38:20,543 [INFO] django.utils.autoreload: Watching for file changes with StatReloader
2025-07-24 12:41:44,680 [INFO] django.utils.autoreload: C:\Users\CPT-003\Desktop\CRM\crm_api\lumina_care\settings.py changed, reloading.
2025-07-24 12:41:54,656 [INFO] django.utils.autoreload: Watching for file changes with StatReloader
2025-07-24 12:42:29,011 [ERROR] users: Failed to send password reset email to admin@prolianceltd.com: [WinError 10060] A connection attempt failed because the connected party did not properly respond after a period of time, or established connection failed because connected host has failed to respond
Traceback (most recent call last):
  File "C:\Users\CPT-003\Desktop\CRM\crm_api\users\views.py", line 175, in post
    email.send(fail_silently=False)
    ~~~~~~~~~~^^^^^^^^^^^^^^^^^^^^^
  File "C:\Users\CPT-003\Desktop\CRM\crm_api\venv\Lib\site-packages\django\core\mail\message.py", line 307, in send
    return self.get_connection(fail_silently).send_messages([self])
           ~~~~~~~~~~~~~~~~~~~~~~~~~~~~~~~~~~~~~~~~~~~~~~~~^^^^^^^^
  File "C:\Users\CPT-003\Desktop\CRM\crm_api\venv\Lib\site-packages\django\core\mail\backends\smtp.py", line 128, in send_messages
    new_conn_created = self.open()
  File "C:\Users\CPT-003\Desktop\CRM\crm_api\venv\Lib\site-packages\django\core\mail\backends\smtp.py", line 86, in open
    self.connection = self.connection_class(
                      ~~~~~~~~~~~~~~~~~~~~~^
        self.host, self.port, **connection_params
        ^^^^^^^^^^^^^^^^^^^^^^^^^^^^^^^^^^^^^^^^^
    )
    ^
  File "C:\Users\CPT-003\AppData\Local\Programs\Python\Python313\Lib\smtplib.py", line 255, in __init__
    (code, msg) = self.connect(host, port)
                  ~~~~~~~~~~~~^^^^^^^^^^^^
  File "C:\Users\CPT-003\AppData\Local\Programs\Python\Python313\Lib\smtplib.py", line 341, in connect
    self.sock = self._get_socket(host, port, self.timeout)
                ~~~~~~~~~~~~~~~~^^^^^^^^^^^^^^^^^^^^^^^^^^
  File "C:\Users\CPT-003\AppData\Local\Programs\Python\Python313\Lib\smtplib.py", line 312, in _get_socket
    return socket.create_connection((host, port), timeout,
           ~~~~~~~~~~~~~~~~~~~~~~~~^^^^^^^^^^^^^^^^^^^^^^^
                                    self.source_address)
                                    ^^^^^^^^^^^^^^^^^^^^
  File "C:\Users\CPT-003\AppData\Local\Programs\Python\Python313\Lib\socket.py", line 864, in create_connection
    raise exceptions[0]
  File "C:\Users\CPT-003\AppData\Local\Programs\Python\Python313\Lib\socket.py", line 849, in create_connection
    sock.connect(sa)
    ~~~~~~~~~~~~^^^^
TimeoutError: [WinError 10060] A connection attempt failed because the connected party did not properly respond after a period of time, or established connection failed because connected host has failed to respond
2025-07-24 12:42:29,019 [ERROR] django.request: Internal Server Error: /api/user/password/reset/
2025-07-24 12:42:29,020 [ERROR] django.server: "POST /api/user/password/reset/ HTTP/1.1" 500 370
2025-07-24 12:48:46,416 [INFO] django.utils.autoreload: C:\Users\CPT-003\Desktop\CRM\crm_api\users\views.py changed, reloading.
2025-07-24 12:48:49,509 [INFO] django.utils.autoreload: Watching for file changes with StatReloader
2025-07-24 12:50:11,488 [ERROR] users: Failed to send password reset email to admin@prolianceltd.com: [WinError 10060] A connection attempt failed because the connected party did not properly respond after a period of time, or established connection failed because connected host has failed to respond
Traceback (most recent call last):
  File "C:\Users\CPT-003\Desktop\CRM\crm_api\users\views.py", line 177, in post
    email.send(fail_silently=False)
    ~~~~~~~~~~^^^^^^^^^^^^^^^^^^^^^
  File "C:\Users\CPT-003\Desktop\CRM\crm_api\venv\Lib\site-packages\django\core\mail\message.py", line 307, in send
    return self.get_connection(fail_silently).send_messages([self])
           ~~~~~~~~~~~~~~~~~~~~~~~~~~~~~~~~~~~~~~~~~~~~~~~~^^^^^^^^
  File "C:\Users\CPT-003\Desktop\CRM\crm_api\venv\Lib\site-packages\django\core\mail\backends\smtp.py", line 128, in send_messages
    new_conn_created = self.open()
  File "C:\Users\CPT-003\Desktop\CRM\crm_api\venv\Lib\site-packages\django\core\mail\backends\smtp.py", line 86, in open
    self.connection = self.connection_class(
                      ~~~~~~~~~~~~~~~~~~~~~^
        self.host, self.port, **connection_params
        ^^^^^^^^^^^^^^^^^^^^^^^^^^^^^^^^^^^^^^^^^
    )
    ^
  File "C:\Users\CPT-003\AppData\Local\Programs\Python\Python313\Lib\smtplib.py", line 255, in __init__
    (code, msg) = self.connect(host, port)
                  ~~~~~~~~~~~~^^^^^^^^^^^^
  File "C:\Users\CPT-003\AppData\Local\Programs\Python\Python313\Lib\smtplib.py", line 341, in connect
    self.sock = self._get_socket(host, port, self.timeout)
                ~~~~~~~~~~~~~~~~^^^^^^^^^^^^^^^^^^^^^^^^^^
  File "C:\Users\CPT-003\AppData\Local\Programs\Python\Python313\Lib\smtplib.py", line 312, in _get_socket
    return socket.create_connection((host, port), timeout,
           ~~~~~~~~~~~~~~~~~~~~~~~~^^^^^^^^^^^^^^^^^^^^^^^
                                    self.source_address)
                                    ^^^^^^^^^^^^^^^^^^^^
  File "C:\Users\CPT-003\AppData\Local\Programs\Python\Python313\Lib\socket.py", line 864, in create_connection
    raise exceptions[0]
  File "C:\Users\CPT-003\AppData\Local\Programs\Python\Python313\Lib\socket.py", line 849, in create_connection
    sock.connect(sa)
    ~~~~~~~~~~~~^^^^
TimeoutError: [WinError 10060] A connection attempt failed because the connected party did not properly respond after a period of time, or established connection failed because connected host has failed to respond
2025-07-24 12:50:11,498 [ERROR] django.request: Internal Server Error: /api/user/password/reset/
2025-07-24 12:50:11,499 [ERROR] django.server: "POST /api/user/password/reset/ HTTP/1.1" 500 370
2025-07-24 12:50:24,696 [WARNING] django.request: Bad Request: /api/user/password/reset/confirm/
2025-07-24 12:50:24,697 [WARNING] django.server: "POST /api/user/password/reset/confirm/ HTTP/1.1" 400 30
2025-07-24 12:51:38,017 [INFO] django.utils.autoreload: C:\Users\CPT-003\Desktop\CRM\crm_api\users\models.py changed, reloading.
2025-07-24 12:51:40,961 [INFO] django.utils.autoreload: Watching for file changes with StatReloader
2025-07-24 12:51:53,794 [INFO] django.utils.autoreload: C:\Users\CPT-003\Desktop\CRM\crm_api\users\models.py changed, reloading.
2025-07-24 12:51:57,667 [INFO] django.utils.autoreload: Watching for file changes with StatReloader
2025-07-24 12:56:57,032 [INFO] django.utils.autoreload: C:\Users\CPT-003\Desktop\CRM\crm_api\users\views.py changed, reloading.
2025-07-24 12:57:00,224 [INFO] django.utils.autoreload: Watching for file changes with StatReloader
2025-07-24 13:01:35,844 [INFO] django.utils.autoreload: C:\Users\CPT-003\Desktop\CRM\crm_api\users\views.py changed, reloading.
2025-07-24 13:01:38,971 [INFO] django.utils.autoreload: Watching for file changes with StatReloader
2025-07-24 13:01:57,988 [INFO] django.utils.autoreload: C:\Users\CPT-003\Desktop\CRM\crm_api\users\views.py changed, reloading.
2025-07-24 13:02:00,927 [INFO] django.utils.autoreload: Watching for file changes with StatReloader
2025-07-24 13:02:29,731 [INFO] django.utils.autoreload: C:\Users\CPT-003\Desktop\CRM\crm_api\lumina_care\settings.py changed, reloading.
2025-07-24 13:02:32,793 [INFO] django.utils.autoreload: Watching for file changes with StatReloader
2025-07-24 13:05:02,028 [INFO] django.utils.autoreload: C:\Users\CPT-003\Desktop\CRM\crm_api\users\views.py changed, reloading.
2025-07-24 13:05:05,657 [INFO] django.utils.autoreload: Watching for file changes with StatReloader
2025-07-24 13:08:16,726 [INFO] django.utils.autoreload: C:\Users\CPT-003\Desktop\CRM\crm_api\lumina_care\middleware.py changed, reloading.
2025-07-24 13:08:20,139 [INFO] django.utils.autoreload: Watching for file changes with StatReloader
2025-07-24 13:08:46,322 [INFO] django.utils.autoreload: C:\Users\CPT-003\Desktop\CRM\crm_api\lumina_care\middleware.py changed, reloading.
2025-07-24 13:08:50,181 [INFO] django.utils.autoreload: Watching for file changes with StatReloader
2025-07-24 13:11:21,053 [INFO] django.utils.autoreload: Watching for file changes with StatReloader
2025-07-24 13:12:47,090 [INFO] django.server: "OPTIONS /api/token/ HTTP/1.1" 200 0
2025-07-24 13:12:48,244 [INFO] django.server: "POST /api/token/ HTTP/1.1" 200 965
2025-07-24 13:12:48,284 [INFO] django.server: "OPTIONS /api/token/validate/ HTTP/1.1" 200 0
2025-07-24 13:12:48,290 [INFO] django.server: "OPTIONS /api/token/validate/ HTTP/1.1" 200 0
2025-07-24 13:12:48,308 [INFO] django.server: "GET /api/token/validate/ HTTP/1.1" 200 389
2025-07-24 13:12:48,397 [INFO] django.server: "GET /api/token/validate/ HTTP/1.1" 200 389
2025-07-24 13:12:48,623 [INFO] django.server: "OPTIONS /api/user/tenant-users/ HTTP/1.1" 200 0
2025-07-24 13:12:48,623 [INFO] django.server: "OPTIONS /api/user/tenant-users/ HTTP/1.1" 200 0
2025-07-24 13:12:48,645 [INFO] users: Retrieved 3 users for tenant proliance
2025-07-24 13:12:48,658 [INFO] django.server: "GET /api/user/tenant-users/ HTTP/1.1" 200 1022
2025-07-24 13:12:48,668 [INFO] users: Retrieved 3 users for tenant proliance
2025-07-24 13:12:48,681 [INFO] django.server: "GET /api/user/tenant-users/ HTTP/1.1" 200 1022
2025-07-24 13:13:24,452 [INFO] django.utils.autoreload: C:\Users\CPT-003\Desktop\CRM\crm_api\lumina_care\settings.py changed, reloading.
2025-07-24 13:13:28,434 [INFO] django.utils.autoreload: Watching for file changes with StatReloader
2025-07-24 13:14:01,997 [INFO] django.utils.autoreload: C:\Users\CPT-003\Desktop\CRM\crm_api\job_application\views.py changed, reloading.
2025-07-24 13:14:05,997 [INFO] django.utils.autoreload: Watching for file changes with StatReloader
2025-07-24 13:18:03,573 [INFO] django.utils.autoreload: C:\Users\CPT-003\Desktop\CRM\crm_api\job_application\views.py changed, reloading.
2025-07-24 13:18:07,874 [INFO] django.utils.autoreload: Watching for file changes with StatReloader
2025-07-24 13:19:23,021 [INFO] django.utils.autoreload: C:\Users\CPT-003\Desktop\CRM\crm_api\job_application\views.py changed, reloading.
2025-07-24 13:19:27,848 [INFO] django.utils.autoreload: Watching for file changes with StatReloader
2025-07-24 13:23:27,508 [INFO] django.utils.autoreload: C:\Users\CPT-003\Desktop\CRM\crm_api\lumina_care\settings.py changed, reloading.
2025-07-24 13:23:30,907 [INFO] django.utils.autoreload: Watching for file changes with StatReloader
2025-07-24 13:30:08,523 [INFO] django.utils.autoreload: C:\Users\CPT-003\Desktop\CRM\crm_api\lumina_care\settings.py changed, reloading.
2025-07-24 13:30:12,136 [INFO] django.utils.autoreload: Watching for file changes with StatReloader
2025-07-24 13:33:46,765 [INFO] django.utils.autoreload: C:\Users\CPT-003\Desktop\CRM\crm_api\lumina_care\settings.py changed, reloading.
2025-07-24 13:33:50,303 [INFO] django.utils.autoreload: Watching for file changes with StatReloader
2025-07-24 13:34:32,426 [INFO] django.server: "POST /api/token/ HTTP/1.1" 200 965
2025-07-24 13:34:32,467 [INFO] django.server: "GET /api/token/validate/ HTTP/1.1" 200 389
2025-07-24 13:34:32,550 [INFO] django.server: "GET /api/token/validate/ HTTP/1.1" 200 389
2025-07-24 13:34:32,567 [INFO] users: Retrieved 3 users for tenant proliance
2025-07-24 13:34:32,581 [INFO] django.server: "GET /api/user/tenant-users/ HTTP/1.1" 200 1022
2025-07-24 13:34:32,593 [INFO] users: Retrieved 3 users for tenant proliance
2025-07-24 13:34:32,613 [INFO] django.server: "GET /api/user/tenant-users/ HTTP/1.1" 200 1022
2025-07-24 13:34:36,023 [INFO] django.server: "OPTIONS /api/talent-engine/requisitions/ HTTP/1.1" 200 0
2025-07-24 13:34:36,026 [INFO] django.server: "OPTIONS /api/talent-engine/requisitions/ HTTP/1.1" 200 0
2025-07-24 13:34:36,147 [INFO] django.server: "GET /api/talent-engine/requisitions/ HTTP/1.1" 200 6330
2025-07-24 13:34:36,198 [INFO] django.server: "GET /api/talent-engine/requisitions/ HTTP/1.1" 200 6330
2025-07-24 13:34:39,308 [INFO] django.server: "GET /api/talent-engine/requisitions/ HTTP/1.1" 200 6330
2025-07-24 13:34:39,334 [INFO] django.server: "GET /api/talent-engine/requisitions/ HTTP/1.1" 200 6330
2025-07-24 13:34:42,966 [INFO] django.server: "OPTIONS /api/talent-engine-job-applications/applications/job-requisitions/PRO-0001/applications/ HTTP/1.1" 200 0
2025-07-24 13:34:42,967 [INFO] django.server: "OPTIONS /api/talent-engine-job-applications/applications/job-requisitions/PRO-0001/applications/ HTTP/1.1" 200 0
2025-07-24 13:34:48,978 [INFO] django.server: "GET /api/talent-engine-job-applications/applications/job-requisitions/PRO-0001/applications/ HTTP/1.1" 200 5674185
2025-07-24 13:34:55,126 [INFO] django.server: "GET /api/talent-engine-job-applications/applications/job-requisitions/PRO-0001/applications/ HTTP/1.1" 200 5674185
2025-07-24 13:41:19,780 [INFO] django.utils.autoreload: C:\Users\CPT-003\Desktop\CRM\crm_api\users\views.py changed, reloading.
2025-07-24 13:41:23,295 [INFO] django.utils.autoreload: Watching for file changes with StatReloader
2025-07-24 13:42:57,806 [WARNING] django.request: Bad Request: /api/user/password/reset/
2025-07-24 13:42:57,806 [WARNING] django.server: "POST /api/user/password/reset/ HTTP/1.1" 400 30
2025-07-24 13:43:18,058 [WARNING] django.request: Bad Request: /api/user/password/reset/
2025-07-24 13:43:18,059 [WARNING] django.server: "POST /api/user/password/reset/ HTTP/1.1" 400 30
2025-07-24 13:43:27,108 [WARNING] django.request: Bad Request: /api/user/password/reset/
2025-07-24 13:43:27,109 [WARNING] django.server: "POST /api/user/password/reset/ HTTP/1.1" 400 30
2025-07-24 13:44:08,196 [INFO] django.utils.autoreload: C:\Users\CPT-003\Desktop\CRM\crm_api\lumina_care\middleware.py changed, reloading.
2025-07-24 13:44:11,338 [INFO] django.utils.autoreload: Watching for file changes with StatReloader
2025-07-24 13:44:54,473 [ERROR] users: Failed to send password reset email to support@prolianceltd.com: [WinError 10060] A connection attempt failed because the connected party did not properly respond after a period of time, or established connection failed because connected host has failed to respond
Traceback (most recent call last):
  File "C:\Users\CPT-003\Desktop\CRM\crm_api\users\views.py", line 179, in post
    email.send(fail_silently=False)
    ~~~~~~~~~~^^^^^^^^^^^^^^^^^^^^^
  File "C:\Users\CPT-003\Desktop\CRM\crm_api\venv\Lib\site-packages\django\core\mail\message.py", line 307, in send
    return self.get_connection(fail_silently).send_messages([self])
           ~~~~~~~~~~~~~~~~~~~~~~~~~~~~~~~~~~~~~~~~~~~~~~~~^^^^^^^^
  File "C:\Users\CPT-003\Desktop\CRM\crm_api\venv\Lib\site-packages\django\core\mail\backends\smtp.py", line 128, in send_messages
    new_conn_created = self.open()
  File "C:\Users\CPT-003\Desktop\CRM\crm_api\venv\Lib\site-packages\django\core\mail\backends\smtp.py", line 86, in open
    self.connection = self.connection_class(
                      ~~~~~~~~~~~~~~~~~~~~~^
        self.host, self.port, **connection_params
        ^^^^^^^^^^^^^^^^^^^^^^^^^^^^^^^^^^^^^^^^^
    )
    ^
  File "C:\Users\CPT-003\AppData\Local\Programs\Python\Python313\Lib\smtplib.py", line 255, in __init__
    (code, msg) = self.connect(host, port)
                  ~~~~~~~~~~~~^^^^^^^^^^^^
  File "C:\Users\CPT-003\AppData\Local\Programs\Python\Python313\Lib\smtplib.py", line 341, in connect
    self.sock = self._get_socket(host, port, self.timeout)
                ~~~~~~~~~~~~~~~~^^^^^^^^^^^^^^^^^^^^^^^^^^
  File "C:\Users\CPT-003\AppData\Local\Programs\Python\Python313\Lib\smtplib.py", line 312, in _get_socket
    return socket.create_connection((host, port), timeout,
           ~~~~~~~~~~~~~~~~~~~~~~~~^^^^^^^^^^^^^^^^^^^^^^^
                                    self.source_address)
                                    ^^^^^^^^^^^^^^^^^^^^
  File "C:\Users\CPT-003\AppData\Local\Programs\Python\Python313\Lib\socket.py", line 864, in create_connection
    raise exceptions[0]
  File "C:\Users\CPT-003\AppData\Local\Programs\Python\Python313\Lib\socket.py", line 849, in create_connection
    sock.connect(sa)
    ~~~~~~~~~~~~^^^^
TimeoutError: [WinError 10060] A connection attempt failed because the connected party did not properly respond after a period of time, or established connection failed because connected host has failed to respond
2025-07-24 13:44:54,484 [ERROR] django.request: Internal Server Error: /api/user/password/reset/
2025-07-24 13:44:54,484 [ERROR] django.server: "POST /api/user/password/reset/ HTTP/1.1" 500 370
2025-07-24 13:46:19,955 [INFO] django.utils.autoreload: C:\Users\CPT-003\Desktop\CRM\crm_api\users\views.py changed, reloading.
2025-07-24 13:46:23,291 [INFO] django.utils.autoreload: Watching for file changes with StatReloader
2025-07-24 13:46:56,631 [ERROR] users: Failed to send password reset email to support@prolianceltd.com: [WinError 10060] A connection attempt failed because the connected party did not properly respond after a period of time, or established connection failed because connected host has failed to respond
Traceback (most recent call last):
  File "C:\Users\CPT-003\Desktop\CRM\crm_api\users\views.py", line 179, in post
    email.send(fail_silently=False)
    ~~~~~~~~~~^^^^^^^^^^^^^^^^^^^^^
  File "C:\Users\CPT-003\Desktop\CRM\crm_api\venv\Lib\site-packages\django\core\mail\message.py", line 307, in send
    return self.get_connection(fail_silently).send_messages([self])
           ~~~~~~~~~~~~~~~~~~~~~~~~~~~~~~~~~~~~~~~~~~~~~~~~^^^^^^^^
  File "C:\Users\CPT-003\Desktop\CRM\crm_api\venv\Lib\site-packages\django\core\mail\backends\smtp.py", line 128, in send_messages
    new_conn_created = self.open()
  File "C:\Users\CPT-003\Desktop\CRM\crm_api\venv\Lib\site-packages\django\core\mail\backends\smtp.py", line 86, in open
    self.connection = self.connection_class(
                      ~~~~~~~~~~~~~~~~~~~~~^
        self.host, self.port, **connection_params
        ^^^^^^^^^^^^^^^^^^^^^^^^^^^^^^^^^^^^^^^^^
    )
    ^
  File "C:\Users\CPT-003\AppData\Local\Programs\Python\Python313\Lib\smtplib.py", line 255, in __init__
    (code, msg) = self.connect(host, port)
                  ~~~~~~~~~~~~^^^^^^^^^^^^
  File "C:\Users\CPT-003\AppData\Local\Programs\Python\Python313\Lib\smtplib.py", line 341, in connect
    self.sock = self._get_socket(host, port, self.timeout)
                ~~~~~~~~~~~~~~~~^^^^^^^^^^^^^^^^^^^^^^^^^^
  File "C:\Users\CPT-003\AppData\Local\Programs\Python\Python313\Lib\smtplib.py", line 312, in _get_socket
    return socket.create_connection((host, port), timeout,
           ~~~~~~~~~~~~~~~~~~~~~~~~^^^^^^^^^^^^^^^^^^^^^^^
                                    self.source_address)
                                    ^^^^^^^^^^^^^^^^^^^^
  File "C:\Users\CPT-003\AppData\Local\Programs\Python\Python313\Lib\socket.py", line 864, in create_connection
    raise exceptions[0]
  File "C:\Users\CPT-003\AppData\Local\Programs\Python\Python313\Lib\socket.py", line 849, in create_connection
    sock.connect(sa)
    ~~~~~~~~~~~~^^^^
TimeoutError: [WinError 10060] A connection attempt failed because the connected party did not properly respond after a period of time, or established connection failed because connected host has failed to respond
2025-07-24 13:46:56,643 [ERROR] django.request: Internal Server Error: /api/user/password/reset/
2025-07-24 13:46:56,644 [ERROR] django.server: "POST /api/user/password/reset/ HTTP/1.1" 500 370
2025-07-24 13:47:32,062 [INFO] django.utils.autoreload: C:\Users\CPT-003\Desktop\CRM\crm_api\users\views.py changed, reloading.
2025-07-24 13:47:35,935 [INFO] django.utils.autoreload: Watching for file changes with StatReloader
2025-07-24 13:55:43,519 [INFO] django.utils.autoreload: C:\Users\CPT-003\Desktop\CRM\crm_api\lumina_care\settings.py changed, reloading.
2025-07-24 13:55:46,693 [INFO] django.utils.autoreload: Watching for file changes with StatReloader
2025-07-24 13:57:26,700 [INFO] django.utils.autoreload: C:\Users\CPT-003\Desktop\CRM\crm_api\lumina_care\settings.py changed, reloading.
2025-07-24 13:57:33,446 [INFO] django.utils.autoreload: Watching for file changes with StatReloader
2025-07-24 14:00:33,464 [INFO] django.utils.autoreload: C:\Users\CPT-003\Desktop\CRM\crm_api\lumina_care\settings.py changed, reloading.
2025-07-24 14:00:40,493 [INFO] django.utils.autoreload: Watching for file changes with StatReloader
2025-07-24 14:01:25,281 [INFO] django.utils.autoreload: C:\Users\CPT-003\Desktop\CRM\crm_api\lumina_care\settings.py changed, reloading.
2025-07-24 14:01:33,032 [INFO] django.utils.autoreload: Watching for file changes with StatReloader
2025-07-24 14:02:05,811 [INFO] django.utils.autoreload: C:\Users\CPT-003\Desktop\CRM\crm_api\lumina_care\settings.py changed, reloading.
2025-07-24 14:02:11,664 [INFO] django.utils.autoreload: Watching for file changes with StatReloader
2025-07-24 14:02:47,362 [INFO] django.server: "POST /api/token/ HTTP/1.1" 200 955
2025-07-24 14:03:12,690 [INFO] django.utils.autoreload: C:\Users\CPT-003\Desktop\CRM\crm_api\lumina_care\settings.py changed, reloading.
2025-07-24 14:03:18,815 [INFO] django.utils.autoreload: Watching for file changes with StatReloader
2025-07-28 09:35:31,161 [INFO] django.utils.autoreload: Watching for file changes with StatReloader
2025-07-28 09:37:44,425 [INFO] django.utils.autoreload: C:\Users\CPT-003\Desktop\CRM\crm_api\lumina_care\settings.py changed, reloading.
2025-07-28 09:37:59,091 [INFO] django.utils.autoreload: Watching for file changes with StatReloader
2025-07-28 09:39:02,290 [INFO] django.server: "OPTIONS /api/token/ HTTP/1.1" 200 0
2025-07-28 09:39:04,471 [WARNING] django.request: Unauthorized: /api/token/
2025-07-28 09:39:04,472 [WARNING] django.server: "POST /api/token/ HTTP/1.1" 401 63
2025-07-28 09:39:12,088 [WARNING] django.request: Unauthorized: /api/token/
2025-07-28 09:39:12,088 [WARNING] django.server: "POST /api/token/ HTTP/1.1" 401 63
2025-07-28 09:39:18,229 [INFO] django.server: "POST /api/token/ HTTP/1.1" 200 965
2025-07-28 09:39:18,272 [INFO] django.server: "OPTIONS /api/token/validate/ HTTP/1.1" 200 0
2025-07-28 09:39:18,279 [INFO] django.server: "OPTIONS /api/token/validate/ HTTP/1.1" 200 0
2025-07-28 09:39:18,302 [INFO] django.server: "GET /api/token/validate/ HTTP/1.1" 200 389
2025-07-28 09:39:18,450 [INFO] django.server: "GET /api/token/validate/ HTTP/1.1" 200 389
2025-07-28 09:39:18,736 [INFO] django.server: "OPTIONS /api/user/tenant-users/ HTTP/1.1" 200 0
2025-07-28 09:39:18,737 [INFO] django.server: "OPTIONS /api/user/tenant-users/ HTTP/1.1" 200 0
2025-07-28 09:39:18,766 [INFO] users: Retrieved 3 users for tenant proliance
2025-07-28 09:39:18,790 [INFO] django.server: "GET /api/user/tenant-users/ HTTP/1.1" 200 1022
2025-07-28 09:39:18,804 [INFO] users: Retrieved 3 users for tenant proliance
2025-07-28 09:39:18,825 [INFO] django.server: "GET /api/user/tenant-users/ HTTP/1.1" 200 1022
2025-07-28 10:22:44,645 [WARNING] django.request: Unauthorized: /api/token/
2025-07-28 10:22:44,648 [WARNING] django.server: "POST /api/token/ HTTP/1.1" 401 63
2025-07-28 10:35:59,220 [INFO] django.utils.autoreload: C:\Users\CPT-003\Desktop\CRM\crm_api\lumina_care\settings.py changed, reloading.
2025-07-28 10:36:05,540 [INFO] django.utils.autoreload: Watching for file changes with StatReloader
2025-07-28 10:51:12,008 [INFO] django.utils.autoreload: C:\Users\CPT-003\Desktop\CRM\crm_api\lumina_care\settings.py changed, reloading.
2025-07-28 10:51:15,295 [INFO] django.utils.autoreload: Watching for file changes with StatReloader
2025-07-28 11:05:01,231 [INFO] django.utils.autoreload: C:\Users\CPT-003\Desktop\CRM\crm_api\lumina_care\settings.py changed, reloading.
2025-07-28 11:06:17,083 [INFO] django.utils.autoreload: Watching for file changes with StatReloader
2025-07-28 11:07:21,543 [INFO] django.utils.autoreload: C:\Users\CPT-003\Desktop\CRM\crm_api\lumina_care\settings.py changed, reloading.
2025-07-28 11:07:25,708 [INFO] django.utils.autoreload: Watching for file changes with StatReloader
2025-07-28 11:07:36,399 [INFO] django.utils.autoreload: Watching for file changes with StatReloader
2025-07-28 11:07:43,349 [INFO] django.utils.autoreload: C:\Users\CPT-003\Desktop\CRM\crm_api\lumina_care\settings.py changed, reloading.
2025-07-28 11:07:46,780 [INFO] django.utils.autoreload: Watching for file changes with StatReloader
2025-07-28 11:43:08,301 [ERROR] django.server: "OPTIONS /api/token/validate/ HTTP/1.1" 500 59
2025-07-28 11:43:08,308 [ERROR] django.server: "OPTIONS /api/token/validate/ HTTP/1.1" 500 59
2025-07-28 11:53:50,763 [INFO] django.utils.autoreload: C:\Users\CPT-003\Desktop\CRM\crm_api\lumina_care\settings.py changed, reloading.
2025-07-28 11:53:54,449 [INFO] django.utils.autoreload: Watching for file changes with StatReloader
2025-07-28 11:54:15,363 [INFO] django.utils.autoreload: C:\Users\CPT-003\Desktop\CRM\crm_api\lumina_care\settings.py changed, reloading.
2025-07-28 11:54:19,902 [INFO] django.utils.autoreload: Watching for file changes with StatReloader
2025-07-28 11:54:37,406 [INFO] django.utils.autoreload: Watching for file changes with StatReloader
2025-07-28 11:55:17,232 [INFO] django.server: "OPTIONS /api/token/ HTTP/1.1" 200 0
2025-07-28 11:55:22,172 [WARNING] django.request: Unauthorized: /api/token/
2025-07-28 11:55:22,173 [WARNING] django.server: "POST /api/token/ HTTP/1.1" 401 63
2025-07-28 11:55:38,550 [INFO] django.server: "POST /api/token/ HTTP/1.1" 200 964
2025-07-28 11:55:38,580 [INFO] django.server: "OPTIONS /api/token/validate/ HTTP/1.1" 200 0
2025-07-28 11:55:38,591 [INFO] django.server: "OPTIONS /api/token/validate/ HTTP/1.1" 200 0
2025-07-28 11:55:42,990 [INFO] django.server: "GET /api/token/validate/ HTTP/1.1" 200 388
2025-07-28 11:55:43,160 [INFO] django.server: "OPTIONS /api/user/tenant-users/ HTTP/1.1" 200 0
2025-07-28 11:55:43,166 [INFO] django.server: "OPTIONS /api/user/tenant-users/ HTTP/1.1" 200 0
2025-07-28 11:55:45,859 [INFO] django.server: "OPTIONS /api/talent-engine/requisitions/ HTTP/1.1" 200 0
2025-07-28 11:55:45,865 [INFO] django.server: "OPTIONS /api/talent-engine/requisitions/ HTTP/1.1" 200 0
2025-07-28 11:55:47,372 [INFO] django.server: "GET /api/token/validate/ HTTP/1.1" 200 388
2025-07-28 11:55:47,590 [INFO] users: Retrieved 6 users for tenant proliance
2025-07-28 11:55:55,267 [INFO] django.server: "OPTIONS /api/tenant/tenants/1/ HTTP/1.1" 200 0
2025-07-28 11:55:55,267 [INFO] django.server: "OPTIONS /api/tenant/tenants/1/ HTTP/1.1" 200 0
2025-07-28 11:55:55,720 [INFO] django.server: "GET /api/user/tenant-users/ HTTP/1.1" 200 1986
2025-07-28 11:55:58,542 [INFO] django.server: "OPTIONS /api/tenant/config/ HTTP/1.1" 200 0
2025-07-28 11:55:58,546 [INFO] django.server: "OPTIONS /api/tenant/config/ HTTP/1.1" 200 0
2025-07-28 11:55:59,452 [INFO] django.server: "GET /api/talent-engine/requisitions/ HTTP/1.1" 200 7736
2025-07-28 11:56:00,106 [INFO] users: Retrieved 6 users for tenant proliance
2025-07-28 11:56:00,680 [INFO] core: Retrieving tenant: 1 for tenant proliance
2025-07-28 11:56:01,792 [INFO] django.server: "GET /api/tenant/tenants/1/ HTTP/1.1" 200 1826
2025-07-28 11:56:03,509 [INFO] core: Fetched TenantConfig for tenant proliance
2025-07-28 11:56:03,511 [INFO] django.server: "GET /api/tenant/config/ HTTP/1.1" 200 1453
2025-07-28 11:56:07,409 [INFO] core: Retrieving tenant: 1 for tenant proliance
2025-07-28 11:56:08,058 [INFO] django.server: "GET /api/user/tenant-users/ HTTP/1.1" 200 1986
2025-07-28 11:56:08,523 [INFO] django.server: "GET /api/tenant/tenants/1/ HTTP/1.1" 200 1826
2025-07-28 11:56:08,688 [INFO] core: Fetched TenantConfig for tenant proliance
2025-07-28 11:56:08,689 [INFO] django.server: "GET /api/tenant/config/ HTTP/1.1" 200 1453
2025-07-28 11:56:13,023 [INFO] django.server: "GET /api/talent-engine/requisitions/ HTTP/1.1" 200 7736
2025-07-28 11:56:14,053 [INFO] core: Retrieving tenant: 1 for tenant proliance
2025-07-28 11:56:15,198 [INFO] django.server: "GET /api/tenant/tenants/1/ HTTP/1.1" 200 1826
2025-07-28 11:56:20,821 [INFO] core: Retrieving tenant: 1 for tenant proliance
2025-07-28 11:56:21,942 [INFO] django.server: "GET /api/tenant/tenants/1/ HTTP/1.1" 200 1826
2025-07-28 11:56:26,498 [INFO] django.server: "GET /api/talent-engine/requisitions/ HTTP/1.1" 200 7736
2025-07-28 11:56:40,251 [INFO] django.server: "GET /api/talent-engine/requisitions/ HTTP/1.1" 200 7736
2025-07-28 12:04:42,476 [INFO] django.server: "GET /api/talent-engine/requisitions/ HTTP/1.1" 200 7736
2025-07-28 12:04:55,934 [INFO] django.server: "GET /api/talent-engine/requisitions/ HTTP/1.1" 200 7736
2025-07-28 12:05:02,734 [INFO] django.server: "GET /api/talent-engine/requisitions/ HTTP/1.1" 200 7736
2025-07-28 12:05:02,758 [INFO] django.server: "GET /api/talent-engine/requisitions/ HTTP/1.1" 200 7736
2025-07-28 12:10:06,723 [INFO] django.server: "GET /api/token/validate/ HTTP/1.1" 200 388
2025-07-28 12:10:11,070 [INFO] django.server: "GET /api/token/validate/ HTTP/1.1" 200 388
2025-07-28 12:10:20,524 [INFO] django.server: "GET /api/talent-engine/requisitions/ HTTP/1.1" 200 7736
2025-07-28 12:10:34,825 [INFO] django.server: "GET /api/talent-engine/requisitions/ HTTP/1.1" 200 7736
2025-07-28 12:19:18,866 [INFO] django.utils.autoreload: Watching for file changes with StatReloader
2025-07-28 12:35:02,448 [INFO] django.server: "GET /api/token/validate/ HTTP/1.1" 200 388
2025-07-28 12:35:07,049 [INFO] django.server: "GET /api/token/validate/ HTTP/1.1" 200 388
2025-07-28 12:39:19,597 [INFO] django.server: "GET /api/token/validate/ HTTP/1.1" 200 388
2025-07-28 12:39:24,019 [INFO] django.server: "GET /api/token/validate/ HTTP/1.1" 200 388
2025-07-28 12:40:42,465 [INFO] django.utils.autoreload: Watching for file changes with StatReloader
2025-07-28 12:41:21,960 [INFO] django.server: "GET /api/token/validate/ HTTP/1.1" 200 388
2025-07-28 12:41:26,463 [INFO] django.server: "GET /api/token/validate/ HTTP/1.1" 200 388
2025-07-28 12:41:48,646 [INFO] django.server: "GET / HTTP/1.1" 200 188
2025-07-28 12:41:52,680 [WARNING] django.request: Not Found: /favicon.ico
2025-07-28 12:41:52,681 [WARNING] django.server: "GET /favicon.ico HTTP/1.1" 404 4265
2025-07-28 12:42:01,862 [INFO] django.server: "GET /api/docs/ HTTP/1.1" 200 4640
2025-07-28 12:42:06,380 [WARNING] talent_engine: Invalid unique_link format: 
2025-07-28 12:42:06,421 [WARNING] core: No valid Bearer token provided
2025-07-28 12:42:06,422 [ERROR] core: Error extracting tenant: Invalid token format
2025-07-28 12:42:06,426 [WARNING] core: No valid Bearer token provided
2025-07-28 12:42:06,427 [ERROR] core: Error extracting tenant: Invalid token format
2025-07-28 12:42:06,430 [WARNING] core: No valid Bearer token provided
2025-07-28 12:42:06,430 [ERROR] core: Error extracting tenant: Invalid token format
2025-07-28 12:42:06,432 [WARNING] core: No valid Bearer token provided
2025-07-28 12:42:06,433 [ERROR] core: Error extracting tenant: Invalid token format
2025-07-28 12:42:06,435 [WARNING] core: No valid Bearer token provided
2025-07-28 12:42:06,435 [ERROR] core: Error extracting tenant: Invalid token format
2025-07-28 12:42:06,439 [WARNING] core: No valid Bearer token provided
2025-07-28 12:42:06,440 [ERROR] core: Error extracting tenant: Invalid token format
2025-07-28 12:42:06,604 [INFO] django.server: "GET /api/schema/ HTTP/1.1" 200 188983
2025-07-28 12:43:38,293 [INFO] django.server: "GET /api/token/validate/ HTTP/1.1" 200 388
2025-07-28 12:43:43,151 [INFO] django.server: "GET /api/token/validate/ HTTP/1.1" 200 388
2025-07-28 13:14:19,955 [INFO] django.utils.autoreload: Watching for file changes with StatReloader
2025-07-28 13:25:49,727 [INFO] django.utils.autoreload: Watching for file changes with StatReloader
2025-07-28 13:37:48,808 [INFO] django.utils.autoreload: C:\Users\CPT-003\Desktop\CRM\crm_api\job_application\views.py changed, reloading.
2025-07-28 13:37:55,391 [INFO] django.utils.autoreload: Watching for file changes with StatReloader
2025-07-28 13:41:20,619 [INFO] django.utils.autoreload: C:\Users\CPT-003\Desktop\CRM\crm_api\lumina_care\settings.py changed, reloading.
2025-07-28 13:41:25,336 [INFO] django.utils.autoreload: Watching for file changes with StatReloader
2025-07-28 13:54:17,874 [INFO] django.utils.autoreload: C:\Users\CPT-003\Desktop\CRM\crm_api\lumina_care\settings.py changed, reloading.
2025-07-28 13:54:22,987 [INFO] django.utils.autoreload: Watching for file changes with StatReloader
2025-07-28 13:54:39,607 [INFO] django.utils.autoreload: C:\Users\CPT-003\Desktop\CRM\crm_api\lumina_care\settings.py changed, reloading.
2025-07-28 13:54:44,541 [INFO] django.utils.autoreload: Watching for file changes with StatReloader
2025-07-28 14:04:48,337 [INFO] django.utils.autoreload: C:\Users\CPT-003\Desktop\CRM\crm_api\lumina_care\settings.py changed, reloading.
2025-07-28 14:24:58,093 [INFO] django.utils.autoreload: Watching for file changes with StatReloader
2025-07-28 14:25:15,561 [INFO] django.utils.autoreload: Watching for file changes with StatReloader
2025-07-28 14:29:31,070 [INFO] django.server: "OPTIONS /api/token/validate/ HTTP/1.1" 200 0
2025-07-28 14:29:31,073 [INFO] django.server: "OPTIONS /api/talent-engine-job-applications/applications/job-requisitions/PRO-0024/applications/ HTTP/1.1" 200 0
2025-07-28 14:29:31,331 [INFO] django.server: "GET /api/token/validate/ HTTP/1.1" 200 389
2025-07-28 14:29:31,383 [ERROR] django.request: Internal Server Error: /api/talent-engine-job-applications/applications/job-requisitions/PRO-0024/applications/
2025-07-28 14:29:31,385 [ERROR] django.server: "GET /api/talent-engine-job-applications/applications/job-requisitions/PRO-0024/applications/ HTTP/1.1" 500 217
2025-07-28 14:29:41,278 [INFO] django.server: "GET /api/token/validate/ HTTP/1.1" 200 389
2025-07-28 14:29:41,310 [ERROR] django.request: Internal Server Error: /api/talent-engine-job-applications/applications/job-requisitions/PRO-0024/applications/
2025-07-28 14:29:41,313 [ERROR] django.server: "GET /api/talent-engine-job-applications/applications/job-requisitions/PRO-0024/applications/ HTTP/1.1" 500 217
2025-07-28 14:30:05,175 [INFO] django.server: "OPTIONS /api/token/ HTTP/1.1" 200 0
2025-07-28 14:30:08,462 [WARNING] django.request: Unauthorized: /api/token/
2025-07-28 14:30:08,464 [WARNING] django.server: "POST /api/token/ HTTP/1.1" 401 63
2025-07-28 14:30:18,092 [WARNING] django.request: Unauthorized: /api/token/
2025-07-28 14:30:18,095 [WARNING] django.server: "POST /api/token/ HTTP/1.1" 401 63
2025-07-28 14:30:34,282 [WARNING] django.request: Unauthorized: /api/token/
2025-07-28 14:30:34,283 [WARNING] django.server: "POST /api/token/ HTTP/1.1" 401 63
2025-07-28 14:30:46,945 [INFO] django.server: "POST /api/token/ HTTP/1.1" 200 965
2025-07-28 14:30:47,208 [INFO] django.server: "GET /api/token/validate/ HTTP/1.1" 200 389
2025-07-28 14:30:47,378 [INFO] django.server: "OPTIONS /api/user/tenant-users/ HTTP/1.1" 200 0
2025-07-28 14:30:47,384 [INFO] django.server: "OPTIONS /api/user/tenant-users/ HTTP/1.1" 200 0
2025-07-28 14:30:47,449 [INFO] django.server: "GET /api/token/validate/ HTTP/1.1" 200 389
2025-07-28 14:30:47,656 [INFO] users: Retrieved 3 users for tenant proliance
2025-07-28 14:30:47,689 [INFO] django.server: "GET /api/user/tenant-users/ HTTP/1.1" 200 1022
2025-07-28 14:30:47,944 [INFO] users: Retrieved 3 users for tenant proliance
2025-07-28 14:30:47,988 [INFO] django.server: "GET /api/user/tenant-users/ HTTP/1.1" 200 1022
2025-07-28 14:30:55,129 [INFO] django.server: "OPTIONS /api/talent-engine/requisitions/ HTTP/1.1" 200 0
2025-07-28 14:30:55,130 [INFO] django.server: "OPTIONS /api/talent-engine/requisitions/ HTTP/1.1" 200 0
2025-07-28 14:30:55,621 [INFO] django.server: "GET /api/talent-engine/requisitions/ HTTP/1.1" 200 6330
2025-07-28 14:30:55,885 [INFO] django.server: "GET /api/talent-engine/requisitions/ HTTP/1.1" 200 6330
2025-07-28 14:30:57,187 [INFO] django.server: "GET /api/talent-engine/requisitions/ HTTP/1.1" 200 6330
2025-07-28 14:30:57,462 [INFO] django.server: "GET /api/talent-engine/requisitions/ HTTP/1.1" 200 6330
2025-07-28 14:31:01,075 [INFO] django.server: "OPTIONS /api/talent-engine-job-applications/applications/job-requisitions/PRO-0003/applications/ HTTP/1.1" 200 0
2025-07-28 14:31:01,078 [INFO] django.server: "OPTIONS /api/talent-engine-job-applications/applications/job-requisitions/PRO-0003/applications/ HTTP/1.1" 200 0
2025-07-28 14:31:01,338 [INFO] django.server: "GET /api/talent-engine-job-applications/applications/job-requisitions/PRO-0003/applications/ HTTP/1.1" 200 6987
2025-07-28 14:31:01,559 [INFO] django.server: "GET /api/talent-engine-job-applications/applications/job-requisitions/PRO-0003/applications/ HTTP/1.1" 200 6987
2025-07-28 14:31:06,768 [INFO] django.server: "OPTIONS /api/talent-engine-job-applications/requisitions/PRO-0003/screen-resumes/ HTTP/1.1" 200 0
2025-07-28 14:31:29,195 [INFO] django.server: "POST /api/talent-engine-job-applications/requisitions/PRO-0003/screen-resumes/ HTTP/1.1" 200 855
2025-07-28 14:31:29,471 [INFO] django.server: "GET /api/talent-engine-job-applications/applications/job-requisitions/PRO-0003/applications/ HTTP/1.1" 200 6987
2025-07-28 14:31:36,464 [INFO] django.server: "POST /api/talent-engine-job-applications/requisitions/PRO-0003/screen-resumes/ HTTP/1.1" 200 855
2025-07-28 14:31:36,706 [INFO] django.server: "GET /api/talent-engine-job-applications/applications/job-requisitions/PRO-0003/applications/ HTTP/1.1" 200 6987
2025-07-28 15:42:33,981 [INFO] django.utils.autoreload: Watching for file changes with StatReloader
2025-07-28 15:52:22,543 [WARNING] django.request: Unauthorized: /api/talent-engine/requisitions/
2025-07-28 15:52:22,545 [WARNING] django.server: "GET /api/talent-engine/requisitions/ HTTP/1.1" 401 58
2025-07-28 15:52:26,008 [WARNING] django.request: Unauthorized: /api/talent-engine/requisitions/
2025-07-28 15:52:26,010 [INFO] django.server: - Broken pipe from ('127.0.0.1', 51158)
2025-07-28 15:52:52,378 [INFO] django.utils.autoreload: Watching for file changes with StatReloader
2025-07-28 15:53:34,881 [WARNING] django.request: Unauthorized: /api/token/
2025-07-28 15:53:34,882 [WARNING] django.server: "POST /api/token/ HTTP/1.1" 401 63
2025-07-28 15:53:45,225 [WARNING] django.request: Unauthorized: /api/token/
2025-07-28 15:53:45,227 [WARNING] django.server: "POST /api/token/ HTTP/1.1" 401 63
2025-07-28 15:53:54,464 [WARNING] django.request: Unauthorized: /api/token/
2025-07-28 15:53:54,465 [WARNING] django.server: "POST /api/token/ HTTP/1.1" 401 63
2025-07-28 15:54:00,339 [WARNING] django.request: Unauthorized: /api/token/
2025-07-28 15:54:00,341 [WARNING] django.server: "POST /api/token/ HTTP/1.1" 401 63
2025-07-28 15:54:15,947 [INFO] django.server: "POST /api/token/ HTTP/1.1" 200 965
2025-07-28 15:54:16,148 [INFO] django.server: "GET /api/token/validate/ HTTP/1.1" 200 389
2025-07-28 15:54:16,300 [INFO] django.server: "GET /api/token/validate/ HTTP/1.1" 200 389
2025-07-28 15:54:16,600 [INFO] users: Retrieved 3 users for tenant proliance
2025-07-28 15:54:16,627 [INFO] django.server: "GET /api/user/tenant-users/ HTTP/1.1" 200 1022
2025-07-28 15:54:16,788 [INFO] users: Retrieved 3 users for tenant proliance
2025-07-28 15:54:16,821 [INFO] django.server: "GET /api/user/tenant-users/ HTTP/1.1" 200 1022
2025-07-28 15:54:22,579 [INFO] django.server: "GET /api/talent-engine/requisitions/ HTTP/1.1" 200 6330
2025-07-28 15:54:22,799 [INFO] django.server: "GET /api/talent-engine/requisitions/ HTTP/1.1" 200 6330
2025-07-28 15:54:26,680 [INFO] django.server: "GET /api/talent-engine/requisitions/ HTTP/1.1" 200 6330
2025-07-28 15:54:26,991 [INFO] django.server: "GET /api/talent-engine/requisitions/ HTTP/1.1" 200 6330
2025-07-28 15:54:27,263 [INFO] django.server: "GET /api/talent-engine/requisitions/ HTTP/1.1" 200 6330
2025-07-28 15:54:27,517 [INFO] django.server: "GET /api/talent-engine/requisitions/ HTTP/1.1" 200 6330
2025-07-28 15:54:30,984 [INFO] django.server: "GET /api/talent-engine/requisitions/ HTTP/1.1" 200 6330
2025-07-28 15:54:31,228 [INFO] django.server: "GET /api/talent-engine/requisitions/ HTTP/1.1" 200 6330
2025-07-28 15:54:35,068 [INFO] django.server: "OPTIONS /api/talent-engine-job-applications/published-requisitions-with-shortlisted/ HTTP/1.1" 200 0
2025-07-28 15:54:35,072 [INFO] django.server: "OPTIONS /api/tenant/config/?t=1753714475047 HTTP/1.1" 200 0
2025-07-28 15:54:35,086 [INFO] django.server: "OPTIONS /api/tenant/config/?t=1753714475049 HTTP/1.1" 200 0
2025-07-28 15:54:35,100 [INFO] django.server: "OPTIONS /api/talent-engine-job-applications/published-requisitions-with-shortlisted/ HTTP/1.1" 200 0
2025-07-28 15:54:35,351 [INFO] core: Fetched TenantConfig for tenant proliance
2025-07-28 15:54:35,358 [INFO] django.server: "GET /api/tenant/config/?t=1753714475049 HTTP/1.1" 200 2185
2025-07-28 15:54:35,367 [INFO] core: Fetched TenantConfig for tenant proliance
2025-07-28 15:54:35,372 [INFO] django.server: "GET /api/tenant/config/?t=1753714475047 HTTP/1.1" 200 2185
2025-07-28 15:54:36,122 [INFO] django.server: "GET /api/talent-engine-job-applications/published-requisitions-with-shortlisted/ HTTP/1.1" 200 14595
2025-07-28 15:54:37,211 [INFO] django.server: "GET /api/talent-engine-job-applications/published-requisitions-with-shortlisted/ HTTP/1.1" 200 14595
2025-07-28 15:54:37,737 [INFO] django.server: "GET /api/talent-engine/requisitions/ HTTP/1.1" 200 6330
2025-07-28 15:54:37,945 [INFO] django.server: "GET /api/talent-engine/requisitions/ HTTP/1.1" 200 6330
2025-07-28 15:54:38,444 [INFO] django.server: "GET /api/talent-engine/requisitions/ HTTP/1.1" 200 6330
2025-07-28 15:54:38,634 [INFO] django.server: "GET /api/talent-engine/requisitions/ HTTP/1.1" 200 6330
2025-07-28 15:54:43,101 [INFO] django.server: "GET /api/talent-engine-job-applications/applications/job-requisitions/PRO-0003/applications/ HTTP/1.1" 200 6987
2025-07-28 15:54:43,366 [INFO] django.server: "GET /api/talent-engine-job-applications/applications/job-requisitions/PRO-0003/applications/ HTTP/1.1" 200 6987
2025-07-28 15:55:24,045 [INFO] django.server: "POST /api/talent-engine-job-applications/requisitions/PRO-0003/screen-resumes/ HTTP/1.1" 200 855
2025-07-28 15:55:24,315 [INFO] django.server: "GET /api/talent-engine-job-applications/applications/job-requisitions/PRO-0003/applications/ HTTP/1.1" 200 6987
2025-07-28 15:55:59,380 [INFO] django.server: "POST /api/talent-engine-job-applications/requisitions/PRO-0003/screen-resumes/ HTTP/1.1" 200 855
2025-07-28 15:55:59,679 [INFO] django.server: "GET /api/talent-engine-job-applications/applications/job-requisitions/PRO-0003/applications/ HTTP/1.1" 200 6987
2025-07-28 15:56:08,834 [INFO] django.server: "POST /api/talent-engine-job-applications/requisitions/PRO-0003/screen-resumes/ HTTP/1.1" 200 855
2025-07-28 15:56:09,086 [INFO] django.server: "GET /api/talent-engine-job-applications/applications/job-requisitions/PRO-0003/applications/ HTTP/1.1" 200 6987
2025-07-28 15:56:22,058 [INFO] django.server: "POST /api/talent-engine-job-applications/requisitions/PRO-0003/screen-resumes/ HTTP/1.1" 200 855
2025-07-28 15:56:22,347 [INFO] django.server: "GET /api/talent-engine-job-applications/applications/job-requisitions/PRO-0003/applications/ HTTP/1.1" 200 6987
2025-07-28 15:56:30,146 [INFO] django.server: "POST /api/talent-engine-job-applications/requisitions/PRO-0003/screen-resumes/ HTTP/1.1" 200 855
2025-07-28 15:56:30,375 [INFO] django.server: "GET /api/talent-engine-job-applications/applications/job-requisitions/PRO-0003/applications/ HTTP/1.1" 200 6987
2025-07-28 15:56:44,199 [INFO] django.server: "POST /api/talent-engine-job-applications/requisitions/PRO-0003/screen-resumes/ HTTP/1.1" 200 855
2025-07-28 15:56:44,426 [INFO] django.server: "GET /api/talent-engine-job-applications/applications/job-requisitions/PRO-0003/applications/ HTTP/1.1" 200 6987
2025-07-28 15:57:12,260 [INFO] django.server: "POST /api/talent-engine-job-applications/requisitions/PRO-0003/screen-resumes/ HTTP/1.1" 200 855
2025-07-28 15:57:12,491 [INFO] django.server: "GET /api/talent-engine-job-applications/applications/job-requisitions/PRO-0003/applications/ HTTP/1.1" 200 6987
2025-07-28 15:57:30,898 [INFO] django.server: "POST /api/talent-engine-job-applications/requisitions/PRO-0003/screen-resumes/ HTTP/1.1" 200 855
2025-07-28 15:57:31,115 [INFO] django.server: "GET /api/talent-engine-job-applications/applications/job-requisitions/PRO-0003/applications/ HTTP/1.1" 200 6987
2025-07-28 16:07:24,409 [INFO] django.utils.autoreload: C:\Users\CPT-003\Desktop\CRM\crm_api\job_application\views.py changed, reloading.
2025-07-28 16:07:32,063 [INFO] django.utils.autoreload: Watching for file changes with StatReloader
2025-07-28 16:16:48,413 [INFO] django.utils.autoreload: Watching for file changes with StatReloader
2025-07-28 16:17:28,548 [ERROR] django.security.DisallowedHost: Invalid HTTP_HOST header: '0e279ae7ea4b.ngrok-free.app'. You may need to add '0e279ae7ea4b.ngrok-free.app' to ALLOWED_HOSTS.
Traceback (most recent call last):
  File "C:\Users\CPT-003\Desktop\CRM\crm_api\venv\Lib\site-packages\django\core\handlers\exception.py", line 55, in inner
    response = get_response(request)
  File "C:\Users\CPT-003\Desktop\CRM\crm_api\venv\Lib\site-packages\django\utils\deprecation.py", line 119, in __call__
    response = self.process_request(request)
  File "C:\Users\CPT-003\Desktop\CRM\crm_api\lumina_care\middleware.py", line 178, in process_request
    logger.debug(f"Processing request: {request.path}, Host: {request.get_host()}")
                                                              ~~~~~~~~~~~~~~~~^^
  File "C:\Users\CPT-003\Desktop\CRM\crm_api\venv\Lib\site-packages\django\http\request.py", line 191, in get_host
    raise DisallowedHost(msg)
django.core.exceptions.DisallowedHost: Invalid HTTP_HOST header: '0e279ae7ea4b.ngrok-free.app'. You may need to add '0e279ae7ea4b.ngrok-free.app' to ALLOWED_HOSTS.
2025-07-28 16:17:29,268 [WARNING] django.request: Bad Request: /
2025-07-28 16:17:29,270 [WARNING] django.server: "GET / HTTP/1.1" 400 87394
2025-07-28 16:17:30,612 [ERROR] django.security.DisallowedHost: Invalid HTTP_HOST header: '0e279ae7ea4b.ngrok-free.app'. You may need to add '0e279ae7ea4b.ngrok-free.app' to ALLOWED_HOSTS.
Traceback (most recent call last):
  File "C:\Users\CPT-003\Desktop\CRM\crm_api\venv\Lib\site-packages\django\core\handlers\exception.py", line 55, in inner
    response = get_response(request)
  File "C:\Users\CPT-003\Desktop\CRM\crm_api\venv\Lib\site-packages\django\utils\deprecation.py", line 119, in __call__
    response = self.process_request(request)
  File "C:\Users\CPT-003\Desktop\CRM\crm_api\lumina_care\middleware.py", line 178, in process_request
    logger.debug(f"Processing request: {request.path}, Host: {request.get_host()}")
                                                              ~~~~~~~~~~~~~~~~^^
  File "C:\Users\CPT-003\Desktop\CRM\crm_api\venv\Lib\site-packages\django\http\request.py", line 191, in get_host
    raise DisallowedHost(msg)
django.core.exceptions.DisallowedHost: Invalid HTTP_HOST header: '0e279ae7ea4b.ngrok-free.app'. You may need to add '0e279ae7ea4b.ngrok-free.app' to ALLOWED_HOSTS.
2025-07-28 16:17:30,690 [WARNING] django.request: Bad Request: /favicon.ico
2025-07-28 16:17:30,692 [WARNING] django.server: "GET /favicon.ico HTTP/1.1" 400 87085
2025-07-28 16:20:34,536 [ERROR] django.security.DisallowedHost: Invalid HTTP_HOST header: '0e279ae7ea4b.ngrok-free.app'. You may need to add '0e279ae7ea4b.ngrok-free.app' to ALLOWED_HOSTS.
Traceback (most recent call last):
  File "C:\Users\CPT-003\Desktop\CRM\crm_api\venv\Lib\site-packages\django\core\handlers\exception.py", line 55, in inner
    response = get_response(request)
  File "C:\Users\CPT-003\Desktop\CRM\crm_api\venv\Lib\site-packages\django\utils\deprecation.py", line 119, in __call__
    response = self.process_request(request)
  File "C:\Users\CPT-003\Desktop\CRM\crm_api\lumina_care\middleware.py", line 178, in process_request
    logger.debug(f"Processing request: {request.path}, Host: {request.get_host()}")
                                                              ~~~~~~~~~~~~~~~~^^
  File "C:\Users\CPT-003\Desktop\CRM\crm_api\venv\Lib\site-packages\django\http\request.py", line 191, in get_host
    raise DisallowedHost(msg)
django.core.exceptions.DisallowedHost: Invalid HTTP_HOST header: '0e279ae7ea4b.ngrok-free.app'. You may need to add '0e279ae7ea4b.ngrok-free.app' to ALLOWED_HOSTS.
2025-07-28 16:20:34,652 [WARNING] django.request: Bad Request: /
2025-07-28 16:20:34,654 [WARNING] django.server: "GET / HTTP/1.1" 400 87394
2025-07-28 16:20:35,924 [ERROR] django.security.DisallowedHost: Invalid HTTP_HOST header: '0e279ae7ea4b.ngrok-free.app'. You may need to add '0e279ae7ea4b.ngrok-free.app' to ALLOWED_HOSTS.
Traceback (most recent call last):
  File "C:\Users\CPT-003\Desktop\CRM\crm_api\venv\Lib\site-packages\django\core\handlers\exception.py", line 55, in inner
    response = get_response(request)
  File "C:\Users\CPT-003\Desktop\CRM\crm_api\venv\Lib\site-packages\django\utils\deprecation.py", line 119, in __call__
    response = self.process_request(request)
  File "C:\Users\CPT-003\Desktop\CRM\crm_api\lumina_care\middleware.py", line 178, in process_request
    logger.debug(f"Processing request: {request.path}, Host: {request.get_host()}")
                                                              ~~~~~~~~~~~~~~~~^^
  File "C:\Users\CPT-003\Desktop\CRM\crm_api\venv\Lib\site-packages\django\http\request.py", line 191, in get_host
    raise DisallowedHost(msg)
django.core.exceptions.DisallowedHost: Invalid HTTP_HOST header: '0e279ae7ea4b.ngrok-free.app'. You may need to add '0e279ae7ea4b.ngrok-free.app' to ALLOWED_HOSTS.
2025-07-28 16:20:36,046 [WARNING] django.request: Bad Request: /favicon.ico
2025-07-28 16:20:36,048 [WARNING] django.server: "GET /favicon.ico HTTP/1.1" 400 87085
2025-07-28 16:21:09,020 [INFO] django.utils.autoreload: Watching for file changes with StatReloader
2025-07-28 16:22:52,112 [WARNING] django.request: Not Found: /
2025-07-28 16:22:52,115 [WARNING] django.server: "GET / HTTP/1.1" 404 1953
2025-07-28 16:22:55,532 [WARNING] django.request: Not Found: /favicon.ico
2025-07-28 16:22:55,535 [WARNING] django.server: "GET /favicon.ico HTTP/1.1" 404 1861
2025-07-28 16:24:16,517 [INFO] django.utils.autoreload: C:\Users\CPT-003\Desktop\CRM\crm_api\talent_engine\views.py changed, reloading.
2025-07-28 16:24:24,148 [INFO] django.utils.autoreload: Watching for file changes with StatReloader
2025-07-28 16:59:52,001 [INFO] django.utils.autoreload: C:\Users\CPT-003\Desktop\CRM\crm_api\talent_engine\views.py changed, reloading.
2025-07-28 17:00:01,097 [INFO] django.utils.autoreload: Watching for file changes with StatReloader
2025-07-28 17:02:46,950 [INFO] django.server: "OPTIONS /api/token/validate/ HTTP/1.1" 200 0
2025-07-28 17:02:46,954 [INFO] django.server: "OPTIONS /api/token/validate/ HTTP/1.1" 200 0
2025-07-28 17:03:40,808 [ERROR] django.request: Internal Server Error: /api/token/validate/
Traceback (most recent call last):
  File "C:\Users\CPT-003\Desktop\CRM\crm_api\venv\Lib\site-packages\django\db\backends\base\base.py", line 279, in ensure_connection
    self.connect()
    ~~~~~~~~~~~~^^
  File "C:\Users\CPT-003\Desktop\CRM\crm_api\venv\Lib\site-packages\django\utils\asyncio.py", line 26, in inner
    return func(*args, **kwargs)
  File "C:\Users\CPT-003\Desktop\CRM\crm_api\venv\Lib\site-packages\django\db\backends\base\base.py", line 256, in connect
    self.connection = self.get_new_connection(conn_params)
                      ~~~~~~~~~~~~~~~~~~~~~~~^^^^^^^^^^^^^
  File "C:\Users\CPT-003\Desktop\CRM\crm_api\venv\Lib\site-packages\django\utils\asyncio.py", line 26, in inner
    return func(*args, **kwargs)
  File "C:\Users\CPT-003\Desktop\CRM\crm_api\venv\Lib\site-packages\django\db\backends\postgresql\base.py", line 332, in get_new_connection
    connection = self.Database.connect(**conn_params)
  File "C:\Users\CPT-003\Desktop\CRM\crm_api\venv\Lib\site-packages\psycopg2\__init__.py", line 135, in connect
    conn = _connect(dsn, connection_factory=connection_factory, **kwasync)
psycopg2.OperationalError: connection to server at "dpg-d208jbje5dus73d4h87g-a.oregon-postgres.render.com" (192.168.50.48), port 5432 failed: Connection timed out (0x0000274C/10060)
	Is the server running on that host and accepting TCP/IP connections?


The above exception was the direct cause of the following exception:

Traceback (most recent call last):
  File "C:\Users\CPT-003\Desktop\CRM\crm_api\venv\Lib\site-packages\django\core\handlers\exception.py", line 55, in inner
    response = get_response(request)
  File "C:\Users\CPT-003\Desktop\CRM\crm_api\venv\Lib\site-packages\django\utils\deprecation.py", line 119, in __call__
    response = self.process_request(request)
  File "C:\Users\CPT-003\Desktop\CRM\crm_api\lumina_care\middleware.py", line 188, in process_request
    public_tenant = Tenant.objects.get(schema_name=get_public_schema_name())
  File "C:\Users\CPT-003\Desktop\CRM\crm_api\venv\Lib\site-packages\django\db\models\manager.py", line 87, in manager_method
    return getattr(self.get_queryset(), name)(*args, **kwargs)
           ~~~~~~~~~~~~~~~~~~~~~~~~~~~~~~~~~~^^^^^^^^^^^^^^^^^
  File "C:\Users\CPT-003\Desktop\CRM\crm_api\venv\Lib\site-packages\django\db\models\query.py", line 629, in get
    num = len(clone)
  File "C:\Users\CPT-003\Desktop\CRM\crm_api\venv\Lib\site-packages\django\db\models\query.py", line 366, in __len__
    self._fetch_all()
    ~~~~~~~~~~~~~~~^^
  File "C:\Users\CPT-003\Desktop\CRM\crm_api\venv\Lib\site-packages\django\db\models\query.py", line 1949, in _fetch_all
    self._result_cache = list(self._iterable_class(self))
                         ~~~~^^^^^^^^^^^^^^^^^^^^^^^^^^^^
  File "C:\Users\CPT-003\Desktop\CRM\crm_api\venv\Lib\site-packages\django\db\models\query.py", line 91, in __iter__
    results = compiler.execute_sql(
        chunked_fetch=self.chunked_fetch, chunk_size=self.chunk_size
    )
  File "C:\Users\CPT-003\Desktop\CRM\crm_api\venv\Lib\site-packages\django\db\models\sql\compiler.py", line 1621, in execute_sql
    cursor = self.connection.cursor()
  File "C:\Users\CPT-003\Desktop\CRM\crm_api\venv\Lib\site-packages\django\utils\asyncio.py", line 26, in inner
    return func(*args, **kwargs)
  File "C:\Users\CPT-003\Desktop\CRM\crm_api\venv\Lib\site-packages\django\db\backends\base\base.py", line 320, in cursor
    return self._cursor()
           ~~~~~~~~~~~~^^
  File "C:\Users\CPT-003\Desktop\CRM\crm_api\venv\Lib\site-packages\django_tenants\postgresql_backend\base.py", line 144, in _cursor
    cursor = super()._cursor()
  File "C:\Users\CPT-003\Desktop\CRM\crm_api\venv\Lib\site-packages\django\db\backends\base\base.py", line 296, in _cursor
    self.ensure_connection()
    ~~~~~~~~~~~~~~~~~~~~~~^^
  File "C:\Users\CPT-003\Desktop\CRM\crm_api\venv\Lib\site-packages\django\utils\asyncio.py", line 26, in inner
    return func(*args, **kwargs)
  File "C:\Users\CPT-003\Desktop\CRM\crm_api\venv\Lib\site-packages\django\db\backends\base\base.py", line 278, in ensure_connection
    with self.wrap_database_errors:
         ^^^^^^^^^^^^^^^^^^^^^^^^^
  File "C:\Users\CPT-003\Desktop\CRM\crm_api\venv\Lib\site-packages\django\db\utils.py", line 91, in __exit__
    raise dj_exc_value.with_traceback(traceback) from exc_value
  File "C:\Users\CPT-003\Desktop\CRM\crm_api\venv\Lib\site-packages\django\db\backends\base\base.py", line 279, in ensure_connection
    self.connect()
    ~~~~~~~~~~~~^^
  File "C:\Users\CPT-003\Desktop\CRM\crm_api\venv\Lib\site-packages\django\utils\asyncio.py", line 26, in inner
    return func(*args, **kwargs)
  File "C:\Users\CPT-003\Desktop\CRM\crm_api\venv\Lib\site-packages\django\db\backends\base\base.py", line 256, in connect
    self.connection = self.get_new_connection(conn_params)
                      ~~~~~~~~~~~~~~~~~~~~~~~^^^^^^^^^^^^^
  File "C:\Users\CPT-003\Desktop\CRM\crm_api\venv\Lib\site-packages\django\utils\asyncio.py", line 26, in inner
    return func(*args, **kwargs)
  File "C:\Users\CPT-003\Desktop\CRM\crm_api\venv\Lib\site-packages\django\db\backends\postgresql\base.py", line 332, in get_new_connection
    connection = self.Database.connect(**conn_params)
  File "C:\Users\CPT-003\Desktop\CRM\crm_api\venv\Lib\site-packages\psycopg2\__init__.py", line 135, in connect
    conn = _connect(dsn, connection_factory=connection_factory, **kwasync)
django.db.utils.OperationalError: connection to server at "dpg-d208jbje5dus73d4h87g-a.oregon-postgres.render.com" (192.168.50.48), port 5432 failed: Connection timed out (0x0000274C/10060)
	Is the server running on that host and accepting TCP/IP connections?

2025-07-28 17:03:40,809 [ERROR] django.request: Internal Server Error: /api/token/validate/
Traceback (most recent call last):
  File "C:\Users\CPT-003\Desktop\CRM\crm_api\venv\Lib\site-packages\django\db\backends\base\base.py", line 279, in ensure_connection
    self.connect()
    ~~~~~~~~~~~~^^
  File "C:\Users\CPT-003\Desktop\CRM\crm_api\venv\Lib\site-packages\django\utils\asyncio.py", line 26, in inner
    return func(*args, **kwargs)
  File "C:\Users\CPT-003\Desktop\CRM\crm_api\venv\Lib\site-packages\django\db\backends\base\base.py", line 256, in connect
    self.connection = self.get_new_connection(conn_params)
                      ~~~~~~~~~~~~~~~~~~~~~~~^^^^^^^^^^^^^
  File "C:\Users\CPT-003\Desktop\CRM\crm_api\venv\Lib\site-packages\django\utils\asyncio.py", line 26, in inner
    return func(*args, **kwargs)
  File "C:\Users\CPT-003\Desktop\CRM\crm_api\venv\Lib\site-packages\django\db\backends\postgresql\base.py", line 332, in get_new_connection
    connection = self.Database.connect(**conn_params)
  File "C:\Users\CPT-003\Desktop\CRM\crm_api\venv\Lib\site-packages\psycopg2\__init__.py", line 135, in connect
    conn = _connect(dsn, connection_factory=connection_factory, **kwasync)
psycopg2.OperationalError: connection to server at "dpg-d208jbje5dus73d4h87g-a.oregon-postgres.render.com" (192.168.50.48), port 5432 failed: Connection timed out (0x0000274C/10060)
	Is the server running on that host and accepting TCP/IP connections?


The above exception was the direct cause of the following exception:

Traceback (most recent call last):
  File "C:\Users\CPT-003\Desktop\CRM\crm_api\venv\Lib\site-packages\django\core\handlers\exception.py", line 55, in inner
    response = get_response(request)
  File "C:\Users\CPT-003\Desktop\CRM\crm_api\venv\Lib\site-packages\django\utils\deprecation.py", line 119, in __call__
    response = self.process_request(request)
  File "C:\Users\CPT-003\Desktop\CRM\crm_api\lumina_care\middleware.py", line 188, in process_request
    public_tenant = Tenant.objects.get(schema_name=get_public_schema_name())
  File "C:\Users\CPT-003\Desktop\CRM\crm_api\venv\Lib\site-packages\django\db\models\manager.py", line 87, in manager_method
    return getattr(self.get_queryset(), name)(*args, **kwargs)
           ~~~~~~~~~~~~~~~~~~~~~~~~~~~~~~~~~~^^^^^^^^^^^^^^^^^
  File "C:\Users\CPT-003\Desktop\CRM\crm_api\venv\Lib\site-packages\django\db\models\query.py", line 629, in get
    num = len(clone)
  File "C:\Users\CPT-003\Desktop\CRM\crm_api\venv\Lib\site-packages\django\db\models\query.py", line 366, in __len__
    self._fetch_all()
    ~~~~~~~~~~~~~~~^^
  File "C:\Users\CPT-003\Desktop\CRM\crm_api\venv\Lib\site-packages\django\db\models\query.py", line 1949, in _fetch_all
    self._result_cache = list(self._iterable_class(self))
                         ~~~~^^^^^^^^^^^^^^^^^^^^^^^^^^^^
  File "C:\Users\CPT-003\Desktop\CRM\crm_api\venv\Lib\site-packages\django\db\models\query.py", line 91, in __iter__
    results = compiler.execute_sql(
        chunked_fetch=self.chunked_fetch, chunk_size=self.chunk_size
    )
  File "C:\Users\CPT-003\Desktop\CRM\crm_api\venv\Lib\site-packages\django\db\models\sql\compiler.py", line 1621, in execute_sql
    cursor = self.connection.cursor()
  File "C:\Users\CPT-003\Desktop\CRM\crm_api\venv\Lib\site-packages\django\utils\asyncio.py", line 26, in inner
    return func(*args, **kwargs)
  File "C:\Users\CPT-003\Desktop\CRM\crm_api\venv\Lib\site-packages\django\db\backends\base\base.py", line 320, in cursor
    return self._cursor()
           ~~~~~~~~~~~~^^
  File "C:\Users\CPT-003\Desktop\CRM\crm_api\venv\Lib\site-packages\django_tenants\postgresql_backend\base.py", line 144, in _cursor
    cursor = super()._cursor()
  File "C:\Users\CPT-003\Desktop\CRM\crm_api\venv\Lib\site-packages\django\db\backends\base\base.py", line 296, in _cursor
    self.ensure_connection()
    ~~~~~~~~~~~~~~~~~~~~~~^^
  File "C:\Users\CPT-003\Desktop\CRM\crm_api\venv\Lib\site-packages\django\utils\asyncio.py", line 26, in inner
    return func(*args, **kwargs)
  File "C:\Users\CPT-003\Desktop\CRM\crm_api\venv\Lib\site-packages\django\db\backends\base\base.py", line 278, in ensure_connection
    with self.wrap_database_errors:
         ^^^^^^^^^^^^^^^^^^^^^^^^^
  File "C:\Users\CPT-003\Desktop\CRM\crm_api\venv\Lib\site-packages\django\db\utils.py", line 91, in __exit__
    raise dj_exc_value.with_traceback(traceback) from exc_value
  File "C:\Users\CPT-003\Desktop\CRM\crm_api\venv\Lib\site-packages\django\db\backends\base\base.py", line 279, in ensure_connection
    self.connect()
    ~~~~~~~~~~~~^^
  File "C:\Users\CPT-003\Desktop\CRM\crm_api\venv\Lib\site-packages\django\utils\asyncio.py", line 26, in inner
    return func(*args, **kwargs)
  File "C:\Users\CPT-003\Desktop\CRM\crm_api\venv\Lib\site-packages\django\db\backends\base\base.py", line 256, in connect
    self.connection = self.get_new_connection(conn_params)
                      ~~~~~~~~~~~~~~~~~~~~~~~^^^^^^^^^^^^^
  File "C:\Users\CPT-003\Desktop\CRM\crm_api\venv\Lib\site-packages\django\utils\asyncio.py", line 26, in inner
    return func(*args, **kwargs)
  File "C:\Users\CPT-003\Desktop\CRM\crm_api\venv\Lib\site-packages\django\db\backends\postgresql\base.py", line 332, in get_new_connection
    connection = self.Database.connect(**conn_params)
  File "C:\Users\CPT-003\Desktop\CRM\crm_api\venv\Lib\site-packages\psycopg2\__init__.py", line 135, in connect
    conn = _connect(dsn, connection_factory=connection_factory, **kwasync)
django.db.utils.OperationalError: connection to server at "dpg-d208jbje5dus73d4h87g-a.oregon-postgres.render.com" (192.168.50.48), port 5432 failed: Connection timed out (0x0000274C/10060)
	Is the server running on that host and accepting TCP/IP connections?

2025-07-28 17:03:40,899 [ERROR] django.server: "GET /api/token/validate/ HTTP/1.1" 500 194111
2025-07-28 17:03:40,916 [ERROR] django.server: "GET /api/token/validate/ HTTP/1.1" 500 194212
2025-07-28 17:03:51,474 [INFO] django.server: "OPTIONS /api/token/ HTTP/1.1" 200 0
2025-07-28 17:03:51,755 [ERROR] django.request: Internal Server Error: /api/token/
Traceback (most recent call last):
  File "C:\Users\CPT-003\Desktop\CRM\crm_api\venv\Lib\site-packages\django\db\backends\base\base.py", line 279, in ensure_connection
    self.connect()
    ~~~~~~~~~~~~^^
  File "C:\Users\CPT-003\Desktop\CRM\crm_api\venv\Lib\site-packages\django\utils\asyncio.py", line 26, in inner
    return func(*args, **kwargs)
  File "C:\Users\CPT-003\Desktop\CRM\crm_api\venv\Lib\site-packages\django\db\backends\base\base.py", line 256, in connect
    self.connection = self.get_new_connection(conn_params)
                      ~~~~~~~~~~~~~~~~~~~~~~~^^^^^^^^^^^^^
  File "C:\Users\CPT-003\Desktop\CRM\crm_api\venv\Lib\site-packages\django\utils\asyncio.py", line 26, in inner
    return func(*args, **kwargs)
  File "C:\Users\CPT-003\Desktop\CRM\crm_api\venv\Lib\site-packages\django\db\backends\postgresql\base.py", line 332, in get_new_connection
    connection = self.Database.connect(**conn_params)
  File "C:\Users\CPT-003\Desktop\CRM\crm_api\venv\Lib\site-packages\psycopg2\__init__.py", line 135, in connect
    conn = _connect(dsn, connection_factory=connection_factory, **kwasync)
psycopg2.OperationalError: could not translate host name "dpg-d208jbje5dus73d4h87g-a.oregon-postgres.render.com" to address: Name or service not known


The above exception was the direct cause of the following exception:

Traceback (most recent call last):
  File "C:\Users\CPT-003\Desktop\CRM\crm_api\venv\Lib\site-packages\django\core\handlers\exception.py", line 55, in inner
    response = get_response(request)
  File "C:\Users\CPT-003\Desktop\CRM\crm_api\venv\Lib\site-packages\django\utils\deprecation.py", line 119, in __call__
    response = self.process_request(request)
  File "C:\Users\CPT-003\Desktop\CRM\crm_api\lumina_care\middleware.py", line 188, in process_request
    public_tenant = Tenant.objects.get(schema_name=get_public_schema_name())
  File "C:\Users\CPT-003\Desktop\CRM\crm_api\venv\Lib\site-packages\django\db\models\manager.py", line 87, in manager_method
    return getattr(self.get_queryset(), name)(*args, **kwargs)
           ~~~~~~~~~~~~~~~~~~~~~~~~~~~~~~~~~~^^^^^^^^^^^^^^^^^
  File "C:\Users\CPT-003\Desktop\CRM\crm_api\venv\Lib\site-packages\django\db\models\query.py", line 629, in get
    num = len(clone)
  File "C:\Users\CPT-003\Desktop\CRM\crm_api\venv\Lib\site-packages\django\db\models\query.py", line 366, in __len__
    self._fetch_all()
    ~~~~~~~~~~~~~~~^^
  File "C:\Users\CPT-003\Desktop\CRM\crm_api\venv\Lib\site-packages\django\db\models\query.py", line 1949, in _fetch_all
    self._result_cache = list(self._iterable_class(self))
                         ~~~~^^^^^^^^^^^^^^^^^^^^^^^^^^^^
  File "C:\Users\CPT-003\Desktop\CRM\crm_api\venv\Lib\site-packages\django\db\models\query.py", line 91, in __iter__
    results = compiler.execute_sql(
        chunked_fetch=self.chunked_fetch, chunk_size=self.chunk_size
    )
  File "C:\Users\CPT-003\Desktop\CRM\crm_api\venv\Lib\site-packages\django\db\models\sql\compiler.py", line 1621, in execute_sql
    cursor = self.connection.cursor()
  File "C:\Users\CPT-003\Desktop\CRM\crm_api\venv\Lib\site-packages\django\utils\asyncio.py", line 26, in inner
    return func(*args, **kwargs)
  File "C:\Users\CPT-003\Desktop\CRM\crm_api\venv\Lib\site-packages\django\db\backends\base\base.py", line 320, in cursor
    return self._cursor()
           ~~~~~~~~~~~~^^
  File "C:\Users\CPT-003\Desktop\CRM\crm_api\venv\Lib\site-packages\django_tenants\postgresql_backend\base.py", line 144, in _cursor
    cursor = super()._cursor()
  File "C:\Users\CPT-003\Desktop\CRM\crm_api\venv\Lib\site-packages\django\db\backends\base\base.py", line 296, in _cursor
    self.ensure_connection()
    ~~~~~~~~~~~~~~~~~~~~~~^^
  File "C:\Users\CPT-003\Desktop\CRM\crm_api\venv\Lib\site-packages\django\utils\asyncio.py", line 26, in inner
    return func(*args, **kwargs)
  File "C:\Users\CPT-003\Desktop\CRM\crm_api\venv\Lib\site-packages\django\db\backends\base\base.py", line 278, in ensure_connection
    with self.wrap_database_errors:
         ^^^^^^^^^^^^^^^^^^^^^^^^^
  File "C:\Users\CPT-003\Desktop\CRM\crm_api\venv\Lib\site-packages\django\db\utils.py", line 91, in __exit__
    raise dj_exc_value.with_traceback(traceback) from exc_value
  File "C:\Users\CPT-003\Desktop\CRM\crm_api\venv\Lib\site-packages\django\db\backends\base\base.py", line 279, in ensure_connection
    self.connect()
    ~~~~~~~~~~~~^^
  File "C:\Users\CPT-003\Desktop\CRM\crm_api\venv\Lib\site-packages\django\utils\asyncio.py", line 26, in inner
    return func(*args, **kwargs)
  File "C:\Users\CPT-003\Desktop\CRM\crm_api\venv\Lib\site-packages\django\db\backends\base\base.py", line 256, in connect
    self.connection = self.get_new_connection(conn_params)
                      ~~~~~~~~~~~~~~~~~~~~~~~^^^^^^^^^^^^^
  File "C:\Users\CPT-003\Desktop\CRM\crm_api\venv\Lib\site-packages\django\utils\asyncio.py", line 26, in inner
    return func(*args, **kwargs)
  File "C:\Users\CPT-003\Desktop\CRM\crm_api\venv\Lib\site-packages\django\db\backends\postgresql\base.py", line 332, in get_new_connection
    connection = self.Database.connect(**conn_params)
  File "C:\Users\CPT-003\Desktop\CRM\crm_api\venv\Lib\site-packages\psycopg2\__init__.py", line 135, in connect
    conn = _connect(dsn, connection_factory=connection_factory, **kwasync)
django.db.utils.OperationalError: could not translate host name "dpg-d208jbje5dus73d4h87g-a.oregon-postgres.render.com" to address: Name or service not known

2025-07-28 17:03:51,868 [ERROR] django.server: "POST /api/token/ HTTP/1.1" 500 193081
2025-07-28 17:04:01,359 [ERROR] django.request: Internal Server Error: /api/token/
Traceback (most recent call last):
  File "C:\Users\CPT-003\Desktop\CRM\crm_api\venv\Lib\site-packages\django\db\backends\base\base.py", line 279, in ensure_connection
    self.connect()
    ~~~~~~~~~~~~^^
  File "C:\Users\CPT-003\Desktop\CRM\crm_api\venv\Lib\site-packages\django\utils\asyncio.py", line 26, in inner
    return func(*args, **kwargs)
  File "C:\Users\CPT-003\Desktop\CRM\crm_api\venv\Lib\site-packages\django\db\backends\base\base.py", line 256, in connect
    self.connection = self.get_new_connection(conn_params)
                      ~~~~~~~~~~~~~~~~~~~~~~~^^^^^^^^^^^^^
  File "C:\Users\CPT-003\Desktop\CRM\crm_api\venv\Lib\site-packages\django\utils\asyncio.py", line 26, in inner
    return func(*args, **kwargs)
  File "C:\Users\CPT-003\Desktop\CRM\crm_api\venv\Lib\site-packages\django\db\backends\postgresql\base.py", line 332, in get_new_connection
    connection = self.Database.connect(**conn_params)
  File "C:\Users\CPT-003\Desktop\CRM\crm_api\venv\Lib\site-packages\psycopg2\__init__.py", line 135, in connect
    conn = _connect(dsn, connection_factory=connection_factory, **kwasync)
psycopg2.OperationalError: could not translate host name "dpg-d208jbje5dus73d4h87g-a.oregon-postgres.render.com" to address: Name or service not known


The above exception was the direct cause of the following exception:

Traceback (most recent call last):
  File "C:\Users\CPT-003\Desktop\CRM\crm_api\venv\Lib\site-packages\django\core\handlers\exception.py", line 55, in inner
    response = get_response(request)
  File "C:\Users\CPT-003\Desktop\CRM\crm_api\venv\Lib\site-packages\django\utils\deprecation.py", line 119, in __call__
    response = self.process_request(request)
  File "C:\Users\CPT-003\Desktop\CRM\crm_api\lumina_care\middleware.py", line 188, in process_request
    public_tenant = Tenant.objects.get(schema_name=get_public_schema_name())
  File "C:\Users\CPT-003\Desktop\CRM\crm_api\venv\Lib\site-packages\django\db\models\manager.py", line 87, in manager_method
    return getattr(self.get_queryset(), name)(*args, **kwargs)
           ~~~~~~~~~~~~~~~~~~~~~~~~~~~~~~~~~~^^^^^^^^^^^^^^^^^
  File "C:\Users\CPT-003\Desktop\CRM\crm_api\venv\Lib\site-packages\django\db\models\query.py", line 629, in get
    num = len(clone)
  File "C:\Users\CPT-003\Desktop\CRM\crm_api\venv\Lib\site-packages\django\db\models\query.py", line 366, in __len__
    self._fetch_all()
    ~~~~~~~~~~~~~~~^^
  File "C:\Users\CPT-003\Desktop\CRM\crm_api\venv\Lib\site-packages\django\db\models\query.py", line 1949, in _fetch_all
    self._result_cache = list(self._iterable_class(self))
                         ~~~~^^^^^^^^^^^^^^^^^^^^^^^^^^^^
  File "C:\Users\CPT-003\Desktop\CRM\crm_api\venv\Lib\site-packages\django\db\models\query.py", line 91, in __iter__
    results = compiler.execute_sql(
        chunked_fetch=self.chunked_fetch, chunk_size=self.chunk_size
    )
  File "C:\Users\CPT-003\Desktop\CRM\crm_api\venv\Lib\site-packages\django\db\models\sql\compiler.py", line 1621, in execute_sql
    cursor = self.connection.cursor()
  File "C:\Users\CPT-003\Desktop\CRM\crm_api\venv\Lib\site-packages\django\utils\asyncio.py", line 26, in inner
    return func(*args, **kwargs)
  File "C:\Users\CPT-003\Desktop\CRM\crm_api\venv\Lib\site-packages\django\db\backends\base\base.py", line 320, in cursor
    return self._cursor()
           ~~~~~~~~~~~~^^
  File "C:\Users\CPT-003\Desktop\CRM\crm_api\venv\Lib\site-packages\django_tenants\postgresql_backend\base.py", line 144, in _cursor
    cursor = super()._cursor()
  File "C:\Users\CPT-003\Desktop\CRM\crm_api\venv\Lib\site-packages\django\db\backends\base\base.py", line 296, in _cursor
    self.ensure_connection()
    ~~~~~~~~~~~~~~~~~~~~~~^^
  File "C:\Users\CPT-003\Desktop\CRM\crm_api\venv\Lib\site-packages\django\utils\asyncio.py", line 26, in inner
    return func(*args, **kwargs)
  File "C:\Users\CPT-003\Desktop\CRM\crm_api\venv\Lib\site-packages\django\db\backends\base\base.py", line 278, in ensure_connection
    with self.wrap_database_errors:
         ^^^^^^^^^^^^^^^^^^^^^^^^^
  File "C:\Users\CPT-003\Desktop\CRM\crm_api\venv\Lib\site-packages\django\db\utils.py", line 91, in __exit__
    raise dj_exc_value.with_traceback(traceback) from exc_value
  File "C:\Users\CPT-003\Desktop\CRM\crm_api\venv\Lib\site-packages\django\db\backends\base\base.py", line 279, in ensure_connection
    self.connect()
    ~~~~~~~~~~~~^^
  File "C:\Users\CPT-003\Desktop\CRM\crm_api\venv\Lib\site-packages\django\utils\asyncio.py", line 26, in inner
    return func(*args, **kwargs)
  File "C:\Users\CPT-003\Desktop\CRM\crm_api\venv\Lib\site-packages\django\db\backends\base\base.py", line 256, in connect
    self.connection = self.get_new_connection(conn_params)
                      ~~~~~~~~~~~~~~~~~~~~~~~^^^^^^^^^^^^^
  File "C:\Users\CPT-003\Desktop\CRM\crm_api\venv\Lib\site-packages\django\utils\asyncio.py", line 26, in inner
    return func(*args, **kwargs)
  File "C:\Users\CPT-003\Desktop\CRM\crm_api\venv\Lib\site-packages\django\db\backends\postgresql\base.py", line 332, in get_new_connection
    connection = self.Database.connect(**conn_params)
  File "C:\Users\CPT-003\Desktop\CRM\crm_api\venv\Lib\site-packages\psycopg2\__init__.py", line 135, in connect
    conn = _connect(dsn, connection_factory=connection_factory, **kwasync)
django.db.utils.OperationalError: could not translate host name "dpg-d208jbje5dus73d4h87g-a.oregon-postgres.render.com" to address: Name or service not known

2025-07-28 17:04:01,373 [ERROR] django.server: "POST /api/token/ HTTP/1.1" 500 193081
2025-07-28 17:04:49,135 [INFO] django.utils.autoreload: Watching for file changes with StatReloader
2025-07-28 17:09:17,392 [INFO] django.server: "POST /api/token/ HTTP/1.1" 200 965
2025-07-28 17:09:17,693 [INFO] django.server: "GET /api/token/validate/ HTTP/1.1" 200 389
2025-07-28 17:09:17,864 [INFO] django.server: "GET /api/token/validate/ HTTP/1.1" 200 389
2025-07-28 17:09:18,322 [INFO] django.server: "OPTIONS /api/user/tenant-users/ HTTP/1.1" 200 0
2025-07-28 17:09:18,323 [INFO] django.server: "OPTIONS /api/user/tenant-users/ HTTP/1.1" 200 0
2025-07-28 17:09:18,878 [INFO] users: Retrieved 3 users for tenant proliance
2025-07-28 17:09:18,927 [INFO] django.server: "GET /api/user/tenant-users/ HTTP/1.1" 200 1022
2025-07-28 17:09:19,137 [INFO] users: Retrieved 3 users for tenant proliance
2025-07-28 17:09:19,176 [INFO] django.server: "GET /api/user/tenant-users/ HTTP/1.1" 200 1022
2025-07-28 17:09:22,875 [INFO] django.server: "OPTIONS /api/talent-engine/requisitions/ HTTP/1.1" 200 0
2025-07-28 17:09:22,876 [INFO] django.server: "OPTIONS /api/talent-engine/requisitions/ HTTP/1.1" 200 0
2025-07-28 17:09:23,255 [INFO] django.server: "GET /api/talent-engine/requisitions/ HTTP/1.1" 200 6330
2025-07-28 17:09:23,543 [INFO] django.server: "GET /api/talent-engine/requisitions/ HTTP/1.1" 200 6330
2025-07-28 17:09:25,020 [INFO] django.server: "GET /api/talent-engine/requisitions/ HTTP/1.1" 200 6330
2025-07-28 17:09:25,332 [INFO] django.server: "GET /api/talent-engine/requisitions/ HTTP/1.1" 200 6330
2025-07-28 17:09:26,432 [INFO] django.server: "OPTIONS /api/talent-engine-job-applications/applications/job-requisitions/PRO-0003/applications/ HTTP/1.1" 200 0
2025-07-28 17:09:26,433 [INFO] django.server: "OPTIONS /api/talent-engine-job-applications/applications/job-requisitions/PRO-0003/applications/ HTTP/1.1" 200 0
2025-07-28 17:09:26,739 [INFO] django.server: "GET /api/talent-engine-job-applications/applications/job-requisitions/PRO-0003/applications/ HTTP/1.1" 200 6987
2025-07-28 17:09:26,977 [INFO] django.server: "GET /api/talent-engine-job-applications/applications/job-requisitions/PRO-0003/applications/ HTTP/1.1" 200 6987
2025-07-28 17:09:32,226 [INFO] django.server: "OPTIONS /api/talent-engine-job-applications/requisitions/PRO-0003/screen-resumes/ HTTP/1.1" 200 0
2025-07-28 17:09:32,709 [WARNING] django.request: Bad Request: /api/talent-engine-job-applications/requisitions/PRO-0003/screen-resumes/
2025-07-28 17:09:32,714 [WARNING] django.server: "POST /api/talent-engine-job-applications/requisitions/PRO-0003/screen-resumes/ HTTP/1.1" 400 2239
2025-07-28 17:09:51,406 [WARNING] django.request: Bad Request: /api/talent-engine-job-applications/requisitions/PRO-0003/screen-resumes/
2025-07-28 17:09:51,409 [WARNING] django.server: "POST /api/talent-engine-job-applications/requisitions/PRO-0003/screen-resumes/ HTTP/1.1" 400 2239
2025-07-28 17:10:53,447 [WARNING] django.request: Bad Request: /api/talent-engine-job-applications/requisitions/PRO-0003/screen-resumes/
2025-07-28 17:10:53,453 [WARNING] django.server: "POST /api/talent-engine-job-applications/requisitions/PRO-0003/screen-resumes/ HTTP/1.1" 400 2239
2025-07-28 17:10:53,567 [WARNING] django.request: Bad Request: /api/talent-engine-job-applications/requisitions/PRO-0003/screen-resumes/
2025-07-28 17:10:53,576 [WARNING] django.server: "POST /api/talent-engine-job-applications/requisitions/PRO-0003/screen-resumes/ HTTP/1.1" 400 2239
2025-07-28 17:11:06,346 [INFO] django.server: "GET /api/talent-engine/requisitions/ HTTP/1.1" 200 6330
2025-07-28 17:11:06,568 [INFO] django.server: "GET /api/talent-engine/requisitions/ HTTP/1.1" 200 6330
2025-07-28 17:11:07,361 [INFO] django.server: "GET /api/talent-engine/requisitions/ HTTP/1.1" 200 6330
2025-07-28 17:11:07,558 [INFO] django.server: "GET /api/talent-engine/requisitions/ HTTP/1.1" 200 6330
2025-07-28 17:11:08,112 [INFO] django.server: "OPTIONS /api/tenant/config/?t=1753719068084 HTTP/1.1" 200 0
2025-07-28 17:11:08,126 [INFO] django.server: "OPTIONS /api/tenant/config/?t=1753719068090 HTTP/1.1" 200 0
2025-07-28 17:11:08,331 [INFO] core: Fetched TenantConfig for tenant proliance
2025-07-28 17:11:08,334 [INFO] core: Fetched TenantConfig for tenant proliance
2025-07-28 17:11:08,338 [INFO] django.server: "GET /api/tenant/config/?t=1753719068090 HTTP/1.1" 200 2185
2025-07-28 17:11:08,338 [INFO] django.server: "GET /api/tenant/config/?t=1753719068084 HTTP/1.1" 200 2185
2025-07-28 17:11:09,697 [INFO] django.server: "GET /api/talent-engine-job-applications/published-requisitions-with-shortlisted/ HTTP/1.1" 200 14575
2025-07-28 17:11:11,551 [INFO] django.server: "GET /api/talent-engine-job-applications/published-requisitions-with-shortlisted/ HTTP/1.1" 200 14575
2025-07-28 17:11:14,225 [INFO] django.server: "OPTIONS /api/tenant/config/?t=1753719074180 HTTP/1.1" 200 0
2025-07-28 17:11:14,961 [INFO] core: Fetched TenantConfig for tenant proliance
2025-07-28 17:11:14,965 [INFO] django.server: "GET /api/tenant/config/?t=1753719074180 HTTP/1.1" 200 2185
2025-07-28 17:11:15,130 [INFO] django.server: "GET /api/talent-engine/requisitions/ HTTP/1.1" 200 6330
2025-07-28 17:11:15,612 [INFO] django.server: "GET /api/talent-engine/requisitions/ HTTP/1.1" 200 6330
2025-07-28 17:11:16,685 [INFO] django.server: "GET /api/talent-engine-job-applications/published-requisitions-with-shortlisted/ HTTP/1.1" 200 14575
2025-07-28 17:11:17,909 [INFO] django.server: "GET /api/talent-engine/requisitions/ HTTP/1.1" 200 6330
2025-07-28 17:11:18,224 [INFO] django.server: "GET /api/talent-engine/requisitions/ HTTP/1.1" 200 6330
2025-07-28 17:11:54,997 [INFO] django.server: "GET /api/talent-engine/requisitions/ HTTP/1.1" 200 6330
2025-07-28 17:11:55,199 [INFO] django.server: "GET /api/talent-engine/requisitions/ HTTP/1.1" 200 6330
2025-07-28 17:11:58,099 [INFO] django.server: "GET /api/talent-engine-job-applications/applications/job-requisitions/PRO-0003/applications/ HTTP/1.1" 200 6967
2025-07-28 17:11:58,327 [INFO] django.server: "GET /api/talent-engine-job-applications/applications/job-requisitions/PRO-0003/applications/ HTTP/1.1" 200 6967
2025-07-28 17:12:06,326 [INFO] django.server: "GET /api/talent-engine-job-applications/published-requisitions-with-shortlisted/ HTTP/1.1" 200 14575
2025-07-28 17:12:08,304 [INFO] django.server: "GET /api/talent-engine-job-applications/published-requisitions-with-shortlisted/ HTTP/1.1" 200 14575
2025-07-28 17:12:10,374 [INFO] django.server: "GET /api/talent-engine-job-applications/published-requisitions-with-shortlisted/ HTTP/1.1" 200 14575
2025-07-28 17:12:16,403 [INFO] django.server: "OPTIONS /api/tenant/config/ HTTP/1.1" 200 0
2025-07-28 17:12:16,404 [INFO] django.server: "OPTIONS /api/tenant/config/ HTTP/1.1" 200 0
2025-07-28 17:12:16,598 [INFO] core: Fetched TenantConfig for tenant proliance
2025-07-28 17:12:16,601 [INFO] django.server: "GET /api/tenant/config/ HTTP/1.1" 200 2185
2025-07-28 17:12:16,749 [INFO] core: Fetched TenantConfig for tenant proliance
2025-07-28 17:12:16,752 [INFO] django.server: "GET /api/tenant/config/ HTTP/1.1" 200 2185
2025-07-28 17:12:26,710 [INFO] core: Tenant config updated for tenant proliance
2025-07-28 17:12:26,712 [INFO] django.server: "PATCH /api/tenant/config/ HTTP/1.1" 200 2091
2025-07-28 17:13:33,230 [INFO] django.server: "OPTIONS /api/tenant/tenants/2/ HTTP/1.1" 200 0
2025-07-28 17:13:33,231 [INFO] django.server: "OPTIONS /api/tenant/tenants/2/ HTTP/1.1" 200 0
2025-07-28 17:13:33,431 [INFO] core: Retrieving tenant: 2 for tenant proliance
2025-07-28 17:13:33,449 [INFO] django.server: "GET /api/tenant/tenants/2/ HTTP/1.1" 200 2464
2025-07-28 17:13:33,580 [INFO] core: Retrieving tenant: 2 for tenant proliance
2025-07-28 17:13:33,597 [INFO] django.server: "GET /api/tenant/tenants/2/ HTTP/1.1" 200 2464
2025-07-28 17:13:35,924 [INFO] django.server: "OPTIONS /api/talent-engine/requisitions/deleted/soft_deleted/ HTTP/1.1" 200 0
2025-07-28 17:13:35,927 [INFO] django.server: "OPTIONS /api/talent-engine/requisitions/deleted/soft_deleted/ HTTP/1.1" 200 0
2025-07-28 17:13:36,246 [INFO] talent_engine: Retrieved 455 soft-deleted job requisitions for tenant proliance
2025-07-28 17:13:39,028 [INFO] django.server: "GET /api/talent-engine/requisitions/ HTTP/1.1" 200 6330
2025-07-28 17:13:39,361 [INFO] django.server: "GET /api/talent-engine/requisitions/ HTTP/1.1" 200 6330
2025-07-28 17:13:41,410 [INFO] django.server: "GET /api/talent-engine-job-applications/applications/job-requisitions/PRO-0003/applications/ HTTP/1.1" 200 6967
2025-07-28 17:13:41,787 [INFO] django.server: "GET /api/talent-engine-job-applications/applications/job-requisitions/PRO-0003/applications/ HTTP/1.1" 200 6967
2025-07-28 17:13:42,822 [INFO] django.server: "GET /api/talent-engine/requisitions/deleted/soft_deleted/ HTTP/1.1" 200 556529
2025-07-28 17:13:43,085 [INFO] talent_engine: Retrieved 455 soft-deleted job requisitions for tenant proliance
2025-07-28 17:13:48,527 [WARNING] django.request: Bad Request: /api/talent-engine-job-applications/requisitions/PRO-0003/screen-resumes/
2025-07-28 17:13:48,530 [WARNING] django.server: "POST /api/talent-engine-job-applications/requisitions/PRO-0003/screen-resumes/ HTTP/1.1" 400 2239
2025-07-28 17:13:50,416 [INFO] django.server: "GET /api/talent-engine/requisitions/deleted/soft_deleted/ HTTP/1.1" 200 556529
2025-07-28 17:16:40,512 [INFO] django.utils.autoreload: C:\Users\CPT-003\Desktop\CRM\crm_api\job_application\views.py changed, reloading.
2025-07-28 17:16:48,600 [INFO] django.utils.autoreload: Watching for file changes with StatReloader
2025-07-28 17:34:36,917 [INFO] django.server: "GET /api/token/validate/ HTTP/1.1" 200 389
2025-07-28 17:34:37,100 [INFO] django.server: "GET /api/token/validate/ HTTP/1.1" 200 389
2025-07-28 17:34:37,401 [INFO] django.server: "GET /api/talent-engine-job-applications/applications/job-requisitions/PRO-0003/applications/ HTTP/1.1" 200 6967
2025-07-28 17:34:37,719 [INFO] django.server: "GET /api/talent-engine-job-applications/applications/job-requisitions/PRO-0003/applications/ HTTP/1.1" 200 6967
2025-07-28 18:17:20,306 [INFO] django.server: "GET /api/token/validate/ HTTP/1.1" 200 389
2025-07-28 18:17:20,394 [INFO] django.server: "GET /api/talent-engine-job-applications/applications/job-requisitions/PRO-0003/applications/ HTTP/1.1" 200 6967
2025-07-28 18:22:59,785 [INFO] django.utils.autoreload: C:\Users\CPT-003\Desktop\CRM\crm_api\job_application\views.py changed, reloading.
2025-07-28 18:23:05,791 [INFO] django.utils.autoreload: Watching for file changes with StatReloader
2025-07-28 18:24:33,212 [INFO] django.utils.autoreload: C:\Users\CPT-003\Desktop\CRM\crm_api\job_application\views.py changed, reloading.
2025-07-28 18:24:36,859 [INFO] django.utils.autoreload: Watching for file changes with StatReloader
2025-07-28 18:25:56,629 [INFO] django.utils.autoreload: C:\Users\CPT-003\Desktop\CRM\crm_api\job_application\views.py changed, reloading.
2025-07-28 18:26:03,373 [INFO] django.utils.autoreload: Watching for file changes with StatReloader
2025-07-28 18:26:24,911 [INFO] django.utils.autoreload: C:\Users\CPT-003\Desktop\CRM\crm_api\job_application\views.py changed, reloading.
2025-07-28 18:26:30,102 [INFO] django.utils.autoreload: Watching for file changes with StatReloader
2025-07-28 18:27:02,538 [INFO] django.utils.autoreload: C:\Users\CPT-003\Desktop\CRM\crm_api\job_application\views.py changed, reloading.
2025-07-28 18:27:08,466 [INFO] django.utils.autoreload: Watching for file changes with StatReloader
2025-07-28 18:27:50,878 [INFO] django.utils.autoreload: C:\Users\CPT-003\Desktop\CRM\crm_api\job_application\urls.py changed, reloading.
2025-07-28 18:27:55,334 [INFO] django.utils.autoreload: Watching for file changes with StatReloader
2025-07-28 18:28:19,958 [INFO] django.utils.autoreload: C:\Users\CPT-003\Desktop\CRM\crm_api\job_application\urls.py changed, reloading.
2025-07-28 18:28:25,317 [INFO] django.utils.autoreload: Watching for file changes with StatReloader
2025-07-28 18:29:32,458 [INFO] django.utils.autoreload: Watching for file changes with StatReloader
2025-07-28 18:30:29,891 [WARNING] django.request: Unauthorized: /api/talent-engine-job-applications/public-published-requisitions-with-shortlisted/
2025-07-28 18:30:29,892 [WARNING] django.server: "GET /api/talent-engine-job-applications/public-published-requisitions-with-shortlisted/ HTTP/1.1" 401 183
2025-07-28 18:30:34,078 [ERROR] django.request: Internal Server Error: /api/talent-engine-job-applications/public-published-requisitions-with-shortlisted/
2025-07-28 18:30:34,078 [ERROR] django.server: "GET /api/talent-engine-job-applications/public-published-requisitions-with-shortlisted/ HTTP/1.1" 500 61
2025-07-28 18:31:13,291 [INFO] django.utils.autoreload: C:\Users\CPT-003\Desktop\CRM\crm_api\job_application\views.py changed, reloading.
2025-07-28 18:31:18,489 [INFO] django.utils.autoreload: Watching for file changes with StatReloader
2025-07-28 18:31:45,323 [INFO] django.utils.autoreload: C:\Users\CPT-003\Desktop\CRM\crm_api\job_application\views.py changed, reloading.
2025-07-28 18:31:49,134 [INFO] django.utils.autoreload: Watching for file changes with StatReloader
2025-07-28 18:32:01,853 [ERROR] django.request: Internal Server Error: /api/talent-engine-job-applications/public-published-requisitions-with-shortlisted/
2025-07-28 18:32:01,854 [ERROR] django.server: "GET /api/talent-engine-job-applications/public-published-requisitions-with-shortlisted/ HTTP/1.1" 500 61
2025-07-28 18:35:53,839 [INFO] django.utils.autoreload: C:\Users\CPT-003\Desktop\CRM\crm_api\job_application\views.py changed, reloading.
2025-07-28 18:35:57,140 [INFO] django.utils.autoreload: Watching for file changes with StatReloader
2025-07-28 18:36:08,359 [ERROR] django.request: Internal Server Error: /api/talent-engine-job-applications/public-published-requisitions-with-shortlisted/
2025-07-28 18:36:08,360 [ERROR] django.server: "GET /api/talent-engine-job-applications/public-published-requisitions-with-shortlisted/ HTTP/1.1" 500 218
2025-07-28 18:38:17,736 [INFO] django.utils.autoreload: C:\Users\CPT-003\Desktop\CRM\crm_api\job_application\views.py changed, reloading.
2025-07-28 18:38:20,804 [INFO] django.utils.autoreload: Watching for file changes with StatReloader
2025-07-28 18:44:38,373 [INFO] django.utils.autoreload: C:\Users\CPT-003\Desktop\CRM\crm_api\job_application\views.py changed, reloading.
2025-07-28 18:44:44,431 [INFO] django.utils.autoreload: Watching for file changes with StatReloader
2025-07-28 18:46:46,473 [INFO] django.utils.autoreload: C:\Users\CPT-003\Desktop\CRM\crm_api\job_application\views.py changed, reloading.
2025-07-28 18:46:51,616 [INFO] django.utils.autoreload: Watching for file changes with StatReloader
2025-07-28 20:25:56,257 [INFO] django.utils.autoreload: Watching for file changes with StatReloader
2025-07-28 20:27:07,726 [ERROR] django.request: Internal Server Error: /api/talent-engine-job-applications/public-published-requisitions-with-shortlisted/
2025-07-28 20:27:07,727 [ERROR] django.server: "GET /api/talent-engine-job-applications/public-published-requisitions-with-shortlisted/ HTTP/1.1" 500 71
2025-07-28 20:32:17,231 [INFO] django.utils.autoreload: C:\Users\CPT-003\Desktop\CRM\crm_api\job_application\views.py changed, reloading.
2025-07-28 20:32:21,062 [INFO] django.utils.autoreload: Watching for file changes with StatReloader
2025-07-28 20:38:05,457 [INFO] django.utils.autoreload: C:\Users\CPT-003\Desktop\CRM\crm_api\job_application\views.py changed, reloading.
2025-07-28 20:38:10,023 [INFO] django.utils.autoreload: Watching for file changes with StatReloader
2025-07-28 20:39:07,155 [INFO] django.utils.autoreload: C:\Users\CPT-003\Desktop\CRM\crm_api\job_application\views.py changed, reloading.
2025-07-28 20:39:17,174 [INFO] django.utils.autoreload: Watching for file changes with StatReloader
2025-07-28 20:40:20,073 [INFO] django.utils.autoreload: C:\Users\CPT-003\Desktop\CRM\crm_api\job_application\views.py changed, reloading.
2025-07-28 20:40:26,061 [INFO] django.utils.autoreload: Watching for file changes with StatReloader
2025-07-28 20:42:20,065 [ERROR] django.request: Internal Server Error: /api/talent-engine-job-applications/public-published-requisitions-with-shortlisted/
2025-07-28 20:42:20,066 [ERROR] django.server: "GET /api/talent-engine-job-applications/public-published-requisitions-with-shortlisted/?schema_name=proliance HTTP/1.1" 500 131
2025-07-28 20:44:21,459 [INFO] django.utils.autoreload: C:\Users\CPT-003\Desktop\CRM\crm_api\job_application\views.py changed, reloading.
2025-07-28 20:44:27,781 [INFO] django.utils.autoreload: Watching for file changes with StatReloader
2025-07-28 20:44:41,057 [INFO] django.server: "GET /api/talent-engine-job-applications/public-published-requisitions-with-shortlisted/?schema_name=proliance HTTP/1.1" 200 16462
2025-07-28 20:45:07,645 [INFO] django.utils.autoreload: C:\Users\CPT-003\Desktop\CRM\crm_api\job_application\views.py changed, reloading.
2025-07-28 20:45:11,928 [INFO] django.utils.autoreload: Watching for file changes with StatReloader
2025-07-28 20:45:37,633 [INFO] django.server: "GET /api/talent-engine-job-applications/public-published-requisitions-with-shortlisted/?schema_name=proliance HTTP/1.1" 200 9437
2025-07-28 20:58:44,266 [INFO] django.utils.autoreload: C:\Users\CPT-003\Desktop\CRM\crm_api\job_application\views.py changed, reloading.
2025-07-28 20:58:48,922 [INFO] django.utils.autoreload: Watching for file changes with StatReloader
2025-07-28 21:01:33,353 [INFO] django.utils.autoreload: C:\Users\CPT-003\Desktop\CRM\crm_api\core\models.py changed, reloading.
2025-07-28 21:01:39,241 [INFO] django.utils.autoreload: Watching for file changes with StatReloader
2025-07-28 21:03:39,988 [INFO] django.utils.autoreload: C:\Users\CPT-003\Desktop\CRM\crm_api\core\serializers.py changed, reloading.
2025-07-28 21:03:45,122 [INFO] django.utils.autoreload: Watching for file changes with StatReloader
2025-07-28 21:04:25,872 [INFO] django.utils.autoreload: C:\Users\CPT-003\Desktop\CRM\crm_api\core\serializers.py changed, reloading.
2025-07-28 21:04:31,059 [INFO] django.utils.autoreload: Watching for file changes with StatReloader
2025-07-28 21:05:19,758 [INFO] django.utils.autoreload: C:\Users\CPT-003\Desktop\CRM\crm_api\core\serializers.py changed, reloading.
2025-07-28 21:05:24,363 [INFO] django.utils.autoreload: Watching for file changes with StatReloader
2025-07-28 21:06:20,904 [INFO] django.utils.autoreload: C:\Users\CPT-003\Desktop\CRM\crm_api\core\serializers.py changed, reloading.
2025-07-28 21:06:25,913 [INFO] django.utils.autoreload: Watching for file changes with StatReloader
2025-07-28 21:07:06,719 [INFO] django.utils.autoreload: C:\Users\CPT-003\Desktop\CRM\crm_api\core\serializers.py changed, reloading.
2025-07-28 21:07:11,291 [INFO] django.utils.autoreload: Watching for file changes with StatReloader
2025-07-28 21:07:21,462 [INFO] django.utils.autoreload: C:\Users\CPT-003\Desktop\CRM\crm_api\core\serializers.py changed, reloading.
2025-07-28 21:07:25,749 [INFO] django.utils.autoreload: Watching for file changes with StatReloader
2025-07-28 21:08:01,725 [INFO] django.utils.autoreload: C:\Users\CPT-003\Desktop\CRM\crm_api\job_application\models.py changed, reloading.
2025-07-28 21:08:07,526 [INFO] django.utils.autoreload: Watching for file changes with StatReloader
2025-07-28 21:08:25,746 [INFO] django.utils.autoreload: C:\Users\CPT-003\Desktop\CRM\crm_api\core\serializers.py changed, reloading.
2025-07-28 21:08:30,613 [INFO] django.utils.autoreload: Watching for file changes with StatReloader
2025-07-28 21:13:02,064 [INFO] django.utils.autoreload: C:\Users\CPT-003\Desktop\CRM\crm_api\core\serializers.py changed, reloading.
2025-07-28 21:13:06,825 [INFO] django.utils.autoreload: Watching for file changes with StatReloader
2025-07-28 21:13:37,254 [INFO] django.utils.autoreload: C:\Users\CPT-003\Desktop\CRM\crm_api\core\serializers.py changed, reloading.
2025-07-28 21:13:41,107 [INFO] django.utils.autoreload: Watching for file changes with StatReloader
2025-07-28 21:15:07,993 [INFO] django.utils.autoreload: C:\Users\CPT-003\Desktop\CRM\crm_api\core\serializers.py changed, reloading.
2025-07-28 21:15:12,038 [INFO] django.utils.autoreload: Watching for file changes with StatReloader
2025-07-28 21:15:44,125 [INFO] django.utils.autoreload: C:\Users\CPT-003\Desktop\CRM\crm_api\core\models.py changed, reloading.
2025-07-28 21:15:47,768 [INFO] django.utils.autoreload: Watching for file changes with StatReloader
2025-07-28 21:16:05,017 [INFO] django.utils.autoreload: C:\Users\CPT-003\Desktop\CRM\crm_api\core\serializers.py changed, reloading.
2025-07-28 21:16:09,908 [INFO] django.utils.autoreload: Watching for file changes with StatReloader
2025-07-28 21:16:34,591 [INFO] django.utils.autoreload: C:\Users\CPT-003\Desktop\CRM\crm_api\core\models.py changed, reloading.
2025-07-28 21:16:38,932 [INFO] django.utils.autoreload: Watching for file changes with StatReloader
2025-07-28 21:18:25,311 [INFO] django.utils.autoreload: Watching for file changes with StatReloader
2025-07-28 21:30:25,986 [INFO] django.utils.autoreload: Watching for file changes with StatReloader
2025-07-28 21:31:00,336 [INFO] django.server: "OPTIONS /api/token/ HTTP/1.1" 200 0
2025-07-28 21:31:05,204 [WARNING] django.request: Unauthorized: /api/token/
2025-07-28 21:31:05,206 [WARNING] django.server: "POST /api/token/ HTTP/1.1" 401 63
2025-07-28 21:31:13,760 [WARNING] django.request: Unauthorized: /api/token/
2025-07-28 21:31:13,761 [WARNING] django.server: "POST /api/token/ HTTP/1.1" 401 63
2025-07-28 21:31:20,776 [INFO] django.server: "POST /api/token/ HTTP/1.1" 200 964
2025-07-28 21:31:20,816 [INFO] django.server: "OPTIONS /api/token/validate/ HTTP/1.1" 200 0
2025-07-28 21:31:20,822 [INFO] django.server: "OPTIONS /api/token/validate/ HTTP/1.1" 200 0
2025-07-28 21:31:25,182 [INFO] django.server: "GET /api/token/validate/ HTTP/1.1" 200 388
2025-07-28 21:31:25,288 [INFO] django.server: "OPTIONS /api/user/tenant-users/ HTTP/1.1" 200 0
2025-07-28 21:31:25,290 [INFO] django.server: "OPTIONS /api/user/tenant-users/ HTTP/1.1" 200 0
2025-07-28 21:31:29,649 [INFO] django.server: "GET /api/token/validate/ HTTP/1.1" 200 388
2025-07-28 21:31:29,843 [INFO] users: Retrieved 6 users for tenant proliance
2025-07-28 21:31:38,351 [INFO] django.server: "GET /api/user/tenant-users/ HTTP/1.1" 200 1986
2025-07-28 21:31:42,890 [INFO] users: Retrieved 6 users for tenant proliance
2025-07-28 21:31:43,607 [INFO] django.server: "OPTIONS /api/talent-engine/requisitions/ HTTP/1.1" 200 0
2025-07-28 21:31:43,607 [INFO] django.server: "OPTIONS /api/talent-engine/requisitions/ HTTP/1.1" 200 0
2025-07-28 21:31:51,216 [INFO] django.server: "GET /api/user/tenant-users/ HTTP/1.1" 200 1986
2025-07-28 21:31:57,577 [INFO] django.server: "GET /api/talent-engine/requisitions/ HTTP/1.1" 200 7733
2025-07-28 21:32:12,617 [INFO] django.server: "GET /api/talent-engine/requisitions/ HTTP/1.1" 200 7733
2025-07-28 21:32:26,071 [INFO] django.server: "GET /api/talent-engine/requisitions/ HTTP/1.1" 200 7733
2025-07-28 21:32:39,633 [INFO] django.server: "GET /api/talent-engine/requisitions/ HTTP/1.1" 200 7733
2025-07-28 21:33:16,871 [INFO] django.server: "GET /api/talent-engine/requisitions/ HTTP/1.1" 200 7733
2025-07-28 21:34:32,555 [INFO] core: Saving tenant with schema_name: test
2025-07-28 21:36:30,355 [INFO] core: Saving tenant with schema_name: test
2025-07-28 21:45:08,670 [INFO] django.utils.autoreload: Watching for file changes with StatReloader
2025-07-28 21:47:11,464 [WARNING] django.request: Not Found: /api/talent/tenants/
2025-07-28 21:47:11,465 [WARNING] django.server: "GET /api/talent/tenants/ HTTP/1.1" 404 4289
2025-07-28 21:47:15,052 [INFO] django.server: "GET /api/talent-engine/requisitions/ HTTP/1.1" 200 7733
2025-07-28 21:47:41,848 [INFO] django.server: "GET /api/talent-engine/requisitions/ HTTP/1.1" 200 7733
2025-07-28 21:49:24,838 [INFO] django.server: "GET /api/talent-engine/requisitions/ HTTP/1.1" 200 7733
2025-07-28 21:51:36,011 [ERROR] django.request: Internal Server Error: /api/talent-engine/requisitions/
Traceback (most recent call last):
  File "C:\Users\CPT-003\Desktop\CRM\crm_api\venv\Lib\site-packages\django\db\backends\base\base.py", line 279, in ensure_connection
    self.connect()
    ~~~~~~~~~~~~^^
  File "C:\Users\CPT-003\Desktop\CRM\crm_api\venv\Lib\site-packages\django\utils\asyncio.py", line 26, in inner
    return func(*args, **kwargs)
  File "C:\Users\CPT-003\Desktop\CRM\crm_api\venv\Lib\site-packages\django\db\backends\base\base.py", line 256, in connect
    self.connection = self.get_new_connection(conn_params)
                      ~~~~~~~~~~~~~~~~~~~~~~~^^^^^^^^^^^^^
  File "C:\Users\CPT-003\Desktop\CRM\crm_api\venv\Lib\site-packages\django\utils\asyncio.py", line 26, in inner
    return func(*args, **kwargs)
  File "C:\Users\CPT-003\Desktop\CRM\crm_api\venv\Lib\site-packages\django\db\backends\postgresql\base.py", line 332, in get_new_connection
    connection = self.Database.connect(**conn_params)
  File "C:\Users\CPT-003\Desktop\CRM\crm_api\venv\Lib\site-packages\psycopg2\__init__.py", line 135, in connect
    conn = _connect(dsn, connection_factory=connection_factory, **kwasync)
psycopg2.OperationalError: could not translate host name "dpg-d208jbje5dus73d4h87g-a.oregon-postgres.render.com" to address: Name or service not known


The above exception was the direct cause of the following exception:

Traceback (most recent call last):
  File "C:\Users\CPT-003\Desktop\CRM\crm_api\venv\Lib\site-packages\django\core\handlers\exception.py", line 55, in inner
    response = get_response(request)
  File "C:\Users\CPT-003\Desktop\CRM\crm_api\venv\Lib\site-packages\django\utils\deprecation.py", line 119, in __call__
    response = self.process_request(request)
  File "C:\Users\CPT-003\Desktop\CRM\crm_api\lumina_care\middleware.py", line 266, in process_request
    domain = Domain.objects.filter(domain=hostname).first()
  File "C:\Users\CPT-003\Desktop\CRM\crm_api\venv\Lib\site-packages\django\db\models\query.py", line 1104, in first
    for obj in queryset[:1]:
               ~~~~~~~~^^^^
  File "C:\Users\CPT-003\Desktop\CRM\crm_api\venv\Lib\site-packages\django\db\models\query.py", line 384, in __iter__
    self._fetch_all()
    ~~~~~~~~~~~~~~~^^
  File "C:\Users\CPT-003\Desktop\CRM\crm_api\venv\Lib\site-packages\django\db\models\query.py", line 1949, in _fetch_all
    self._result_cache = list(self._iterable_class(self))
                         ~~~~^^^^^^^^^^^^^^^^^^^^^^^^^^^^
  File "C:\Users\CPT-003\Desktop\CRM\crm_api\venv\Lib\site-packages\django\db\models\query.py", line 91, in __iter__
    results = compiler.execute_sql(
        chunked_fetch=self.chunked_fetch, chunk_size=self.chunk_size
    )
  File "C:\Users\CPT-003\Desktop\CRM\crm_api\venv\Lib\site-packages\django\db\models\sql\compiler.py", line 1621, in execute_sql
    cursor = self.connection.cursor()
  File "C:\Users\CPT-003\Desktop\CRM\crm_api\venv\Lib\site-packages\django\utils\asyncio.py", line 26, in inner
    return func(*args, **kwargs)
  File "C:\Users\CPT-003\Desktop\CRM\crm_api\venv\Lib\site-packages\django\db\backends\base\base.py", line 320, in cursor
    return self._cursor()
           ~~~~~~~~~~~~^^
  File "C:\Users\CPT-003\Desktop\CRM\crm_api\venv\Lib\site-packages\django_tenants\postgresql_backend\base.py", line 144, in _cursor
    cursor = super()._cursor()
  File "C:\Users\CPT-003\Desktop\CRM\crm_api\venv\Lib\site-packages\django\db\backends\base\base.py", line 296, in _cursor
    self.ensure_connection()
    ~~~~~~~~~~~~~~~~~~~~~~^^
  File "C:\Users\CPT-003\Desktop\CRM\crm_api\venv\Lib\site-packages\django\utils\asyncio.py", line 26, in inner
    return func(*args, **kwargs)
  File "C:\Users\CPT-003\Desktop\CRM\crm_api\venv\Lib\site-packages\django\db\backends\base\base.py", line 278, in ensure_connection
    with self.wrap_database_errors:
         ^^^^^^^^^^^^^^^^^^^^^^^^^
  File "C:\Users\CPT-003\Desktop\CRM\crm_api\venv\Lib\site-packages\django\db\utils.py", line 91, in __exit__
    raise dj_exc_value.with_traceback(traceback) from exc_value
  File "C:\Users\CPT-003\Desktop\CRM\crm_api\venv\Lib\site-packages\django\db\backends\base\base.py", line 279, in ensure_connection
    self.connect()
    ~~~~~~~~~~~~^^
  File "C:\Users\CPT-003\Desktop\CRM\crm_api\venv\Lib\site-packages\django\utils\asyncio.py", line 26, in inner
    return func(*args, **kwargs)
  File "C:\Users\CPT-003\Desktop\CRM\crm_api\venv\Lib\site-packages\django\db\backends\base\base.py", line 256, in connect
    self.connection = self.get_new_connection(conn_params)
                      ~~~~~~~~~~~~~~~~~~~~~~~^^^^^^^^^^^^^
  File "C:\Users\CPT-003\Desktop\CRM\crm_api\venv\Lib\site-packages\django\utils\asyncio.py", line 26, in inner
    return func(*args, **kwargs)
  File "C:\Users\CPT-003\Desktop\CRM\crm_api\venv\Lib\site-packages\django\db\backends\postgresql\base.py", line 332, in get_new_connection
    connection = self.Database.connect(**conn_params)
  File "C:\Users\CPT-003\Desktop\CRM\crm_api\venv\Lib\site-packages\psycopg2\__init__.py", line 135, in connect
    conn = _connect(dsn, connection_factory=connection_factory, **kwasync)
django.db.utils.OperationalError: could not translate host name "dpg-d208jbje5dus73d4h87g-a.oregon-postgres.render.com" to address: Name or service not known

2025-07-28 21:51:36,021 [ERROR] django.server: "GET /api/talent-engine/requisitions/ HTTP/1.1" 500 188388
2025-07-28 21:51:36,188 [ERROR] django.request: Internal Server Error: /api/talent/tenants/
Traceback (most recent call last):
  File "C:\Users\CPT-003\Desktop\CRM\crm_api\venv\Lib\site-packages\django\db\backends\base\base.py", line 279, in ensure_connection
    self.connect()
    ~~~~~~~~~~~~^^
  File "C:\Users\CPT-003\Desktop\CRM\crm_api\venv\Lib\site-packages\django\utils\asyncio.py", line 26, in inner
    return func(*args, **kwargs)
  File "C:\Users\CPT-003\Desktop\CRM\crm_api\venv\Lib\site-packages\django\db\backends\base\base.py", line 256, in connect
    self.connection = self.get_new_connection(conn_params)
                      ~~~~~~~~~~~~~~~~~~~~~~~^^^^^^^^^^^^^
  File "C:\Users\CPT-003\Desktop\CRM\crm_api\venv\Lib\site-packages\django\utils\asyncio.py", line 26, in inner
    return func(*args, **kwargs)
  File "C:\Users\CPT-003\Desktop\CRM\crm_api\venv\Lib\site-packages\django\db\backends\postgresql\base.py", line 332, in get_new_connection
    connection = self.Database.connect(**conn_params)
  File "C:\Users\CPT-003\Desktop\CRM\crm_api\venv\Lib\site-packages\psycopg2\__init__.py", line 135, in connect
    conn = _connect(dsn, connection_factory=connection_factory, **kwasync)
psycopg2.OperationalError: could not translate host name "dpg-d208jbje5dus73d4h87g-a.oregon-postgres.render.com" to address: Name or service not known


The above exception was the direct cause of the following exception:

Traceback (most recent call last):
  File "C:\Users\CPT-003\Desktop\CRM\crm_api\venv\Lib\site-packages\django\core\handlers\exception.py", line 55, in inner
    response = get_response(request)
  File "C:\Users\CPT-003\Desktop\CRM\crm_api\venv\Lib\site-packages\django\utils\deprecation.py", line 119, in __call__
    response = self.process_request(request)
  File "C:\Users\CPT-003\Desktop\CRM\crm_api\lumina_care\middleware.py", line 266, in process_request
    domain = Domain.objects.filter(domain=hostname).first()
  File "C:\Users\CPT-003\Desktop\CRM\crm_api\venv\Lib\site-packages\django\db\models\query.py", line 1104, in first
    for obj in queryset[:1]:
               ~~~~~~~~^^^^
  File "C:\Users\CPT-003\Desktop\CRM\crm_api\venv\Lib\site-packages\django\db\models\query.py", line 384, in __iter__
    self._fetch_all()
    ~~~~~~~~~~~~~~~^^
  File "C:\Users\CPT-003\Desktop\CRM\crm_api\venv\Lib\site-packages\django\db\models\query.py", line 1949, in _fetch_all
    self._result_cache = list(self._iterable_class(self))
                         ~~~~^^^^^^^^^^^^^^^^^^^^^^^^^^^^
  File "C:\Users\CPT-003\Desktop\CRM\crm_api\venv\Lib\site-packages\django\db\models\query.py", line 91, in __iter__
    results = compiler.execute_sql(
        chunked_fetch=self.chunked_fetch, chunk_size=self.chunk_size
    )
  File "C:\Users\CPT-003\Desktop\CRM\crm_api\venv\Lib\site-packages\django\db\models\sql\compiler.py", line 1621, in execute_sql
    cursor = self.connection.cursor()
  File "C:\Users\CPT-003\Desktop\CRM\crm_api\venv\Lib\site-packages\django\utils\asyncio.py", line 26, in inner
    return func(*args, **kwargs)
  File "C:\Users\CPT-003\Desktop\CRM\crm_api\venv\Lib\site-packages\django\db\backends\base\base.py", line 320, in cursor
    return self._cursor()
           ~~~~~~~~~~~~^^
  File "C:\Users\CPT-003\Desktop\CRM\crm_api\venv\Lib\site-packages\django_tenants\postgresql_backend\base.py", line 144, in _cursor
    cursor = super()._cursor()
  File "C:\Users\CPT-003\Desktop\CRM\crm_api\venv\Lib\site-packages\django\db\backends\base\base.py", line 296, in _cursor
    self.ensure_connection()
    ~~~~~~~~~~~~~~~~~~~~~~^^
  File "C:\Users\CPT-003\Desktop\CRM\crm_api\venv\Lib\site-packages\django\utils\asyncio.py", line 26, in inner
    return func(*args, **kwargs)
  File "C:\Users\CPT-003\Desktop\CRM\crm_api\venv\Lib\site-packages\django\db\backends\base\base.py", line 278, in ensure_connection
    with self.wrap_database_errors:
         ^^^^^^^^^^^^^^^^^^^^^^^^^
  File "C:\Users\CPT-003\Desktop\CRM\crm_api\venv\Lib\site-packages\django\db\utils.py", line 91, in __exit__
    raise dj_exc_value.with_traceback(traceback) from exc_value
  File "C:\Users\CPT-003\Desktop\CRM\crm_api\venv\Lib\site-packages\django\db\backends\base\base.py", line 279, in ensure_connection
    self.connect()
    ~~~~~~~~~~~~^^
  File "C:\Users\CPT-003\Desktop\CRM\crm_api\venv\Lib\site-packages\django\utils\asyncio.py", line 26, in inner
    return func(*args, **kwargs)
  File "C:\Users\CPT-003\Desktop\CRM\crm_api\venv\Lib\site-packages\django\db\backends\base\base.py", line 256, in connect
    self.connection = self.get_new_connection(conn_params)
                      ~~~~~~~~~~~~~~~~~~~~~~~^^^^^^^^^^^^^
  File "C:\Users\CPT-003\Desktop\CRM\crm_api\venv\Lib\site-packages\django\utils\asyncio.py", line 26, in inner
    return func(*args, **kwargs)
  File "C:\Users\CPT-003\Desktop\CRM\crm_api\venv\Lib\site-packages\django\db\backends\postgresql\base.py", line 332, in get_new_connection
    connection = self.Database.connect(**conn_params)
  File "C:\Users\CPT-003\Desktop\CRM\crm_api\venv\Lib\site-packages\psycopg2\__init__.py", line 135, in connect
    conn = _connect(dsn, connection_factory=connection_factory, **kwasync)
django.db.utils.OperationalError: could not translate host name "dpg-d208jbje5dus73d4h87g-a.oregon-postgres.render.com" to address: Name or service not known

2025-07-28 21:51:36,206 [ERROR] django.request: Internal Server Error: /api/talent-engine/requisitions/
Traceback (most recent call last):
  File "C:\Users\CPT-003\Desktop\CRM\crm_api\venv\Lib\site-packages\django\db\backends\base\base.py", line 279, in ensure_connection
    self.connect()
    ~~~~~~~~~~~~^^
  File "C:\Users\CPT-003\Desktop\CRM\crm_api\venv\Lib\site-packages\django\utils\asyncio.py", line 26, in inner
    return func(*args, **kwargs)
  File "C:\Users\CPT-003\Desktop\CRM\crm_api\venv\Lib\site-packages\django\db\backends\base\base.py", line 256, in connect
    self.connection = self.get_new_connection(conn_params)
                      ~~~~~~~~~~~~~~~~~~~~~~~^^^^^^^^^^^^^
  File "C:\Users\CPT-003\Desktop\CRM\crm_api\venv\Lib\site-packages\django\utils\asyncio.py", line 26, in inner
    return func(*args, **kwargs)
  File "C:\Users\CPT-003\Desktop\CRM\crm_api\venv\Lib\site-packages\django\db\backends\postgresql\base.py", line 332, in get_new_connection
    connection = self.Database.connect(**conn_params)
  File "C:\Users\CPT-003\Desktop\CRM\crm_api\venv\Lib\site-packages\psycopg2\__init__.py", line 135, in connect
    conn = _connect(dsn, connection_factory=connection_factory, **kwasync)
psycopg2.OperationalError: could not translate host name "dpg-d208jbje5dus73d4h87g-a.oregon-postgres.render.com" to address: Name or service not known


The above exception was the direct cause of the following exception:

Traceback (most recent call last):
  File "C:\Users\CPT-003\Desktop\CRM\crm_api\venv\Lib\site-packages\django\core\handlers\exception.py", line 55, in inner
    response = get_response(request)
  File "C:\Users\CPT-003\Desktop\CRM\crm_api\venv\Lib\site-packages\django\utils\deprecation.py", line 119, in __call__
    response = self.process_request(request)
  File "C:\Users\CPT-003\Desktop\CRM\crm_api\lumina_care\middleware.py", line 266, in process_request
    domain = Domain.objects.filter(domain=hostname).first()
  File "C:\Users\CPT-003\Desktop\CRM\crm_api\venv\Lib\site-packages\django\db\models\query.py", line 1104, in first
    for obj in queryset[:1]:
               ~~~~~~~~^^^^
  File "C:\Users\CPT-003\Desktop\CRM\crm_api\venv\Lib\site-packages\django\db\models\query.py", line 384, in __iter__
    self._fetch_all()
    ~~~~~~~~~~~~~~~^^
  File "C:\Users\CPT-003\Desktop\CRM\crm_api\venv\Lib\site-packages\django\db\models\query.py", line 1949, in _fetch_all
    self._result_cache = list(self._iterable_class(self))
                         ~~~~^^^^^^^^^^^^^^^^^^^^^^^^^^^^
  File "C:\Users\CPT-003\Desktop\CRM\crm_api\venv\Lib\site-packages\django\db\models\query.py", line 91, in __iter__
    results = compiler.execute_sql(
        chunked_fetch=self.chunked_fetch, chunk_size=self.chunk_size
    )
  File "C:\Users\CPT-003\Desktop\CRM\crm_api\venv\Lib\site-packages\django\db\models\sql\compiler.py", line 1621, in execute_sql
    cursor = self.connection.cursor()
  File "C:\Users\CPT-003\Desktop\CRM\crm_api\venv\Lib\site-packages\django\utils\asyncio.py", line 26, in inner
    return func(*args, **kwargs)
  File "C:\Users\CPT-003\Desktop\CRM\crm_api\venv\Lib\site-packages\django\db\backends\base\base.py", line 320, in cursor
    return self._cursor()
           ~~~~~~~~~~~~^^
  File "C:\Users\CPT-003\Desktop\CRM\crm_api\venv\Lib\site-packages\django_tenants\postgresql_backend\base.py", line 144, in _cursor
    cursor = super()._cursor()
  File "C:\Users\CPT-003\Desktop\CRM\crm_api\venv\Lib\site-packages\django\db\backends\base\base.py", line 296, in _cursor
    self.ensure_connection()
    ~~~~~~~~~~~~~~~~~~~~~~^^
  File "C:\Users\CPT-003\Desktop\CRM\crm_api\venv\Lib\site-packages\django\utils\asyncio.py", line 26, in inner
    return func(*args, **kwargs)
  File "C:\Users\CPT-003\Desktop\CRM\crm_api\venv\Lib\site-packages\django\db\backends\base\base.py", line 278, in ensure_connection
    with self.wrap_database_errors:
         ^^^^^^^^^^^^^^^^^^^^^^^^^
  File "C:\Users\CPT-003\Desktop\CRM\crm_api\venv\Lib\site-packages\django\db\utils.py", line 91, in __exit__
    raise dj_exc_value.with_traceback(traceback) from exc_value
  File "C:\Users\CPT-003\Desktop\CRM\crm_api\venv\Lib\site-packages\django\db\backends\base\base.py", line 279, in ensure_connection
    self.connect()
    ~~~~~~~~~~~~^^
  File "C:\Users\CPT-003\Desktop\CRM\crm_api\venv\Lib\site-packages\django\utils\asyncio.py", line 26, in inner
    return func(*args, **kwargs)
  File "C:\Users\CPT-003\Desktop\CRM\crm_api\venv\Lib\site-packages\django\db\backends\base\base.py", line 256, in connect
    self.connection = self.get_new_connection(conn_params)
                      ~~~~~~~~~~~~~~~~~~~~~~~^^^^^^^^^^^^^
  File "C:\Users\CPT-003\Desktop\CRM\crm_api\venv\Lib\site-packages\django\utils\asyncio.py", line 26, in inner
    return func(*args, **kwargs)
  File "C:\Users\CPT-003\Desktop\CRM\crm_api\venv\Lib\site-packages\django\db\backends\postgresql\base.py", line 332, in get_new_connection
    connection = self.Database.connect(**conn_params)
  File "C:\Users\CPT-003\Desktop\CRM\crm_api\venv\Lib\site-packages\psycopg2\__init__.py", line 135, in connect
    conn = _connect(dsn, connection_factory=connection_factory, **kwasync)
django.db.utils.OperationalError: could not translate host name "dpg-d208jbje5dus73d4h87g-a.oregon-postgres.render.com" to address: Name or service not known

2025-07-28 21:51:36,212 [ERROR] django.server: "GET /api/talent/tenants/ HTTP/1.1" 500 186651
2025-07-28 21:51:36,217 [ERROR] django.server: "GET /api/talent-engine/requisitions/ HTTP/1.1" 500 188388
2025-07-28 21:52:00,129 [INFO] django.server: "GET /api/talent-engine/requisitions/ HTTP/1.1" 200 7733
2025-07-28 21:52:47,892 [INFO] django.server: "GET /api/talent-engine/requisitions/ HTTP/1.1" 200 7733
2025-07-28 21:53:31,866 [INFO] django.server: "GET /api/talent-engine/requisitions/ HTTP/1.1" 200 7733
2025-07-28 21:54:30,196 [INFO] django.server: "GET /api/talent-engine/requisitions/ HTTP/1.1" 200 7733
2025-07-28 21:54:31,101 [WARNING] django.request: Not Found: /api/talent/tenants/
2025-07-28 21:54:31,104 [WARNING] django.server: "GET /api/talent/tenants/ HTTP/1.1" 404 4289
2025-07-28 21:55:51,179 [INFO] django.server: "GET /api/talent-engine/requisitions/ HTTP/1.1" 200 7733
2025-07-28 21:56:00,255 [WARNING] django.request: Not Found: /api/talent/tenants/
2025-07-28 21:56:00,256 [WARNING] django.server: "GET /api/talent/tenants/ HTTP/1.1" 404 4289
2025-07-28 21:56:47,085 [WARNING] django.request: Not Found: /api/talent/tenants/
2025-07-28 21:56:47,091 [WARNING] django.server: "GET /api/talent/tenants/ HTTP/1.1" 404 4289
2025-07-28 21:57:11,763 [INFO] django.utils.autoreload: C:\Users\CPT-003\Desktop\CRM\crm_api\core\serializers.py changed, reloading.
2025-07-28 21:57:19,481 [INFO] django.utils.autoreload: Watching for file changes with StatReloader
2025-07-28 21:58:11,732 [INFO] django.utils.autoreload: Watching for file changes with StatReloader
2025-07-28 21:59:16,320 [ERROR] django.request: Internal Server Error: /api/talent-engine/requisitions/
Traceback (most recent call last):
  File "C:\Users\CPT-003\Desktop\CRM\crm_api\venv\Lib\site-packages\django\db\backends\utils.py", line 105, in _execute
    return self.cursor.execute(sql, params)
           ~~~~~~~~~~~~~~~~~~~^^^^^^^^^^^^^
psycopg2.errors.UndefinedTable: relation "talent_engine_job_requisition" does not exist
LINE 1: ..."talent_engine_job_requisition"."updated_at" FROM "talent_en...
                                                             ^


The above exception was the direct cause of the following exception:

Traceback (most recent call last):
  File "C:\Users\CPT-003\Desktop\CRM\crm_api\venv\Lib\site-packages\django\core\handlers\exception.py", line 55, in inner
    response = get_response(request)
  File "C:\Users\CPT-003\Desktop\CRM\crm_api\venv\Lib\site-packages\django\core\handlers\base.py", line 197, in _get_response
    response = wrapped_callback(request, *callback_args, **callback_kwargs)
  File "C:\Users\CPT-003\Desktop\CRM\crm_api\venv\Lib\site-packages\django\views\decorators\csrf.py", line 65, in _view_wrapper
    return view_func(request, *args, **kwargs)
  File "C:\Users\CPT-003\Desktop\CRM\crm_api\venv\Lib\site-packages\django\views\generic\base.py", line 104, in view
    return self.dispatch(request, *args, **kwargs)
           ~~~~~~~~~~~~~^^^^^^^^^^^^^^^^^^^^^^^^^^
  File "C:\Users\CPT-003\Desktop\CRM\crm_api\venv\Lib\site-packages\rest_framework\views.py", line 515, in dispatch
    response = self.handle_exception(exc)
  File "C:\Users\CPT-003\Desktop\CRM\crm_api\venv\Lib\site-packages\rest_framework\views.py", line 475, in handle_exception
    self.raise_uncaught_exception(exc)
    ~~~~~~~~~~~~~~~~~~~~~~~~~~~~~^^^^^
  File "C:\Users\CPT-003\Desktop\CRM\crm_api\venv\Lib\site-packages\rest_framework\views.py", line 486, in raise_uncaught_exception
    raise exc
  File "C:\Users\CPT-003\Desktop\CRM\crm_api\venv\Lib\site-packages\rest_framework\views.py", line 512, in dispatch
    response = handler(request, *args, **kwargs)
  File "C:\Users\CPT-003\Desktop\CRM\crm_api\venv\Lib\site-packages\rest_framework\generics.py", line 243, in get
    return self.list(request, *args, **kwargs)
           ~~~~~~~~~^^^^^^^^^^^^^^^^^^^^^^^^^^
  File "C:\Users\CPT-003\Desktop\CRM\crm_api\venv\Lib\site-packages\rest_framework\mixins.py", line 46, in list
    return Response(serializer.data)
                    ^^^^^^^^^^^^^^^
  File "C:\Users\CPT-003\Desktop\CRM\crm_api\venv\Lib\site-packages\rest_framework\serializers.py", line 797, in data
    ret = super().data
          ^^^^^^^^^^^^
  File "C:\Users\CPT-003\Desktop\CRM\crm_api\venv\Lib\site-packages\rest_framework\serializers.py", line 251, in data
    self._data = self.to_representation(self.instance)
                 ~~~~~~~~~~~~~~~~~~~~~~^^^^^^^^^^^^^^^
  File "C:\Users\CPT-003\Desktop\CRM\crm_api\venv\Lib\site-packages\rest_framework\serializers.py", line 716, in to_representation
    self.child.to_representation(item) for item in iterable
                                                   ^^^^^^^^
  File "C:\Users\CPT-003\Desktop\CRM\crm_api\venv\Lib\site-packages\django\db\models\query.py", line 384, in __iter__
    self._fetch_all()
    ~~~~~~~~~~~~~~~^^
  File "C:\Users\CPT-003\Desktop\CRM\crm_api\venv\Lib\site-packages\django\db\models\query.py", line 1949, in _fetch_all
    self._result_cache = list(self._iterable_class(self))
                         ~~~~^^^^^^^^^^^^^^^^^^^^^^^^^^^^
  File "C:\Users\CPT-003\Desktop\CRM\crm_api\venv\Lib\site-packages\django\db\models\query.py", line 91, in __iter__
    results = compiler.execute_sql(
        chunked_fetch=self.chunked_fetch, chunk_size=self.chunk_size
    )
  File "C:\Users\CPT-003\Desktop\CRM\crm_api\venv\Lib\site-packages\django\db\models\sql\compiler.py", line 1623, in execute_sql
    cursor.execute(sql, params)
    ~~~~~~~~~~~~~~^^^^^^^^^^^^^
  File "C:\Users\CPT-003\Desktop\CRM\crm_api\venv\Lib\site-packages\django\db\backends\utils.py", line 122, in execute
    return super().execute(sql, params)
           ~~~~~~~~~~~~~~~^^^^^^^^^^^^^
  File "C:\Users\CPT-003\Desktop\CRM\crm_api\venv\Lib\site-packages\django\db\backends\utils.py", line 79, in execute
    return self._execute_with_wrappers(
           ~~~~~~~~~~~~~~~~~~~~~~~~~~~^
        sql, params, many=False, executor=self._execute
        ^^^^^^^^^^^^^^^^^^^^^^^^^^^^^^^^^^^^^^^^^^^^^^^
    )
    ^
  File "C:\Users\CPT-003\Desktop\CRM\crm_api\venv\Lib\site-packages\django\db\backends\utils.py", line 92, in _execute_with_wrappers
    return executor(sql, params, many, context)
  File "C:\Users\CPT-003\Desktop\CRM\crm_api\venv\Lib\site-packages\django\db\backends\utils.py", line 100, in _execute
    with self.db.wrap_database_errors:
         ^^^^^^^^^^^^^^^^^^^^^^^^^^^^
  File "C:\Users\CPT-003\Desktop\CRM\crm_api\venv\Lib\site-packages\django\db\utils.py", line 91, in __exit__
    raise dj_exc_value.with_traceback(traceback) from exc_value
  File "C:\Users\CPT-003\Desktop\CRM\crm_api\venv\Lib\site-packages\django\db\backends\utils.py", line 105, in _execute
    return self.cursor.execute(sql, params)
           ~~~~~~~~~~~~~~~~~~~^^^^^^^^^^^^^
django.db.utils.ProgrammingError: relation "talent_engine_job_requisition" does not exist
LINE 1: ..."talent_engine_job_requisition"."updated_at" FROM "talent_en...
                                                             ^

2025-07-28 21:59:16,338 [ERROR] django.server: "GET /api/talent-engine/requisitions/ HTTP/1.1" 500 203875
2025-07-28 22:00:04,435 [INFO] django.utils.autoreload: C:\Users\CPT-003\Desktop\CRM\crm_api\core\serializers.py changed, reloading.
2025-07-28 22:00:12,313 [INFO] django.utils.autoreload: Watching for file changes with StatReloader
2025-07-28 22:00:48,865 [WARNING] django.request: Not Found: /api/talent/tenants/
2025-07-28 22:00:48,866 [WARNING] django.server: "GET /api/talent/tenants/ HTTP/1.1" 404 4289
2025-07-28 22:01:01,432 [WARNING] django.request: Not Found: /api/tanent/tenants/
2025-07-28 22:01:01,433 [WARNING] django.server: "GET /api/tanent/tenants/ HTTP/1.1" 404 4289
2025-07-28 22:01:16,253 [ERROR] django.request: Internal Server Error: /api/talent-engine/requisitions/
Traceback (most recent call last):
  File "C:\Users\CPT-003\Desktop\CRM\crm_api\venv\Lib\site-packages\django\db\backends\utils.py", line 105, in _execute
    return self.cursor.execute(sql, params)
           ~~~~~~~~~~~~~~~~~~~^^^^^^^^^^^^^
psycopg2.errors.UndefinedTable: relation "talent_engine_job_requisition" does not exist
LINE 1: ..."talent_engine_job_requisition"."updated_at" FROM "talent_en...
                                                             ^


The above exception was the direct cause of the following exception:

Traceback (most recent call last):
  File "C:\Users\CPT-003\Desktop\CRM\crm_api\venv\Lib\site-packages\django\core\handlers\exception.py", line 55, in inner
    response = get_response(request)
  File "C:\Users\CPT-003\Desktop\CRM\crm_api\venv\Lib\site-packages\django\core\handlers\base.py", line 197, in _get_response
    response = wrapped_callback(request, *callback_args, **callback_kwargs)
  File "C:\Users\CPT-003\Desktop\CRM\crm_api\venv\Lib\site-packages\django\views\decorators\csrf.py", line 65, in _view_wrapper
    return view_func(request, *args, **kwargs)
  File "C:\Users\CPT-003\Desktop\CRM\crm_api\venv\Lib\site-packages\django\views\generic\base.py", line 104, in view
    return self.dispatch(request, *args, **kwargs)
           ~~~~~~~~~~~~~^^^^^^^^^^^^^^^^^^^^^^^^^^
  File "C:\Users\CPT-003\Desktop\CRM\crm_api\venv\Lib\site-packages\rest_framework\views.py", line 515, in dispatch
    response = self.handle_exception(exc)
  File "C:\Users\CPT-003\Desktop\CRM\crm_api\venv\Lib\site-packages\rest_framework\views.py", line 475, in handle_exception
    self.raise_uncaught_exception(exc)
    ~~~~~~~~~~~~~~~~~~~~~~~~~~~~~^^^^^
  File "C:\Users\CPT-003\Desktop\CRM\crm_api\venv\Lib\site-packages\rest_framework\views.py", line 486, in raise_uncaught_exception
    raise exc
  File "C:\Users\CPT-003\Desktop\CRM\crm_api\venv\Lib\site-packages\rest_framework\views.py", line 512, in dispatch
    response = handler(request, *args, **kwargs)
  File "C:\Users\CPT-003\Desktop\CRM\crm_api\venv\Lib\site-packages\rest_framework\generics.py", line 243, in get
    return self.list(request, *args, **kwargs)
           ~~~~~~~~~^^^^^^^^^^^^^^^^^^^^^^^^^^
  File "C:\Users\CPT-003\Desktop\CRM\crm_api\venv\Lib\site-packages\rest_framework\mixins.py", line 46, in list
    return Response(serializer.data)
                    ^^^^^^^^^^^^^^^
  File "C:\Users\CPT-003\Desktop\CRM\crm_api\venv\Lib\site-packages\rest_framework\serializers.py", line 797, in data
    ret = super().data
          ^^^^^^^^^^^^
  File "C:\Users\CPT-003\Desktop\CRM\crm_api\venv\Lib\site-packages\rest_framework\serializers.py", line 251, in data
    self._data = self.to_representation(self.instance)
                 ~~~~~~~~~~~~~~~~~~~~~~^^^^^^^^^^^^^^^
  File "C:\Users\CPT-003\Desktop\CRM\crm_api\venv\Lib\site-packages\rest_framework\serializers.py", line 716, in to_representation
    self.child.to_representation(item) for item in iterable
                                                   ^^^^^^^^
  File "C:\Users\CPT-003\Desktop\CRM\crm_api\venv\Lib\site-packages\django\db\models\query.py", line 384, in __iter__
    self._fetch_all()
    ~~~~~~~~~~~~~~~^^
  File "C:\Users\CPT-003\Desktop\CRM\crm_api\venv\Lib\site-packages\django\db\models\query.py", line 1949, in _fetch_all
    self._result_cache = list(self._iterable_class(self))
                         ~~~~^^^^^^^^^^^^^^^^^^^^^^^^^^^^
  File "C:\Users\CPT-003\Desktop\CRM\crm_api\venv\Lib\site-packages\django\db\models\query.py", line 91, in __iter__
    results = compiler.execute_sql(
        chunked_fetch=self.chunked_fetch, chunk_size=self.chunk_size
    )
  File "C:\Users\CPT-003\Desktop\CRM\crm_api\venv\Lib\site-packages\django\db\models\sql\compiler.py", line 1623, in execute_sql
    cursor.execute(sql, params)
    ~~~~~~~~~~~~~~^^^^^^^^^^^^^
  File "C:\Users\CPT-003\Desktop\CRM\crm_api\venv\Lib\site-packages\django\db\backends\utils.py", line 122, in execute
    return super().execute(sql, params)
           ~~~~~~~~~~~~~~~^^^^^^^^^^^^^
  File "C:\Users\CPT-003\Desktop\CRM\crm_api\venv\Lib\site-packages\django\db\backends\utils.py", line 79, in execute
    return self._execute_with_wrappers(
           ~~~~~~~~~~~~~~~~~~~~~~~~~~~^
        sql, params, many=False, executor=self._execute
        ^^^^^^^^^^^^^^^^^^^^^^^^^^^^^^^^^^^^^^^^^^^^^^^
    )
    ^
  File "C:\Users\CPT-003\Desktop\CRM\crm_api\venv\Lib\site-packages\django\db\backends\utils.py", line 92, in _execute_with_wrappers
    return executor(sql, params, many, context)
  File "C:\Users\CPT-003\Desktop\CRM\crm_api\venv\Lib\site-packages\django\db\backends\utils.py", line 100, in _execute
    with self.db.wrap_database_errors:
         ^^^^^^^^^^^^^^^^^^^^^^^^^^^^
  File "C:\Users\CPT-003\Desktop\CRM\crm_api\venv\Lib\site-packages\django\db\utils.py", line 91, in __exit__
    raise dj_exc_value.with_traceback(traceback) from exc_value
  File "C:\Users\CPT-003\Desktop\CRM\crm_api\venv\Lib\site-packages\django\db\backends\utils.py", line 105, in _execute
    return self.cursor.execute(sql, params)
           ~~~~~~~~~~~~~~~~~~~^^^^^^^^^^^^^
django.db.utils.ProgrammingError: relation "talent_engine_job_requisition" does not exist
LINE 1: ..."talent_engine_job_requisition"."updated_at" FROM "talent_en...
                                                             ^

2025-07-28 22:01:16,270 [ERROR] django.server: "GET /api/talent-engine/requisitions/ HTTP/1.1" 500 203875
2025-07-28 22:01:23,191 [WARNING] django.request: Not Found: /api/tanent/tenants/
2025-07-28 22:01:23,192 [WARNING] django.server: "GET /api/tanent/tenants/ HTTP/1.1" 404 4289
2025-07-28 22:02:01,066 [WARNING] django.request: Not Found: /api/tanent/tenants/
2025-07-28 22:02:01,066 [WARNING] django.server: "GET /api/tanent/tenants/ HTTP/1.1" 404 4289
2025-07-28 22:02:16,328 [ERROR] django.request: Internal Server Error: /api/talent-engine/requisitions/
Traceback (most recent call last):
  File "C:\Users\CPT-003\Desktop\CRM\crm_api\venv\Lib\site-packages\django\db\backends\utils.py", line 105, in _execute
    return self.cursor.execute(sql, params)
           ~~~~~~~~~~~~~~~~~~~^^^^^^^^^^^^^
psycopg2.errors.UndefinedTable: relation "talent_engine_job_requisition" does not exist
LINE 1: ..."talent_engine_job_requisition"."updated_at" FROM "talent_en...
                                                             ^


The above exception was the direct cause of the following exception:

Traceback (most recent call last):
  File "C:\Users\CPT-003\Desktop\CRM\crm_api\venv\Lib\site-packages\django\core\handlers\exception.py", line 55, in inner
    response = get_response(request)
  File "C:\Users\CPT-003\Desktop\CRM\crm_api\venv\Lib\site-packages\django\core\handlers\base.py", line 197, in _get_response
    response = wrapped_callback(request, *callback_args, **callback_kwargs)
  File "C:\Users\CPT-003\Desktop\CRM\crm_api\venv\Lib\site-packages\django\views\decorators\csrf.py", line 65, in _view_wrapper
    return view_func(request, *args, **kwargs)
  File "C:\Users\CPT-003\Desktop\CRM\crm_api\venv\Lib\site-packages\django\views\generic\base.py", line 104, in view
    return self.dispatch(request, *args, **kwargs)
           ~~~~~~~~~~~~~^^^^^^^^^^^^^^^^^^^^^^^^^^
  File "C:\Users\CPT-003\Desktop\CRM\crm_api\venv\Lib\site-packages\rest_framework\views.py", line 515, in dispatch
    response = self.handle_exception(exc)
  File "C:\Users\CPT-003\Desktop\CRM\crm_api\venv\Lib\site-packages\rest_framework\views.py", line 475, in handle_exception
    self.raise_uncaught_exception(exc)
    ~~~~~~~~~~~~~~~~~~~~~~~~~~~~~^^^^^
  File "C:\Users\CPT-003\Desktop\CRM\crm_api\venv\Lib\site-packages\rest_framework\views.py", line 486, in raise_uncaught_exception
    raise exc
  File "C:\Users\CPT-003\Desktop\CRM\crm_api\venv\Lib\site-packages\rest_framework\views.py", line 512, in dispatch
    response = handler(request, *args, **kwargs)
  File "C:\Users\CPT-003\Desktop\CRM\crm_api\venv\Lib\site-packages\rest_framework\generics.py", line 243, in get
    return self.list(request, *args, **kwargs)
           ~~~~~~~~~^^^^^^^^^^^^^^^^^^^^^^^^^^
  File "C:\Users\CPT-003\Desktop\CRM\crm_api\venv\Lib\site-packages\rest_framework\mixins.py", line 46, in list
    return Response(serializer.data)
                    ^^^^^^^^^^^^^^^
  File "C:\Users\CPT-003\Desktop\CRM\crm_api\venv\Lib\site-packages\rest_framework\serializers.py", line 797, in data
    ret = super().data
          ^^^^^^^^^^^^
  File "C:\Users\CPT-003\Desktop\CRM\crm_api\venv\Lib\site-packages\rest_framework\serializers.py", line 251, in data
    self._data = self.to_representation(self.instance)
                 ~~~~~~~~~~~~~~~~~~~~~~^^^^^^^^^^^^^^^
  File "C:\Users\CPT-003\Desktop\CRM\crm_api\venv\Lib\site-packages\rest_framework\serializers.py", line 716, in to_representation
    self.child.to_representation(item) for item in iterable
                                                   ^^^^^^^^
  File "C:\Users\CPT-003\Desktop\CRM\crm_api\venv\Lib\site-packages\django\db\models\query.py", line 384, in __iter__
    self._fetch_all()
    ~~~~~~~~~~~~~~~^^
  File "C:\Users\CPT-003\Desktop\CRM\crm_api\venv\Lib\site-packages\django\db\models\query.py", line 1949, in _fetch_all
    self._result_cache = list(self._iterable_class(self))
                         ~~~~^^^^^^^^^^^^^^^^^^^^^^^^^^^^
  File "C:\Users\CPT-003\Desktop\CRM\crm_api\venv\Lib\site-packages\django\db\models\query.py", line 91, in __iter__
    results = compiler.execute_sql(
        chunked_fetch=self.chunked_fetch, chunk_size=self.chunk_size
    )
  File "C:\Users\CPT-003\Desktop\CRM\crm_api\venv\Lib\site-packages\django\db\models\sql\compiler.py", line 1623, in execute_sql
    cursor.execute(sql, params)
    ~~~~~~~~~~~~~~^^^^^^^^^^^^^
  File "C:\Users\CPT-003\Desktop\CRM\crm_api\venv\Lib\site-packages\django\db\backends\utils.py", line 122, in execute
    return super().execute(sql, params)
           ~~~~~~~~~~~~~~~^^^^^^^^^^^^^
  File "C:\Users\CPT-003\Desktop\CRM\crm_api\venv\Lib\site-packages\django\db\backends\utils.py", line 79, in execute
    return self._execute_with_wrappers(
           ~~~~~~~~~~~~~~~~~~~~~~~~~~~^
        sql, params, many=False, executor=self._execute
        ^^^^^^^^^^^^^^^^^^^^^^^^^^^^^^^^^^^^^^^^^^^^^^^
    )
    ^
  File "C:\Users\CPT-003\Desktop\CRM\crm_api\venv\Lib\site-packages\django\db\backends\utils.py", line 92, in _execute_with_wrappers
    return executor(sql, params, many, context)
  File "C:\Users\CPT-003\Desktop\CRM\crm_api\venv\Lib\site-packages\django\db\backends\utils.py", line 100, in _execute
    with self.db.wrap_database_errors:
         ^^^^^^^^^^^^^^^^^^^^^^^^^^^^
  File "C:\Users\CPT-003\Desktop\CRM\crm_api\venv\Lib\site-packages\django\db\utils.py", line 91, in __exit__
    raise dj_exc_value.with_traceback(traceback) from exc_value
  File "C:\Users\CPT-003\Desktop\CRM\crm_api\venv\Lib\site-packages\django\db\backends\utils.py", line 105, in _execute
    return self.cursor.execute(sql, params)
           ~~~~~~~~~~~~~~~~~~~^^^^^^^^^^^^^
django.db.utils.ProgrammingError: relation "talent_engine_job_requisition" does not exist
LINE 1: ..."talent_engine_job_requisition"."updated_at" FROM "talent_en...
                                                             ^

2025-07-28 22:02:16,341 [ERROR] django.server: "GET /api/talent-engine/requisitions/ HTTP/1.1" 500 203875
2025-07-28 22:03:16,494 [ERROR] django.request: Internal Server Error: /api/talent-engine/requisitions/
Traceback (most recent call last):
  File "C:\Users\CPT-003\Desktop\CRM\crm_api\venv\Lib\site-packages\django\db\backends\utils.py", line 105, in _execute
    return self.cursor.execute(sql, params)
           ~~~~~~~~~~~~~~~~~~~^^^^^^^^^^^^^
psycopg2.errors.UndefinedTable: relation "talent_engine_job_requisition" does not exist
LINE 1: ..."talent_engine_job_requisition"."updated_at" FROM "talent_en...
                                                             ^


The above exception was the direct cause of the following exception:

Traceback (most recent call last):
  File "C:\Users\CPT-003\Desktop\CRM\crm_api\venv\Lib\site-packages\django\core\handlers\exception.py", line 55, in inner
    response = get_response(request)
  File "C:\Users\CPT-003\Desktop\CRM\crm_api\venv\Lib\site-packages\django\core\handlers\base.py", line 197, in _get_response
    response = wrapped_callback(request, *callback_args, **callback_kwargs)
  File "C:\Users\CPT-003\Desktop\CRM\crm_api\venv\Lib\site-packages\django\views\decorators\csrf.py", line 65, in _view_wrapper
    return view_func(request, *args, **kwargs)
  File "C:\Users\CPT-003\Desktop\CRM\crm_api\venv\Lib\site-packages\django\views\generic\base.py", line 104, in view
    return self.dispatch(request, *args, **kwargs)
           ~~~~~~~~~~~~~^^^^^^^^^^^^^^^^^^^^^^^^^^
  File "C:\Users\CPT-003\Desktop\CRM\crm_api\venv\Lib\site-packages\rest_framework\views.py", line 515, in dispatch
    response = self.handle_exception(exc)
  File "C:\Users\CPT-003\Desktop\CRM\crm_api\venv\Lib\site-packages\rest_framework\views.py", line 475, in handle_exception
    self.raise_uncaught_exception(exc)
    ~~~~~~~~~~~~~~~~~~~~~~~~~~~~~^^^^^
  File "C:\Users\CPT-003\Desktop\CRM\crm_api\venv\Lib\site-packages\rest_framework\views.py", line 486, in raise_uncaught_exception
    raise exc
  File "C:\Users\CPT-003\Desktop\CRM\crm_api\venv\Lib\site-packages\rest_framework\views.py", line 512, in dispatch
    response = handler(request, *args, **kwargs)
  File "C:\Users\CPT-003\Desktop\CRM\crm_api\venv\Lib\site-packages\rest_framework\generics.py", line 243, in get
    return self.list(request, *args, **kwargs)
           ~~~~~~~~~^^^^^^^^^^^^^^^^^^^^^^^^^^
  File "C:\Users\CPT-003\Desktop\CRM\crm_api\venv\Lib\site-packages\rest_framework\mixins.py", line 46, in list
    return Response(serializer.data)
                    ^^^^^^^^^^^^^^^
  File "C:\Users\CPT-003\Desktop\CRM\crm_api\venv\Lib\site-packages\rest_framework\serializers.py", line 797, in data
    ret = super().data
          ^^^^^^^^^^^^
  File "C:\Users\CPT-003\Desktop\CRM\crm_api\venv\Lib\site-packages\rest_framework\serializers.py", line 251, in data
    self._data = self.to_representation(self.instance)
                 ~~~~~~~~~~~~~~~~~~~~~~^^^^^^^^^^^^^^^
  File "C:\Users\CPT-003\Desktop\CRM\crm_api\venv\Lib\site-packages\rest_framework\serializers.py", line 716, in to_representation
    self.child.to_representation(item) for item in iterable
                                                   ^^^^^^^^
  File "C:\Users\CPT-003\Desktop\CRM\crm_api\venv\Lib\site-packages\django\db\models\query.py", line 384, in __iter__
    self._fetch_all()
    ~~~~~~~~~~~~~~~^^
  File "C:\Users\CPT-003\Desktop\CRM\crm_api\venv\Lib\site-packages\django\db\models\query.py", line 1949, in _fetch_all
    self._result_cache = list(self._iterable_class(self))
                         ~~~~^^^^^^^^^^^^^^^^^^^^^^^^^^^^
  File "C:\Users\CPT-003\Desktop\CRM\crm_api\venv\Lib\site-packages\django\db\models\query.py", line 91, in __iter__
    results = compiler.execute_sql(
        chunked_fetch=self.chunked_fetch, chunk_size=self.chunk_size
    )
  File "C:\Users\CPT-003\Desktop\CRM\crm_api\venv\Lib\site-packages\django\db\models\sql\compiler.py", line 1623, in execute_sql
    cursor.execute(sql, params)
    ~~~~~~~~~~~~~~^^^^^^^^^^^^^
  File "C:\Users\CPT-003\Desktop\CRM\crm_api\venv\Lib\site-packages\django\db\backends\utils.py", line 122, in execute
    return super().execute(sql, params)
           ~~~~~~~~~~~~~~~^^^^^^^^^^^^^
  File "C:\Users\CPT-003\Desktop\CRM\crm_api\venv\Lib\site-packages\django\db\backends\utils.py", line 79, in execute
    return self._execute_with_wrappers(
           ~~~~~~~~~~~~~~~~~~~~~~~~~~~^
        sql, params, many=False, executor=self._execute
        ^^^^^^^^^^^^^^^^^^^^^^^^^^^^^^^^^^^^^^^^^^^^^^^
    )
    ^
  File "C:\Users\CPT-003\Desktop\CRM\crm_api\venv\Lib\site-packages\django\db\backends\utils.py", line 92, in _execute_with_wrappers
    return executor(sql, params, many, context)
  File "C:\Users\CPT-003\Desktop\CRM\crm_api\venv\Lib\site-packages\django\db\backends\utils.py", line 100, in _execute
    with self.db.wrap_database_errors:
         ^^^^^^^^^^^^^^^^^^^^^^^^^^^^
  File "C:\Users\CPT-003\Desktop\CRM\crm_api\venv\Lib\site-packages\django\db\utils.py", line 91, in __exit__
    raise dj_exc_value.with_traceback(traceback) from exc_value
  File "C:\Users\CPT-003\Desktop\CRM\crm_api\venv\Lib\site-packages\django\db\backends\utils.py", line 105, in _execute
    return self.cursor.execute(sql, params)
           ~~~~~~~~~~~~~~~~~~~^^^^^^^^^^^^^
django.db.utils.ProgrammingError: relation "talent_engine_job_requisition" does not exist
LINE 1: ..."talent_engine_job_requisition"."updated_at" FROM "talent_en...
                                                             ^

2025-07-28 22:03:16,530 [ERROR] django.server: "GET /api/talent-engine/requisitions/ HTTP/1.1" 500 203875
2025-07-29 09:32:52,805 [INFO] django.utils.autoreload: Watching for file changes with StatReloader
2025-07-29 09:39:05,679 [INFO] django.utils.autoreload: Watching for file changes with StatReloader
2025-07-29 09:40:02,282 [INFO] django.server: "POST /api/token/ HTTP/1.1" 200 965
2025-07-29 09:40:30,449 [INFO] core: Listing tenants: [2] for tenant proliance
2025-07-29 09:40:30,450 [INFO] django.server: "GET /api/tenant/tenants/ HTTP/1.1" 200 2482
2025-07-29 09:46:34,933 [INFO] django.utils.autoreload: C:\Users\CPT-003\Desktop\CRM\crm_api\core\models.py changed, reloading.
2025-07-29 09:46:39,186 [INFO] django.utils.autoreload: Watching for file changes with StatReloader
2025-07-29 09:47:21,930 [INFO] django.utils.autoreload: C:\Users\CPT-003\Desktop\CRM\crm_api\core\serializers.py changed, reloading.
2025-07-29 09:47:26,739 [INFO] django.utils.autoreload: Watching for file changes with StatReloader
2025-07-29 09:53:42,141 [INFO] django.utils.autoreload: Watching for file changes with StatReloader
2025-07-29 09:53:58,317 [INFO] django.server: "POST /api/token/ HTTP/1.1" 200 965
2025-07-29 09:54:19,568 [INFO] core: Listing tenants: [2] for tenant proliance
2025-07-29 09:54:19,569 [INFO] django.server: "GET /api/tenant/tenants/ HTTP/1.1" 200 2505
2025-07-29 09:54:47,110 [WARNING] django.request: Not Found: /api/tenant/tenants/1/
2025-07-29 09:54:47,111 [WARNING] django.server: "GET /api/tenant/tenants/1/ HTTP/1.1" 404 47
2025-07-29 09:56:20,796 [INFO] core: Listing tenants: [2] for tenant proliance
2025-07-29 09:56:20,797 [INFO] django.server: "GET /api/tenant/tenants/ HTTP/1.1" 200 2505
2025-07-29 09:56:31,031 [INFO] core: Retrieving tenant: 2 for tenant proliance
2025-07-29 09:56:31,040 [INFO] django.server: "GET /api/tenant/tenants/2/ HTTP/1.1" 200 2503
2025-07-29 09:57:10,468 [INFO] core: Saving tenant with schema_name: proliance
2025-07-29 09:57:10,478 [INFO] core: Tenant updated: proliance for tenant proliance
2025-07-29 09:57:10,485 [INFO] django.server: "PATCH /api/tenant/tenants/2/ HTTP/1.1" 200 2536
2025-07-29 09:57:33,222 [INFO] django.server: "OPTIONS /api/token/validate/ HTTP/1.1" 200 0
2025-07-29 09:57:33,224 [INFO] django.server: "OPTIONS /api/token/validate/ HTTP/1.1" 200 0
2025-07-29 09:57:33,289 [WARNING] django.request: Unauthorized: /api/token/validate/
2025-07-29 09:57:33,290 [WARNING] django.server: "GET /api/token/validate/ HTTP/1.1" 401 183
2025-07-29 09:57:33,364 [WARNING] django.request: Unauthorized: /api/token/validate/
2025-07-29 09:57:33,365 [WARNING] django.server: "GET /api/token/validate/ HTTP/1.1" 401 183
2025-07-29 09:57:43,721 [WARNING] django.request: Unauthorized: /api/token/
2025-07-29 09:57:43,722 [WARNING] django.server: "POST /api/token/ HTTP/1.1" 401 63
2025-07-29 09:57:49,484 [WARNING] django.request: Unauthorized: /api/token/
2025-07-29 09:57:49,484 [WARNING] django.server: "POST /api/token/ HTTP/1.1" 401 63
2025-07-29 09:57:59,310 [INFO] django.server: "POST /api/token/ HTTP/1.1" 200 965
2025-07-29 09:57:59,407 [INFO] django.server: "GET /api/token/validate/ HTTP/1.1" 200 389
2025-07-29 09:57:59,475 [INFO] django.server: "GET /api/token/validate/ HTTP/1.1" 200 389
2025-07-29 09:57:59,568 [INFO] django.server: "OPTIONS /api/user/tenant-users/ HTTP/1.1" 200 0
2025-07-29 09:57:59,568 [INFO] django.server: "OPTIONS /api/user/tenant-users/ HTTP/1.1" 200 0
2025-07-29 09:57:59,647 [INFO] users: Retrieved 3 users for tenant proliance
2025-07-29 09:57:59,661 [INFO] django.server: "GET /api/user/tenant-users/ HTTP/1.1" 200 1022
2025-07-29 09:57:59,721 [INFO] users: Retrieved 3 users for tenant proliance
2025-07-29 09:57:59,732 [INFO] django.server: "GET /api/user/tenant-users/ HTTP/1.1" 200 1022
2025-07-29 09:58:04,555 [INFO] django.server: "OPTIONS /api/talent-engine/requisitions/ HTTP/1.1" 200 0
2025-07-29 09:58:04,557 [INFO] django.server: "OPTIONS /api/talent-engine/requisitions/ HTTP/1.1" 200 0
2025-07-29 09:58:04,701 [INFO] django.server: "GET /api/talent-engine/requisitions/ HTTP/1.1" 200 6330
2025-07-29 09:58:04,804 [INFO] django.server: "GET /api/talent-engine/requisitions/ HTTP/1.1" 200 6330
2025-07-29 09:58:07,626 [INFO] django.server: "GET /api/talent-engine/requisitions/ HTTP/1.1" 200 6330
2025-07-29 09:58:07,716 [INFO] django.server: "GET /api/talent-engine/requisitions/ HTTP/1.1" 200 6330
2025-07-29 09:58:09,585 [INFO] django.server: "OPTIONS /api/talent-engine-job-applications/applications/job-requisitions/PRO-0003/applications/ HTTP/1.1" 200 0
2025-07-29 09:58:09,585 [INFO] django.server: "OPTIONS /api/talent-engine-job-applications/applications/job-requisitions/PRO-0003/applications/ HTTP/1.1" 200 0
2025-07-29 09:58:09,765 [INFO] django.server: "GET /api/talent-engine-job-applications/applications/job-requisitions/PRO-0003/applications/ HTTP/1.1" 200 6967
2025-07-29 09:58:09,914 [INFO] django.server: "GET /api/talent-engine-job-applications/applications/job-requisitions/PRO-0003/applications/ HTTP/1.1" 200 6967
2025-07-29 09:58:39,003 [INFO] core: Saving tenant with schema_name: proliance
2025-07-29 09:58:39,008 [INFO] core: Tenant updated: proliance for tenant proliance
2025-07-29 09:58:39,014 [INFO] django.server: "PATCH /api/tenant/tenants/2/ HTTP/1.1" 200 2690
2025-07-29 09:59:48,923 [INFO] core: Saving tenant with schema_name: proliance
2025-07-29 09:59:48,927 [INFO] core: Tenant updated: proliance for tenant proliance
2025-07-29 09:59:48,935 [INFO] django.server: "PATCH /api/tenant/tenants/2/ HTTP/1.1" 200 2838
2025-07-30 07:54:06,198 [INFO] django.utils.autoreload: Watching for file changes with StatReloader
2025-07-30 08:06:29,066 [INFO] django.utils.autoreload: C:\Users\CPT-003\Desktop\CRM\crm_api\job_application\serializers.py changed, reloading.
2025-07-30 08:06:36,827 [INFO] django.utils.autoreload: Watching for file changes with StatReloader
2025-07-30 08:07:49,315 [INFO] django.utils.autoreload: C:\Users\CPT-003\Desktop\CRM\crm_api\core\serializers.py changed, reloading.
2025-07-30 08:07:54,161 [INFO] django.utils.autoreload: Watching for file changes with StatReloader
2025-07-30 08:08:51,472 [INFO] django.utils.autoreload: C:\Users\CPT-003\Desktop\CRM\crm_api\core\serializers.py changed, reloading.
2025-07-30 08:08:57,716 [INFO] django.utils.autoreload: Watching for file changes with StatReloader
2025-07-30 08:09:54,500 [INFO] django.server: "POST /api/token/ HTTP/1.1" 200 964
2025-07-30 08:10:45,000 [INFO] core: Saving tenant with schema_name: proliance
2025-07-30 08:10:46,133 [INFO] core: Tenant updated: proliance for tenant proliance
2025-07-30 08:10:47,605 [INFO] django.server: "PATCH /api/tenant/tenants/1/ HTTP/1.1" 200 1955
2025-07-30 08:11:26,025 [INFO] core: Retrieving tenant: 1 for tenant proliance
2025-07-30 08:11:27,156 [INFO] django.server: "GET /api/tenant/tenants/1/ HTTP/1.1" 200 1955
2025-07-30 08:13:05,579 [INFO] django.utils.autoreload: C:\Users\CPT-003\Desktop\CRM\crm_api\core\serializers.py changed, reloading.
2025-07-30 08:13:09,966 [INFO] django.utils.autoreload: Watching for file changes with StatReloader
2025-07-30 08:13:35,240 [INFO] core: Retrieving tenant: 1 for tenant proliance
2025-07-30 08:13:35,720 [INFO] django.server: "GET /api/tenant/tenants/1/ HTTP/1.1" 200 506
2025-07-30 08:14:08,178 [ERROR] django.request: Internal Server Error: /api/tenant/tenants/1/
Traceback (most recent call last):
  File "C:\Users\CPT-003\Desktop\CRM\crm_api\venv\Lib\site-packages\django\core\handlers\exception.py", line 55, in inner
    response = get_response(request)
  File "C:\Users\CPT-003\Desktop\CRM\crm_api\venv\Lib\site-packages\django\core\handlers\base.py", line 197, in _get_response
    response = wrapped_callback(request, *callback_args, **callback_kwargs)
  File "C:\Users\CPT-003\Desktop\CRM\crm_api\venv\Lib\site-packages\django\views\decorators\csrf.py", line 65, in _view_wrapper
    return view_func(request, *args, **kwargs)
  File "C:\Users\CPT-003\Desktop\CRM\crm_api\venv\Lib\site-packages\rest_framework\viewsets.py", line 125, in view
    return self.dispatch(request, *args, **kwargs)
           ~~~~~~~~~~~~~^^^^^^^^^^^^^^^^^^^^^^^^^^
  File "C:\Users\CPT-003\Desktop\CRM\crm_api\venv\Lib\site-packages\rest_framework\views.py", line 515, in dispatch
    response = self.handle_exception(exc)
  File "C:\Users\CPT-003\Desktop\CRM\crm_api\venv\Lib\site-packages\rest_framework\views.py", line 475, in handle_exception
    self.raise_uncaught_exception(exc)
    ~~~~~~~~~~~~~~~~~~~~~~~~~~~~~^^^^^
  File "C:\Users\CPT-003\Desktop\CRM\crm_api\venv\Lib\site-packages\rest_framework\views.py", line 486, in raise_uncaught_exception
    raise exc
  File "C:\Users\CPT-003\Desktop\CRM\crm_api\venv\Lib\site-packages\rest_framework\views.py", line 512, in dispatch
    response = handler(request, *args, **kwargs)
  File "C:\Users\CPT-003\Desktop\CRM\crm_api\venv\Lib\site-packages\rest_framework\mixins.py", line 82, in partial_update
    return self.update(request, *args, **kwargs)
           ~~~~~~~~~~~^^^^^^^^^^^^^^^^^^^^^^^^^^
  File "C:\Users\CPT-003\Desktop\CRM\crm_api\core\views.py", line 418, in update
    serializer = self.get_serializer(instance, data=request.data, files=request.FILES, partial=partial)
  File "C:\Users\CPT-003\Desktop\CRM\crm_api\venv\Lib\site-packages\rest_framework\generics.py", line 114, in get_serializer
    return serializer_class(*args, **kwargs)
  File "C:\Users\CPT-003\Desktop\CRM\crm_api\venv\Lib\site-packages\rest_framework\serializers.py", line 121, in __init__
    super().__init__(**kwargs)
    ~~~~~~~~~~~~~~~~^^^^^^^^^^
TypeError: Field.__init__() got an unexpected keyword argument 'files'
2025-07-30 08:14:08,184 [ERROR] django.server: "PATCH /api/tenant/tenants/1/ HTTP/1.1" 500 125481
2025-07-30 08:14:59,199 [INFO] django.utils.autoreload: C:\Users\CPT-003\Desktop\CRM\crm_api\core\views.py changed, reloading.
2025-07-30 08:15:03,479 [INFO] django.utils.autoreload: Watching for file changes with StatReloader
2025-07-30 08:15:35,657 [INFO] core: Retrieving tenant: 1 for tenant proliance
2025-07-30 08:15:36,205 [INFO] django.server: "GET /api/tenant/tenants/1/ HTTP/1.1" 200 506
2025-07-30 08:16:10,127 [INFO] core: Saving tenant with schema_name: proliance
2025-07-30 08:16:11,228 [INFO] core: Tenant updated: proliance for tenant proliance
2025-07-30 08:16:11,231 [INFO] django.server: "PATCH /api/tenant/tenants/1/ HTTP/1.1" 200 506
2025-07-30 08:16:45,461 [INFO] core: Saving tenant with schema_name: proliance
2025-07-30 08:16:46,542 [INFO] core: Tenant updated: proliance for tenant proliance
2025-07-30 08:16:46,545 [INFO] django.server: "PATCH /api/tenant/tenants/1/ HTTP/1.1" 200 506
2025-07-30 08:17:18,164 [INFO] core: Saving tenant with schema_name: proliance
2025-07-30 08:17:19,346 [INFO] core: Tenant updated: proliance for tenant proliance
2025-07-30 08:17:19,348 [INFO] django.server: "PATCH /api/tenant/tenants/1/ HTTP/1.1" 200 506
2025-07-30 08:19:22,670 [INFO] core: Retrieving tenant: 1 for tenant proliance
2025-07-30 08:19:22,671 [INFO] django.server: "GET /api/tenant/tenants/1/ HTTP/1.1" 200 506
2025-07-30 08:27:16,280 [INFO] django.utils.autoreload: C:\Users\CPT-003\Desktop\CRM\crm_api\lumina_care\settings.py changed, reloading.
2025-07-30 08:27:21,501 [INFO] django.utils.autoreload: Watching for file changes with StatReloader
2025-07-30 08:36:48,046 [INFO] django.server: "GET /api/talent-engine-job-applications/public-published-requisitions-with-shortlisted/?schema_name=proliance HTTP/1.1" 200 16252
2025-07-30 08:39:52,550 [INFO] django.server: "GET /api/talent-engine-job-applications/public-published-requisitions-with-shortlisted/?schema_name=proliance HTTP/1.1" 200 38891
2025-07-30 08:39:53,325 [INFO] django.server: "GET /static/rest_framework/css/default.css HTTP/1.1" 200 1152
2025-07-30 08:39:53,329 [INFO] django.server: "GET /static/rest_framework/css/prettify.css HTTP/1.1" 200 817
2025-07-30 08:39:53,366 [INFO] django.server: "GET /static/rest_framework/js/csrf.js HTTP/1.1" 200 1793
2025-07-30 08:39:53,387 [INFO] django.server: "GET /static/rest_framework/css/bootstrap.min.css HTTP/1.1" 200 121457
2025-07-30 08:39:53,398 [INFO] django.server: "GET /static/rest_framework/css/bootstrap-tweaks.css HTTP/1.1" 200 3426
2025-07-30 08:39:53,409 [INFO] django.server: "GET /static/rest_framework/js/bootstrap.min.js HTTP/1.1" 200 39680
2025-07-30 08:39:53,418 [INFO] django.server: "GET /static/rest_framework/js/load-ajax-form.js HTTP/1.1" 200 59
2025-07-30 08:39:53,423 [INFO] django.server: "GET /static/rest_framework/js/ajax-form.js HTTP/1.1" 200 3796
2025-07-30 08:39:53,428 [INFO] django.server: "GET /static/rest_framework/js/prettify-min.js HTTP/1.1" 200 13632
2025-07-30 08:39:53,434 [INFO] django.server: "GET /static/rest_framework/js/default.js HTTP/1.1" 200 1268
2025-07-30 08:39:53,450 [INFO] django.server: "GET /static/rest_framework/img/grid.png HTTP/1.1" 200 1458
2025-07-30 08:39:53,476 [INFO] django.server: "GET /static/rest_framework/js/jquery-3.7.1.min.js HTTP/1.1" 200 87533
2025-07-30 08:39:57,145 [WARNING] django.request: Not Found: /favicon.ico
2025-07-30 08:39:57,145 [WARNING] django.server: "GET /favicon.ico HTTP/1.1" 404 4265
2025-07-30 08:44:33,555 [INFO] django.utils.autoreload: C:\Users\CPT-003\Desktop\CRM\crm_api\job_application\views.py changed, reloading.
2025-07-30 08:44:39,643 [INFO] django.utils.autoreload: Watching for file changes with StatReloader
2025-07-30 08:45:34,567 [INFO] django.server: "GET /api/talent-engine-job-applications/public-published-requisitions-with-shortlisted/?schema_name=proliance HTTP/1.1" 200 16252
2025-07-30 08:45:56,379 [INFO] django.server: "GET /api/talent-engine-job-applications/public-published-requisitions-with-shortlisted/?schema_name=proliance HTTP/1.1" 200 38891
2025-07-30 08:50:01,573 [INFO] django.utils.autoreload: C:\Users\CPT-003\Desktop\CRM\crm_api\job_application\views.py changed, reloading.
2025-07-30 08:50:07,792 [INFO] django.utils.autoreload: Watching for file changes with StatReloader
2025-07-30 08:50:50,229 [INFO] django.server: "GET /api/talent-engine-job-applications/public-published-requisitions-with-shortlisted/?schema_name=proliance HTTP/1.1" 200 38891
2025-07-30 08:53:03,622 [INFO] django.server: "GET /api/talent-engine-job-applications/public-published-requisitions-with-shortlisted/?schema_name=proliance HTTP/1.1" 200 38891
2025-07-30 08:53:07,904 [INFO] django.server: "GET /api/talent-engine-job-applications/public-published-requisitions-with-shortlisted/?schema_name=proliance HTTP/1.1" 200 16252
2025-07-30 08:53:34,195 [INFO] django.utils.autoreload: C:\Users\CPT-003\Desktop\CRM\crm_api\job_application\views.py changed, reloading.
2025-07-30 08:53:42,501 [INFO] django.utils.autoreload: Watching for file changes with StatReloader
2025-07-30 08:54:24,837 [INFO] django.server: "GET /api/talent-engine-job-applications/public-published-requisitions-with-shortlisted/?schema_name=proliance HTTP/1.1" 200 16252
2025-07-30 08:56:49,191 [INFO] django.utils.autoreload: C:\Users\CPT-003\Desktop\CRM\crm_api\job_application\views.py changed, reloading.
2025-07-30 08:56:55,733 [INFO] django.utils.autoreload: Watching for file changes with StatReloader
2025-07-30 08:57:38,453 [INFO] django.server: "GET /api/talent-engine-job-applications/public-published-requisitions-with-shortlisted/?schema_name=proliance HTTP/1.1" 200 5926
2025-07-30 08:58:04,092 [INFO] django.server: "GET /api/talent-engine-job-applications/public-published-requisitions-with-shortlisted/?schema_name=proliance HTTP/1.1" 200 17372
2025-07-30 08:59:21,483 [INFO] django.utils.autoreload: C:\Users\CPT-003\Desktop\CRM\crm_api\job_application\views.py changed, reloading.
2025-07-30 08:59:25,853 [INFO] django.utils.autoreload: Watching for file changes with StatReloader
2025-07-30 09:00:06,606 [INFO] django.server: "GET /api/talent-engine-job-applications/public-published-requisitions-with-shortlisted/?schema_name=proliance HTTP/1.1" 200 5926
2025-07-30 09:05:30,587 [INFO] django.server: "GET /api/talent-engine-job-applications/public-published-requisitions-with-shortlisted/?schema_name=proliance HTTP/1.1" 200 17372
2025-07-30 09:07:53,989 [INFO] core: Retrieving tenant: 1 for tenant proliance
2025-07-30 09:07:54,413 [INFO] django.server: "GET /api/tenant/tenants/1/ HTTP/1.1" 200 506
2025-07-30 09:09:57,830 [INFO] django.utils.autoreload: C:\Users\CPT-003\Desktop\CRM\crm_api\core\serializers.py changed, reloading.
2025-07-30 09:10:01,971 [INFO] django.utils.autoreload: Watching for file changes with StatReloader
2025-07-30 09:11:50,044 [INFO] core: Retrieving tenant: 1 for tenant proliance
2025-07-30 09:11:50,603 [INFO] django.server: "GET /api/tenant/tenants/1/ HTTP/1.1" 200 511
2025-07-30 09:13:21,354 [INFO] django.utils.autoreload: C:\Users\CPT-003\Desktop\CRM\crm_api\job_application\views.py changed, reloading.
2025-07-30 09:13:25,718 [INFO] django.utils.autoreload: Watching for file changes with StatReloader
2025-07-30 09:16:18,668 [INFO] django.server: "GET /api/talent-engine-job-applications/public-published-requisitions-with-shortlisted/?schema_name=proliance HTTP/1.1" 200 17387
2025-07-30 09:17:48,215 [INFO] django.utils.autoreload: C:\Users\CPT-003\Desktop\CRM\crm_api\job_application\views.py changed, reloading.
2025-07-30 09:17:56,447 [INFO] django.utils.autoreload: Watching for file changes with StatReloader
2025-07-30 09:18:27,049 [INFO] django.utils.autoreload: C:\Users\CPT-003\Desktop\CRM\crm_api\job_application\views.py changed, reloading.
2025-07-30 09:18:30,609 [INFO] django.utils.autoreload: Watching for file changes with StatReloader
2025-07-30 09:21:19,294 [INFO] django.utils.autoreload: C:\Users\CPT-003\Desktop\CRM\crm_api\job_application\views.py changed, reloading.
2025-07-30 09:21:26,339 [INFO] django.utils.autoreload: Watching for file changes with StatReloader
2025-07-30 09:25:14,285 [INFO] django.utils.autoreload: C:\Users\CPT-003\Desktop\CRM\crm_api\job_application\views.py changed, reloading.
2025-07-30 09:25:21,417 [INFO] django.utils.autoreload: Watching for file changes with StatReloader
2025-07-30 09:30:27,966 [INFO] django.utils.autoreload: C:\Users\CPT-003\Desktop\CRM\crm_api\job_application\views.py changed, reloading.
2025-07-30 09:30:32,099 [INFO] django.utils.autoreload: Watching for file changes with StatReloader
2025-07-30 09:31:15,525 [INFO] django.server: "GET /api/talent-engine-job-applications/public-published-requisitions-with-shortlisted/?schema_name=proliance HTTP/1.1" 200 17387
2025-07-30 09:37:37,444 [INFO] django.utils.autoreload: C:\Users\CPT-003\Desktop\CRM\crm_api\job_application\views.py changed, reloading.
2025-07-30 09:37:42,614 [INFO] django.utils.autoreload: Watching for file changes with StatReloader
2025-07-30 09:38:45,600 [WARNING] django.request: Not Found: /api/talent-engie-job-applications/public-published-requisitions-with-shortlisted/
2025-07-30 09:38:45,601 [WARNING] django.server: "GET /api/talent-engie-job-applications/public-published-requisitions-with-shortlisted/?schema_name=proliance HTTP/1.1" 404 4497
2025-07-30 09:39:30,926 [INFO] django.server: "GET /api/talent-engine-job-applications/public-published-requisitions-with-shortlisted/?schema_name=proliance HTTP/1.1" 200 5941
2025-07-30 09:39:39,067 [INFO] django.server: "GET /api/talent-engine-job-applications/public-published-requisitions-with-shortlisted/?schema_name=proliance HTTP/1.1" 200 17387
2025-07-30 09:40:27,760 [WARNING] django.request: Not Found: /api/tenant/teanats/
2025-07-30 09:40:27,761 [WARNING] django.server: "GET /api/tenant/teanats/ HTTP/1.1" 404 7546
2025-07-30 09:40:42,877 [WARNING] django.request: Unauthorized: /api/tenant/tenants/1/
2025-07-30 09:40:42,878 [WARNING] django.server: "GET /api/tenant/tenants/1/ HTTP/1.1" 401 183
2025-07-30 09:41:25,216 [INFO] django.utils.autoreload: Watching for file changes with StatReloader
2025-07-30 09:41:54,411 [WARNING] django.request: Method Not Allowed: /api/token/
2025-07-30 09:41:54,412 [WARNING] django.server: "GET /api/token/ HTTP/1.1" 405 40
2025-07-30 09:42:03,672 [WARNING] django.request: Unauthorized: /api/token/
2025-07-30 09:42:03,673 [WARNING] django.server: "POST /api/token/ HTTP/1.1" 401 63
2025-07-30 09:42:20,353 [INFO] django.server: "POST /api/token/ HTTP/1.1" 200 965
2025-07-30 09:42:36,379 [WARNING] django.request: Not Found: /api/tenant/tenants/1/
2025-07-30 09:42:36,380 [WARNING] django.server: "GET /api/tenant/tenants/1/ HTTP/1.1" 404 47
2025-07-30 09:42:53,210 [INFO] django.server: "POST /api/token/ HTTP/1.1" 200 965
2025-07-30 09:43:03,515 [WARNING] django.request: Not Found: /api/tenant/tenants/1/
2025-07-30 09:43:03,515 [WARNING] django.server: "GET /api/tenant/tenants/1/ HTTP/1.1" 404 47
2025-07-30 09:43:14,788 [WARNING] django.request: Not Found: /api/tenant/tenants/1/
2025-07-30 09:43:14,789 [WARNING] django.server: "GET /api/tenant/tenants/1/ HTTP/1.1" 404 47
2025-07-30 09:43:31,098 [WARNING] django.request: Not Found: /api/tenant/tenants/1/
2025-07-30 09:43:31,099 [WARNING] django.server: "GET /api/tenant/tenants/1/ HTTP/1.1" 404 47
2025-07-30 09:43:51,577 [INFO] core: Listing tenants: [2] for tenant proliance
2025-07-30 09:43:51,577 [INFO] django.server: "GET /api/tenant/tenants/ HTTP/1.1" 200 674
2025-07-30 09:44:12,306 [INFO] django.utils.autoreload: Watching for file changes with StatReloader
2025-07-30 09:44:27,247 [INFO] django.server: "POST /api/token/ HTTP/1.1" 200 965
2025-07-30 09:44:48,278 [INFO] core: Listing tenants: [2] for tenant proliance
2025-07-30 09:44:48,279 [INFO] django.server: "GET /api/tenant/tenants/ HTTP/1.1" 200 674
2025-07-30 09:45:06,740 [WARNING] django.request: Unauthorized: /api/token/
2025-07-30 09:45:06,740 [WARNING] django.server: "POST /api/token/ HTTP/1.1" 401 63
2025-07-30 09:45:15,281 [INFO] django.server: "POST /api/token/ HTTP/1.1" 200 965
2025-07-30 09:49:09,207 [WARNING] django.request: Not Found: /api/tenant/tenants/1/
2025-07-30 09:49:09,207 [WARNING] django.server: "GET /api/tenant/tenants/1/ HTTP/1.1" 404 47
2025-07-30 09:49:12,768 [INFO] core: Listing tenants: [2] for tenant proliance
2025-07-30 09:49:12,768 [INFO] django.server: "GET /api/tenant/tenants/ HTTP/1.1" 200 674
2025-07-30 09:50:04,508 [INFO] django.server: "GET /api/talent-engine-job-applications/public-published-requisitions-with-shortlisted/?schema_name=proliance HTTP/1.1" 200 15769
2025-07-30 09:50:12,808 [INFO] django.server: "GET /api/talent-engine-job-applications/public-published-requisitions-with-shortlisted/?schema_name=proliance HTTP/1.1" 200 5541
2025-07-30 15:34:29,731 [INFO] django.utils.autoreload: Watching for file changes with StatReloader
2025-07-30 15:36:43,279 [INFO] django.utils.autoreload: C:\Users\CPT-003\Desktop\CRM\crm_api\job_application\views.py changed, reloading.
2025-07-30 15:36:47,244 [INFO] django.utils.autoreload: Watching for file changes with StatReloader
2025-07-30 15:37:38,914 [INFO] django.utils.autoreload: C:\Users\CPT-003\Desktop\CRM\crm_api\job_application\views.py changed, reloading.
2025-07-30 15:37:43,630 [INFO] django.utils.autoreload: Watching for file changes with StatReloader
2025-07-30 15:39:30,058 [INFO] django.utils.autoreload: C:\Users\CPT-003\Desktop\CRM\crm_api\job_application\views.py changed, reloading.
2025-07-30 15:39:33,830 [INFO] django.utils.autoreload: Watching for file changes with StatReloader
2025-07-30 15:39:51,636 [INFO] django.utils.autoreload: C:\Users\CPT-003\Desktop\CRM\crm_api\job_application\views.py changed, reloading.
2025-07-30 15:39:54,733 [INFO] django.utils.autoreload: Watching for file changes with StatReloader
2025-07-30 15:40:47,515 [INFO] django.server: "POST /api/token/ HTTP/1.1" 200 965
2025-07-30 15:41:06,284 [INFO] core: Listing tenants: [2] for tenant proliance
2025-07-30 15:41:06,285 [INFO] django.server: "GET /api/tenant/tenants/ HTTP/1.1" 200 674
2025-07-30 15:41:22,578 [WARNING] django.request: Unauthorized: /api/talent-engine-job-applications/public-published-requisitions-with-shortlisted/
2025-07-30 15:41:22,578 [WARNING] django.server: "GET /api/talent-engine-job-applications/public-published-requisitions-with-shortlisted/?schema_name=proliance HTTP/1.1" 401 183
2025-07-30 15:41:28,995 [INFO] django.server: "GET /api/talent-engine-job-applications/public-published-requisitions-with-shortlisted/?schema_name=proliance HTTP/1.1" 200 5541
