2025-07-23 13:52:38,019 [INFO] django.server: "POST /api/user/password/reset/ HTTP/1.1" 200 52
2025-07-23 13:52:59,367 [INFO] django.utils.autoreload: C:\Users\CPT-003\Desktop\CRM\crm_api\users\views.py changed, reloading.
2025-07-23 13:53:02,160 [INFO] django.utils.autoreload: Watching for file changes with StatReloader
2025-07-23 13:53:18,778 [INFO] django.server: "POST /api/user/password/reset/ HTTP/1.1" 200 52
2025-07-23 13:53:38,031 [INFO] django.utils.autoreload: C:\Users\CPT-003\Desktop\CRM\crm_api\users\views.py changed, reloading.
2025-07-23 13:53:40,776 [INFO] django.utils.autoreload: Watching for file changes with StatReloader
2025-07-23 13:53:53,351 [INFO] django.server: "POST /api/user/password/reset/ HTTP/1.1" 200 52
2025-07-23 13:54:16,685 [INFO] django.utils.autoreload: C:\Users\CPT-003\Desktop\CRM\crm_api\users\views.py changed, reloading.
2025-07-23 13:54:19,466 [INFO] django.utils.autoreload: Watching for file changes with StatReloader
2025-07-23 13:54:31,753 [INFO] django.server: "POST /api/user/password/reset/ HTTP/1.1" 200 52
2025-07-23 13:54:53,374 [INFO] django.utils.autoreload: C:\Users\CPT-003\Desktop\CRM\crm_api\users\views.py changed, reloading.
2025-07-23 13:54:56,066 [INFO] django.utils.autoreload: Watching for file changes with StatReloader
2025-07-23 13:55:07,558 [INFO] django.server: "POST /api/user/password/reset/ HTTP/1.1" 200 52
2025-07-23 13:55:54,204 [INFO] django.utils.autoreload: C:\Users\CPT-003\Desktop\CRM\crm_api\users\views.py changed, reloading.
2025-07-23 13:55:56,991 [INFO] django.utils.autoreload: Watching for file changes with StatReloader
2025-07-23 13:56:35,689 [INFO] django.server: "POST /api/user/password/reset/ HTTP/1.1" 200 52
2025-07-23 13:57:28,949 [INFO] django.utils.autoreload: C:\Users\CPT-003\Desktop\CRM\crm_api\users\views.py changed, reloading.
2025-07-23 13:57:32,193 [INFO] django.utils.autoreload: Watching for file changes with StatReloader
2025-07-23 13:58:06,575 [INFO] django.server: "POST /api/user/password/reset/ HTTP/1.1" 200 52
2025-07-23 13:59:06,958 [INFO] django.utils.autoreload: C:\Users\CPT-003\Desktop\CRM\crm_api\users\views.py changed, reloading.
2025-07-23 13:59:10,229 [INFO] django.utils.autoreload: Watching for file changes with StatReloader
2025-07-23 13:59:29,328 [INFO] core: Tenant config updated for tenant proliance
2025-07-23 13:59:29,330 [INFO] django.server: "PATCH /api/tenant/config/ HTTP/1.1" 200 2185
2025-07-23 13:59:38,265 [INFO] users: Email configuration for tenant proliance: host=smtp.gmail.com, port=587, use_ssl=False, host_user=ekenehanson@gmail.com, host_password=*******************, default_from_email=ekenehanson@gmail.com
2025-07-23 13:59:59,361 [ERROR] users: Failed to send password reset email to support@prolianceltd.com: [WinError 10060] A connection attempt failed because the connected party did not properly respond after a period of time, or established connection failed because connected host has failed to respond
Traceback (most recent call last):
  File "C:\Users\CPT-003\Desktop\CRM\crm_api\users\views.py", line 160, in post
    email.send(fail_silently=False)
    ~~~~~~~~~~^^^^^^^^^^^^^^^^^^^^^
  File "C:\Users\CPT-003\Desktop\CRM\crm_api\venv\Lib\site-packages\django\core\mail\message.py", line 307, in send
    return self.get_connection(fail_silently).send_messages([self])
           ~~~~~~~~~~~~~~~~~~~~~~~~~~~~~~~~~~~~~~~~~~~~~~~~^^^^^^^^
  File "C:\Users\CPT-003\Desktop\CRM\crm_api\venv\Lib\site-packages\django\core\mail\backends\smtp.py", line 128, in send_messages
    new_conn_created = self.open()
  File "C:\Users\CPT-003\Desktop\CRM\crm_api\venv\Lib\site-packages\django\core\mail\backends\smtp.py", line 86, in open
    self.connection = self.connection_class(
                      ~~~~~~~~~~~~~~~~~~~~~^
        self.host, self.port, **connection_params
        ^^^^^^^^^^^^^^^^^^^^^^^^^^^^^^^^^^^^^^^^^
    )
    ^
  File "C:\Users\CPT-003\AppData\Local\Programs\Python\Python313\Lib\smtplib.py", line 255, in __init__
    (code, msg) = self.connect(host, port)
                  ~~~~~~~~~~~~^^^^^^^^^^^^
  File "C:\Users\CPT-003\AppData\Local\Programs\Python\Python313\Lib\smtplib.py", line 341, in connect
    self.sock = self._get_socket(host, port, self.timeout)
                ~~~~~~~~~~~~~~~~^^^^^^^^^^^^^^^^^^^^^^^^^^
  File "C:\Users\CPT-003\AppData\Local\Programs\Python\Python313\Lib\smtplib.py", line 312, in _get_socket
    return socket.create_connection((host, port), timeout,
           ~~~~~~~~~~~~~~~~~~~~~~~~^^^^^^^^^^^^^^^^^^^^^^^
                                    self.source_address)
                                    ^^^^^^^^^^^^^^^^^^^^
  File "C:\Users\CPT-003\AppData\Local\Programs\Python\Python313\Lib\socket.py", line 864, in create_connection
    raise exceptions[0]
  File "C:\Users\CPT-003\AppData\Local\Programs\Python\Python313\Lib\socket.py", line 849, in create_connection
    sock.connect(sa)
    ~~~~~~~~~~~~^^^^
TimeoutError: [WinError 10060] A connection attempt failed because the connected party did not properly respond after a period of time, or established connection failed because connected host has failed to respond
2025-07-23 13:59:59,419 [ERROR] django.request: Internal Server Error: /api/user/password/reset/
2025-07-23 13:59:59,420 [ERROR] django.server: "POST /api/user/password/reset/ HTTP/1.1" 500 370
2025-07-23 14:00:55,438 [INFO] django.utils.autoreload: C:\Users\CPT-003\Desktop\CRM\crm_api\users\views.py changed, reloading.
2025-07-23 14:00:58,419 [INFO] django.utils.autoreload: Watching for file changes with StatReloader
2025-07-23 14:01:12,129 [INFO] users: Email configuration for tenant proliance: host=smtp.gmail.com, port=587, use_ssl=False, host_user=ekenehanson@gmail.com, host_password=*******************, default_from_email=ekenehanson@gmail.com
2025-07-23 14:01:33,165 [ERROR] users: Failed to send password reset email to support@prolianceltd.com: [WinError 10060] A connection attempt failed because the connected party did not properly respond after a period of time, or established connection failed because connected host has failed to respond
Traceback (most recent call last):
  File "C:\Users\CPT-003\Desktop\CRM\crm_api\users\views.py", line 165, in post
    email.send(fail_silently=False)
    ~~~~~~~~~~^^^^^^^^^^^^^^^^^^^^^
  File "C:\Users\CPT-003\Desktop\CRM\crm_api\venv\Lib\site-packages\django\core\mail\message.py", line 307, in send
    return self.get_connection(fail_silently).send_messages([self])
           ~~~~~~~~~~~~~~~~~~~~~~~~~~~~~~~~~~~~~~~~~~~~~~~~^^^^^^^^
  File "C:\Users\CPT-003\Desktop\CRM\crm_api\venv\Lib\site-packages\django\core\mail\backends\smtp.py", line 128, in send_messages
    new_conn_created = self.open()
  File "C:\Users\CPT-003\Desktop\CRM\crm_api\venv\Lib\site-packages\django\core\mail\backends\smtp.py", line 86, in open
    self.connection = self.connection_class(
                      ~~~~~~~~~~~~~~~~~~~~~^
        self.host, self.port, **connection_params
        ^^^^^^^^^^^^^^^^^^^^^^^^^^^^^^^^^^^^^^^^^
    )
    ^
  File "C:\Users\CPT-003\AppData\Local\Programs\Python\Python313\Lib\smtplib.py", line 255, in __init__
    (code, msg) = self.connect(host, port)
                  ~~~~~~~~~~~~^^^^^^^^^^^^
  File "C:\Users\CPT-003\AppData\Local\Programs\Python\Python313\Lib\smtplib.py", line 341, in connect
    self.sock = self._get_socket(host, port, self.timeout)
                ~~~~~~~~~~~~~~~~^^^^^^^^^^^^^^^^^^^^^^^^^^
  File "C:\Users\CPT-003\AppData\Local\Programs\Python\Python313\Lib\smtplib.py", line 312, in _get_socket
    return socket.create_connection((host, port), timeout,
           ~~~~~~~~~~~~~~~~~~~~~~~~^^^^^^^^^^^^^^^^^^^^^^^
                                    self.source_address)
                                    ^^^^^^^^^^^^^^^^^^^^
  File "C:\Users\CPT-003\AppData\Local\Programs\Python\Python313\Lib\socket.py", line 864, in create_connection
    raise exceptions[0]
  File "C:\Users\CPT-003\AppData\Local\Programs\Python\Python313\Lib\socket.py", line 849, in create_connection
    sock.connect(sa)
    ~~~~~~~~~~~~^^^^
TimeoutError: [WinError 10060] A connection attempt failed because the connected party did not properly respond after a period of time, or established connection failed because connected host has failed to respond
2025-07-23 14:01:33,186 [ERROR] django.request: Internal Server Error: /api/user/password/reset/
2025-07-23 14:01:33,188 [ERROR] django.server: "POST /api/user/password/reset/ HTTP/1.1" 500 370
2025-07-23 14:08:22,605 [INFO] users: Email configuration for tenant proliance: host=smtp.gmail.com, port=587, use_ssl=False, host_user=ekenehanson@gmail.com, host_password=*******************, default_from_email=ekenehanson@gmail.com
2025-07-23 14:08:43,674 [ERROR] users: Failed to send password reset email to support@prolianceltd.com: [WinError 10060] A connection attempt failed because the connected party did not properly respond after a period of time, or established connection failed because connected host has failed to respond
Traceback (most recent call last):
  File "C:\Users\CPT-003\Desktop\CRM\crm_api\users\views.py", line 165, in post
    email.send(fail_silently=False)
    ~~~~~~~~~~^^^^^^^^^^^^^^^^^^^^^
  File "C:\Users\CPT-003\Desktop\CRM\crm_api\venv\Lib\site-packages\django\core\mail\message.py", line 307, in send
    return self.get_connection(fail_silently).send_messages([self])
           ~~~~~~~~~~~~~~~~~~~~~~~~~~~~~~~~~~~~~~~~~~~~~~~~^^^^^^^^
  File "C:\Users\CPT-003\Desktop\CRM\crm_api\venv\Lib\site-packages\django\core\mail\backends\smtp.py", line 128, in send_messages
    new_conn_created = self.open()
  File "C:\Users\CPT-003\Desktop\CRM\crm_api\venv\Lib\site-packages\django\core\mail\backends\smtp.py", line 86, in open
    self.connection = self.connection_class(
                      ~~~~~~~~~~~~~~~~~~~~~^
        self.host, self.port, **connection_params
        ^^^^^^^^^^^^^^^^^^^^^^^^^^^^^^^^^^^^^^^^^
    )
    ^
  File "C:\Users\CPT-003\AppData\Local\Programs\Python\Python313\Lib\smtplib.py", line 255, in __init__
    (code, msg) = self.connect(host, port)
                  ~~~~~~~~~~~~^^^^^^^^^^^^
  File "C:\Users\CPT-003\AppData\Local\Programs\Python\Python313\Lib\smtplib.py", line 341, in connect
    self.sock = self._get_socket(host, port, self.timeout)
                ~~~~~~~~~~~~~~~~^^^^^^^^^^^^^^^^^^^^^^^^^^
  File "C:\Users\CPT-003\AppData\Local\Programs\Python\Python313\Lib\smtplib.py", line 312, in _get_socket
    return socket.create_connection((host, port), timeout,
           ~~~~~~~~~~~~~~~~~~~~~~~~^^^^^^^^^^^^^^^^^^^^^^^
                                    self.source_address)
                                    ^^^^^^^^^^^^^^^^^^^^
  File "C:\Users\CPT-003\AppData\Local\Programs\Python\Python313\Lib\socket.py", line 864, in create_connection
    raise exceptions[0]
  File "C:\Users\CPT-003\AppData\Local\Programs\Python\Python313\Lib\socket.py", line 849, in create_connection
    sock.connect(sa)
    ~~~~~~~~~~~~^^^^
TimeoutError: [WinError 10060] A connection attempt failed because the connected party did not properly respond after a period of time, or established connection failed because connected host has failed to respond
2025-07-23 14:08:43,697 [ERROR] django.request: Internal Server Error: /api/user/password/reset/
2025-07-23 14:08:43,698 [ERROR] django.server: "POST /api/user/password/reset/ HTTP/1.1" 500 370
2025-07-23 14:08:44,043 [INFO] django.utils.autoreload: C:\Users\CPT-003\Desktop\CRM\crm_api\users\views.py changed, reloading.
2025-07-23 14:08:46,648 [INFO] django.utils.autoreload: Watching for file changes with StatReloader
2025-07-23 14:09:09,829 [INFO] django.server: "OPTIONS /api/tenant/tenants/2/ HTTP/1.1" 200 0
2025-07-23 14:09:09,830 [INFO] django.server: "OPTIONS /api/tenant/tenants/2/ HTTP/1.1" 200 0
2025-07-23 14:09:09,913 [INFO] core: Retrieving tenant: 2 for tenant proliance
2025-07-23 14:09:10,118 [INFO] django.server: "GET /api/tenant/tenants/2/ HTTP/1.1" 200 2558
2025-07-23 14:09:10,192 [INFO] core: Retrieving tenant: 2 for tenant proliance
2025-07-23 14:09:10,206 [INFO] django.server: "GET /api/tenant/tenants/2/ HTTP/1.1" 200 2558
2025-07-23 14:09:14,649 [INFO] core: Saving tenant with schema_name: proliance
2025-07-23 14:09:14,657 [INFO] core: Tenant updated: proliance for tenant proliance
2025-07-23 14:09:14,661 [INFO] django.server: "PATCH /api/tenant/tenants/2/ HTTP/1.1" 200 2557
2025-07-23 14:09:23,666 [ERROR] users: Failed to send password reset email to support@prolianceltd.com: EMAIL_USE_TLS/EMAIL_USE_SSL are mutually exclusive, so only set one of those settings to True.
Traceback (most recent call last):
  File "C:\Users\CPT-003\Desktop\CRM\crm_api\users\views.py", line 141, in post
    email_connection = configure_email_backend(tenant)
  File "C:\Users\CPT-003\Desktop\CRM\crm_api\users\views.py", line 32, in configure_email_backend
    return EmailBackend(
        host=tenant.email_host,
    ...<4 lines>...
        fail_silently=False
    )
  File "C:\Users\CPT-003\Desktop\CRM\crm_api\venv\Lib\site-packages\django\core\mail\backends\smtp.py", line 48, in __init__
    raise ValueError(
    ...<2 lines>...
    )
ValueError: EMAIL_USE_TLS/EMAIL_USE_SSL are mutually exclusive, so only set one of those settings to True.
2025-07-23 14:09:23,672 [ERROR] django.request: Internal Server Error: /api/user/password/reset/
2025-07-23 14:09:23,673 [ERROR] django.server: "POST /api/user/password/reset/ HTTP/1.1" 500 265
2025-07-23 14:09:55,739 [INFO] core: Saving tenant with schema_name: proliance
2025-07-23 14:09:55,741 [INFO] core: Tenant updated: proliance for tenant proliance
2025-07-23 14:09:55,745 [INFO] django.server: "PATCH /api/tenant/tenants/2/ HTTP/1.1" 200 2558
2025-07-23 14:29:17,727 [INFO] django.utils.autoreload: C:\Users\CPT-003\Desktop\CRM\crm_api\users\views.py changed, reloading.
2025-07-23 14:29:20,224 [INFO] django.utils.autoreload: Watching for file changes with StatReloader
2025-07-23 14:29:32,928 [INFO] users: Email configuration for tenant proliance: host=smtp.gmail.com, port=587, use_ssl=False, host_user=ekenehanson@gmail.com, host_password=*******************, default_from_email=ekenehanson@gmail.com
2025-07-23 14:29:44,011 [ERROR] users: Failed to send password reset email to support@prolianceltd.com: [Errno 11001] getaddrinfo failed
Traceback (most recent call last):
  File "C:\Users\CPT-003\Desktop\CRM\crm_api\users\views.py", line 165, in post
    email.send(fail_silently=False)
    ~~~~~~~~~~^^^^^^^^^^^^^^^^^^^^^
  File "C:\Users\CPT-003\Desktop\CRM\crm_api\venv\Lib\site-packages\django\core\mail\message.py", line 307, in send
    return self.get_connection(fail_silently).send_messages([self])
           ~~~~~~~~~~~~~~~~~~~~~~~~~~~~~~~~~~~~~~~~~~~~~~~~^^^^^^^^
  File "C:\Users\CPT-003\Desktop\CRM\crm_api\venv\Lib\site-packages\django\core\mail\backends\smtp.py", line 128, in send_messages
    new_conn_created = self.open()
  File "C:\Users\CPT-003\Desktop\CRM\crm_api\venv\Lib\site-packages\django\core\mail\backends\smtp.py", line 86, in open
    self.connection = self.connection_class(
                      ~~~~~~~~~~~~~~~~~~~~~^
        self.host, self.port, **connection_params
        ^^^^^^^^^^^^^^^^^^^^^^^^^^^^^^^^^^^^^^^^^
    )
    ^
  File "C:\Users\CPT-003\AppData\Local\Programs\Python\Python313\Lib\smtplib.py", line 255, in __init__
    (code, msg) = self.connect(host, port)
                  ~~~~~~~~~~~~^^^^^^^^^^^^
  File "C:\Users\CPT-003\AppData\Local\Programs\Python\Python313\Lib\smtplib.py", line 341, in connect
    self.sock = self._get_socket(host, port, self.timeout)
                ~~~~~~~~~~~~~~~~^^^^^^^^^^^^^^^^^^^^^^^^^^
  File "C:\Users\CPT-003\AppData\Local\Programs\Python\Python313\Lib\smtplib.py", line 312, in _get_socket
    return socket.create_connection((host, port), timeout,
           ~~~~~~~~~~~~~~~~~~~~~~~~^^^^^^^^^^^^^^^^^^^^^^^
                                    self.source_address)
                                    ^^^^^^^^^^^^^^^^^^^^
  File "C:\Users\CPT-003\AppData\Local\Programs\Python\Python313\Lib\socket.py", line 840, in create_connection
    for res in getaddrinfo(host, port, 0, SOCK_STREAM):
               ~~~~~~~~~~~^^^^^^^^^^^^^^^^^^^^^^^^^^^^
  File "C:\Users\CPT-003\AppData\Local\Programs\Python\Python313\Lib\socket.py", line 977, in getaddrinfo
    for res in _socket.getaddrinfo(host, port, family, type, proto, flags):
               ~~~~~~~~~~~~~~~~~~~^^^^^^^^^^^^^^^^^^^^^^^^^^^^^^^^^^^^^^^^
socket.gaierror: [Errno 11001] getaddrinfo failed
2025-07-23 14:29:44,041 [ERROR] django.request: Internal Server Error: /api/user/password/reset/
2025-07-23 14:29:44,043 [ERROR] django.server: "POST /api/user/password/reset/ HTTP/1.1" 500 203
2025-07-23 14:30:20,365 [INFO] django.utils.autoreload: C:\Users\CPT-003\Desktop\CRM\crm_api\users\views.py changed, reloading.
2025-07-23 14:30:22,782 [INFO] django.utils.autoreload: Watching for file changes with StatReloader
2025-07-23 14:30:40,213 [INFO] users: Email configuration for tenant proliance: host=smtp.gmail.com, port=587, use_ssl=False, host_user=ekenehanson@gmail.com, host_password=*******************, default_from_email=ekenehanson@gmail.com
2025-07-23 14:31:01,286 [ERROR] users: Failed to send password reset email to support@prolianceltd.com: [WinError 10060] A connection attempt failed because the connected party did not properly respond after a period of time, or established connection failed because connected host has failed to respond
Traceback (most recent call last):
  File "C:\Users\CPT-003\Desktop\CRM\crm_api\users\views.py", line 166, in post
    email.send(fail_silently=False)
    ~~~~~~~~~~^^^^^^^^^^^^^^^^^^^^^
  File "C:\Users\CPT-003\Desktop\CRM\crm_api\venv\Lib\site-packages\django\core\mail\message.py", line 307, in send
    return self.get_connection(fail_silently).send_messages([self])
           ~~~~~~~~~~~~~~~~~~~~~~~~~~~~~~~~~~~~~~~~~~~~~~~~^^^^^^^^
  File "C:\Users\CPT-003\Desktop\CRM\crm_api\venv\Lib\site-packages\django\core\mail\backends\smtp.py", line 128, in send_messages
    new_conn_created = self.open()
  File "C:\Users\CPT-003\Desktop\CRM\crm_api\venv\Lib\site-packages\django\core\mail\backends\smtp.py", line 86, in open
    self.connection = self.connection_class(
                      ~~~~~~~~~~~~~~~~~~~~~^
        self.host, self.port, **connection_params
        ^^^^^^^^^^^^^^^^^^^^^^^^^^^^^^^^^^^^^^^^^
    )
    ^
  File "C:\Users\CPT-003\AppData\Local\Programs\Python\Python313\Lib\smtplib.py", line 255, in __init__
    (code, msg) = self.connect(host, port)
                  ~~~~~~~~~~~~^^^^^^^^^^^^
  File "C:\Users\CPT-003\AppData\Local\Programs\Python\Python313\Lib\smtplib.py", line 341, in connect
    self.sock = self._get_socket(host, port, self.timeout)
                ~~~~~~~~~~~~~~~~^^^^^^^^^^^^^^^^^^^^^^^^^^
  File "C:\Users\CPT-003\AppData\Local\Programs\Python\Python313\Lib\smtplib.py", line 312, in _get_socket
    return socket.create_connection((host, port), timeout,
           ~~~~~~~~~~~~~~~~~~~~~~~~^^^^^^^^^^^^^^^^^^^^^^^
                                    self.source_address)
                                    ^^^^^^^^^^^^^^^^^^^^
  File "C:\Users\CPT-003\AppData\Local\Programs\Python\Python313\Lib\socket.py", line 864, in create_connection
    raise exceptions[0]
  File "C:\Users\CPT-003\AppData\Local\Programs\Python\Python313\Lib\socket.py", line 849, in create_connection
    sock.connect(sa)
    ~~~~~~~~~~~~^^^^
TimeoutError: [WinError 10060] A connection attempt failed because the connected party did not properly respond after a period of time, or established connection failed because connected host has failed to respond
2025-07-23 14:31:01,317 [ERROR] django.request: Internal Server Error: /api/user/password/reset/
2025-07-23 14:31:01,319 [ERROR] django.server: "POST /api/user/password/reset/ HTTP/1.1" 500 370
2025-07-23 14:32:39,234 [WARNING] django.request: Not Found: /api/user/password/confirm/
2025-07-23 14:32:39,234 [WARNING] django.server: "POST /api/user/password/confirm/ HTTP/1.1" 404 179
2025-07-23 14:33:12,192 [WARNING] django.request: Bad Request: /api/user/password/reset/confirm/
2025-07-23 14:33:12,193 [WARNING] django.server: "POST /api/user/password/reset/confirm/ HTTP/1.1" 400 30
2025-07-23 14:34:02,204 [ERROR] users: Validation failed for password reset confirmation: {'new_password': [ErrorDetail(string='Password must contain at least one uppercase letter and one number.', code='invalid')]}
2025-07-23 14:34:02,205 [WARNING] django.request: Bad Request: /api/user/password/reset/confirm/
2025-07-23 14:34:02,205 [WARNING] django.server: "POST /api/user/password/reset/confirm/ HTTP/1.1" 400 88
2025-07-23 14:34:29,581 [INFO] users: Password reset successfully for user support@prolianceltd.com in tenant proliance
2025-07-23 14:34:29,582 [ERROR] users: Error confirming password reset for tenant proliance: 'RefreshToken' object has no attribute 'blacklist'
Traceback (most recent call last):
  File "C:\Users\CPT-003\Desktop\CRM\crm_api\users\views.py", line 231, in post
    RefreshToken.for_user(user).blacklist()
    ^^^^^^^^^^^^^^^^^^^^^^^^^^^^^^^^^^^^^
AttributeError: 'RefreshToken' object has no attribute 'blacklist'
2025-07-23 14:34:29,583 [WARNING] django.request: Bad Request: /api/user/password/reset/confirm/
2025-07-23 14:34:29,584 [WARNING] django.server: "POST /api/user/password/reset/confirm/ HTTP/1.1" 400 63
2025-07-23 14:35:11,980 [WARNING] django.request: Bad Request: /api/user/password/reset/confirm/
2025-07-23 14:35:11,981 [WARNING] django.server: "POST /api/user/password/reset/confirm/ HTTP/1.1" 400 30
2025-07-23 14:37:28,129 [INFO] django.utils.autoreload: C:\Users\CPT-003\Desktop\CRM\crm_api\lumina_care\settings.py changed, reloading.
2025-07-23 14:37:32,521 [INFO] django.utils.autoreload: Watching for file changes with StatReloader
2025-07-23 14:39:08,531 [INFO] django.utils.autoreload: Watching for file changes with StatReloader
2025-07-23 16:00:58,398 [INFO] django.utils.autoreload: Watching for file changes with StatReloader
2025-07-23 16:02:03,256 [WARNING] django.request: Bad Request: /api/user/password/reset/confirm/
2025-07-23 16:02:03,256 [WARNING] django.server: "POST /api/user/password/reset/confirm/ HTTP/1.1" 400 30
2025-07-23 16:03:08,278 [INFO] django.utils.autoreload: C:\Users\CPT-003\Desktop\CRM\crm_api\users\serializers.py changed, reloading.
2025-07-23 16:03:10,726 [INFO] django.utils.autoreload: Watching for file changes with StatReloader
2025-07-23 16:03:20,980 [INFO] users: Email configuration for tenant proliance: host=smtp.gmail.com, port=587, use_ssl=False, host_user=ekenehanson@gmail.com, host_password=*******************, default_from_email=ekenehanson@gmail.com
2025-07-23 16:03:39,901 [ERROR] users: Validation failed for password reset confirmation: {'token': [ErrorDetail(string='Invalid token.', code='invalid')]}
2025-07-23 16:03:39,903 [WARNING] django.request: Bad Request: /api/user/password/reset/confirm/
2025-07-23 16:03:39,904 [WARNING] django.server: "POST /api/user/password/reset/confirm/ HTTP/1.1" 400 28
2025-07-23 16:03:42,069 [ERROR] users: Failed to send password reset email to support@prolianceltd.com: [WinError 10060] A connection attempt failed because the connected party did not properly respond after a period of time, or established connection failed because connected host has failed to respond
Traceback (most recent call last):
  File "C:\Users\CPT-003\Desktop\CRM\crm_api\users\views.py", line 166, in post
    email.send(fail_silently=False)
    ~~~~~~~~~~^^^^^^^^^^^^^^^^^^^^^
  File "C:\Users\CPT-003\Desktop\CRM\crm_api\venv\Lib\site-packages\django\core\mail\message.py", line 307, in send
    return self.get_connection(fail_silently).send_messages([self])
           ~~~~~~~~~~~~~~~~~~~~~~~~~~~~~~~~~~~~~~~~~~~~~~~~^^^^^^^^
  File "C:\Users\CPT-003\Desktop\CRM\crm_api\venv\Lib\site-packages\django\core\mail\backends\smtp.py", line 128, in send_messages
    new_conn_created = self.open()
  File "C:\Users\CPT-003\Desktop\CRM\crm_api\venv\Lib\site-packages\django\core\mail\backends\smtp.py", line 86, in open
    self.connection = self.connection_class(
                      ~~~~~~~~~~~~~~~~~~~~~^
        self.host, self.port, **connection_params
        ^^^^^^^^^^^^^^^^^^^^^^^^^^^^^^^^^^^^^^^^^
    )
    ^
  File "C:\Users\CPT-003\AppData\Local\Programs\Python\Python313\Lib\smtplib.py", line 255, in __init__
    (code, msg) = self.connect(host, port)
                  ~~~~~~~~~~~~^^^^^^^^^^^^
  File "C:\Users\CPT-003\AppData\Local\Programs\Python\Python313\Lib\smtplib.py", line 341, in connect
    self.sock = self._get_socket(host, port, self.timeout)
                ~~~~~~~~~~~~~~~~^^^^^^^^^^^^^^^^^^^^^^^^^^
  File "C:\Users\CPT-003\AppData\Local\Programs\Python\Python313\Lib\smtplib.py", line 312, in _get_socket
    return socket.create_connection((host, port), timeout,
           ~~~~~~~~~~~~~~~~~~~~~~~~^^^^^^^^^^^^^^^^^^^^^^^
                                    self.source_address)
                                    ^^^^^^^^^^^^^^^^^^^^
  File "C:\Users\CPT-003\AppData\Local\Programs\Python\Python313\Lib\socket.py", line 864, in create_connection
    raise exceptions[0]
  File "C:\Users\CPT-003\AppData\Local\Programs\Python\Python313\Lib\socket.py", line 849, in create_connection
    sock.connect(sa)
    ~~~~~~~~~~~~^^^^
TimeoutError: [WinError 10060] A connection attempt failed because the connected party did not properly respond after a period of time, or established connection failed because connected host has failed to respond
2025-07-23 16:03:42,084 [ERROR] django.request: Internal Server Error: /api/user/password/reset/
2025-07-23 16:03:42,085 [ERROR] django.server: "POST /api/user/password/reset/ HTTP/1.1" 500 370
2025-07-23 16:03:46,955 [INFO] users: Email configuration for tenant proliance: host=smtp.gmail.com, port=587, use_ssl=False, host_user=ekenehanson@gmail.com, host_password=*******************, default_from_email=ekenehanson@gmail.com
2025-07-23 16:04:08,005 [ERROR] users: Failed to send password reset email to support@prolianceltd.com: [WinError 10060] A connection attempt failed because the connected party did not properly respond after a period of time, or established connection failed because connected host has failed to respond
Traceback (most recent call last):
  File "C:\Users\CPT-003\Desktop\CRM\crm_api\users\views.py", line 166, in post
    email.send(fail_silently=False)
    ~~~~~~~~~~^^^^^^^^^^^^^^^^^^^^^
  File "C:\Users\CPT-003\Desktop\CRM\crm_api\venv\Lib\site-packages\django\core\mail\message.py", line 307, in send
    return self.get_connection(fail_silently).send_messages([self])
           ~~~~~~~~~~~~~~~~~~~~~~~~~~~~~~~~~~~~~~~~~~~~~~~~^^^^^^^^
  File "C:\Users\CPT-003\Desktop\CRM\crm_api\venv\Lib\site-packages\django\core\mail\backends\smtp.py", line 128, in send_messages
    new_conn_created = self.open()
  File "C:\Users\CPT-003\Desktop\CRM\crm_api\venv\Lib\site-packages\django\core\mail\backends\smtp.py", line 86, in open
    self.connection = self.connection_class(
                      ~~~~~~~~~~~~~~~~~~~~~^
        self.host, self.port, **connection_params
        ^^^^^^^^^^^^^^^^^^^^^^^^^^^^^^^^^^^^^^^^^
    )
    ^
  File "C:\Users\CPT-003\AppData\Local\Programs\Python\Python313\Lib\smtplib.py", line 255, in __init__
    (code, msg) = self.connect(host, port)
                  ~~~~~~~~~~~~^^^^^^^^^^^^
  File "C:\Users\CPT-003\AppData\Local\Programs\Python\Python313\Lib\smtplib.py", line 341, in connect
    self.sock = self._get_socket(host, port, self.timeout)
                ~~~~~~~~~~~~~~~~^^^^^^^^^^^^^^^^^^^^^^^^^^
  File "C:\Users\CPT-003\AppData\Local\Programs\Python\Python313\Lib\smtplib.py", line 312, in _get_socket
    return socket.create_connection((host, port), timeout,
           ~~~~~~~~~~~~~~~~~~~~~~~~^^^^^^^^^^^^^^^^^^^^^^^
                                    self.source_address)
                                    ^^^^^^^^^^^^^^^^^^^^
  File "C:\Users\CPT-003\AppData\Local\Programs\Python\Python313\Lib\socket.py", line 864, in create_connection
    raise exceptions[0]
  File "C:\Users\CPT-003\AppData\Local\Programs\Python\Python313\Lib\socket.py", line 849, in create_connection
    sock.connect(sa)
    ~~~~~~~~~~~~^^^^
TimeoutError: [WinError 10060] A connection attempt failed because the connected party did not properly respond after a period of time, or established connection failed because connected host has failed to respond
2025-07-23 16:04:08,024 [ERROR] django.request: Internal Server Error: /api/user/password/reset/
2025-07-23 16:04:08,026 [ERROR] django.server: "POST /api/user/password/reset/ HTTP/1.1" 500 370
2025-07-23 16:04:17,587 [INFO] users: Password reset successfully for user support@prolianceltd.com in tenant proliance
2025-07-23 16:04:17,596 [ERROR] users: Error confirming password reset for tenant proliance: relation "token_blacklist_outstandingtoken" does not exist
LINE 1: INSERT INTO "token_blacklist_outstandingtoken" ("user_id", "...
                    ^
Traceback (most recent call last):
  File "C:\Users\CPT-003\Desktop\CRM\crm_api\venv\Lib\site-packages\django\db\backends\utils.py", line 105, in _execute
    return self.cursor.execute(sql, params)
           ~~~~~~~~~~~~~~~~~~~^^^^^^^^^^^^^
psycopg2.errors.UndefinedTable: relation "token_blacklist_outstandingtoken" does not exist
LINE 1: INSERT INTO "token_blacklist_outstandingtoken" ("user_id", "...
                    ^


The above exception was the direct cause of the following exception:

Traceback (most recent call last):
  File "C:\Users\CPT-003\Desktop\CRM\crm_api\users\views.py", line 231, in post
    RefreshToken.for_user(user).blacklist()
    ~~~~~~~~~~~~~~~~~~~~~^^^^^^
  File "C:\Users\CPT-003\Desktop\CRM\crm_api\venv\Lib\site-packages\rest_framework_simplejwt\tokens.py", line 293, in for_user
    OutstandingToken.objects.create(
    ~~~~~~~~~~~~~~~~~~~~~~~~~~~~~~~^
        user=user,
        ^^^^^^^^^^
    ...<3 lines>...
        expires_at=datetime_from_epoch(exp),
        ^^^^^^^^^^^^^^^^^^^^^^^^^^^^^^^^^^^^
    )
    ^
  File "C:\Users\CPT-003\Desktop\CRM\crm_api\venv\Lib\site-packages\django\db\models\manager.py", line 87, in manager_method
    return getattr(self.get_queryset(), name)(*args, **kwargs)
           ~~~~~~~~~~~~~~~~~~~~~~~~~~~~~~~~~~^^^^^^^^^^^^^^^^^
  File "C:\Users\CPT-003\Desktop\CRM\crm_api\venv\Lib\site-packages\django\db\models\query.py", line 663, in create
    obj.save(force_insert=True, using=self.db)
    ~~~~~~~~^^^^^^^^^^^^^^^^^^^^^^^^^^^^^^^^^^
  File "C:\Users\CPT-003\Desktop\CRM\crm_api\venv\Lib\site-packages\django\db\models\base.py", line 902, in save
    self.save_base(
    ~~~~~~~~~~~~~~^
        using=using,
        ^^^^^^^^^^^^
    ...<2 lines>...
        update_fields=update_fields,
        ^^^^^^^^^^^^^^^^^^^^^^^^^^^^
    )
    ^
  File "C:\Users\CPT-003\Desktop\CRM\crm_api\venv\Lib\site-packages\django\db\models\base.py", line 1008, in save_base
    updated = self._save_table(
        raw,
    ...<4 lines>...
        update_fields,
    )
  File "C:\Users\CPT-003\Desktop\CRM\crm_api\venv\Lib\site-packages\django\db\models\base.py", line 1169, in _save_table
    results = self._do_insert(
        cls._base_manager, using, fields, returning_fields, raw
    )
  File "C:\Users\CPT-003\Desktop\CRM\crm_api\venv\Lib\site-packages\django\db\models\base.py", line 1210, in _do_insert
    return manager._insert(
           ~~~~~~~~~~~~~~~^
        [self],
        ^^^^^^^
    ...<3 lines>...
        raw=raw,
        ^^^^^^^^
    )
    ^
  File "C:\Users\CPT-003\Desktop\CRM\crm_api\venv\Lib\site-packages\django\db\models\manager.py", line 87, in manager_method
    return getattr(self.get_queryset(), name)(*args, **kwargs)
           ~~~~~~~~~~~~~~~~~~~~~~~~~~~~~~~~~~^^^^^^^^^^^^^^^^^
  File "C:\Users\CPT-003\Desktop\CRM\crm_api\venv\Lib\site-packages\django\db\models\query.py", line 1868, in _insert
    return query.get_compiler(using=using).execute_sql(returning_fields)
           ~~~~~~~~~~~~~~~~~~~~~~~~~~~~~~~~~~~~~~~~~~~^^^^^^^^^^^^^^^^^^
  File "C:\Users\CPT-003\Desktop\CRM\crm_api\venv\Lib\site-packages\django\db\models\sql\compiler.py", line 1882, in execute_sql
    cursor.execute(sql, params)
    ~~~~~~~~~~~~~~^^^^^^^^^^^^^
  File "C:\Users\CPT-003\Desktop\CRM\crm_api\venv\Lib\site-packages\django\db\backends\utils.py", line 79, in execute
    return self._execute_with_wrappers(
           ~~~~~~~~~~~~~~~~~~~~~~~~~~~^
        sql, params, many=False, executor=self._execute
        ^^^^^^^^^^^^^^^^^^^^^^^^^^^^^^^^^^^^^^^^^^^^^^^
    )
    ^
  File "C:\Users\CPT-003\Desktop\CRM\crm_api\venv\Lib\site-packages\django\db\backends\utils.py", line 92, in _execute_with_wrappers
    return executor(sql, params, many, context)
  File "C:\Users\CPT-003\Desktop\CRM\crm_api\venv\Lib\site-packages\django\db\backends\utils.py", line 100, in _execute
    with self.db.wrap_database_errors:
         ^^^^^^^^^^^^^^^^^^^^^^^^^^^^
  File "C:\Users\CPT-003\Desktop\CRM\crm_api\venv\Lib\site-packages\django\db\utils.py", line 91, in __exit__
    raise dj_exc_value.with_traceback(traceback) from exc_value
  File "C:\Users\CPT-003\Desktop\CRM\crm_api\venv\Lib\site-packages\django\db\backends\utils.py", line 105, in _execute
    return self.cursor.execute(sql, params)
           ~~~~~~~~~~~~~~~~~~~^^^^^^^^^^^^^
django.db.utils.ProgrammingError: relation "token_blacklist_outstandingtoken" does not exist
LINE 1: INSERT INTO "token_blacklist_outstandingtoken" ("user_id", "...
                    ^

2025-07-23 16:04:17,623 [WARNING] django.request: Bad Request: /api/user/password/reset/confirm/
2025-07-23 16:04:17,623 [WARNING] django.server: "POST /api/user/password/reset/confirm/ HTTP/1.1" 400 176
2025-07-23 16:06:58,341 [INFO] django.utils.autoreload: Watching for file changes with StatReloader
2025-07-23 16:07:23,544 [INFO] users: Email configuration for tenant proliance: host=smtp.gmail.com, port=587, use_ssl=False, host_user=ekenehanson@gmail.com, host_password=*******************, default_from_email=ekenehanson@gmail.com
2025-07-23 16:07:44,651 [ERROR] users: Failed to send password reset email to support@prolianceltd.com: [WinError 10060] A connection attempt failed because the connected party did not properly respond after a period of time, or established connection failed because connected host has failed to respond
Traceback (most recent call last):
  File "C:\Users\CPT-003\Desktop\CRM\crm_api\users\views.py", line 166, in post
    email.send(fail_silently=False)
    ~~~~~~~~~~^^^^^^^^^^^^^^^^^^^^^
  File "C:\Users\CPT-003\Desktop\CRM\crm_api\venv\Lib\site-packages\django\core\mail\message.py", line 307, in send
    return self.get_connection(fail_silently).send_messages([self])
           ~~~~~~~~~~~~~~~~~~~~~~~~~~~~~~~~~~~~~~~~~~~~~~~~^^^^^^^^
  File "C:\Users\CPT-003\Desktop\CRM\crm_api\venv\Lib\site-packages\django\core\mail\backends\smtp.py", line 128, in send_messages
    new_conn_created = self.open()
  File "C:\Users\CPT-003\Desktop\CRM\crm_api\venv\Lib\site-packages\django\core\mail\backends\smtp.py", line 86, in open
    self.connection = self.connection_class(
                      ~~~~~~~~~~~~~~~~~~~~~^
        self.host, self.port, **connection_params
        ^^^^^^^^^^^^^^^^^^^^^^^^^^^^^^^^^^^^^^^^^
    )
    ^
  File "C:\Users\CPT-003\AppData\Local\Programs\Python\Python313\Lib\smtplib.py", line 255, in __init__
    (code, msg) = self.connect(host, port)
                  ~~~~~~~~~~~~^^^^^^^^^^^^
  File "C:\Users\CPT-003\AppData\Local\Programs\Python\Python313\Lib\smtplib.py", line 341, in connect
    self.sock = self._get_socket(host, port, self.timeout)
                ~~~~~~~~~~~~~~~~^^^^^^^^^^^^^^^^^^^^^^^^^^
  File "C:\Users\CPT-003\AppData\Local\Programs\Python\Python313\Lib\smtplib.py", line 312, in _get_socket
    return socket.create_connection((host, port), timeout,
           ~~~~~~~~~~~~~~~~~~~~~~~~^^^^^^^^^^^^^^^^^^^^^^^
                                    self.source_address)
                                    ^^^^^^^^^^^^^^^^^^^^
  File "C:\Users\CPT-003\AppData\Local\Programs\Python\Python313\Lib\socket.py", line 864, in create_connection
    raise exceptions[0]
  File "C:\Users\CPT-003\AppData\Local\Programs\Python\Python313\Lib\socket.py", line 849, in create_connection
    sock.connect(sa)
    ~~~~~~~~~~~~^^^^
TimeoutError: [WinError 10060] A connection attempt failed because the connected party did not properly respond after a period of time, or established connection failed because connected host has failed to respond
2025-07-23 16:07:44,660 [ERROR] django.request: Internal Server Error: /api/user/password/reset/
2025-07-23 16:07:44,661 [ERROR] django.server: "POST /api/user/password/reset/ HTTP/1.1" 500 370
2025-07-23 16:07:56,039 [INFO] users: Password reset successfully for user support@prolianceltd.com in tenant proliance
2025-07-23 16:07:56,042 [ERROR] users: Error confirming password reset for tenant proliance: relation "token_blacklist_outstandingtoken" does not exist
LINE 1: INSERT INTO "token_blacklist_outstandingtoken" ("user_id", "...
                    ^
Traceback (most recent call last):
  File "C:\Users\CPT-003\Desktop\CRM\crm_api\venv\Lib\site-packages\django\db\backends\utils.py", line 105, in _execute
    return self.cursor.execute(sql, params)
           ~~~~~~~~~~~~~~~~~~~^^^^^^^^^^^^^
psycopg2.errors.UndefinedTable: relation "token_blacklist_outstandingtoken" does not exist
LINE 1: INSERT INTO "token_blacklist_outstandingtoken" ("user_id", "...
                    ^


The above exception was the direct cause of the following exception:

Traceback (most recent call last):
  File "C:\Users\CPT-003\Desktop\CRM\crm_api\users\views.py", line 231, in post
    RefreshToken.for_user(user).blacklist()
    ~~~~~~~~~~~~~~~~~~~~~^^^^^^
  File "C:\Users\CPT-003\Desktop\CRM\crm_api\venv\Lib\site-packages\rest_framework_simplejwt\tokens.py", line 293, in for_user
    OutstandingToken.objects.create(
    ~~~~~~~~~~~~~~~~~~~~~~~~~~~~~~~^
        user=user,
        ^^^^^^^^^^
    ...<3 lines>...
        expires_at=datetime_from_epoch(exp),
        ^^^^^^^^^^^^^^^^^^^^^^^^^^^^^^^^^^^^
    )
    ^
  File "C:\Users\CPT-003\Desktop\CRM\crm_api\venv\Lib\site-packages\django\db\models\manager.py", line 87, in manager_method
    return getattr(self.get_queryset(), name)(*args, **kwargs)
           ~~~~~~~~~~~~~~~~~~~~~~~~~~~~~~~~~~^^^^^^^^^^^^^^^^^
  File "C:\Users\CPT-003\Desktop\CRM\crm_api\venv\Lib\site-packages\django\db\models\query.py", line 663, in create
    obj.save(force_insert=True, using=self.db)
    ~~~~~~~~^^^^^^^^^^^^^^^^^^^^^^^^^^^^^^^^^^
  File "C:\Users\CPT-003\Desktop\CRM\crm_api\venv\Lib\site-packages\django\db\models\base.py", line 902, in save
    self.save_base(
    ~~~~~~~~~~~~~~^
        using=using,
        ^^^^^^^^^^^^
    ...<2 lines>...
        update_fields=update_fields,
        ^^^^^^^^^^^^^^^^^^^^^^^^^^^^
    )
    ^
  File "C:\Users\CPT-003\Desktop\CRM\crm_api\venv\Lib\site-packages\django\db\models\base.py", line 1008, in save_base
    updated = self._save_table(
        raw,
    ...<4 lines>...
        update_fields,
    )
  File "C:\Users\CPT-003\Desktop\CRM\crm_api\venv\Lib\site-packages\django\db\models\base.py", line 1169, in _save_table
    results = self._do_insert(
        cls._base_manager, using, fields, returning_fields, raw
    )
  File "C:\Users\CPT-003\Desktop\CRM\crm_api\venv\Lib\site-packages\django\db\models\base.py", line 1210, in _do_insert
    return manager._insert(
           ~~~~~~~~~~~~~~~^
        [self],
        ^^^^^^^
    ...<3 lines>...
        raw=raw,
        ^^^^^^^^
    )
    ^
  File "C:\Users\CPT-003\Desktop\CRM\crm_api\venv\Lib\site-packages\django\db\models\manager.py", line 87, in manager_method
    return getattr(self.get_queryset(), name)(*args, **kwargs)
           ~~~~~~~~~~~~~~~~~~~~~~~~~~~~~~~~~~^^^^^^^^^^^^^^^^^
  File "C:\Users\CPT-003\Desktop\CRM\crm_api\venv\Lib\site-packages\django\db\models\query.py", line 1868, in _insert
    return query.get_compiler(using=using).execute_sql(returning_fields)
           ~~~~~~~~~~~~~~~~~~~~~~~~~~~~~~~~~~~~~~~~~~~^^^^^^^^^^^^^^^^^^
  File "C:\Users\CPT-003\Desktop\CRM\crm_api\venv\Lib\site-packages\django\db\models\sql\compiler.py", line 1882, in execute_sql
    cursor.execute(sql, params)
    ~~~~~~~~~~~~~~^^^^^^^^^^^^^
  File "C:\Users\CPT-003\Desktop\CRM\crm_api\venv\Lib\site-packages\django\db\backends\utils.py", line 79, in execute
    return self._execute_with_wrappers(
           ~~~~~~~~~~~~~~~~~~~~~~~~~~~^
        sql, params, many=False, executor=self._execute
        ^^^^^^^^^^^^^^^^^^^^^^^^^^^^^^^^^^^^^^^^^^^^^^^
    )
    ^
  File "C:\Users\CPT-003\Desktop\CRM\crm_api\venv\Lib\site-packages\django\db\backends\utils.py", line 92, in _execute_with_wrappers
    return executor(sql, params, many, context)
  File "C:\Users\CPT-003\Desktop\CRM\crm_api\venv\Lib\site-packages\django\db\backends\utils.py", line 100, in _execute
    with self.db.wrap_database_errors:
         ^^^^^^^^^^^^^^^^^^^^^^^^^^^^
  File "C:\Users\CPT-003\Desktop\CRM\crm_api\venv\Lib\site-packages\django\db\utils.py", line 91, in __exit__
    raise dj_exc_value.with_traceback(traceback) from exc_value
  File "C:\Users\CPT-003\Desktop\CRM\crm_api\venv\Lib\site-packages\django\db\backends\utils.py", line 105, in _execute
    return self.cursor.execute(sql, params)
           ~~~~~~~~~~~~~~~~~~~^^^^^^^^^^^^^
django.db.utils.ProgrammingError: relation "token_blacklist_outstandingtoken" does not exist
LINE 1: INSERT INTO "token_blacklist_outstandingtoken" ("user_id", "...
                    ^

2025-07-23 16:07:56,048 [WARNING] django.request: Bad Request: /api/user/password/reset/confirm/
2025-07-23 16:07:56,049 [WARNING] django.server: "POST /api/user/password/reset/confirm/ HTTP/1.1" 400 176
2025-07-23 16:09:58,179 [INFO] django.utils.autoreload: C:\Users\CPT-003\Desktop\CRM\crm_api\users\views.py changed, reloading.
2025-07-23 16:10:01,436 [INFO] django.utils.autoreload: Watching for file changes with StatReloader
2025-07-23 16:11:36,248 [INFO] django.utils.autoreload: C:\Users\CPT-003\Desktop\CRM\crm_api\users\models.py changed, reloading.
2025-07-23 16:11:38,490 [INFO] django.utils.autoreload: Watching for file changes with StatReloader
2025-07-23 16:14:19,064 [INFO] django.utils.autoreload: Watching for file changes with StatReloader
2025-07-23 16:15:21,155 [INFO] django.utils.autoreload: C:\Users\CPT-003\Desktop\CRM\crm_api\lumina_care\views.py changed, reloading.
2025-07-23 16:15:22,921 [INFO] django.utils.autoreload: Watching for file changes with StatReloader
2025-07-23 16:15:46,697 [INFO] django.utils.autoreload: C:\Users\CPT-003\Desktop\CRM\crm_api\lumina_care\views.py changed, reloading.
2025-07-23 16:15:49,919 [INFO] django.utils.autoreload: Watching for file changes with StatReloader
2025-07-23 16:16:31,307 [INFO] django.utils.autoreload: C:\Users\CPT-003\Desktop\CRM\crm_api\lumina_care\views.py changed, reloading.
2025-07-23 16:16:34,623 [INFO] django.utils.autoreload: Watching for file changes with StatReloader
2025-07-23 16:17:05,071 [INFO] django.utils.autoreload: C:\Users\CPT-003\Desktop\CRM\crm_api\lumina_care\views.py changed, reloading.
2025-07-23 16:17:08,314 [INFO] django.utils.autoreload: Watching for file changes with StatReloader
2025-07-23 16:17:26,280 [INFO] users: Email configuration for tenant proliance: host=smtp.gmail.com, port=587, use_ssl=False, host_user=ekenehanson@gmail.com, host_password=*******************, default_from_email=ekenehanson@gmail.com
2025-07-23 16:17:47,347 [ERROR] users: Failed to send password reset email to support@prolianceltd.com: [WinError 10060] A connection attempt failed because the connected party did not properly respond after a period of time, or established connection failed because connected host has failed to respond
Traceback (most recent call last):
  File "C:\Users\CPT-003\Desktop\CRM\crm_api\users\views.py", line 166, in post
    email.send(fail_silently=False)
    ~~~~~~~~~~^^^^^^^^^^^^^^^^^^^^^
  File "C:\Users\CPT-003\Desktop\CRM\crm_api\venv\Lib\site-packages\django\core\mail\message.py", line 307, in send
    return self.get_connection(fail_silently).send_messages([self])
           ~~~~~~~~~~~~~~~~~~~~~~~~~~~~~~~~~~~~~~~~~~~~~~~~^^^^^^^^
  File "C:\Users\CPT-003\Desktop\CRM\crm_api\venv\Lib\site-packages\django\core\mail\backends\smtp.py", line 128, in send_messages
    new_conn_created = self.open()
  File "C:\Users\CPT-003\Desktop\CRM\crm_api\venv\Lib\site-packages\django\core\mail\backends\smtp.py", line 86, in open
    self.connection = self.connection_class(
                      ~~~~~~~~~~~~~~~~~~~~~^
        self.host, self.port, **connection_params
        ^^^^^^^^^^^^^^^^^^^^^^^^^^^^^^^^^^^^^^^^^
    )
    ^
  File "C:\Users\CPT-003\AppData\Local\Programs\Python\Python313\Lib\smtplib.py", line 255, in __init__
    (code, msg) = self.connect(host, port)
                  ~~~~~~~~~~~~^^^^^^^^^^^^
  File "C:\Users\CPT-003\AppData\Local\Programs\Python\Python313\Lib\smtplib.py", line 341, in connect
    self.sock = self._get_socket(host, port, self.timeout)
                ~~~~~~~~~~~~~~~~^^^^^^^^^^^^^^^^^^^^^^^^^^
  File "C:\Users\CPT-003\AppData\Local\Programs\Python\Python313\Lib\smtplib.py", line 312, in _get_socket
    return socket.create_connection((host, port), timeout,
           ~~~~~~~~~~~~~~~~~~~~~~~~^^^^^^^^^^^^^^^^^^^^^^^
                                    self.source_address)
                                    ^^^^^^^^^^^^^^^^^^^^
  File "C:\Users\CPT-003\AppData\Local\Programs\Python\Python313\Lib\socket.py", line 864, in create_connection
    raise exceptions[0]
  File "C:\Users\CPT-003\AppData\Local\Programs\Python\Python313\Lib\socket.py", line 849, in create_connection
    sock.connect(sa)
    ~~~~~~~~~~~~^^^^
TimeoutError: [WinError 10060] A connection attempt failed because the connected party did not properly respond after a period of time, or established connection failed because connected host has failed to respond
2025-07-23 16:17:47,359 [ERROR] django.request: Internal Server Error: /api/user/password/reset/
2025-07-23 16:17:47,359 [ERROR] django.server: "POST /api/user/password/reset/ HTTP/1.1" 500 370
2025-07-23 16:17:51,650 [INFO] users: Password reset successfully for user support@prolianceltd.com in tenant proliance
2025-07-23 16:17:51,652 [INFO] django.server: "POST /api/user/password/reset/confirm/ HTTP/1.1" 200 41
2025-07-23 16:18:21,218 [INFO] django.server: "OPTIONS /api/token/ HTTP/1.1" 200 0
2025-07-23 16:18:22,140 [ERROR] django.request: Internal Server Error: /api/token/
Traceback (most recent call last):
  File "C:\Users\CPT-003\Desktop\CRM\crm_api\venv\Lib\site-packages\django\db\backends\utils.py", line 105, in _execute
    return self.cursor.execute(sql, params)
           ~~~~~~~~~~~~~~~~~~~^^^^^^^^^^^^^
psycopg2.errors.UndefinedTable: relation "account_emailaddress" does not exist
LINE 1: ...."tenant_id", "users_customuser"."branch_id" FROM "account_e...
                                                             ^


The above exception was the direct cause of the following exception:

Traceback (most recent call last):
  File "C:\Users\CPT-003\Desktop\CRM\crm_api\venv\Lib\site-packages\django\core\handlers\exception.py", line 55, in inner
    response = get_response(request)
  File "C:\Users\CPT-003\Desktop\CRM\crm_api\venv\Lib\site-packages\django\core\handlers\base.py", line 197, in _get_response
    response = wrapped_callback(request, *callback_args, **callback_kwargs)
  File "C:\Users\CPT-003\Desktop\CRM\crm_api\venv\Lib\site-packages\django\views\decorators\csrf.py", line 65, in _view_wrapper
    return view_func(request, *args, **kwargs)
  File "C:\Users\CPT-003\Desktop\CRM\crm_api\venv\Lib\site-packages\django\views\generic\base.py", line 104, in view
    return self.dispatch(request, *args, **kwargs)
           ~~~~~~~~~~~~~^^^^^^^^^^^^^^^^^^^^^^^^^^
  File "C:\Users\CPT-003\Desktop\CRM\crm_api\venv\Lib\site-packages\rest_framework\views.py", line 515, in dispatch
    response = self.handle_exception(exc)
  File "C:\Users\CPT-003\Desktop\CRM\crm_api\venv\Lib\site-packages\rest_framework\views.py", line 475, in handle_exception
    self.raise_uncaught_exception(exc)
    ~~~~~~~~~~~~~~~~~~~~~~~~~~~~~^^^^^
  File "C:\Users\CPT-003\Desktop\CRM\crm_api\venv\Lib\site-packages\rest_framework\views.py", line 486, in raise_uncaught_exception
    raise exc
  File "C:\Users\CPT-003\Desktop\CRM\crm_api\venv\Lib\site-packages\rest_framework\views.py", line 512, in dispatch
    response = handler(request, *args, **kwargs)
  File "C:\Users\CPT-003\Desktop\CRM\crm_api\venv\Lib\site-packages\rest_framework_simplejwt\views.py", line 44, in post
    serializer.is_valid(raise_exception=True)
    ~~~~~~~~~~~~~~~~~~~^^^^^^^^^^^^^^^^^^^^^^
  File "C:\Users\CPT-003\Desktop\CRM\crm_api\venv\Lib\site-packages\rest_framework\serializers.py", line 225, in is_valid
    self._validated_data = self.run_validation(self.initial_data)
                           ~~~~~~~~~~~~~~~~~~~^^^^^^^^^^^^^^^^^^^
  File "C:\Users\CPT-003\Desktop\CRM\crm_api\venv\Lib\site-packages\rest_framework\serializers.py", line 447, in run_validation
    value = self.validate(value)
  File "C:\Users\CPT-003\Desktop\CRM\crm_api\lumina_care\views.py", line 185, in validate
    data = super().validate(attrs)
  File "C:\Users\CPT-003\Desktop\CRM\crm_api\venv\Lib\site-packages\rest_framework_simplejwt\serializers.py", line 73, in validate
    data = super().validate(attrs)
  File "C:\Users\CPT-003\Desktop\CRM\crm_api\venv\Lib\site-packages\rest_framework_simplejwt\serializers.py", line 54, in validate
    self.user = authenticate(**authenticate_kwargs)
                ~~~~~~~~~~~~^^^^^^^^^^^^^^^^^^^^^^^
  File "C:\Users\CPT-003\Desktop\CRM\crm_api\venv\Lib\site-packages\django\views\decorators\debug.py", line 75, in sensitive_variables_wrapper
    return func(*func_args, **func_kwargs)
  File "C:\Users\CPT-003\Desktop\CRM\crm_api\venv\Lib\site-packages\django\contrib\auth\__init__.py", line 114, in authenticate
    user = backend.authenticate(request, **credentials)
  File "C:\Users\CPT-003\Desktop\CRM\crm_api\venv\Lib\site-packages\allauth\account\auth_backends.py", line 22, in authenticate
    user = self._authenticate(request, **credentials)
  File "C:\Users\CPT-003\Desktop\CRM\crm_api\venv\Lib\site-packages\allauth\account\auth_backends.py", line 46, in _authenticate
    user = self._authenticate_by_email(email, password)
  File "C:\Users\CPT-003\Desktop\CRM\crm_api\venv\Lib\site-packages\allauth\account\auth_backends.py", line 81, in _authenticate_by_email
    users = filter_users_by_email(email, prefer_verified=True)
  File "C:\Users\CPT-003\Desktop\CRM\crm_api\venv\Lib\site-packages\allauth\account\utils.py", line 284, in filter_users_by_email
    mails = list(EmailAddress.objects.filter(email=email).select_related("user"))
  File "C:\Users\CPT-003\Desktop\CRM\crm_api\venv\Lib\site-packages\django\db\models\query.py", line 384, in __iter__
    self._fetch_all()
    ~~~~~~~~~~~~~~~^^
  File "C:\Users\CPT-003\Desktop\CRM\crm_api\venv\Lib\site-packages\django\db\models\query.py", line 1949, in _fetch_all
    self._result_cache = list(self._iterable_class(self))
                         ~~~~^^^^^^^^^^^^^^^^^^^^^^^^^^^^
  File "C:\Users\CPT-003\Desktop\CRM\crm_api\venv\Lib\site-packages\django\db\models\query.py", line 91, in __iter__
    results = compiler.execute_sql(
        chunked_fetch=self.chunked_fetch, chunk_size=self.chunk_size
    )
  File "C:\Users\CPT-003\Desktop\CRM\crm_api\venv\Lib\site-packages\django\db\models\sql\compiler.py", line 1623, in execute_sql
    cursor.execute(sql, params)
    ~~~~~~~~~~~~~~^^^^^^^^^^^^^
  File "C:\Users\CPT-003\Desktop\CRM\crm_api\venv\Lib\site-packages\django\db\backends\utils.py", line 79, in execute
    return self._execute_with_wrappers(
           ~~~~~~~~~~~~~~~~~~~~~~~~~~~^
        sql, params, many=False, executor=self._execute
        ^^^^^^^^^^^^^^^^^^^^^^^^^^^^^^^^^^^^^^^^^^^^^^^
    )
    ^
  File "C:\Users\CPT-003\Desktop\CRM\crm_api\venv\Lib\site-packages\django\db\backends\utils.py", line 92, in _execute_with_wrappers
    return executor(sql, params, many, context)
  File "C:\Users\CPT-003\Desktop\CRM\crm_api\venv\Lib\site-packages\django\db\backends\utils.py", line 100, in _execute
    with self.db.wrap_database_errors:
         ^^^^^^^^^^^^^^^^^^^^^^^^^^^^
  File "C:\Users\CPT-003\Desktop\CRM\crm_api\venv\Lib\site-packages\django\db\utils.py", line 91, in __exit__
    raise dj_exc_value.with_traceback(traceback) from exc_value
  File "C:\Users\CPT-003\Desktop\CRM\crm_api\venv\Lib\site-packages\django\db\backends\utils.py", line 105, in _execute
    return self.cursor.execute(sql, params)
           ~~~~~~~~~~~~~~~~~~~^^^^^^^^^^^^^
django.db.utils.ProgrammingError: relation "account_emailaddress" does not exist
LINE 1: ...."tenant_id", "users_customuser"."branch_id" FROM "account_e...
                                                             ^

2025-07-23 16:18:22,209 [ERROR] django.server: "POST /api/token/ HTTP/1.1" 500 145
2025-07-23 16:18:27,434 [INFO] django.server: "POST /api/token/ HTTP/1.1" 200 965
2025-07-23 16:18:27,471 [INFO] django.server: "OPTIONS /api/token/validate/ HTTP/1.1" 200 0
2025-07-23 16:18:27,475 [INFO] django.server: "OPTIONS /api/token/validate/ HTTP/1.1" 200 0
2025-07-23 16:18:27,539 [INFO] django.server: "GET /api/token/validate/ HTTP/1.1" 200 389
2025-07-23 16:18:27,548 [INFO] django.server: "GET /api/token/validate/ HTTP/1.1" 200 389
2025-07-23 16:18:27,647 [INFO] django.server: "OPTIONS /api/user/tenant-users/ HTTP/1.1" 200 0
2025-07-23 16:18:27,647 [INFO] django.server: "OPTIONS /api/user/tenant-users/ HTTP/1.1" 200 0
2025-07-23 16:18:27,660 [INFO] users: Retrieved 3 users for tenant proliance
2025-07-23 16:18:27,682 [INFO] django.server: "GET /api/user/tenant-users/ HTTP/1.1" 200 1022
2025-07-23 16:18:27,694 [INFO] users: Retrieved 3 users for tenant proliance
2025-07-23 16:18:27,710 [INFO] django.server: "GET /api/user/tenant-users/ HTTP/1.1" 200 1022
2025-07-23 16:18:30,321 [INFO] django.server: "OPTIONS /api/talent-engine/requisitions/ HTTP/1.1" 200 0
2025-07-23 16:18:30,326 [INFO] django.server: "OPTIONS /api/talent-engine/requisitions/ HTTP/1.1" 200 0
2025-07-23 16:18:30,440 [INFO] django.server: "GET /api/talent-engine/requisitions/ HTTP/1.1" 200 6330
2025-07-23 16:18:30,550 [INFO] django.server: "GET /api/talent-engine/requisitions/ HTTP/1.1" 200 6330
2025-07-23 16:18:54,024 [INFO] django.utils.autoreload: C:\Users\CPT-003\Desktop\CRM\crm_api\lumina_care\settings.py changed, reloading.
2025-07-23 17:11:25,448 [INFO] django.utils.autoreload: Watching for file changes with StatReloader
2025-07-23 17:12:55,831 [ERROR] django.request: Internal Server Error: /api/token/
Traceback (most recent call last):
  File "C:\Users\CPT-003\Desktop\CRM\crm_api\venv\Lib\site-packages\django\db\backends\utils.py", line 105, in _execute
    return self.cursor.execute(sql, params)
           ~~~~~~~~~~~~~~~~~~~^^^^^^^^^^^^^
psycopg2.errors.UndefinedTable: relation "account_emailaddress" does not exist
LINE 1: ...."tenant_id", "users_customuser"."branch_id" FROM "account_e...
                                                             ^


The above exception was the direct cause of the following exception:

Traceback (most recent call last):
  File "C:\Users\CPT-003\Desktop\CRM\crm_api\venv\Lib\site-packages\django\core\handlers\exception.py", line 55, in inner
    response = get_response(request)
  File "C:\Users\CPT-003\Desktop\CRM\crm_api\venv\Lib\site-packages\django\core\handlers\base.py", line 197, in _get_response
    response = wrapped_callback(request, *callback_args, **callback_kwargs)
  File "C:\Users\CPT-003\Desktop\CRM\crm_api\venv\Lib\site-packages\django\views\decorators\csrf.py", line 65, in _view_wrapper
    return view_func(request, *args, **kwargs)
  File "C:\Users\CPT-003\Desktop\CRM\crm_api\venv\Lib\site-packages\django\views\generic\base.py", line 104, in view
    return self.dispatch(request, *args, **kwargs)
           ~~~~~~~~~~~~~^^^^^^^^^^^^^^^^^^^^^^^^^^
  File "C:\Users\CPT-003\Desktop\CRM\crm_api\venv\Lib\site-packages\rest_framework\views.py", line 515, in dispatch
    response = self.handle_exception(exc)
  File "C:\Users\CPT-003\Desktop\CRM\crm_api\venv\Lib\site-packages\rest_framework\views.py", line 475, in handle_exception
    self.raise_uncaught_exception(exc)
    ~~~~~~~~~~~~~~~~~~~~~~~~~~~~~^^^^^
  File "C:\Users\CPT-003\Desktop\CRM\crm_api\venv\Lib\site-packages\rest_framework\views.py", line 486, in raise_uncaught_exception
    raise exc
  File "C:\Users\CPT-003\Desktop\CRM\crm_api\venv\Lib\site-packages\rest_framework\views.py", line 512, in dispatch
    response = handler(request, *args, **kwargs)
  File "C:\Users\CPT-003\Desktop\CRM\crm_api\venv\Lib\site-packages\rest_framework_simplejwt\views.py", line 44, in post
    serializer.is_valid(raise_exception=True)
    ~~~~~~~~~~~~~~~~~~~^^^^^^^^^^^^^^^^^^^^^^
  File "C:\Users\CPT-003\Desktop\CRM\crm_api\venv\Lib\site-packages\rest_framework\serializers.py", line 225, in is_valid
    self._validated_data = self.run_validation(self.initial_data)
                           ~~~~~~~~~~~~~~~~~~~^^^^^^^^^^^^^^^^^^^
  File "C:\Users\CPT-003\Desktop\CRM\crm_api\venv\Lib\site-packages\rest_framework\serializers.py", line 447, in run_validation
    value = self.validate(value)
  File "C:\Users\CPT-003\Desktop\CRM\crm_api\lumina_care\views.py", line 185, in validate
    data = super().validate(attrs)
  File "C:\Users\CPT-003\Desktop\CRM\crm_api\venv\Lib\site-packages\rest_framework_simplejwt\serializers.py", line 73, in validate
    data = super().validate(attrs)
  File "C:\Users\CPT-003\Desktop\CRM\crm_api\venv\Lib\site-packages\rest_framework_simplejwt\serializers.py", line 54, in validate
    self.user = authenticate(**authenticate_kwargs)
                ~~~~~~~~~~~~^^^^^^^^^^^^^^^^^^^^^^^
  File "C:\Users\CPT-003\Desktop\CRM\crm_api\venv\Lib\site-packages\django\views\decorators\debug.py", line 75, in sensitive_variables_wrapper
    return func(*func_args, **func_kwargs)
  File "C:\Users\CPT-003\Desktop\CRM\crm_api\venv\Lib\site-packages\django\contrib\auth\__init__.py", line 114, in authenticate
    user = backend.authenticate(request, **credentials)
  File "C:\Users\CPT-003\Desktop\CRM\crm_api\venv\Lib\site-packages\allauth\account\auth_backends.py", line 22, in authenticate
    user = self._authenticate(request, **credentials)
  File "C:\Users\CPT-003\Desktop\CRM\crm_api\venv\Lib\site-packages\allauth\account\auth_backends.py", line 46, in _authenticate
    user = self._authenticate_by_email(email, password)
  File "C:\Users\CPT-003\Desktop\CRM\crm_api\venv\Lib\site-packages\allauth\account\auth_backends.py", line 81, in _authenticate_by_email
    users = filter_users_by_email(email, prefer_verified=True)
  File "C:\Users\CPT-003\Desktop\CRM\crm_api\venv\Lib\site-packages\allauth\account\utils.py", line 284, in filter_users_by_email
    mails = list(EmailAddress.objects.filter(email=email).select_related("user"))
  File "C:\Users\CPT-003\Desktop\CRM\crm_api\venv\Lib\site-packages\django\db\models\query.py", line 384, in __iter__
    self._fetch_all()
    ~~~~~~~~~~~~~~~^^
  File "C:\Users\CPT-003\Desktop\CRM\crm_api\venv\Lib\site-packages\django\db\models\query.py", line 1949, in _fetch_all
    self._result_cache = list(self._iterable_class(self))
                         ~~~~^^^^^^^^^^^^^^^^^^^^^^^^^^^^
  File "C:\Users\CPT-003\Desktop\CRM\crm_api\venv\Lib\site-packages\django\db\models\query.py", line 91, in __iter__
    results = compiler.execute_sql(
        chunked_fetch=self.chunked_fetch, chunk_size=self.chunk_size
    )
  File "C:\Users\CPT-003\Desktop\CRM\crm_api\venv\Lib\site-packages\django\db\models\sql\compiler.py", line 1623, in execute_sql
    cursor.execute(sql, params)
    ~~~~~~~~~~~~~~^^^^^^^^^^^^^
  File "C:\Users\CPT-003\Desktop\CRM\crm_api\venv\Lib\site-packages\django\db\backends\utils.py", line 79, in execute
    return self._execute_with_wrappers(
           ~~~~~~~~~~~~~~~~~~~~~~~~~~~^
        sql, params, many=False, executor=self._execute
        ^^^^^^^^^^^^^^^^^^^^^^^^^^^^^^^^^^^^^^^^^^^^^^^
    )
    ^
  File "C:\Users\CPT-003\Desktop\CRM\crm_api\venv\Lib\site-packages\django\db\backends\utils.py", line 92, in _execute_with_wrappers
    return executor(sql, params, many, context)
  File "C:\Users\CPT-003\Desktop\CRM\crm_api\venv\Lib\site-packages\django\db\backends\utils.py", line 100, in _execute
    with self.db.wrap_database_errors:
         ^^^^^^^^^^^^^^^^^^^^^^^^^^^^
  File "C:\Users\CPT-003\Desktop\CRM\crm_api\venv\Lib\site-packages\django\db\utils.py", line 91, in __exit__
    raise dj_exc_value.with_traceback(traceback) from exc_value
  File "C:\Users\CPT-003\Desktop\CRM\crm_api\venv\Lib\site-packages\django\db\backends\utils.py", line 105, in _execute
    return self.cursor.execute(sql, params)
           ~~~~~~~~~~~~~~~~~~~^^^^^^^^^^^^^
django.db.utils.ProgrammingError: relation "account_emailaddress" does not exist
LINE 1: ...."tenant_id", "users_customuser"."branch_id" FROM "account_e...
                                                             ^

2025-07-23 17:12:55,847 [ERROR] django.server: "POST /api/token/ HTTP/1.1" 500 145
2025-07-23 17:13:19,597 [ERROR] django.request: Internal Server Error: /api/token/
Traceback (most recent call last):
  File "C:\Users\CPT-003\Desktop\CRM\crm_api\venv\Lib\site-packages\django\db\backends\utils.py", line 105, in _execute
    return self.cursor.execute(sql, params)
           ~~~~~~~~~~~~~~~~~~~^^^^^^^^^^^^^
psycopg2.errors.UndefinedTable: relation "account_emailaddress" does not exist
LINE 1: ...."tenant_id", "users_customuser"."branch_id" FROM "account_e...
                                                             ^


The above exception was the direct cause of the following exception:

Traceback (most recent call last):
  File "C:\Users\CPT-003\Desktop\CRM\crm_api\venv\Lib\site-packages\django\core\handlers\exception.py", line 55, in inner
    response = get_response(request)
  File "C:\Users\CPT-003\Desktop\CRM\crm_api\venv\Lib\site-packages\django\core\handlers\base.py", line 197, in _get_response
    response = wrapped_callback(request, *callback_args, **callback_kwargs)
  File "C:\Users\CPT-003\Desktop\CRM\crm_api\venv\Lib\site-packages\django\views\decorators\csrf.py", line 65, in _view_wrapper
    return view_func(request, *args, **kwargs)
  File "C:\Users\CPT-003\Desktop\CRM\crm_api\venv\Lib\site-packages\django\views\generic\base.py", line 104, in view
    return self.dispatch(request, *args, **kwargs)
           ~~~~~~~~~~~~~^^^^^^^^^^^^^^^^^^^^^^^^^^
  File "C:\Users\CPT-003\Desktop\CRM\crm_api\venv\Lib\site-packages\rest_framework\views.py", line 515, in dispatch
    response = self.handle_exception(exc)
  File "C:\Users\CPT-003\Desktop\CRM\crm_api\venv\Lib\site-packages\rest_framework\views.py", line 475, in handle_exception
    self.raise_uncaught_exception(exc)
    ~~~~~~~~~~~~~~~~~~~~~~~~~~~~~^^^^^
  File "C:\Users\CPT-003\Desktop\CRM\crm_api\venv\Lib\site-packages\rest_framework\views.py", line 486, in raise_uncaught_exception
    raise exc
  File "C:\Users\CPT-003\Desktop\CRM\crm_api\venv\Lib\site-packages\rest_framework\views.py", line 512, in dispatch
    response = handler(request, *args, **kwargs)
  File "C:\Users\CPT-003\Desktop\CRM\crm_api\venv\Lib\site-packages\rest_framework_simplejwt\views.py", line 44, in post
    serializer.is_valid(raise_exception=True)
    ~~~~~~~~~~~~~~~~~~~^^^^^^^^^^^^^^^^^^^^^^
  File "C:\Users\CPT-003\Desktop\CRM\crm_api\venv\Lib\site-packages\rest_framework\serializers.py", line 225, in is_valid
    self._validated_data = self.run_validation(self.initial_data)
                           ~~~~~~~~~~~~~~~~~~~^^^^^^^^^^^^^^^^^^^
  File "C:\Users\CPT-003\Desktop\CRM\crm_api\venv\Lib\site-packages\rest_framework\serializers.py", line 447, in run_validation
    value = self.validate(value)
  File "C:\Users\CPT-003\Desktop\CRM\crm_api\lumina_care\views.py", line 185, in validate
    data = super().validate(attrs)
  File "C:\Users\CPT-003\Desktop\CRM\crm_api\venv\Lib\site-packages\rest_framework_simplejwt\serializers.py", line 73, in validate
    data = super().validate(attrs)
  File "C:\Users\CPT-003\Desktop\CRM\crm_api\venv\Lib\site-packages\rest_framework_simplejwt\serializers.py", line 54, in validate
    self.user = authenticate(**authenticate_kwargs)
                ~~~~~~~~~~~~^^^^^^^^^^^^^^^^^^^^^^^
  File "C:\Users\CPT-003\Desktop\CRM\crm_api\venv\Lib\site-packages\django\views\decorators\debug.py", line 75, in sensitive_variables_wrapper
    return func(*func_args, **func_kwargs)
  File "C:\Users\CPT-003\Desktop\CRM\crm_api\venv\Lib\site-packages\django\contrib\auth\__init__.py", line 114, in authenticate
    user = backend.authenticate(request, **credentials)
  File "C:\Users\CPT-003\Desktop\CRM\crm_api\venv\Lib\site-packages\allauth\account\auth_backends.py", line 22, in authenticate
    user = self._authenticate(request, **credentials)
  File "C:\Users\CPT-003\Desktop\CRM\crm_api\venv\Lib\site-packages\allauth\account\auth_backends.py", line 46, in _authenticate
    user = self._authenticate_by_email(email, password)
  File "C:\Users\CPT-003\Desktop\CRM\crm_api\venv\Lib\site-packages\allauth\account\auth_backends.py", line 81, in _authenticate_by_email
    users = filter_users_by_email(email, prefer_verified=True)
  File "C:\Users\CPT-003\Desktop\CRM\crm_api\venv\Lib\site-packages\allauth\account\utils.py", line 284, in filter_users_by_email
    mails = list(EmailAddress.objects.filter(email=email).select_related("user"))
  File "C:\Users\CPT-003\Desktop\CRM\crm_api\venv\Lib\site-packages\django\db\models\query.py", line 384, in __iter__
    self._fetch_all()
    ~~~~~~~~~~~~~~~^^
  File "C:\Users\CPT-003\Desktop\CRM\crm_api\venv\Lib\site-packages\django\db\models\query.py", line 1949, in _fetch_all
    self._result_cache = list(self._iterable_class(self))
                         ~~~~^^^^^^^^^^^^^^^^^^^^^^^^^^^^
  File "C:\Users\CPT-003\Desktop\CRM\crm_api\venv\Lib\site-packages\django\db\models\query.py", line 91, in __iter__
    results = compiler.execute_sql(
        chunked_fetch=self.chunked_fetch, chunk_size=self.chunk_size
    )
  File "C:\Users\CPT-003\Desktop\CRM\crm_api\venv\Lib\site-packages\django\db\models\sql\compiler.py", line 1623, in execute_sql
    cursor.execute(sql, params)
    ~~~~~~~~~~~~~~^^^^^^^^^^^^^
  File "C:\Users\CPT-003\Desktop\CRM\crm_api\venv\Lib\site-packages\django\db\backends\utils.py", line 79, in execute
    return self._execute_with_wrappers(
           ~~~~~~~~~~~~~~~~~~~~~~~~~~~^
        sql, params, many=False, executor=self._execute
        ^^^^^^^^^^^^^^^^^^^^^^^^^^^^^^^^^^^^^^^^^^^^^^^
    )
    ^
  File "C:\Users\CPT-003\Desktop\CRM\crm_api\venv\Lib\site-packages\django\db\backends\utils.py", line 92, in _execute_with_wrappers
    return executor(sql, params, many, context)
  File "C:\Users\CPT-003\Desktop\CRM\crm_api\venv\Lib\site-packages\django\db\backends\utils.py", line 100, in _execute
    with self.db.wrap_database_errors:
         ^^^^^^^^^^^^^^^^^^^^^^^^^^^^
  File "C:\Users\CPT-003\Desktop\CRM\crm_api\venv\Lib\site-packages\django\db\utils.py", line 91, in __exit__
    raise dj_exc_value.with_traceback(traceback) from exc_value
  File "C:\Users\CPT-003\Desktop\CRM\crm_api\venv\Lib\site-packages\django\db\backends\utils.py", line 105, in _execute
    return self.cursor.execute(sql, params)
           ~~~~~~~~~~~~~~~~~~~^^^^^^^^^^^^^
django.db.utils.ProgrammingError: relation "account_emailaddress" does not exist
LINE 1: ...."tenant_id", "users_customuser"."branch_id" FROM "account_e...
                                                             ^

2025-07-23 17:13:19,605 [ERROR] django.server: "POST /api/token/ HTTP/1.1" 500 145
2025-07-23 17:15:47,303 [INFO] django.utils.autoreload: Watching for file changes with StatReloader
2025-07-23 17:17:50,954 [INFO] django.utils.autoreload: C:\Users\CPT-003\Desktop\CRM\crm_api\lumina_care\settings.py changed, reloading.
2025-07-23 17:18:00,344 [INFO] django.utils.autoreload: Watching for file changes with StatReloader
2025-07-23 17:18:39,947 [INFO] django.utils.autoreload: Watching for file changes with StatReloader
2025-07-23 17:19:44,262 [INFO] django.utils.autoreload: C:\Users\CPT-003\Desktop\CRM\crm_api\lumina_care\settings.py changed, reloading.
2025-07-23 17:19:54,202 [INFO] django.utils.autoreload: Watching for file changes with StatReloader
2025-07-23 17:20:39,004 [INFO] django.utils.autoreload: Watching for file changes with StatReloader
2025-07-23 17:20:50,270 [INFO] django.utils.autoreload: C:\Users\CPT-003\Desktop\CRM\crm_api\users\views.py changed, reloading.
2025-07-23 17:20:58,677 [INFO] django.utils.autoreload: Watching for file changes with StatReloader
2025-07-23 17:21:35,231 [INFO] django.utils.autoreload: Watching for file changes with StatReloader
2025-07-23 17:22:42,443 [INFO] django.utils.autoreload: C:\Users\CPT-003\Desktop\CRM\crm_api\lumina_care\settings.py changed, reloading.
2025-07-23 17:22:51,889 [INFO] django.utils.autoreload: Watching for file changes with StatReloader
2025-07-23 17:23:05,833 [ERROR] django.request: Internal Server Error: /api/token/
Traceback (most recent call last):
  File "C:\Users\CPT-003\Desktop\CRM\crm_api\venv\Lib\site-packages\django\core\handlers\exception.py", line 55, in inner
    response = get_response(request)
  File "C:\Users\CPT-003\Desktop\CRM\crm_api\venv\Lib\site-packages\django\core\handlers\base.py", line 197, in _get_response
    response = wrapped_callback(request, *callback_args, **callback_kwargs)
  File "C:\Users\CPT-003\Desktop\CRM\crm_api\venv\Lib\site-packages\django\views\decorators\csrf.py", line 65, in _view_wrapper
    return view_func(request, *args, **kwargs)
  File "C:\Users\CPT-003\Desktop\CRM\crm_api\venv\Lib\site-packages\django\views\generic\base.py", line 104, in view
    return self.dispatch(request, *args, **kwargs)
           ~~~~~~~~~~~~~^^^^^^^^^^^^^^^^^^^^^^^^^^
  File "C:\Users\CPT-003\Desktop\CRM\crm_api\venv\Lib\site-packages\rest_framework\views.py", line 515, in dispatch
    response = self.handle_exception(exc)
  File "C:\Users\CPT-003\Desktop\CRM\crm_api\venv\Lib\site-packages\rest_framework\views.py", line 475, in handle_exception
    self.raise_uncaught_exception(exc)
    ~~~~~~~~~~~~~~~~~~~~~~~~~~~~~^^^^^
  File "C:\Users\CPT-003\Desktop\CRM\crm_api\venv\Lib\site-packages\rest_framework\views.py", line 486, in raise_uncaught_exception
    raise exc
  File "C:\Users\CPT-003\Desktop\CRM\crm_api\venv\Lib\site-packages\rest_framework\views.py", line 512, in dispatch
    response = handler(request, *args, **kwargs)
  File "C:\Users\CPT-003\Desktop\CRM\crm_api\venv\Lib\site-packages\rest_framework_simplejwt\views.py", line 44, in post
    serializer.is_valid(raise_exception=True)
    ~~~~~~~~~~~~~~~~~~~^^^^^^^^^^^^^^^^^^^^^^
  File "C:\Users\CPT-003\Desktop\CRM\crm_api\venv\Lib\site-packages\rest_framework\serializers.py", line 225, in is_valid
    self._validated_data = self.run_validation(self.initial_data)
                           ~~~~~~~~~~~~~~~~~~~^^^^^^^^^^^^^^^^^^^
  File "C:\Users\CPT-003\Desktop\CRM\crm_api\venv\Lib\site-packages\rest_framework\serializers.py", line 447, in run_validation
    value = self.validate(value)
  File "C:\Users\CPT-003\Desktop\CRM\crm_api\lumina_care\views.py", line 185, in validate
    data = super().validate(attrs)
  File "C:\Users\CPT-003\Desktop\CRM\crm_api\venv\Lib\site-packages\rest_framework_simplejwt\serializers.py", line 73, in validate
    data = super().validate(attrs)
  File "C:\Users\CPT-003\Desktop\CRM\crm_api\venv\Lib\site-packages\rest_framework_simplejwt\serializers.py", line 54, in validate
    self.user = authenticate(**authenticate_kwargs)
                ~~~~~~~~~~~~^^^^^^^^^^^^^^^^^^^^^^^
  File "C:\Users\CPT-003\Desktop\CRM\crm_api\venv\Lib\site-packages\django\views\decorators\debug.py", line 75, in sensitive_variables_wrapper
    return func(*func_args, **func_kwargs)
  File "C:\Users\CPT-003\Desktop\CRM\crm_api\venv\Lib\site-packages\django\contrib\auth\__init__.py", line 112, in authenticate
    for backend, backend_path in _get_compatible_backends(request, **credentials):
                                 ~~~~~~~~~~~~~~~~~~~~~~~~^^^^^^^^^^^^^^^^^^^^^^^^
  File "C:\Users\CPT-003\Desktop\CRM\crm_api\venv\Lib\site-packages\django\contrib\auth\__init__.py", line 44, in _get_compatible_backends
    for backend, backend_path in _get_backends(return_tuples=True):
                                 ~~~~~~~~~~~~~^^^^^^^^^^^^^^^^^^^^
  File "C:\Users\CPT-003\Desktop\CRM\crm_api\venv\Lib\site-packages\django\contrib\auth\__init__.py", line 29, in _get_backends
    backend = load_backend(backend_path)
  File "C:\Users\CPT-003\Desktop\CRM\crm_api\venv\Lib\site-packages\django\contrib\auth\__init__.py", line 23, in load_backend
    return import_string(path)()
           ~~~~~~~~~~~~~^^^^^^
  File "C:\Users\CPT-003\Desktop\CRM\crm_api\venv\Lib\site-packages\django\utils\module_loading.py", line 30, in import_string
    return cached_import(module_path, class_name)
  File "C:\Users\CPT-003\Desktop\CRM\crm_api\venv\Lib\site-packages\django\utils\module_loading.py", line 15, in cached_import
    module = import_module(module_path)
  File "C:\Users\CPT-003\AppData\Local\Programs\Python\Python313\Lib\importlib\__init__.py", line 88, in import_module
    return _bootstrap._gcd_import(name[level:], package, level)
           ~~~~~~~~~~~~~~~~~~~~~~^^^^^^^^^^^^^^^^^^^^^^^^^^^^^^
  File "<frozen importlib._bootstrap>", line 1387, in _gcd_import
  File "<frozen importlib._bootstrap>", line 1360, in _find_and_load
  File "<frozen importlib._bootstrap>", line 1310, in _find_and_load_unlocked
  File "<frozen importlib._bootstrap>", line 488, in _call_with_frames_removed
  File "<frozen importlib._bootstrap>", line 1387, in _gcd_import
  File "<frozen importlib._bootstrap>", line 1360, in _find_and_load
  File "<frozen importlib._bootstrap>", line 1310, in _find_and_load_unlocked
  File "<frozen importlib._bootstrap>", line 488, in _call_with_frames_removed
  File "<frozen importlib._bootstrap>", line 1387, in _gcd_import
  File "<frozen importlib._bootstrap>", line 1360, in _find_and_load
  File "<frozen importlib._bootstrap>", line 1324, in _find_and_load_unlocked
ModuleNotFoundError: No module named 'allauth'
2025-07-23 17:23:05,844 [ERROR] django.server: "POST /api/token/ HTTP/1.1" 500 145
2025-07-23 17:24:38,996 [INFO] django.utils.autoreload: C:\Users\CPT-003\Desktop\CRM\crm_api\lumina_care\settings.py changed, reloading.
2025-07-23 17:24:43,542 [INFO] django.utils.autoreload: Watching for file changes with StatReloader
2025-07-23 17:24:56,000 [INFO] django.utils.autoreload: Watching for file changes with StatReloader
2025-07-23 17:25:09,418 [WARNING] django.request: Unauthorized: /api/token/
2025-07-23 17:25:09,419 [WARNING] django.server: "POST /api/token/ HTTP/1.1" 401 63
2025-07-23 17:25:21,874 [INFO] django.server: "POST /api/token/ HTTP/1.1" 200 965
2025-07-23 17:25:49,014 [INFO] users: Email configuration for tenant proliance: host=smtp.gmail.com, port=587, use_ssl=False, host_user=ekenehanson@gmail.com, host_password=*******************, default_from_email=ekenehanson@gmail.com
2025-07-23 17:26:00,912 [ERROR] users: Validation failed for password reset confirmation: {'token': [ErrorDetail(string='Invalid token.', code='invalid')], 'new_password': [ErrorDetail(string='Ensure this field has at least 8 characters.', code='min_length')]}
2025-07-23 17:26:00,913 [WARNING] django.request: Bad Request: /api/user/password/reset/confirm/
2025-07-23 17:26:00,913 [WARNING] django.server: "POST /api/user/password/reset/confirm/ HTTP/1.1" 400 92
2025-07-23 17:26:09,308 [INFO] django.server: "POST /api/token/ HTTP/1.1" 200 965
2025-07-23 17:26:10,118 [ERROR] users: Failed to send password reset email to support@prolianceltd.com: [WinError 10060] A connection attempt failed because the connected party did not properly respond after a period of time, or established connection failed because connected host has failed to respond
Traceback (most recent call last):
  File "C:\Users\CPT-003\Desktop\CRM\crm_api\users\views.py", line 165, in post
    email.send(fail_silently=False)
    ~~~~~~~~~~^^^^^^^^^^^^^^^^^^^^^
  File "C:\Users\CPT-003\Desktop\CRM\crm_api\venv\Lib\site-packages\django\core\mail\message.py", line 307, in send
    return self.get_connection(fail_silently).send_messages([self])
           ~~~~~~~~~~~~~~~~~~~~~~~~~~~~~~~~~~~~~~~~~~~~~~~~^^^^^^^^
  File "C:\Users\CPT-003\Desktop\CRM\crm_api\venv\Lib\site-packages\django\core\mail\backends\smtp.py", line 128, in send_messages
    new_conn_created = self.open()
  File "C:\Users\CPT-003\Desktop\CRM\crm_api\venv\Lib\site-packages\django\core\mail\backends\smtp.py", line 86, in open
    self.connection = self.connection_class(
                      ~~~~~~~~~~~~~~~~~~~~~^
        self.host, self.port, **connection_params
        ^^^^^^^^^^^^^^^^^^^^^^^^^^^^^^^^^^^^^^^^^
    )
    ^
  File "C:\Users\CPT-003\AppData\Local\Programs\Python\Python313\Lib\smtplib.py", line 255, in __init__
    (code, msg) = self.connect(host, port)
                  ~~~~~~~~~~~~^^^^^^^^^^^^
  File "C:\Users\CPT-003\AppData\Local\Programs\Python\Python313\Lib\smtplib.py", line 341, in connect
    self.sock = self._get_socket(host, port, self.timeout)
                ~~~~~~~~~~~~~~~~^^^^^^^^^^^^^^^^^^^^^^^^^^
  File "C:\Users\CPT-003\AppData\Local\Programs\Python\Python313\Lib\smtplib.py", line 312, in _get_socket
    return socket.create_connection((host, port), timeout,
           ~~~~~~~~~~~~~~~~~~~~~~~~^^^^^^^^^^^^^^^^^^^^^^^
                                    self.source_address)
                                    ^^^^^^^^^^^^^^^^^^^^
  File "C:\Users\CPT-003\AppData\Local\Programs\Python\Python313\Lib\socket.py", line 864, in create_connection
    raise exceptions[0]
  File "C:\Users\CPT-003\AppData\Local\Programs\Python\Python313\Lib\socket.py", line 849, in create_connection
    sock.connect(sa)
    ~~~~~~~~~~~~^^^^
TimeoutError: [WinError 10060] A connection attempt failed because the connected party did not properly respond after a period of time, or established connection failed because connected host has failed to respond
2025-07-23 17:26:10,126 [ERROR] django.request: Internal Server Error: /api/user/password/reset/
2025-07-23 17:26:10,127 [ERROR] django.server: "POST /api/user/password/reset/ HTTP/1.1" 500 370
2025-07-23 17:28:23,036 [INFO] django.server: "POST /api/talent-engine/video-sessions HTTP/1.1" 301 0
2025-07-23 17:28:23,097 [WARNING] django.request: Unauthorized: /api/talent-engine/video-sessions/
2025-07-23 17:28:23,098 [WARNING] django.server: "POST /api/talent-engine/video-sessions/ HTTP/1.1" 401 58
2025-07-23 17:28:40,214 [INFO] django.server: "POST /api/talent-engine/video-sessions HTTP/1.1" 301 0
2025-07-23 17:28:40,291 [WARNING] django.request: Bad Request: /api/talent-engine/video-sessions/
2025-07-23 17:28:40,292 [WARNING] django.server: "POST /api/talent-engine/video-sessions/ HTTP/1.1" 400 47
2025-07-23 17:32:58,459 [INFO] django.server: "GET /api/talent-engine-job-applications/applications/ HTTP/1.1" 200 5681171
2025-07-23 17:34:06,425 [INFO] django.server: "GET /api/talent-engine-job-applications/applications/PRO-0004/ HTTP/1.1" 200 1850
2025-07-23 17:34:16,120 [INFO] django.server: "POST /api/talent-engine/video-sessions HTTP/1.1" 301 0
2025-07-23 17:34:16,183 [WARNING] django.request: Bad Request: /api/talent-engine/video-sessions/
2025-07-23 17:34:16,183 [WARNING] django.server: "POST /api/talent-engine/video-sessions/ HTTP/1.1" 400 47
2025-07-23 17:34:30,697 [INFO] django.server: "POST /api/talent-engine/video-sessions HTTP/1.1" 301 0
2025-07-23 17:34:30,786 [ERROR] django.request: Internal Server Error: /api/talent-engine/video-sessions/
Traceback (most recent call last):
  File "C:\Users\CPT-003\Desktop\CRM\crm_api\venv\Lib\site-packages\django\db\backends\utils.py", line 105, in _execute
    return self.cursor.execute(sql, params)
           ~~~~~~~~~~~~~~~~~~~^^^^^^^^^^^^^
psycopg2.errors.UndefinedTable: relation "job_applications_job_application" does not exist
LINE 1: ...pplications_job_application"."date_of_birth" FROM "job_appli...
                                                             ^


The above exception was the direct cause of the following exception:

Traceback (most recent call last):
  File "C:\Users\CPT-003\Desktop\CRM\crm_api\venv\Lib\site-packages\django\core\handlers\exception.py", line 55, in inner
    response = get_response(request)
  File "C:\Users\CPT-003\Desktop\CRM\crm_api\venv\Lib\site-packages\django\core\handlers\base.py", line 197, in _get_response
    response = wrapped_callback(request, *callback_args, **callback_kwargs)
  File "C:\Users\CPT-003\Desktop\CRM\crm_api\venv\Lib\site-packages\django\views\decorators\csrf.py", line 65, in _view_wrapper
    return view_func(request, *args, **kwargs)
  File "C:\Users\CPT-003\Desktop\CRM\crm_api\venv\Lib\site-packages\rest_framework\viewsets.py", line 125, in view
    return self.dispatch(request, *args, **kwargs)
           ~~~~~~~~~~~~~^^^^^^^^^^^^^^^^^^^^^^^^^^
  File "C:\Users\CPT-003\Desktop\CRM\crm_api\venv\Lib\site-packages\rest_framework\views.py", line 515, in dispatch
    response = self.handle_exception(exc)
  File "C:\Users\CPT-003\Desktop\CRM\crm_api\venv\Lib\site-packages\rest_framework\views.py", line 475, in handle_exception
    self.raise_uncaught_exception(exc)
    ~~~~~~~~~~~~~~~~~~~~~~~~~~~~~^^^^^
  File "C:\Users\CPT-003\Desktop\CRM\crm_api\venv\Lib\site-packages\rest_framework\views.py", line 486, in raise_uncaught_exception
    raise exc
  File "C:\Users\CPT-003\Desktop\CRM\crm_api\venv\Lib\site-packages\rest_framework\views.py", line 512, in dispatch
    response = handler(request, *args, **kwargs)
  File "C:\Users\CPT-003\Desktop\CRM\crm_api\venv\Lib\site-packages\rest_framework\mixins.py", line 18, in create
    serializer.is_valid(raise_exception=True)
    ~~~~~~~~~~~~~~~~~~~^^^^^^^^^^^^^^^^^^^^^^
  File "C:\Users\CPT-003\Desktop\CRM\crm_api\venv\Lib\site-packages\rest_framework\serializers.py", line 225, in is_valid
    self._validated_data = self.run_validation(self.initial_data)
                           ~~~~~~~~~~~~~~~~~~~^^^^^^^^^^^^^^^^^^^
  File "C:\Users\CPT-003\Desktop\CRM\crm_api\venv\Lib\site-packages\rest_framework\serializers.py", line 444, in run_validation
    value = self.to_internal_value(data)
  File "C:\Users\CPT-003\Desktop\CRM\crm_api\venv\Lib\site-packages\rest_framework\serializers.py", line 501, in to_internal_value
    validated_value = field.run_validation(primitive_value)
  File "C:\Users\CPT-003\Desktop\CRM\crm_api\venv\Lib\site-packages\rest_framework\relations.py", line 155, in run_validation
    return super().run_validation(data)
           ~~~~~~~~~~~~~~~~~~~~~~^^^^^^
  File "C:\Users\CPT-003\Desktop\CRM\crm_api\venv\Lib\site-packages\rest_framework\fields.py", line 538, in run_validation
    value = self.to_internal_value(data)
  File "C:\Users\CPT-003\Desktop\CRM\crm_api\venv\Lib\site-packages\rest_framework\relations.py", line 259, in to_internal_value
    return queryset.get(pk=data)
           ~~~~~~~~~~~~^^^^^^^^^
  File "C:\Users\CPT-003\Desktop\CRM\crm_api\venv\Lib\site-packages\django\db\models\query.py", line 629, in get
    num = len(clone)
  File "C:\Users\CPT-003\Desktop\CRM\crm_api\venv\Lib\site-packages\django\db\models\query.py", line 366, in __len__
    self._fetch_all()
    ~~~~~~~~~~~~~~~^^
  File "C:\Users\CPT-003\Desktop\CRM\crm_api\venv\Lib\site-packages\django\db\models\query.py", line 1949, in _fetch_all
    self._result_cache = list(self._iterable_class(self))
                         ~~~~^^^^^^^^^^^^^^^^^^^^^^^^^^^^
  File "C:\Users\CPT-003\Desktop\CRM\crm_api\venv\Lib\site-packages\django\db\models\query.py", line 91, in __iter__
    results = compiler.execute_sql(
        chunked_fetch=self.chunked_fetch, chunk_size=self.chunk_size
    )
  File "C:\Users\CPT-003\Desktop\CRM\crm_api\venv\Lib\site-packages\django\db\models\sql\compiler.py", line 1623, in execute_sql
    cursor.execute(sql, params)
    ~~~~~~~~~~~~~~^^^^^^^^^^^^^
  File "C:\Users\CPT-003\Desktop\CRM\crm_api\venv\Lib\site-packages\django\db\backends\utils.py", line 79, in execute
    return self._execute_with_wrappers(
           ~~~~~~~~~~~~~~~~~~~~~~~~~~~^
        sql, params, many=False, executor=self._execute
        ^^^^^^^^^^^^^^^^^^^^^^^^^^^^^^^^^^^^^^^^^^^^^^^
    )
    ^
  File "C:\Users\CPT-003\Desktop\CRM\crm_api\venv\Lib\site-packages\django\db\backends\utils.py", line 92, in _execute_with_wrappers
    return executor(sql, params, many, context)
  File "C:\Users\CPT-003\Desktop\CRM\crm_api\venv\Lib\site-packages\django\db\backends\utils.py", line 100, in _execute
    with self.db.wrap_database_errors:
         ^^^^^^^^^^^^^^^^^^^^^^^^^^^^
  File "C:\Users\CPT-003\Desktop\CRM\crm_api\venv\Lib\site-packages\django\db\utils.py", line 91, in __exit__
    raise dj_exc_value.with_traceback(traceback) from exc_value
  File "C:\Users\CPT-003\Desktop\CRM\crm_api\venv\Lib\site-packages\django\db\backends\utils.py", line 105, in _execute
    return self.cursor.execute(sql, params)
           ~~~~~~~~~~~~~~~~~~~^^^^^^^^^^^^^
django.db.utils.ProgrammingError: relation "job_applications_job_application" does not exist
LINE 1: ...pplications_job_application"."date_of_birth" FROM "job_appli...
                                                             ^

2025-07-23 17:34:30,799 [ERROR] django.server: "POST /api/talent-engine/video-sessions/ HTTP/1.1" 500 145
2025-07-23 17:37:18,275 [INFO] django.server: "GET /api/talent-engine-job-applications/applications/PRO-0005/ HTTP/1.1" 200 1047
2025-07-23 17:37:23,337 [INFO] django.server: "GET /api/talent-engine-job-applications/applications/PRO-0004/ HTTP/1.1" 200 1850
2025-07-23 17:37:26,689 [INFO] django.server: "GET /api/talent-engine-job-applications/applications/PRO-0005/ HTTP/1.1" 200 1047
2025-07-23 17:38:04,348 [INFO] django.server: "POST /api/talent-engine/video-sessions HTTP/1.1" 301 0
2025-07-23 17:38:04,411 [ERROR] django.request: Internal Server Error: /api/talent-engine/video-sessions/
Traceback (most recent call last):
  File "C:\Users\CPT-003\Desktop\CRM\crm_api\venv\Lib\site-packages\django\db\backends\utils.py", line 105, in _execute
    return self.cursor.execute(sql, params)
           ~~~~~~~~~~~~~~~~~~~^^^^^^^^^^^^^
psycopg2.errors.UndefinedTable: relation "job_applications_job_application" does not exist
LINE 1: ...pplications_job_application"."date_of_birth" FROM "job_appli...
                                                             ^


The above exception was the direct cause of the following exception:

Traceback (most recent call last):
  File "C:\Users\CPT-003\Desktop\CRM\crm_api\venv\Lib\site-packages\django\core\handlers\exception.py", line 55, in inner
    response = get_response(request)
  File "C:\Users\CPT-003\Desktop\CRM\crm_api\venv\Lib\site-packages\django\core\handlers\base.py", line 197, in _get_response
    response = wrapped_callback(request, *callback_args, **callback_kwargs)
  File "C:\Users\CPT-003\Desktop\CRM\crm_api\venv\Lib\site-packages\django\views\decorators\csrf.py", line 65, in _view_wrapper
    return view_func(request, *args, **kwargs)
  File "C:\Users\CPT-003\Desktop\CRM\crm_api\venv\Lib\site-packages\rest_framework\viewsets.py", line 125, in view
    return self.dispatch(request, *args, **kwargs)
           ~~~~~~~~~~~~~^^^^^^^^^^^^^^^^^^^^^^^^^^
  File "C:\Users\CPT-003\Desktop\CRM\crm_api\venv\Lib\site-packages\rest_framework\views.py", line 515, in dispatch
    response = self.handle_exception(exc)
  File "C:\Users\CPT-003\Desktop\CRM\crm_api\venv\Lib\site-packages\rest_framework\views.py", line 475, in handle_exception
    self.raise_uncaught_exception(exc)
    ~~~~~~~~~~~~~~~~~~~~~~~~~~~~~^^^^^
  File "C:\Users\CPT-003\Desktop\CRM\crm_api\venv\Lib\site-packages\rest_framework\views.py", line 486, in raise_uncaught_exception
    raise exc
  File "C:\Users\CPT-003\Desktop\CRM\crm_api\venv\Lib\site-packages\rest_framework\views.py", line 512, in dispatch
    response = handler(request, *args, **kwargs)
  File "C:\Users\CPT-003\Desktop\CRM\crm_api\venv\Lib\site-packages\rest_framework\mixins.py", line 18, in create
    serializer.is_valid(raise_exception=True)
    ~~~~~~~~~~~~~~~~~~~^^^^^^^^^^^^^^^^^^^^^^
  File "C:\Users\CPT-003\Desktop\CRM\crm_api\venv\Lib\site-packages\rest_framework\serializers.py", line 225, in is_valid
    self._validated_data = self.run_validation(self.initial_data)
                           ~~~~~~~~~~~~~~~~~~~^^^^^^^^^^^^^^^^^^^
  File "C:\Users\CPT-003\Desktop\CRM\crm_api\venv\Lib\site-packages\rest_framework\serializers.py", line 444, in run_validation
    value = self.to_internal_value(data)
  File "C:\Users\CPT-003\Desktop\CRM\crm_api\venv\Lib\site-packages\rest_framework\serializers.py", line 501, in to_internal_value
    validated_value = field.run_validation(primitive_value)
  File "C:\Users\CPT-003\Desktop\CRM\crm_api\venv\Lib\site-packages\rest_framework\relations.py", line 155, in run_validation
    return super().run_validation(data)
           ~~~~~~~~~~~~~~~~~~~~~~^^^^^^
  File "C:\Users\CPT-003\Desktop\CRM\crm_api\venv\Lib\site-packages\rest_framework\fields.py", line 538, in run_validation
    value = self.to_internal_value(data)
  File "C:\Users\CPT-003\Desktop\CRM\crm_api\venv\Lib\site-packages\rest_framework\relations.py", line 259, in to_internal_value
    return queryset.get(pk=data)
           ~~~~~~~~~~~~^^^^^^^^^
  File "C:\Users\CPT-003\Desktop\CRM\crm_api\venv\Lib\site-packages\django\db\models\query.py", line 629, in get
    num = len(clone)
  File "C:\Users\CPT-003\Desktop\CRM\crm_api\venv\Lib\site-packages\django\db\models\query.py", line 366, in __len__
    self._fetch_all()
    ~~~~~~~~~~~~~~~^^
  File "C:\Users\CPT-003\Desktop\CRM\crm_api\venv\Lib\site-packages\django\db\models\query.py", line 1949, in _fetch_all
    self._result_cache = list(self._iterable_class(self))
                         ~~~~^^^^^^^^^^^^^^^^^^^^^^^^^^^^
  File "C:\Users\CPT-003\Desktop\CRM\crm_api\venv\Lib\site-packages\django\db\models\query.py", line 91, in __iter__
    results = compiler.execute_sql(
        chunked_fetch=self.chunked_fetch, chunk_size=self.chunk_size
    )
  File "C:\Users\CPT-003\Desktop\CRM\crm_api\venv\Lib\site-packages\django\db\models\sql\compiler.py", line 1623, in execute_sql
    cursor.execute(sql, params)
    ~~~~~~~~~~~~~~^^^^^^^^^^^^^
  File "C:\Users\CPT-003\Desktop\CRM\crm_api\venv\Lib\site-packages\django\db\backends\utils.py", line 79, in execute
    return self._execute_with_wrappers(
           ~~~~~~~~~~~~~~~~~~~~~~~~~~~^
        sql, params, many=False, executor=self._execute
        ^^^^^^^^^^^^^^^^^^^^^^^^^^^^^^^^^^^^^^^^^^^^^^^
    )
    ^
  File "C:\Users\CPT-003\Desktop\CRM\crm_api\venv\Lib\site-packages\django\db\backends\utils.py", line 92, in _execute_with_wrappers
    return executor(sql, params, many, context)
  File "C:\Users\CPT-003\Desktop\CRM\crm_api\venv\Lib\site-packages\django\db\backends\utils.py", line 100, in _execute
    with self.db.wrap_database_errors:
         ^^^^^^^^^^^^^^^^^^^^^^^^^^^^
  File "C:\Users\CPT-003\Desktop\CRM\crm_api\venv\Lib\site-packages\django\db\utils.py", line 91, in __exit__
    raise dj_exc_value.with_traceback(traceback) from exc_value
  File "C:\Users\CPT-003\Desktop\CRM\crm_api\venv\Lib\site-packages\django\db\backends\utils.py", line 105, in _execute
    return self.cursor.execute(sql, params)
           ~~~~~~~~~~~~~~~~~~~^^^^^^^^^^^^^
django.db.utils.ProgrammingError: relation "job_applications_job_application" does not exist
LINE 1: ...pplications_job_application"."date_of_birth" FROM "job_appli...
                                                             ^

2025-07-23 17:38:04,419 [ERROR] django.server: "POST /api/talent-engine/video-sessions/ HTTP/1.1" 500 145
2025-07-23 17:38:12,948 [INFO] django.server: "POST /api/talent-engine/video-sessions HTTP/1.1" 301 0
2025-07-23 17:38:13,007 [ERROR] django.request: Internal Server Error: /api/talent-engine/video-sessions/
Traceback (most recent call last):
  File "C:\Users\CPT-003\Desktop\CRM\crm_api\venv\Lib\site-packages\django\db\backends\utils.py", line 105, in _execute
    return self.cursor.execute(sql, params)
           ~~~~~~~~~~~~~~~~~~~^^^^^^^^^^^^^
psycopg2.errors.UndefinedTable: relation "job_applications_job_application" does not exist
LINE 1: ...pplications_job_application"."date_of_birth" FROM "job_appli...
                                                             ^


The above exception was the direct cause of the following exception:

Traceback (most recent call last):
  File "C:\Users\CPT-003\Desktop\CRM\crm_api\venv\Lib\site-packages\django\core\handlers\exception.py", line 55, in inner
    response = get_response(request)
  File "C:\Users\CPT-003\Desktop\CRM\crm_api\venv\Lib\site-packages\django\core\handlers\base.py", line 197, in _get_response
    response = wrapped_callback(request, *callback_args, **callback_kwargs)
  File "C:\Users\CPT-003\Desktop\CRM\crm_api\venv\Lib\site-packages\django\views\decorators\csrf.py", line 65, in _view_wrapper
    return view_func(request, *args, **kwargs)
  File "C:\Users\CPT-003\Desktop\CRM\crm_api\venv\Lib\site-packages\rest_framework\viewsets.py", line 125, in view
    return self.dispatch(request, *args, **kwargs)
           ~~~~~~~~~~~~~^^^^^^^^^^^^^^^^^^^^^^^^^^
  File "C:\Users\CPT-003\Desktop\CRM\crm_api\venv\Lib\site-packages\rest_framework\views.py", line 515, in dispatch
    response = self.handle_exception(exc)
  File "C:\Users\CPT-003\Desktop\CRM\crm_api\venv\Lib\site-packages\rest_framework\views.py", line 475, in handle_exception
    self.raise_uncaught_exception(exc)
    ~~~~~~~~~~~~~~~~~~~~~~~~~~~~~^^^^^
  File "C:\Users\CPT-003\Desktop\CRM\crm_api\venv\Lib\site-packages\rest_framework\views.py", line 486, in raise_uncaught_exception
    raise exc
  File "C:\Users\CPT-003\Desktop\CRM\crm_api\venv\Lib\site-packages\rest_framework\views.py", line 512, in dispatch
    response = handler(request, *args, **kwargs)
  File "C:\Users\CPT-003\Desktop\CRM\crm_api\venv\Lib\site-packages\rest_framework\mixins.py", line 18, in create
    serializer.is_valid(raise_exception=True)
    ~~~~~~~~~~~~~~~~~~~^^^^^^^^^^^^^^^^^^^^^^
  File "C:\Users\CPT-003\Desktop\CRM\crm_api\venv\Lib\site-packages\rest_framework\serializers.py", line 225, in is_valid
    self._validated_data = self.run_validation(self.initial_data)
                           ~~~~~~~~~~~~~~~~~~~^^^^^^^^^^^^^^^^^^^
  File "C:\Users\CPT-003\Desktop\CRM\crm_api\venv\Lib\site-packages\rest_framework\serializers.py", line 444, in run_validation
    value = self.to_internal_value(data)
  File "C:\Users\CPT-003\Desktop\CRM\crm_api\venv\Lib\site-packages\rest_framework\serializers.py", line 501, in to_internal_value
    validated_value = field.run_validation(primitive_value)
  File "C:\Users\CPT-003\Desktop\CRM\crm_api\venv\Lib\site-packages\rest_framework\relations.py", line 155, in run_validation
    return super().run_validation(data)
           ~~~~~~~~~~~~~~~~~~~~~~^^^^^^
  File "C:\Users\CPT-003\Desktop\CRM\crm_api\venv\Lib\site-packages\rest_framework\fields.py", line 538, in run_validation
    value = self.to_internal_value(data)
  File "C:\Users\CPT-003\Desktop\CRM\crm_api\venv\Lib\site-packages\rest_framework\relations.py", line 259, in to_internal_value
    return queryset.get(pk=data)
           ~~~~~~~~~~~~^^^^^^^^^
  File "C:\Users\CPT-003\Desktop\CRM\crm_api\venv\Lib\site-packages\django\db\models\query.py", line 629, in get
    num = len(clone)
  File "C:\Users\CPT-003\Desktop\CRM\crm_api\venv\Lib\site-packages\django\db\models\query.py", line 366, in __len__
    self._fetch_all()
    ~~~~~~~~~~~~~~~^^
  File "C:\Users\CPT-003\Desktop\CRM\crm_api\venv\Lib\site-packages\django\db\models\query.py", line 1949, in _fetch_all
    self._result_cache = list(self._iterable_class(self))
                         ~~~~^^^^^^^^^^^^^^^^^^^^^^^^^^^^
  File "C:\Users\CPT-003\Desktop\CRM\crm_api\venv\Lib\site-packages\django\db\models\query.py", line 91, in __iter__
    results = compiler.execute_sql(
        chunked_fetch=self.chunked_fetch, chunk_size=self.chunk_size
    )
  File "C:\Users\CPT-003\Desktop\CRM\crm_api\venv\Lib\site-packages\django\db\models\sql\compiler.py", line 1623, in execute_sql
    cursor.execute(sql, params)
    ~~~~~~~~~~~~~~^^^^^^^^^^^^^
  File "C:\Users\CPT-003\Desktop\CRM\crm_api\venv\Lib\site-packages\django\db\backends\utils.py", line 79, in execute
    return self._execute_with_wrappers(
           ~~~~~~~~~~~~~~~~~~~~~~~~~~~^
        sql, params, many=False, executor=self._execute
        ^^^^^^^^^^^^^^^^^^^^^^^^^^^^^^^^^^^^^^^^^^^^^^^
    )
    ^
  File "C:\Users\CPT-003\Desktop\CRM\crm_api\venv\Lib\site-packages\django\db\backends\utils.py", line 92, in _execute_with_wrappers
    return executor(sql, params, many, context)
  File "C:\Users\CPT-003\Desktop\CRM\crm_api\venv\Lib\site-packages\django\db\backends\utils.py", line 100, in _execute
    with self.db.wrap_database_errors:
         ^^^^^^^^^^^^^^^^^^^^^^^^^^^^
  File "C:\Users\CPT-003\Desktop\CRM\crm_api\venv\Lib\site-packages\django\db\utils.py", line 91, in __exit__
    raise dj_exc_value.with_traceback(traceback) from exc_value
  File "C:\Users\CPT-003\Desktop\CRM\crm_api\venv\Lib\site-packages\django\db\backends\utils.py", line 105, in _execute
    return self.cursor.execute(sql, params)
           ~~~~~~~~~~~~~~~~~~~^^^^^^^^^^^^^
django.db.utils.ProgrammingError: relation "job_applications_job_application" does not exist
LINE 1: ...pplications_job_application"."date_of_birth" FROM "job_appli...
                                                             ^

2025-07-23 17:38:13,012 [ERROR] django.server: "POST /api/talent-engine/video-sessions/ HTTP/1.1" 500 145
2025-07-23 17:39:28,496 [INFO] django.utils.autoreload: C:\Users\CPT-003\Desktop\CRM\crm_api\job_application\serializers.py changed, reloading.
2025-07-23 17:39:32,780 [INFO] django.utils.autoreload: Watching for file changes with StatReloader
2025-07-23 17:39:59,073 [INFO] django.utils.autoreload: Watching for file changes with StatReloader
2025-07-23 17:40:10,107 [INFO] django.server: "POST /api/talent-engine/video-sessions HTTP/1.1" 301 0
2025-07-23 17:40:10,193 [ERROR] django.request: Internal Server Error: /api/talent-engine/video-sessions/
Traceback (most recent call last):
  File "C:\Users\CPT-003\Desktop\CRM\crm_api\venv\Lib\site-packages\django\db\backends\utils.py", line 105, in _execute
    return self.cursor.execute(sql, params)
           ~~~~~~~~~~~~~~~~~~~^^^^^^^^^^^^^
psycopg2.errors.UndefinedTable: relation "job_applications_job_application" does not exist
LINE 1: ...pplications_job_application"."date_of_birth" FROM "job_appli...
                                                             ^


The above exception was the direct cause of the following exception:

Traceback (most recent call last):
  File "C:\Users\CPT-003\Desktop\CRM\crm_api\venv\Lib\site-packages\django\core\handlers\exception.py", line 55, in inner
    response = get_response(request)
  File "C:\Users\CPT-003\Desktop\CRM\crm_api\venv\Lib\site-packages\django\core\handlers\base.py", line 197, in _get_response
    response = wrapped_callback(request, *callback_args, **callback_kwargs)
  File "C:\Users\CPT-003\Desktop\CRM\crm_api\venv\Lib\site-packages\django\views\decorators\csrf.py", line 65, in _view_wrapper
    return view_func(request, *args, **kwargs)
  File "C:\Users\CPT-003\Desktop\CRM\crm_api\venv\Lib\site-packages\rest_framework\viewsets.py", line 125, in view
    return self.dispatch(request, *args, **kwargs)
           ~~~~~~~~~~~~~^^^^^^^^^^^^^^^^^^^^^^^^^^
  File "C:\Users\CPT-003\Desktop\CRM\crm_api\venv\Lib\site-packages\rest_framework\views.py", line 515, in dispatch
    response = self.handle_exception(exc)
  File "C:\Users\CPT-003\Desktop\CRM\crm_api\venv\Lib\site-packages\rest_framework\views.py", line 475, in handle_exception
    self.raise_uncaught_exception(exc)
    ~~~~~~~~~~~~~~~~~~~~~~~~~~~~~^^^^^
  File "C:\Users\CPT-003\Desktop\CRM\crm_api\venv\Lib\site-packages\rest_framework\views.py", line 486, in raise_uncaught_exception
    raise exc
  File "C:\Users\CPT-003\Desktop\CRM\crm_api\venv\Lib\site-packages\rest_framework\views.py", line 512, in dispatch
    response = handler(request, *args, **kwargs)
  File "C:\Users\CPT-003\Desktop\CRM\crm_api\venv\Lib\site-packages\rest_framework\mixins.py", line 18, in create
    serializer.is_valid(raise_exception=True)
    ~~~~~~~~~~~~~~~~~~~^^^^^^^^^^^^^^^^^^^^^^
  File "C:\Users\CPT-003\Desktop\CRM\crm_api\venv\Lib\site-packages\rest_framework\serializers.py", line 225, in is_valid
    self._validated_data = self.run_validation(self.initial_data)
                           ~~~~~~~~~~~~~~~~~~~^^^^^^^^^^^^^^^^^^^
  File "C:\Users\CPT-003\Desktop\CRM\crm_api\venv\Lib\site-packages\rest_framework\serializers.py", line 444, in run_validation
    value = self.to_internal_value(data)
  File "C:\Users\CPT-003\Desktop\CRM\crm_api\venv\Lib\site-packages\rest_framework\serializers.py", line 501, in to_internal_value
    validated_value = field.run_validation(primitive_value)
  File "C:\Users\CPT-003\Desktop\CRM\crm_api\venv\Lib\site-packages\rest_framework\relations.py", line 155, in run_validation
    return super().run_validation(data)
           ~~~~~~~~~~~~~~~~~~~~~~^^^^^^
  File "C:\Users\CPT-003\Desktop\CRM\crm_api\venv\Lib\site-packages\rest_framework\fields.py", line 538, in run_validation
    value = self.to_internal_value(data)
  File "C:\Users\CPT-003\Desktop\CRM\crm_api\venv\Lib\site-packages\rest_framework\relations.py", line 259, in to_internal_value
    return queryset.get(pk=data)
           ~~~~~~~~~~~~^^^^^^^^^
  File "C:\Users\CPT-003\Desktop\CRM\crm_api\venv\Lib\site-packages\django\db\models\query.py", line 629, in get
    num = len(clone)
  File "C:\Users\CPT-003\Desktop\CRM\crm_api\venv\Lib\site-packages\django\db\models\query.py", line 366, in __len__
    self._fetch_all()
    ~~~~~~~~~~~~~~~^^
  File "C:\Users\CPT-003\Desktop\CRM\crm_api\venv\Lib\site-packages\django\db\models\query.py", line 1949, in _fetch_all
    self._result_cache = list(self._iterable_class(self))
                         ~~~~^^^^^^^^^^^^^^^^^^^^^^^^^^^^
  File "C:\Users\CPT-003\Desktop\CRM\crm_api\venv\Lib\site-packages\django\db\models\query.py", line 91, in __iter__
    results = compiler.execute_sql(
        chunked_fetch=self.chunked_fetch, chunk_size=self.chunk_size
    )
  File "C:\Users\CPT-003\Desktop\CRM\crm_api\venv\Lib\site-packages\django\db\models\sql\compiler.py", line 1623, in execute_sql
    cursor.execute(sql, params)
    ~~~~~~~~~~~~~~^^^^^^^^^^^^^
  File "C:\Users\CPT-003\Desktop\CRM\crm_api\venv\Lib\site-packages\django\db\backends\utils.py", line 79, in execute
    return self._execute_with_wrappers(
           ~~~~~~~~~~~~~~~~~~~~~~~~~~~^
        sql, params, many=False, executor=self._execute
        ^^^^^^^^^^^^^^^^^^^^^^^^^^^^^^^^^^^^^^^^^^^^^^^
    )
    ^
  File "C:\Users\CPT-003\Desktop\CRM\crm_api\venv\Lib\site-packages\django\db\backends\utils.py", line 92, in _execute_with_wrappers
    return executor(sql, params, many, context)
  File "C:\Users\CPT-003\Desktop\CRM\crm_api\venv\Lib\site-packages\django\db\backends\utils.py", line 100, in _execute
    with self.db.wrap_database_errors:
         ^^^^^^^^^^^^^^^^^^^^^^^^^^^^
  File "C:\Users\CPT-003\Desktop\CRM\crm_api\venv\Lib\site-packages\django\db\utils.py", line 91, in __exit__
    raise dj_exc_value.with_traceback(traceback) from exc_value
  File "C:\Users\CPT-003\Desktop\CRM\crm_api\venv\Lib\site-packages\django\db\backends\utils.py", line 105, in _execute
    return self.cursor.execute(sql, params)
           ~~~~~~~~~~~~~~~~~~~^^^^^^^^^^^^^
django.db.utils.ProgrammingError: relation "job_applications_job_application" does not exist
LINE 1: ...pplications_job_application"."date_of_birth" FROM "job_appli...
                                                             ^

2025-07-23 17:40:10,204 [ERROR] django.server: "POST /api/talent-engine/video-sessions/ HTTP/1.1" 500 145
2025-07-23 17:40:25,336 [INFO] django.utils.autoreload: C:\Users\CPT-003\Desktop\CRM\crm_api\job_application\serializers.py changed, reloading.
2025-07-23 17:40:29,286 [INFO] django.utils.autoreload: Watching for file changes with StatReloader
2025-07-23 17:46:13,474 [INFO] django.utils.autoreload: C:\Users\CPT-003\Desktop\CRM\crm_api\talent_engine\views.py changed, reloading.
2025-07-23 17:46:19,253 [INFO] django.utils.autoreload: Watching for file changes with StatReloader
2025-07-23 17:48:10,465 [INFO] django.server: "POST /api/talent-engine/video-sessions HTTP/1.1" 301 0
2025-07-23 17:48:10,533 [ERROR] django.request: Internal Server Error: /api/talent-engine/video-sessions/
Traceback (most recent call last):
  File "C:\Users\CPT-003\Desktop\CRM\crm_api\venv\Lib\site-packages\django\db\backends\utils.py", line 105, in _execute
    return self.cursor.execute(sql, params)
           ~~~~~~~~~~~~~~~~~~~^^^^^^^^^^^^^
psycopg2.errors.UndefinedTable: relation "job_applications_job_application" does not exist
LINE 1: ...pplications_job_application"."date_of_birth" FROM "job_appli...
                                                             ^


The above exception was the direct cause of the following exception:

Traceback (most recent call last):
  File "C:\Users\CPT-003\Desktop\CRM\crm_api\venv\Lib\site-packages\django\core\handlers\exception.py", line 55, in inner
    response = get_response(request)
  File "C:\Users\CPT-003\Desktop\CRM\crm_api\venv\Lib\site-packages\django\core\handlers\base.py", line 197, in _get_response
    response = wrapped_callback(request, *callback_args, **callback_kwargs)
  File "C:\Users\CPT-003\Desktop\CRM\crm_api\venv\Lib\site-packages\django\views\decorators\csrf.py", line 65, in _view_wrapper
    return view_func(request, *args, **kwargs)
  File "C:\Users\CPT-003\Desktop\CRM\crm_api\venv\Lib\site-packages\rest_framework\viewsets.py", line 125, in view
    return self.dispatch(request, *args, **kwargs)
           ~~~~~~~~~~~~~^^^^^^^^^^^^^^^^^^^^^^^^^^
  File "C:\Users\CPT-003\Desktop\CRM\crm_api\venv\Lib\site-packages\rest_framework\views.py", line 515, in dispatch
    response = self.handle_exception(exc)
  File "C:\Users\CPT-003\Desktop\CRM\crm_api\venv\Lib\site-packages\rest_framework\views.py", line 475, in handle_exception
    self.raise_uncaught_exception(exc)
    ~~~~~~~~~~~~~~~~~~~~~~~~~~~~~^^^^^
  File "C:\Users\CPT-003\Desktop\CRM\crm_api\venv\Lib\site-packages\rest_framework\views.py", line 486, in raise_uncaught_exception
    raise exc
  File "C:\Users\CPT-003\Desktop\CRM\crm_api\venv\Lib\site-packages\rest_framework\views.py", line 512, in dispatch
    response = handler(request, *args, **kwargs)
  File "C:\Users\CPT-003\Desktop\CRM\crm_api\venv\Lib\site-packages\rest_framework\mixins.py", line 18, in create
    serializer.is_valid(raise_exception=True)
    ~~~~~~~~~~~~~~~~~~~^^^^^^^^^^^^^^^^^^^^^^
  File "C:\Users\CPT-003\Desktop\CRM\crm_api\venv\Lib\site-packages\rest_framework\serializers.py", line 225, in is_valid
    self._validated_data = self.run_validation(self.initial_data)
                           ~~~~~~~~~~~~~~~~~~~^^^^^^^^^^^^^^^^^^^
  File "C:\Users\CPT-003\Desktop\CRM\crm_api\venv\Lib\site-packages\rest_framework\serializers.py", line 444, in run_validation
    value = self.to_internal_value(data)
  File "C:\Users\CPT-003\Desktop\CRM\crm_api\venv\Lib\site-packages\rest_framework\serializers.py", line 501, in to_internal_value
    validated_value = field.run_validation(primitive_value)
  File "C:\Users\CPT-003\Desktop\CRM\crm_api\venv\Lib\site-packages\rest_framework\relations.py", line 155, in run_validation
    return super().run_validation(data)
           ~~~~~~~~~~~~~~~~~~~~~~^^^^^^
  File "C:\Users\CPT-003\Desktop\CRM\crm_api\venv\Lib\site-packages\rest_framework\fields.py", line 538, in run_validation
    value = self.to_internal_value(data)
  File "C:\Users\CPT-003\Desktop\CRM\crm_api\venv\Lib\site-packages\rest_framework\relations.py", line 259, in to_internal_value
    return queryset.get(pk=data)
           ~~~~~~~~~~~~^^^^^^^^^
  File "C:\Users\CPT-003\Desktop\CRM\crm_api\venv\Lib\site-packages\django\db\models\query.py", line 629, in get
    num = len(clone)
  File "C:\Users\CPT-003\Desktop\CRM\crm_api\venv\Lib\site-packages\django\db\models\query.py", line 366, in __len__
    self._fetch_all()
    ~~~~~~~~~~~~~~~^^
  File "C:\Users\CPT-003\Desktop\CRM\crm_api\venv\Lib\site-packages\django\db\models\query.py", line 1949, in _fetch_all
    self._result_cache = list(self._iterable_class(self))
                         ~~~~^^^^^^^^^^^^^^^^^^^^^^^^^^^^
  File "C:\Users\CPT-003\Desktop\CRM\crm_api\venv\Lib\site-packages\django\db\models\query.py", line 91, in __iter__
    results = compiler.execute_sql(
        chunked_fetch=self.chunked_fetch, chunk_size=self.chunk_size
    )
  File "C:\Users\CPT-003\Desktop\CRM\crm_api\venv\Lib\site-packages\django\db\models\sql\compiler.py", line 1623, in execute_sql
    cursor.execute(sql, params)
    ~~~~~~~~~~~~~~^^^^^^^^^^^^^
  File "C:\Users\CPT-003\Desktop\CRM\crm_api\venv\Lib\site-packages\django\db\backends\utils.py", line 79, in execute
    return self._execute_with_wrappers(
           ~~~~~~~~~~~~~~~~~~~~~~~~~~~^
        sql, params, many=False, executor=self._execute
        ^^^^^^^^^^^^^^^^^^^^^^^^^^^^^^^^^^^^^^^^^^^^^^^
    )
    ^
  File "C:\Users\CPT-003\Desktop\CRM\crm_api\venv\Lib\site-packages\django\db\backends\utils.py", line 92, in _execute_with_wrappers
    return executor(sql, params, many, context)
  File "C:\Users\CPT-003\Desktop\CRM\crm_api\venv\Lib\site-packages\django\db\backends\utils.py", line 100, in _execute
    with self.db.wrap_database_errors:
         ^^^^^^^^^^^^^^^^^^^^^^^^^^^^
  File "C:\Users\CPT-003\Desktop\CRM\crm_api\venv\Lib\site-packages\django\db\utils.py", line 91, in __exit__
    raise dj_exc_value.with_traceback(traceback) from exc_value
  File "C:\Users\CPT-003\Desktop\CRM\crm_api\venv\Lib\site-packages\django\db\backends\utils.py", line 105, in _execute
    return self.cursor.execute(sql, params)
           ~~~~~~~~~~~~~~~~~~~^^^^^^^^^^^^^
django.db.utils.ProgrammingError: relation "job_applications_job_application" does not exist
LINE 1: ...pplications_job_application"."date_of_birth" FROM "job_appli...
                                                             ^

2025-07-23 17:48:10,542 [ERROR] django.server: "POST /api/talent-engine/video-sessions/ HTTP/1.1" 500 145
2025-07-23 17:48:17,875 [INFO] django.server: "GET /api/talent-engine/video-sessions HTTP/1.1" 301 0
2025-07-23 17:48:17,943 [INFO] django.server: "GET /api/talent-engine/video-sessions/ HTTP/1.1" 200 2
2025-07-23 21:01:45,036 [INFO] django.utils.autoreload: Watching for file changes with StatReloader
2025-07-23 21:03:33,320 [INFO] django.utils.autoreload: Watching for file changes with StatReloader
2025-07-23 21:04:08,104 [INFO] django.server: "OPTIONS /api/token/validate/ HTTP/1.1" 200 0
2025-07-23 21:04:08,118 [INFO] django.server: "OPTIONS /api/token/validate/ HTTP/1.1" 200 0
2025-07-23 21:04:11,644 [WARNING] django.request: Unauthorized: /api/token/validate/
2025-07-23 21:04:11,646 [WARNING] django.server: "GET /api/token/validate/ HTTP/1.1" 401 183
2025-07-23 21:04:15,109 [WARNING] django.request: Unauthorized: /api/token/validate/
2025-07-23 21:04:15,110 [WARNING] django.server: "GET /api/token/validate/ HTTP/1.1" 401 183
2025-07-23 21:06:21,452 [INFO] django.server: "OPTIONS /api/token/ HTTP/1.1" 200 0
2025-07-23 21:06:32,136 [INFO] django.server: "POST /api/token/ HTTP/1.1" 200 964
2025-07-23 21:06:37,446 [INFO] django.server: "GET /api/token/validate/ HTTP/1.1" 200 388
2025-07-23 21:06:37,823 [INFO] django.server: "OPTIONS /api/user/tenant-users/ HTTP/1.1" 200 0
2025-07-23 21:06:37,830 [INFO] django.server: "OPTIONS /api/user/tenant-users/ HTTP/1.1" 200 0
2025-07-23 21:06:41,153 [INFO] django.server: "OPTIONS /api/talent-engine/requisitions/ HTTP/1.1" 200 0
2025-07-23 21:06:41,156 [INFO] django.server: "OPTIONS /api/talent-engine/requisitions/ HTTP/1.1" 200 0
2025-07-23 21:06:43,993 [INFO] django.server: "GET /api/token/validate/ HTTP/1.1" 200 388
2025-07-23 21:06:44,738 [INFO] users: Retrieved 5 users for tenant proliance
2025-07-23 21:06:54,718 [INFO] django.server: "GET /api/user/tenant-users/ HTTP/1.1" 200 1674
2025-07-23 21:06:58,026 [INFO] django.server: "GET /api/talent-engine/requisitions/ HTTP/1.1" 200 6589
2025-07-23 21:06:59,767 [INFO] users: Retrieved 5 users for tenant proliance
2025-07-23 21:07:14,747 [INFO] django.server: "GET /api/user/tenant-users/ HTTP/1.1" 200 1674
2025-07-23 21:07:20,865 [INFO] django.server: "GET /api/talent-engine/requisitions/ HTTP/1.1" 200 6589
2025-07-23 21:10:30,646 [INFO] django.server: "OPTIONS /api/talent-engine-job-applications/published-requisitions-with-shortlisted/ HTTP/1.1" 200 0
2025-07-23 21:10:30,657 [INFO] django.server: "OPTIONS /api/tenant/config/?t=1753301430611 HTTP/1.1" 200 0
2025-07-23 21:10:30,657 [INFO] django.server: "OPTIONS /api/talent-engine-job-applications/published-requisitions-with-shortlisted/ HTTP/1.1" 200 0
2025-07-23 21:10:30,664 [INFO] django.server: "OPTIONS /api/tenant/config/?t=1753301430612 HTTP/1.1" 200 0
2025-07-23 21:10:36,547 [INFO] core: Fetched TenantConfig for tenant proliance
2025-07-23 21:10:36,555 [INFO] django.server: "GET /api/tenant/config/?t=1753301430612 HTTP/1.1" 200 1453
2025-07-23 21:10:36,863 [INFO] core: Fetched TenantConfig for tenant proliance
2025-07-23 21:10:36,865 [INFO] django.server: "GET /api/tenant/config/?t=1753301430611 HTTP/1.1" 200 1453
2025-07-23 21:10:40,140 [INFO] django.server: "GET /api/talent-engine-job-applications/published-requisitions-with-shortlisted/ HTTP/1.1" 200 1533
2025-07-23 21:10:49,045 [INFO] django.server: "GET /api/talent-engine-job-applications/published-requisitions-with-shortlisted/ HTTP/1.1" 200 1533
2025-07-23 21:10:51,913 [INFO] django.server: "GET /api/talent-engine/requisitions/ HTTP/1.1" 200 6589
2025-07-23 21:11:02,040 [INFO] django.server: "OPTIONS /api/talent-engine-job-applications/applications/job-requisitions/PRO-0024/applications/ HTTP/1.1" 200 0
2025-07-23 21:11:02,041 [INFO] django.server: "OPTIONS /api/talent-engine-job-applications/applications/job-requisitions/PRO-0024/applications/ HTTP/1.1" 200 0
2025-07-23 21:11:08,607 [INFO] django.server: "GET /api/talent-engine/requisitions/ HTTP/1.1" 200 6589
2025-07-23 21:11:08,913 [INFO] django.server: "GET /api/talent-engine-job-applications/applications/job-requisitions/PRO-0024/applications/ HTTP/1.1" 200 1010
2025-07-23 21:11:16,187 [INFO] django.server: "GET /api/talent-engine-job-applications/applications/job-requisitions/PRO-0024/applications/ HTTP/1.1" 200 1010
2025-07-23 21:11:27,449 [INFO] django.server: "GET /api/talent-engine/requisitions/ HTTP/1.1" 200 6589
2025-07-23 21:11:42,910 [INFO] django.server: "GET /api/talent-engine/requisitions/ HTTP/1.1" 200 6589
2025-07-23 21:11:54,895 [INFO] django.server: "GET /api/talent-engine/requisitions/ HTTP/1.1" 200 6589
2025-07-23 21:11:54,896 [INFO] django.server: "GET /api/talent-engine/requisitions/ HTTP/1.1" 200 6589
2025-07-23 21:12:09,148 [INFO] django.server: "GET /api/talent-engine-job-applications/applications/job-requisitions/PRO-0024/applications/ HTTP/1.1" 200 1010
2025-07-23 21:12:16,591 [INFO] django.server: "GET /api/talent-engine-job-applications/applications/job-requisitions/PRO-0024/applications/ HTTP/1.1" 200 1010
2025-07-23 21:12:39,742 [INFO] django.server: "GET /api/talent-engine/requisitions/ HTTP/1.1" 200 6589
2025-07-23 21:12:54,590 [INFO] django.server: "GET /api/talent-engine/requisitions/ HTTP/1.1" 200 6589
2025-07-23 21:13:30,838 [INFO] django.server: "GET /api/talent-engine/requisitions/ HTTP/1.1" 200 6589
2025-07-23 21:14:19,990 [INFO] django.server: "GET /api/talent-engine/requisitions/ HTTP/1.1" 200 6589
2025-07-23 21:15:11,805 [INFO] django.server: "GET /api/talent-engine/requisitions/ HTTP/1.1" 200 6589
2025-07-23 21:15:56,192 [INFO] django.server: "OPTIONS /api/talent-engine/requisitions/deleted/soft_deleted/ HTTP/1.1" 200 0
2025-07-23 21:15:56,192 [INFO] django.server: "OPTIONS /api/talent-engine/requisitions/deleted/soft_deleted/ HTTP/1.1" 200 0
2025-07-23 21:16:00,550 [INFO] django.server: "GET /api/talent-engine/requisitions/ HTTP/1.1" 200 6589
2025-07-23 21:16:01,577 [INFO] talent_engine: Retrieved 20 soft-deleted job requisitions for tenant proliance
2025-07-23 21:16:21,944 [INFO] talent_engine: Retrieved 20 soft-deleted job requisitions for tenant proliance
2025-07-23 21:16:46,732 [INFO] django.server: "GET /api/talent-engine/requisitions/deleted/soft_deleted/ HTTP/1.1" 200 24503
2025-07-23 21:16:59,490 [INFO] django.server: "OPTIONS /api/talent-engine-job-applications/applications/deleted/soft_deleted/ HTTP/1.1" 200 0
2025-07-23 21:17:06,394 [INFO] django.server: "GET /api/talent-engine-job-applications/applications/deleted/soft_deleted/ HTTP/1.1" 200 63
2025-07-23 21:17:07,311 [INFO] django.server: "GET /api/talent-engine/requisitions/deleted/soft_deleted/ HTTP/1.1" 200 24503
2025-07-23 21:17:29,075 [INFO] django.server: "OPTIONS /api/talent-engine-job-applications/applications/recover/application/ HTTP/1.1" 200 0
2025-07-23 21:17:34,855 [WARNING] django.request: Not Found: /api/talent-engine-job-applications/applications/recover/application/
2025-07-23 21:17:34,856 [WARNING] django.server: "POST /api/talent-engine-job-applications/applications/recover/application/ HTTP/1.1" 404 48
2025-07-23 21:17:42,499 [INFO] django.server: "OPTIONS /api/talent-engine-job-applications/applications/permanent-delete/application/ HTTP/1.1" 200 0
2025-07-23 21:17:49,193 [WARNING] django.request: Not Found: /api/talent-engine-job-applications/applications/permanent-delete/application/
2025-07-23 21:17:49,196 [WARNING] django.server: "POST /api/talent-engine-job-applications/applications/permanent-delete/application/ HTTP/1.1" 404 48
2025-07-23 21:18:10,491 [WARNING] django.request: Not Found: /api/talent-engine-job-applications/applications/permanent-delete/application/
2025-07-23 21:18:10,492 [WARNING] django.server: "POST /api/talent-engine-job-applications/applications/permanent-delete/application/ HTTP/1.1" 404 48
2025-07-23 21:18:19,651 [INFO] django.server: "OPTIONS /api/talent-engine-job-applications/schedules/deleted/soft_deleted/ HTTP/1.1" 200 0
2025-07-23 21:18:27,184 [INFO] django.server: "GET /api/talent-engine-job-applications/schedules/deleted/soft_deleted/ HTTP/1.1" 200 60
2025-07-23 21:18:37,902 [INFO] django.server: "OPTIONS /api/tenant/config/?t=1753301917871 HTTP/1.1" 200 0
2025-07-23 21:18:37,904 [INFO] django.server: "OPTIONS /api/tenant/config/?t=1753301917868 HTTP/1.1" 200 0
2025-07-23 21:18:43,815 [INFO] core: Fetched TenantConfig for tenant proliance
2025-07-23 21:18:43,821 [INFO] django.server: "GET /api/tenant/config/?t=1753301917868 HTTP/1.1" 200 1453
2025-07-23 21:18:44,183 [INFO] core: Fetched TenantConfig for tenant proliance
2025-07-23 21:18:44,188 [INFO] django.server: "GET /api/tenant/config/?t=1753301917871 HTTP/1.1" 200 1453
2025-07-23 21:18:47,048 [INFO] django.server: "GET /api/talent-engine-job-applications/published-requisitions-with-shortlisted/ HTTP/1.1" 200 1533
2025-07-23 21:18:57,698 [INFO] django.server: "GET /api/talent-engine-job-applications/published-requisitions-with-shortlisted/ HTTP/1.1" 200 1533
2025-07-23 21:24:47,317 [INFO] django.server: "OPTIONS /api/tenant/config/?t=1753302287226 HTTP/1.1" 200 0
2025-07-23 21:24:56,532 [INFO] core: Fetched TenantConfig for tenant proliance
2025-07-23 21:24:56,535 [INFO] django.server: "GET /api/tenant/config/?t=1753302287226 HTTP/1.1" 200 1453
2025-07-23 21:24:59,990 [INFO] django.server: "GET /api/talent-engine-job-applications/published-requisitions-with-shortlisted/ HTTP/1.1" 200 1533
2025-07-23 21:25:32,555 [INFO] django.server: "GET /api/talent-engine/requisitions/ HTTP/1.1" 200 6589
2025-07-23 21:25:47,716 [INFO] django.server: "GET /api/talent-engine/requisitions/ HTTP/1.1" 200 6589
2025-07-23 21:25:54,167 [INFO] django.server: "GET /api/talent-engine/requisitions/ HTTP/1.1" 200 6589
2025-07-23 21:25:54,168 [INFO] django.server: "GET /api/talent-engine/requisitions/ HTTP/1.1" 200 6589
2025-07-23 21:26:27,236 [INFO] django.server: "GET /api/talent-engine/requisitions/ HTTP/1.1" 200 6589
2025-07-23 21:46:39,001 [ERROR] django.request: Internal Server Error: /api/talent-engine/requisitions/
Traceback (most recent call last):
  File "C:\Users\CPT-003\Desktop\CRM\crm_api\venv\Lib\site-packages\django\db\backends\base\base.py", line 279, in ensure_connection
    self.connect()
    ~~~~~~~~~~~~^^
  File "C:\Users\CPT-003\Desktop\CRM\crm_api\venv\Lib\site-packages\django\utils\asyncio.py", line 26, in inner
    return func(*args, **kwargs)
  File "C:\Users\CPT-003\Desktop\CRM\crm_api\venv\Lib\site-packages\django\db\backends\base\base.py", line 256, in connect
    self.connection = self.get_new_connection(conn_params)
                      ~~~~~~~~~~~~~~~~~~~~~~~^^^^^^^^^^^^^
  File "C:\Users\CPT-003\Desktop\CRM\crm_api\venv\Lib\site-packages\django\utils\asyncio.py", line 26, in inner
    return func(*args, **kwargs)
  File "C:\Users\CPT-003\Desktop\CRM\crm_api\venv\Lib\site-packages\django\db\backends\postgresql\base.py", line 332, in get_new_connection
    connection = self.Database.connect(**conn_params)
  File "C:\Users\CPT-003\Desktop\CRM\crm_api\venv\Lib\site-packages\psycopg2\__init__.py", line 135, in connect
    conn = _connect(dsn, connection_factory=connection_factory, **kwasync)
psycopg2.OperationalError: could not translate host name "dpg-d208jbje5dus73d4h87g-a.oregon-postgres.render.com" to address: Name or service not known


The above exception was the direct cause of the following exception:

Traceback (most recent call last):
  File "C:\Users\CPT-003\Desktop\CRM\crm_api\venv\Lib\site-packages\django\core\handlers\exception.py", line 55, in inner
    response = get_response(request)
  File "C:\Users\CPT-003\Desktop\CRM\crm_api\venv\Lib\site-packages\django\utils\deprecation.py", line 119, in __call__
    response = self.process_request(request)
  File "C:\Users\CPT-003\Desktop\CRM\crm_api\lumina_care\middleware.py", line 262, in process_request
    domain = Domain.objects.filter(domain=hostname).first()
  File "C:\Users\CPT-003\Desktop\CRM\crm_api\venv\Lib\site-packages\django\db\models\query.py", line 1104, in first
    for obj in queryset[:1]:
               ~~~~~~~~^^^^
  File "C:\Users\CPT-003\Desktop\CRM\crm_api\venv\Lib\site-packages\django\db\models\query.py", line 384, in __iter__
    self._fetch_all()
    ~~~~~~~~~~~~~~~^^
  File "C:\Users\CPT-003\Desktop\CRM\crm_api\venv\Lib\site-packages\django\db\models\query.py", line 1949, in _fetch_all
    self._result_cache = list(self._iterable_class(self))
                         ~~~~^^^^^^^^^^^^^^^^^^^^^^^^^^^^
  File "C:\Users\CPT-003\Desktop\CRM\crm_api\venv\Lib\site-packages\django\db\models\query.py", line 91, in __iter__
    results = compiler.execute_sql(
        chunked_fetch=self.chunked_fetch, chunk_size=self.chunk_size
    )
  File "C:\Users\CPT-003\Desktop\CRM\crm_api\venv\Lib\site-packages\django\db\models\sql\compiler.py", line 1621, in execute_sql
    cursor = self.connection.cursor()
  File "C:\Users\CPT-003\Desktop\CRM\crm_api\venv\Lib\site-packages\django\utils\asyncio.py", line 26, in inner
    return func(*args, **kwargs)
  File "C:\Users\CPT-003\Desktop\CRM\crm_api\venv\Lib\site-packages\django\db\backends\base\base.py", line 320, in cursor
    return self._cursor()
           ~~~~~~~~~~~~^^
  File "C:\Users\CPT-003\Desktop\CRM\crm_api\venv\Lib\site-packages\django_tenants\postgresql_backend\base.py", line 144, in _cursor
    cursor = super()._cursor()
  File "C:\Users\CPT-003\Desktop\CRM\crm_api\venv\Lib\site-packages\django\db\backends\base\base.py", line 296, in _cursor
    self.ensure_connection()
    ~~~~~~~~~~~~~~~~~~~~~~^^
  File "C:\Users\CPT-003\Desktop\CRM\crm_api\venv\Lib\site-packages\django\utils\asyncio.py", line 26, in inner
    return func(*args, **kwargs)
  File "C:\Users\CPT-003\Desktop\CRM\crm_api\venv\Lib\site-packages\django\db\backends\base\base.py", line 278, in ensure_connection
    with self.wrap_database_errors:
         ^^^^^^^^^^^^^^^^^^^^^^^^^
  File "C:\Users\CPT-003\Desktop\CRM\crm_api\venv\Lib\site-packages\django\db\utils.py", line 91, in __exit__
    raise dj_exc_value.with_traceback(traceback) from exc_value
  File "C:\Users\CPT-003\Desktop\CRM\crm_api\venv\Lib\site-packages\django\db\backends\base\base.py", line 279, in ensure_connection
    self.connect()
    ~~~~~~~~~~~~^^
  File "C:\Users\CPT-003\Desktop\CRM\crm_api\venv\Lib\site-packages\django\utils\asyncio.py", line 26, in inner
    return func(*args, **kwargs)
  File "C:\Users\CPT-003\Desktop\CRM\crm_api\venv\Lib\site-packages\django\db\backends\base\base.py", line 256, in connect
    self.connection = self.get_new_connection(conn_params)
                      ~~~~~~~~~~~~~~~~~~~~~~~^^^^^^^^^^^^^
  File "C:\Users\CPT-003\Desktop\CRM\crm_api\venv\Lib\site-packages\django\utils\asyncio.py", line 26, in inner
    return func(*args, **kwargs)
  File "C:\Users\CPT-003\Desktop\CRM\crm_api\venv\Lib\site-packages\django\db\backends\postgresql\base.py", line 332, in get_new_connection
    connection = self.Database.connect(**conn_params)
  File "C:\Users\CPT-003\Desktop\CRM\crm_api\venv\Lib\site-packages\psycopg2\__init__.py", line 135, in connect
    conn = _connect(dsn, connection_factory=connection_factory, **kwasync)
django.db.utils.OperationalError: could not translate host name "dpg-d208jbje5dus73d4h87g-a.oregon-postgres.render.com" to address: Name or service not known

2025-07-23 21:46:39,040 [ERROR] django.server: "GET /api/talent-engine/requisitions/ HTTP/1.1" 500 145
